[2025-09-08T14:57:32.448+0530] {local_task_job_runner.py:120} INFO - ::group::Pre task execution logs
[2025-09-08T14:57:32.460+0530] {taskinstance.py:2076} INFO - Dependencies all met for dep_context=non-requeueable deps ti=<TaskInstance: synth_stream_5min.run_synth_stream scheduled__2025-09-08T09:20:00+00:00 [queued]>
[2025-09-08T14:57:32.463+0530] {taskinstance.py:2076} INFO - Dependencies all met for dep_context=requeueable deps ti=<TaskInstance: synth_stream_5min.run_synth_stream scheduled__2025-09-08T09:20:00+00:00 [queued]>
[2025-09-08T14:57:32.463+0530] {taskinstance.py:2306} INFO - Starting attempt 1 of 2
[2025-09-08T14:57:32.637+0530] {taskinstance.py:2330} INFO - Executing <Task(BashOperator): run_synth_stream> on 2025-09-08 09:20:00+00:00
[2025-09-08T14:57:32.644+0530] {standard_task_runner.py:64} INFO - Started process 737628 to run task
[2025-09-08T14:57:32.646+0530] {standard_task_runner.py:90} INFO - Running: ['airflow', 'tasks', 'run', 'synth_stream_5min', 'run_synth_stream', 'scheduled__2025-09-08T09:20:00+00:00', '--job-id', '53', '--raw', '--subdir', 'DAGS_FOLDER/ecom_schedules.py', '--cfg-path', '/tmp/tmpmcz9b4ff']
[2025-09-08T14:57:32.646+0530] {standard_task_runner.py:91} INFO - Job 53: Subtask run_synth_stream
[2025-09-08T14:57:32.872+0530] {task_command.py:426} INFO - Running <TaskInstance: synth_stream_5min.run_synth_stream scheduled__2025-09-08T09:20:00+00:00 [running]> on host softsuave-ASUS-EXPERTCENTER-D700ME-D500ME
[2025-09-08T14:57:33.199+0530] {taskinstance.py:2648} INFO - Exporting env vars: AIRFLOW_CTX_DAG_OWNER='airflow' AIRFLOW_CTX_DAG_ID='synth_stream_5min' AIRFLOW_CTX_TASK_ID='run_synth_stream' AIRFLOW_CTX_EXECUTION_DATE='2025-09-08T09:20:00+00:00' AIRFLOW_CTX_TRY_NUMBER='1' AIRFLOW_CTX_DAG_RUN_ID='scheduled__2025-09-08T09:20:00+00:00'
[2025-09-08T14:57:33.201+0530] {taskinstance.py:430} INFO - ::endgroup::
[2025-09-08T14:57:33.201+0530] {subprocess.py:63} INFO - Tmp dir root location: /tmp
[2025-09-08T14:57:33.202+0530] {subprocess.py:75} INFO - Running command: ['/usr/bin/bash', '-c', 'bash /media/softsuave/DATA-HDD/DataEngineering/Apache_Airflow/scripts/synth/run_synth_stream.sh | cat']
[2025-09-08T14:57:33.210+0530] {subprocess.py:86} INFO - Output:
[2025-09-08T14:57:33.240+0530] {subprocess.py:93} INFO - [2025-09-08 14:57:33] üöÄ Starting Synthetic E-commerce Data Stream...
[2025-09-08T14:57:33.240+0530] {subprocess.py:93} INFO - ----------------------------------------------
[2025-09-08T14:57:33.240+0530] {subprocess.py:93} INFO -  Database   : ecom_db
[2025-09-08T14:57:33.241+0530] {subprocess.py:93} INFO -  User       : sa
[2025-09-08T14:57:33.241+0530] {subprocess.py:93} INFO -  Server     : localhost:1433
[2025-09-08T14:57:33.241+0530] {subprocess.py:93} INFO -  Interval   : 5 min
[2025-09-08T14:57:33.241+0530] {subprocess.py:93} INFO -  Orders     : 50
[2025-09-08T14:57:33.241+0530] {subprocess.py:93} INFO -  Clicks     : 100
[2025-09-08T14:57:33.241+0530] {subprocess.py:93} INFO -  Webhook    : http://localhost:5000/webhook
[2025-09-08T14:57:33.241+0530] {subprocess.py:93} INFO - ----------------------------------------------
[2025-09-08T14:57:33.241+0530] {subprocess.py:93} INFO - 
[2025-09-08T14:57:33.265+0530] {subprocess.py:93} INFO - [2025-09-08 14:57:33] üîß Activating virtual environment...
[2025-09-08T14:57:33.268+0530] {subprocess.py:93} INFO - [2025-09-08 14:57:33] üîç Checking database connection...
[2025-09-08T14:57:33.303+0530] {subprocess.py:93} INFO - ‚úÖ Database connection successful
[2025-09-08T14:57:33.309+0530] {subprocess.py:93} INFO - [2025-09-08 14:57:33] üîÑ Starting synthetic data stream...
[2025-09-08T14:57:33.309+0530] {subprocess.py:93} INFO - Press Ctrl+C to stop
[2025-09-08T14:57:33.310+0530] {subprocess.py:93} INFO - 
[2025-09-08T14:57:33.486+0530] {subprocess.py:93} INFO - 2025-09-08 14:57:33,486 INFO: Tables ensured/created (if needed).
[2025-09-08T14:57:33.500+0530] {subprocess.py:93} INFO - 2025-09-08 14:57:33,500 INFO: Customers: 1000 already present; skipping seeding.
[2025-09-08T14:57:33.502+0530] {subprocess.py:93} INFO - 2025-09-08 14:57:33,502 INFO: Products: 500 already present; skipping seeding.
[2025-09-08T14:57:33.502+0530] {subprocess.py:93} INFO - 2025-09-08 14:57:33,502 INFO: Running one-shot generation: orders=5000, sessions=3000
[2025-09-08T14:57:33.517+0530] {subprocess.py:93} INFO - /media/softsuave/DATA-HDD/DataEngineering/Apache_Airflow/src/synth_ecom_mssql_stream.py:397: RemovedIn20Warning: Deprecated API features detected! These feature(s) are not compatible with SQLAlchemy 2.0. To prevent incompatible upgrades prior to updating applications, ensure requirements files are pinned to "sqlalchemy<2.0". Set environment variable SQLALCHEMY_WARN_20=1 to show all deprecation warnings.  Set environment variable SQLALCHEMY_SILENCE_UBER_WARNING=1 to silence this message. (Background on SQLAlchemy 2.0 at: https://sqlalche.me/e/b8d9)
[2025-09-08T14:57:33.517+0530] {subprocess.py:93} INFO -   customers = [dict(r) for r in conn.execute(select(self.tables["customers"])).fetchall()]
[2025-09-08T14:57:33.530+0530] {subprocess.py:93} INFO - 2025-09-08 14:57:33,530 INFO: Generating 5000 orders (batch_size=200, force_order_date_now=False)...
[2025-09-08T14:57:34.223+0530] {subprocess.py:93} INFO - 2025-09-08 14:57:34,223 INFO: Flushed batch: orders=200 items=327
[2025-09-08T14:57:34.229+0530] {subprocess.py:93} INFO - 2025-09-08 14:57:34,229 WARNING: Failed to send webhook notification: HTTPConnectionPool(host='localhost', port=5000): Max retries exceeded with url: /webhook (Caused by NewConnectionError('<urllib3.connection.HTTPConnection object at 0x7c7398d00a60>: Failed to establish a new connection: [Errno 111] Connection refused'))
[2025-09-08T14:57:34.926+0530] {subprocess.py:93} INFO - 2025-09-08 14:57:34,926 INFO: Flushed batch: orders=200 items=341
[2025-09-08T14:57:34.929+0530] {subprocess.py:93} INFO - 2025-09-08 14:57:34,929 WARNING: Failed to send webhook notification: HTTPConnectionPool(host='localhost', port=5000): Max retries exceeded with url: /webhook (Caused by NewConnectionError('<urllib3.connection.HTTPConnection object at 0x7c7398d7e770>: Failed to establish a new connection: [Errno 111] Connection refused'))
[2025-09-08T14:57:35.880+0530] {subprocess.py:93} INFO - 2025-09-08 14:57:35,879 INFO: Flushed batch: orders=200 items=379
[2025-09-08T14:57:35.883+0530] {subprocess.py:93} INFO - 2025-09-08 14:57:35,883 WARNING: Failed to send webhook notification: HTTPConnectionPool(host='localhost', port=5000): Max retries exceeded with url: /webhook (Caused by NewConnectionError('<urllib3.connection.HTTPConnection object at 0x7c7398cc9390>: Failed to establish a new connection: [Errno 111] Connection refused'))
[2025-09-08T14:57:36.339+0530] {subprocess.py:93} INFO - 2025-09-08 14:57:36,339 INFO: Flushed batch: orders=200 items=331
[2025-09-08T14:57:36.342+0530] {subprocess.py:93} INFO - 2025-09-08 14:57:36,342 WARNING: Failed to send webhook notification: HTTPConnectionPool(host='localhost', port=5000): Max retries exceeded with url: /webhook (Caused by NewConnectionError('<urllib3.connection.HTTPConnection object at 0x7c7398cc94b0>: Failed to establish a new connection: [Errno 111] Connection refused'))
[2025-09-08T14:57:36.698+0530] {subprocess.py:93} INFO - 2025-09-08 14:57:36,698 INFO: Flushed batch: orders=200 items=350
[2025-09-08T14:57:36.701+0530] {subprocess.py:93} INFO - 2025-09-08 14:57:36,701 WARNING: Failed to send webhook notification: HTTPConnectionPool(host='localhost', port=5000): Max retries exceeded with url: /webhook (Caused by NewConnectionError('<urllib3.connection.HTTPConnection object at 0x7c7398cd6920>: Failed to establish a new connection: [Errno 111] Connection refused'))
[2025-09-08T14:57:37.372+0530] {subprocess.py:93} INFO - 2025-09-08 14:57:37,372 INFO: Flushed batch: orders=200 items=336
[2025-09-08T14:57:37.374+0530] {subprocess.py:93} INFO - 2025-09-08 14:57:37,374 WARNING: Failed to send webhook notification: HTTPConnectionPool(host='localhost', port=5000): Max retries exceeded with url: /webhook (Caused by NewConnectionError('<urllib3.connection.HTTPConnection object at 0x7c73993fc250>: Failed to establish a new connection: [Errno 111] Connection refused'))
[2025-09-08T14:57:38.023+0530] {subprocess.py:93} INFO - 2025-09-08 14:57:38,023 INFO: Flushed batch: orders=200 items=343
[2025-09-08T14:57:38.026+0530] {subprocess.py:93} INFO - 2025-09-08 14:57:38,026 WARNING: Failed to send webhook notification: HTTPConnectionPool(host='localhost', port=5000): Max retries exceeded with url: /webhook (Caused by NewConnectionError('<urllib3.connection.HTTPConnection object at 0x7c7398cdc700>: Failed to establish a new connection: [Errno 111] Connection refused'))
[2025-09-08T14:57:39.190+0530] {subprocess.py:93} INFO - 2025-09-08 14:57:39,190 INFO: Flushed batch: orders=200 items=366
[2025-09-08T14:57:39.191+0530] {subprocess.py:93} INFO - 2025-09-08 14:57:39,191 WARNING: Failed to send webhook notification: HTTPConnectionPool(host='localhost', port=5000): Max retries exceeded with url: /webhook (Caused by NewConnectionError('<urllib3.connection.HTTPConnection object at 0x7c73993fc790>: Failed to establish a new connection: [Errno 111] Connection refused'))
[2025-09-08T14:57:39.642+0530] {subprocess.py:93} INFO - 2025-09-08 14:57:39,641 INFO: Flushed batch: orders=200 items=336
[2025-09-08T14:57:39.644+0530] {subprocess.py:93} INFO - 2025-09-08 14:57:39,644 WARNING: Failed to send webhook notification: HTTPConnectionPool(host='localhost', port=5000): Max retries exceeded with url: /webhook (Caused by NewConnectionError('<urllib3.connection.HTTPConnection object at 0x7c7398cf3cd0>: Failed to establish a new connection: [Errno 111] Connection refused'))
[2025-09-08T14:57:40.201+0530] {subprocess.py:93} INFO - 2025-09-08 14:57:40,201 INFO: Flushed batch: orders=200 items=323
[2025-09-08T14:57:40.204+0530] {subprocess.py:93} INFO - 2025-09-08 14:57:40,204 WARNING: Failed to send webhook notification: HTTPConnectionPool(host='localhost', port=5000): Max retries exceeded with url: /webhook (Caused by NewConnectionError('<urllib3.connection.HTTPConnection object at 0x7c73993349d0>: Failed to establish a new connection: [Errno 111] Connection refused'))
[2025-09-08T14:57:40.618+0530] {subprocess.py:93} INFO - 2025-09-08 14:57:40,618 INFO: Flushed batch: orders=200 items=334
[2025-09-08T14:57:40.621+0530] {subprocess.py:93} INFO - 2025-09-08 14:57:40,621 WARNING: Failed to send webhook notification: HTTPConnectionPool(host='localhost', port=5000): Max retries exceeded with url: /webhook (Caused by NewConnectionError('<urllib3.connection.HTTPConnection object at 0x7c7398b09e10>: Failed to establish a new connection: [Errno 111] Connection refused'))
[2025-09-08T14:57:41.254+0530] {subprocess.py:93} INFO - 2025-09-08 14:57:41,253 INFO: Flushed batch: orders=200 items=352
[2025-09-08T14:57:41.256+0530] {subprocess.py:93} INFO - 2025-09-08 14:57:41,256 WARNING: Failed to send webhook notification: HTTPConnectionPool(host='localhost', port=5000): Max retries exceeded with url: /webhook (Caused by NewConnectionError('<urllib3.connection.HTTPConnection object at 0x7c7398cf0670>: Failed to establish a new connection: [Errno 111] Connection refused'))
[2025-09-08T14:57:41.811+0530] {subprocess.py:93} INFO - 2025-09-08 14:57:41,810 INFO: Flushed batch: orders=200 items=316
[2025-09-08T14:57:41.814+0530] {subprocess.py:93} INFO - 2025-09-08 14:57:41,813 WARNING: Failed to send webhook notification: HTTPConnectionPool(host='localhost', port=5000): Max retries exceeded with url: /webhook (Caused by NewConnectionError('<urllib3.connection.HTTPConnection object at 0x7c73993ff790>: Failed to establish a new connection: [Errno 111] Connection refused'))
[2025-09-08T14:57:42.230+0530] {subprocess.py:93} INFO - 2025-09-08 14:57:42,230 INFO: Flushed batch: orders=200 items=355
[2025-09-08T14:57:42.233+0530] {subprocess.py:93} INFO - 2025-09-08 14:57:42,233 WARNING: Failed to send webhook notification: HTTPConnectionPool(host='localhost', port=5000): Max retries exceeded with url: /webhook (Caused by NewConnectionError('<urllib3.connection.HTTPConnection object at 0x7c7398b25ea0>: Failed to establish a new connection: [Errno 111] Connection refused'))
[2025-09-08T14:57:42.866+0530] {subprocess.py:93} INFO - 2025-09-08 14:57:42,866 INFO: Flushed batch: orders=200 items=313
[2025-09-08T14:57:42.869+0530] {subprocess.py:93} INFO - 2025-09-08 14:57:42,869 WARNING: Failed to send webhook notification: HTTPConnectionPool(host='localhost', port=5000): Max retries exceeded with url: /webhook (Caused by NewConnectionError('<urllib3.connection.HTTPConnection object at 0x7c7398b09c60>: Failed to establish a new connection: [Errno 111] Connection refused'))
[2025-09-08T14:57:43.056+0530] {subprocess.py:93} INFO - 2025-09-08 14:57:43,056 INFO: Flushed batch: orders=200 items=314
[2025-09-08T14:57:43.059+0530] {subprocess.py:93} INFO - 2025-09-08 14:57:43,059 WARNING: Failed to send webhook notification: HTTPConnectionPool(host='localhost', port=5000): Max retries exceeded with url: /webhook (Caused by NewConnectionError('<urllib3.connection.HTTPConnection object at 0x7c73993ff490>: Failed to establish a new connection: [Errno 111] Connection refused'))
[2025-09-08T14:57:44.091+0530] {subprocess.py:93} INFO - 2025-09-08 14:57:44,090 INFO: Flushed batch: orders=200 items=350
[2025-09-08T14:57:44.094+0530] {subprocess.py:93} INFO - 2025-09-08 14:57:44,093 WARNING: Failed to send webhook notification: HTTPConnectionPool(host='localhost', port=5000): Max retries exceeded with url: /webhook (Caused by NewConnectionError('<urllib3.connection.HTTPConnection object at 0x7c73993fc8b0>: Failed to establish a new connection: [Errno 111] Connection refused'))
[2025-09-08T14:57:44.709+0530] {subprocess.py:93} INFO - 2025-09-08 14:57:44,708 INFO: Flushed batch: orders=200 items=355
[2025-09-08T14:57:44.712+0530] {subprocess.py:93} INFO - 2025-09-08 14:57:44,712 WARNING: Failed to send webhook notification: HTTPConnectionPool(host='localhost', port=5000): Max retries exceeded with url: /webhook (Caused by NewConnectionError('<urllib3.connection.HTTPConnection object at 0x7c7398b08fa0>: Failed to establish a new connection: [Errno 111] Connection refused'))
[2025-09-08T14:57:45.158+0530] {subprocess.py:93} INFO - 2025-09-08 14:57:45,158 INFO: Flushed batch: orders=200 items=363
[2025-09-08T14:57:45.161+0530] {subprocess.py:93} INFO - 2025-09-08 14:57:45,161 WARNING: Failed to send webhook notification: HTTPConnectionPool(host='localhost', port=5000): Max retries exceeded with url: /webhook (Caused by NewConnectionError('<urllib3.connection.HTTPConnection object at 0x7c7398b09600>: Failed to establish a new connection: [Errno 111] Connection refused'))
[2025-09-08T14:57:45.618+0530] {subprocess.py:93} INFO - 2025-09-08 14:57:45,618 INFO: Flushed batch: orders=200 items=339
[2025-09-08T14:57:45.622+0530] {subprocess.py:93} INFO - 2025-09-08 14:57:45,621 WARNING: Failed to send webhook notification: HTTPConnectionPool(host='localhost', port=5000): Max retries exceeded with url: /webhook (Caused by NewConnectionError('<urllib3.connection.HTTPConnection object at 0x7c7398b24c40>: Failed to establish a new connection: [Errno 111] Connection refused'))
[2025-09-08T14:57:46.326+0530] {subprocess.py:93} INFO - 2025-09-08 14:57:46,326 INFO: Flushed batch: orders=200 items=351
[2025-09-08T14:57:46.329+0530] {subprocess.py:93} INFO - 2025-09-08 14:57:46,329 WARNING: Failed to send webhook notification: HTTPConnectionPool(host='localhost', port=5000): Max retries exceeded with url: /webhook (Caused by NewConnectionError('<urllib3.connection.HTTPConnection object at 0x7c7398b42770>: Failed to establish a new connection: [Errno 111] Connection refused'))
[2025-09-08T14:57:46.711+0530] {subprocess.py:93} INFO - 2025-09-08 14:57:46,711 INFO: Flushed batch: orders=200 items=363
[2025-09-08T14:57:46.714+0530] {subprocess.py:93} INFO - 2025-09-08 14:57:46,714 WARNING: Failed to send webhook notification: HTTPConnectionPool(host='localhost', port=5000): Max retries exceeded with url: /webhook (Caused by NewConnectionError('<urllib3.connection.HTTPConnection object at 0x7c7398b41000>: Failed to establish a new connection: [Errno 111] Connection refused'))
[2025-09-08T14:57:47.161+0530] {subprocess.py:93} INFO - 2025-09-08 14:57:47,161 INFO: Flushed batch: orders=200 items=322
[2025-09-08T14:57:47.164+0530] {subprocess.py:93} INFO - 2025-09-08 14:57:47,164 WARNING: Failed to send webhook notification: HTTPConnectionPool(host='localhost', port=5000): Max retries exceeded with url: /webhook (Caused by NewConnectionError('<urllib3.connection.HTTPConnection object at 0x7c73993fc700>: Failed to establish a new connection: [Errno 111] Connection refused'))
[2025-09-08T14:57:47.680+0530] {subprocess.py:93} INFO - 2025-09-08 14:57:47,679 INFO: Flushed batch: orders=200 items=388
[2025-09-08T14:57:47.683+0530] {subprocess.py:93} INFO - 2025-09-08 14:57:47,683 WARNING: Failed to send webhook notification: HTTPConnectionPool(host='localhost', port=5000): Max retries exceeded with url: /webhook (Caused by NewConnectionError('<urllib3.connection.HTTPConnection object at 0x7c7398cdca60>: Failed to establish a new connection: [Errno 111] Connection refused'))
[2025-09-08T14:57:48.080+0530] {subprocess.py:93} INFO - 2025-09-08 14:57:48,080 INFO: Flushed batch: orders=200 items=340
[2025-09-08T14:57:48.084+0530] {subprocess.py:93} INFO - 2025-09-08 14:57:48,084 WARNING: Failed to send webhook notification: HTTPConnectionPool(host='localhost', port=5000): Max retries exceeded with url: /webhook (Caused by NewConnectionError('<urllib3.connection.HTTPConnection object at 0x7c7398b417e0>: Failed to establish a new connection: [Errno 111] Connection refused'))
[2025-09-08T14:57:48.084+0530] {subprocess.py:93} INFO - 2025-09-08 14:57:48,084 INFO: Generated 5000 orders
[2025-09-08T14:58:38.117+0530] {subprocess.py:93} INFO - 2025-09-08 14:58:38,117 INFO: Inserted 47928 clickstream events.
[2025-09-08T14:58:38.118+0530] {subprocess.py:93} INFO - 2025-09-08 14:58:38,118 WARNING: Failed to send webhook notification: HTTPConnectionPool(host='localhost', port=5000): Max retries exceeded with url: /webhook (Caused by NewConnectionError('<urllib3.connection.HTTPConnection object at 0x7c739799df60>: Failed to establish a new connection: [Errno 111] Connection refused'))
[2025-09-08T14:58:40.535+0530] {subprocess.py:93} INFO - 2025-09-08 14:58:40,535 INFO: Validation done: orphans orders=0 items=0 inventory=0 mismatches=0
[2025-09-08T14:58:40.550+0530] {subprocess.py:93} INFO - 2025-09-08 14:58:40,550 INFO: Integrity report: {'orphan_orders': 0, 'orphan_order_items': 0, 'inventory_orphans': 0, 'order_amount_mismatches': []}
[2025-09-08T14:58:40.580+0530] {subprocess.py:93} INFO - [2025-09-08 14:58:40] ‚úÖ Synthetic data streaming completed successfully!
[2025-09-08T14:58:40.580+0530] {subprocess.py:97} INFO - Command exited with return code 0
[2025-09-08T14:58:40.581+0530] {taskinstance.py:441} INFO - ::group::Post task execution logs
[2025-09-08T14:58:41.280+0530] {taskinstance.py:1206} INFO - Marking task as SUCCESS. dag_id=synth_stream_5min, task_id=run_synth_stream, run_id=scheduled__2025-09-08T09:20:00+00:00, execution_date=20250908T092000, start_date=20250908T092732, end_date=20250908T092841
[2025-09-08T14:58:41.760+0530] {local_task_job_runner.py:243} INFO - Task exited with return code 0
[2025-09-08T14:58:41.775+0530] {taskinstance.py:3503} INFO - 0 downstream tasks scheduled from follow-on schedule check
[2025-09-08T14:58:41.776+0530] {local_task_job_runner.py:222} INFO - ::endgroup::
