[2025-09-08T13:35:03.697+0530] {local_task_job_runner.py:120} INFO - ::group::Pre task execution logs
[2025-09-08T13:35:03.709+0530] {taskinstance.py:2076} INFO - Dependencies all met for dep_context=non-requeueable deps ti=<TaskInstance: synth_stream_5min.run_synth_stream scheduled__2025-09-08T08:00:00+00:00 [queued]>
[2025-09-08T13:35:03.712+0530] {taskinstance.py:2076} INFO - Dependencies all met for dep_context=requeueable deps ti=<TaskInstance: synth_stream_5min.run_synth_stream scheduled__2025-09-08T08:00:00+00:00 [queued]>
[2025-09-08T13:35:03.712+0530] {taskinstance.py:2306} INFO - Starting attempt 1 of 2
[2025-09-08T13:35:03.783+0530] {taskinstance.py:2330} INFO - Executing <Task(BashOperator): run_synth_stream> on 2025-09-08 08:00:00+00:00
[2025-09-08T13:35:03.790+0530] {standard_task_runner.py:64} INFO - Started process 717772 to run task
[2025-09-08T13:35:03.796+0530] {standard_task_runner.py:90} INFO - Running: ['airflow', 'tasks', 'run', 'synth_stream_5min', 'run_synth_stream', 'scheduled__2025-09-08T08:00:00+00:00', '--job-id', '30', '--raw', '--subdir', 'DAGS_FOLDER/ecom_schedules.py', '--cfg-path', '/tmp/tmp68ub3lpc']
[2025-09-08T13:35:03.799+0530] {standard_task_runner.py:91} INFO - Job 30: Subtask run_synth_stream
[2025-09-08T13:35:03.876+0530] {task_command.py:426} INFO - Running <TaskInstance: synth_stream_5min.run_synth_stream scheduled__2025-09-08T08:00:00+00:00 [running]> on host softsuave-ASUS-EXPERTCENTER-D700ME-D500ME
[2025-09-08T13:35:04.038+0530] {taskinstance.py:2648} INFO - Exporting env vars: AIRFLOW_CTX_DAG_OWNER='airflow' AIRFLOW_CTX_DAG_ID='synth_stream_5min' AIRFLOW_CTX_TASK_ID='run_synth_stream' AIRFLOW_CTX_EXECUTION_DATE='2025-09-08T08:00:00+00:00' AIRFLOW_CTX_TRY_NUMBER='1' AIRFLOW_CTX_DAG_RUN_ID='scheduled__2025-09-08T08:00:00+00:00'
[2025-09-08T13:35:04.039+0530] {taskinstance.py:430} INFO - ::endgroup::
[2025-09-08T13:35:04.040+0530] {subprocess.py:63} INFO - Tmp dir root location: /tmp
[2025-09-08T13:35:04.040+0530] {subprocess.py:75} INFO - Running command: ['/usr/bin/bash', '-c', 'bash /media/softsuave/DATA-HDD/DataEngineering/Apache_Airflow/scripts/synth/run_synth_stream.sh | cat']
[2025-09-08T13:35:04.047+0530] {subprocess.py:86} INFO - Output:
[2025-09-08T13:35:04.076+0530] {subprocess.py:93} INFO - [2025-09-08 13:35:04] üöÄ Starting Synthetic E-commerce Data Stream...
[2025-09-08T13:35:04.076+0530] {subprocess.py:93} INFO - ----------------------------------------------
[2025-09-08T13:35:04.076+0530] {subprocess.py:93} INFO -  Database   : ecom_db
[2025-09-08T13:35:04.076+0530] {subprocess.py:93} INFO -  User       : sa
[2025-09-08T13:35:04.076+0530] {subprocess.py:93} INFO -  Server     : localhost:1433
[2025-09-08T13:35:04.076+0530] {subprocess.py:93} INFO -  Interval   : 5 min
[2025-09-08T13:35:04.076+0530] {subprocess.py:93} INFO -  Orders     : 50
[2025-09-08T13:35:04.077+0530] {subprocess.py:93} INFO -  Clicks     : 100
[2025-09-08T13:35:04.077+0530] {subprocess.py:93} INFO -  Webhook    : http://localhost:5000/webhook
[2025-09-08T13:35:04.077+0530] {subprocess.py:93} INFO - ----------------------------------------------
[2025-09-08T13:35:04.077+0530] {subprocess.py:93} INFO - 
[2025-09-08T13:35:04.104+0530] {subprocess.py:93} INFO - [2025-09-08 13:35:04] üîß Activating virtual environment...
[2025-09-08T13:35:04.108+0530] {subprocess.py:93} INFO - [2025-09-08 13:35:04] üîç Checking database connection...
[2025-09-08T13:35:04.144+0530] {subprocess.py:93} INFO - ‚úÖ Database connection successful
[2025-09-08T13:35:04.156+0530] {subprocess.py:93} INFO - [2025-09-08 13:35:04] üîÑ Starting synthetic data stream...
[2025-09-08T13:35:04.156+0530] {subprocess.py:93} INFO - Press Ctrl+C to stop
[2025-09-08T13:35:04.157+0530] {subprocess.py:93} INFO - 
[2025-09-08T13:35:04.335+0530] {subprocess.py:93} INFO - 2025-09-08 13:35:04,334 INFO: Tables ensured/created (if needed).
[2025-09-08T13:35:04.347+0530] {subprocess.py:93} INFO - 2025-09-08 13:35:04,347 INFO: Customers: 1000 already present; skipping seeding.
[2025-09-08T13:35:04.348+0530] {subprocess.py:93} INFO - 2025-09-08 13:35:04,348 INFO: Products: 500 already present; skipping seeding.
[2025-09-08T13:35:04.348+0530] {subprocess.py:93} INFO - 2025-09-08 13:35:04,348 INFO: Running one-shot generation: orders=5000, sessions=3000
[2025-09-08T13:35:04.354+0530] {subprocess.py:93} INFO - /media/softsuave/DATA-HDD/DataEngineering/Apache_Airflow/src/synth_ecom_mssql_stream.py:397: RemovedIn20Warning: Deprecated API features detected! These feature(s) are not compatible with SQLAlchemy 2.0. To prevent incompatible upgrades prior to updating applications, ensure requirements files are pinned to "sqlalchemy<2.0". Set environment variable SQLALCHEMY_WARN_20=1 to show all deprecation warnings.  Set environment variable SQLALCHEMY_SILENCE_UBER_WARNING=1 to silence this message. (Background on SQLAlchemy 2.0 at: https://sqlalche.me/e/b8d9)
[2025-09-08T13:35:04.354+0530] {subprocess.py:93} INFO -   customers = [dict(r) for r in conn.execute(select(self.tables["customers"])).fetchall()]
[2025-09-08T13:35:04.361+0530] {subprocess.py:93} INFO - 2025-09-08 13:35:04,361 INFO: Generating 5000 orders (batch_size=200, force_order_date_now=False)...
[2025-09-08T13:35:04.569+0530] {subprocess.py:93} INFO - 2025-09-08 13:35:04,568 INFO: Flushed batch: orders=200 items=329
[2025-09-08T13:35:04.574+0530] {subprocess.py:93} INFO - 2025-09-08 13:35:04,574 WARNING: Failed to send webhook notification: HTTPConnectionPool(host='localhost', port=5000): Max retries exceeded with url: /webhook (Caused by NewConnectionError('<urllib3.connection.HTTPConnection object at 0x7775c55ca710>: Failed to establish a new connection: [Errno 111] Connection refused'))
[2025-09-08T13:35:05.045+0530] {subprocess.py:93} INFO - 2025-09-08 13:35:05,045 INFO: Flushed batch: orders=200 items=344
[2025-09-08T13:35:05.046+0530] {subprocess.py:93} INFO - 2025-09-08 13:35:05,046 WARNING: Failed to send webhook notification: HTTPConnectionPool(host='localhost', port=5000): Max retries exceeded with url: /webhook (Caused by NewConnectionError('<urllib3.connection.HTTPConnection object at 0x7775c4e90a30>: Failed to establish a new connection: [Errno 111] Connection refused'))
[2025-09-08T13:35:05.261+0530] {subprocess.py:93} INFO - 2025-09-08 13:35:05,261 INFO: Flushed batch: orders=200 items=353
[2025-09-08T13:35:05.264+0530] {subprocess.py:93} INFO - 2025-09-08 13:35:05,264 WARNING: Failed to send webhook notification: HTTPConnectionPool(host='localhost', port=5000): Max retries exceeded with url: /webhook (Caused by NewConnectionError('<urllib3.connection.HTTPConnection object at 0x7775c4ef67d0>: Failed to establish a new connection: [Errno 111] Connection refused'))
[2025-09-08T13:35:05.428+0530] {subprocess.py:93} INFO - 2025-09-08 13:35:05,428 INFO: Flushed batch: orders=200 items=310
[2025-09-08T13:35:05.430+0530] {subprocess.py:93} INFO - 2025-09-08 13:35:05,430 WARNING: Failed to send webhook notification: HTTPConnectionPool(host='localhost', port=5000): Max retries exceeded with url: /webhook (Caused by NewConnectionError('<urllib3.connection.HTTPConnection object at 0x7775c4edf9d0>: Failed to establish a new connection: [Errno 111] Connection refused'))
[2025-09-08T13:35:05.603+0530] {subprocess.py:93} INFO - 2025-09-08 13:35:05,603 INFO: Flushed batch: orders=200 items=321
[2025-09-08T13:35:05.605+0530] {subprocess.py:93} INFO - 2025-09-08 13:35:05,605 WARNING: Failed to send webhook notification: HTTPConnectionPool(host='localhost', port=5000): Max retries exceeded with url: /webhook (Caused by NewConnectionError('<urllib3.connection.HTTPConnection object at 0x7775c4d0ac80>: Failed to establish a new connection: [Errno 111] Connection refused'))
[2025-09-08T13:35:05.846+0530] {subprocess.py:93} INFO - 2025-09-08 13:35:05,846 INFO: Flushed batch: orders=200 items=345
[2025-09-08T13:35:05.850+0530] {subprocess.py:93} INFO - 2025-09-08 13:35:05,850 WARNING: Failed to send webhook notification: HTTPConnectionPool(host='localhost', port=5000): Max retries exceeded with url: /webhook (Caused by NewConnectionError('<urllib3.connection.HTTPConnection object at 0x7775c4d28cd0>: Failed to establish a new connection: [Errno 111] Connection refused'))
[2025-09-08T13:35:06.029+0530] {subprocess.py:93} INFO - 2025-09-08 13:35:06,029 INFO: Flushed batch: orders=200 items=360
[2025-09-08T13:35:06.033+0530] {subprocess.py:93} INFO - 2025-09-08 13:35:06,033 WARNING: Failed to send webhook notification: HTTPConnectionPool(host='localhost', port=5000): Max retries exceeded with url: /webhook (Caused by NewConnectionError('<urllib3.connection.HTTPConnection object at 0x7775c4ef7070>: Failed to establish a new connection: [Errno 111] Connection refused'))
[2025-09-08T13:35:06.196+0530] {subprocess.py:93} INFO - 2025-09-08 13:35:06,195 INFO: Flushed batch: orders=200 items=321
[2025-09-08T13:35:06.198+0530] {subprocess.py:93} INFO - 2025-09-08 13:35:06,198 WARNING: Failed to send webhook notification: HTTPConnectionPool(host='localhost', port=5000): Max retries exceeded with url: /webhook (Caused by NewConnectionError('<urllib3.connection.HTTPConnection object at 0x7775c4d1c280>: Failed to establish a new connection: [Errno 111] Connection refused'))
[2025-09-08T13:35:06.364+0530] {subprocess.py:93} INFO - 2025-09-08 13:35:06,364 INFO: Flushed batch: orders=200 items=351
[2025-09-08T13:35:06.366+0530] {subprocess.py:93} INFO - 2025-09-08 13:35:06,366 WARNING: Failed to send webhook notification: HTTPConnectionPool(host='localhost', port=5000): Max retries exceeded with url: /webhook (Caused by NewConnectionError('<urllib3.connection.HTTPConnection object at 0x7775c4d3ba90>: Failed to establish a new connection: [Errno 111] Connection refused'))
[2025-09-08T13:35:06.531+0530] {subprocess.py:93} INFO - 2025-09-08 13:35:06,531 INFO: Flushed batch: orders=200 items=342
[2025-09-08T13:35:06.534+0530] {subprocess.py:93} INFO - 2025-09-08 13:35:06,533 WARNING: Failed to send webhook notification: HTTPConnectionPool(host='localhost', port=5000): Max retries exceeded with url: /webhook (Caused by NewConnectionError('<urllib3.connection.HTTPConnection object at 0x7775c4d003a0>: Failed to establish a new connection: [Errno 111] Connection refused'))
[2025-09-08T13:35:06.799+0530] {subprocess.py:93} INFO - 2025-09-08 13:35:06,799 INFO: Flushed batch: orders=200 items=354
[2025-09-08T13:35:06.802+0530] {subprocess.py:93} INFO - 2025-09-08 13:35:06,802 WARNING: Failed to send webhook notification: HTTPConnectionPool(host='localhost', port=5000): Max retries exceeded with url: /webhook (Caused by NewConnectionError('<urllib3.connection.HTTPConnection object at 0x7775c4d3b880>: Failed to establish a new connection: [Errno 111] Connection refused'))
[2025-09-08T13:35:07.116+0530] {subprocess.py:93} INFO - 2025-09-08 13:35:07,116 INFO: Flushed batch: orders=200 items=347
[2025-09-08T13:35:07.119+0530] {subprocess.py:93} INFO - 2025-09-08 13:35:07,118 WARNING: Failed to send webhook notification: HTTPConnectionPool(host='localhost', port=5000): Max retries exceeded with url: /webhook (Caused by NewConnectionError('<urllib3.connection.HTTPConnection object at 0x7775c4d0b640>: Failed to establish a new connection: [Errno 111] Connection refused'))
[2025-09-08T13:35:07.290+0530] {subprocess.py:93} INFO - 2025-09-08 13:35:07,290 INFO: Flushed batch: orders=200 items=337
[2025-09-08T13:35:07.292+0530] {subprocess.py:93} INFO - 2025-09-08 13:35:07,292 WARNING: Failed to send webhook notification: HTTPConnectionPool(host='localhost', port=5000): Max retries exceeded with url: /webhook (Caused by NewConnectionError('<urllib3.connection.HTTPConnection object at 0x7775c4d38f10>: Failed to establish a new connection: [Errno 111] Connection refused'))
[2025-09-08T13:35:07.448+0530] {subprocess.py:93} INFO - 2025-09-08 13:35:07,448 INFO: Flushed batch: orders=200 items=344
[2025-09-08T13:35:07.450+0530] {subprocess.py:93} INFO - 2025-09-08 13:35:07,450 WARNING: Failed to send webhook notification: HTTPConnectionPool(host='localhost', port=5000): Max retries exceeded with url: /webhook (Caused by NewConnectionError('<urllib3.connection.HTTPConnection object at 0x7775c4d50e80>: Failed to establish a new connection: [Errno 111] Connection refused'))
[2025-09-08T13:35:07.632+0530] {subprocess.py:93} INFO - 2025-09-08 13:35:07,632 INFO: Flushed batch: orders=200 items=337
[2025-09-08T13:35:07.633+0530] {subprocess.py:93} INFO - 2025-09-08 13:35:07,633 WARNING: Failed to send webhook notification: HTTPConnectionPool(host='localhost', port=5000): Max retries exceeded with url: /webhook (Caused by NewConnectionError('<urllib3.connection.HTTPConnection object at 0x7775c4d09870>: Failed to establish a new connection: [Errno 111] Connection refused'))
[2025-09-08T13:35:07.808+0530] {subprocess.py:93} INFO - 2025-09-08 13:35:07,807 INFO: Flushed batch: orders=200 items=357
[2025-09-08T13:35:07.808+0530] {subprocess.py:93} INFO - 2025-09-08 13:35:07,808 WARNING: Failed to send webhook notification: HTTPConnectionPool(host='localhost', port=5000): Max retries exceeded with url: /webhook (Caused by NewConnectionError('<urllib3.connection.HTTPConnection object at 0x7775c4d09d50>: Failed to establish a new connection: [Errno 111] Connection refused'))
[2025-09-08T13:35:07.983+0530] {subprocess.py:93} INFO - 2025-09-08 13:35:07,982 INFO: Flushed batch: orders=200 items=349
[2025-09-08T13:35:07.984+0530] {subprocess.py:93} INFO - 2025-09-08 13:35:07,983 WARNING: Failed to send webhook notification: HTTPConnectionPool(host='localhost', port=5000): Max retries exceeded with url: /webhook (Caused by NewConnectionError('<urllib3.connection.HTTPConnection object at 0x7775c4d1cc10>: Failed to establish a new connection: [Errno 111] Connection refused'))
[2025-09-08T13:35:08.175+0530] {subprocess.py:93} INFO - 2025-09-08 13:35:08,175 INFO: Flushed batch: orders=200 items=360
[2025-09-08T13:35:08.176+0530] {subprocess.py:93} INFO - 2025-09-08 13:35:08,176 WARNING: Failed to send webhook notification: HTTPConnectionPool(host='localhost', port=5000): Max retries exceeded with url: /webhook (Caused by NewConnectionError('<urllib3.connection.HTTPConnection object at 0x7775c4d3b9d0>: Failed to establish a new connection: [Errno 111] Connection refused'))
[2025-09-08T13:35:08.367+0530] {subprocess.py:93} INFO - 2025-09-08 13:35:08,366 INFO: Flushed batch: orders=200 items=355
[2025-09-08T13:35:08.369+0530] {subprocess.py:93} INFO - 2025-09-08 13:35:08,368 WARNING: Failed to send webhook notification: HTTPConnectionPool(host='localhost', port=5000): Max retries exceeded with url: /webhook (Caused by NewConnectionError('<urllib3.connection.HTTPConnection object at 0x7775c4d3f790>: Failed to establish a new connection: [Errno 111] Connection refused'))
[2025-09-08T13:35:08.550+0530] {subprocess.py:93} INFO - 2025-09-08 13:35:08,550 INFO: Flushed batch: orders=200 items=334
[2025-09-08T13:35:08.554+0530] {subprocess.py:93} INFO - 2025-09-08 13:35:08,554 WARNING: Failed to send webhook notification: HTTPConnectionPool(host='localhost', port=5000): Max retries exceeded with url: /webhook (Caused by NewConnectionError('<urllib3.connection.HTTPConnection object at 0x7775c4d539d0>: Failed to establish a new connection: [Errno 111] Connection refused'))
[2025-09-08T13:35:08.742+0530] {subprocess.py:93} INFO - 2025-09-08 13:35:08,742 INFO: Flushed batch: orders=200 items=351
[2025-09-08T13:35:08.745+0530] {subprocess.py:93} INFO - 2025-09-08 13:35:08,745 WARNING: Failed to send webhook notification: HTTPConnectionPool(host='localhost', port=5000): Max retries exceeded with url: /webhook (Caused by NewConnectionError('<urllib3.connection.HTTPConnection object at 0x7775c4d50790>: Failed to establish a new connection: [Errno 111] Connection refused'))
[2025-09-08T13:35:09.135+0530] {subprocess.py:93} INFO - 2025-09-08 13:35:09,134 INFO: Flushed batch: orders=200 items=377
[2025-09-08T13:35:09.137+0530] {subprocess.py:93} INFO - 2025-09-08 13:35:09,137 WARNING: Failed to send webhook notification: HTTPConnectionPool(host='localhost', port=5000): Max retries exceeded with url: /webhook (Caused by NewConnectionError('<urllib3.connection.HTTPConnection object at 0x7775c4d50c10>: Failed to establish a new connection: [Errno 111] Connection refused'))
[2025-09-08T13:35:09.317+0530] {subprocess.py:93} INFO - 2025-09-08 13:35:09,317 INFO: Flushed batch: orders=200 items=339
[2025-09-08T13:35:09.319+0530] {subprocess.py:93} INFO - 2025-09-08 13:35:09,318 WARNING: Failed to send webhook notification: HTTPConnectionPool(host='localhost', port=5000): Max retries exceeded with url: /webhook (Caused by NewConnectionError('<urllib3.connection.HTTPConnection object at 0x7775c4d53b20>: Failed to establish a new connection: [Errno 111] Connection refused'))
[2025-09-08T13:35:09.501+0530] {subprocess.py:93} INFO - 2025-09-08 13:35:09,501 INFO: Flushed batch: orders=200 items=327
[2025-09-08T13:35:09.502+0530] {subprocess.py:93} INFO - 2025-09-08 13:35:09,502 WARNING: Failed to send webhook notification: HTTPConnectionPool(host='localhost', port=5000): Max retries exceeded with url: /webhook (Caused by NewConnectionError('<urllib3.connection.HTTPConnection object at 0x7775c4d1d6f0>: Failed to establish a new connection: [Errno 111] Connection refused'))
[2025-09-08T13:35:09.677+0530] {subprocess.py:93} INFO - 2025-09-08 13:35:09,677 INFO: Flushed batch: orders=200 items=333
[2025-09-08T13:35:09.679+0530] {subprocess.py:93} INFO - 2025-09-08 13:35:09,679 WARNING: Failed to send webhook notification: HTTPConnectionPool(host='localhost', port=5000): Max retries exceeded with url: /webhook (Caused by NewConnectionError('<urllib3.connection.HTTPConnection object at 0x7775c4ef7eb0>: Failed to establish a new connection: [Errno 111] Connection refused'))
[2025-09-08T13:35:09.680+0530] {subprocess.py:93} INFO - 2025-09-08 13:35:09,680 INFO: Generated 5000 orders
[2025-09-08T13:35:32.199+0530] {subprocess.py:93} INFO - 2025-09-08 13:35:32,199 INFO: Inserted 47898 clickstream events.
[2025-09-08T13:35:32.200+0530] {subprocess.py:93} INFO - 2025-09-08 13:35:32,200 WARNING: Failed to send webhook notification: HTTPConnectionPool(host='localhost', port=5000): Max retries exceeded with url: /webhook (Caused by NewConnectionError('<urllib3.connection.HTTPConnection object at 0x7775c3bc5cc0>: Failed to establish a new connection: [Errno 111] Connection refused'))
[2025-09-08T13:35:32.814+0530] {subprocess.py:93} INFO - 2025-09-08 13:35:32,814 INFO: Validation done: orphans orders=0 items=0 inventory=0 mismatches=0
[2025-09-08T13:35:32.819+0530] {subprocess.py:93} INFO - 2025-09-08 13:35:32,819 INFO: Integrity report: {'orphan_orders': 0, 'orphan_order_items': 0, 'inventory_orphans': 0, 'order_amount_mismatches': []}
[2025-09-08T13:35:32.847+0530] {subprocess.py:93} INFO - [2025-09-08 13:35:32] ‚úÖ Synthetic data streaming completed successfully!
[2025-09-08T13:35:32.848+0530] {subprocess.py:97} INFO - Command exited with return code 0
[2025-09-08T13:35:32.848+0530] {taskinstance.py:441} INFO - ::group::Post task execution logs
[2025-09-08T13:35:33.090+0530] {taskinstance.py:1206} INFO - Marking task as SUCCESS. dag_id=synth_stream_5min, task_id=run_synth_stream, run_id=scheduled__2025-09-08T08:00:00+00:00, execution_date=20250908T080000, start_date=20250908T080503, end_date=20250908T080533
[2025-09-08T13:35:33.389+0530] {local_task_job_runner.py:243} INFO - Task exited with return code 0
[2025-09-08T13:35:33.398+0530] {taskinstance.py:3503} INFO - 0 downstream tasks scheduled from follow-on schedule check
[2025-09-08T13:35:33.398+0530] {local_task_job_runner.py:222} INFO - ::endgroup::
