[2025-09-08T14:25:04.737+0530] {local_task_job_runner.py:120} INFO - ::group::Pre task execution logs
[2025-09-08T14:25:04.754+0530] {taskinstance.py:2076} INFO - Dependencies all met for dep_context=non-requeueable deps ti=<TaskInstance: synth_stream_5min.run_synth_stream scheduled__2025-09-08T08:50:00+00:00 [queued]>
[2025-09-08T14:25:04.757+0530] {taskinstance.py:2076} INFO - Dependencies all met for dep_context=requeueable deps ti=<TaskInstance: synth_stream_5min.run_synth_stream scheduled__2025-09-08T08:50:00+00:00 [queued]>
[2025-09-08T14:25:04.757+0530] {taskinstance.py:2306} INFO - Starting attempt 1 of 2
[2025-09-08T14:25:05.016+0530] {taskinstance.py:2330} INFO - Executing <Task(BashOperator): run_synth_stream> on 2025-09-08 08:50:00+00:00
[2025-09-08T14:25:05.024+0530] {standard_task_runner.py:64} INFO - Started process 730323 to run task
[2025-09-08T14:25:05.030+0530] {standard_task_runner.py:90} INFO - Running: ['airflow', 'tasks', 'run', 'synth_stream_5min', 'run_synth_stream', 'scheduled__2025-09-08T08:50:00+00:00', '--job-id', '45', '--raw', '--subdir', 'DAGS_FOLDER/ecom_schedules.py', '--cfg-path', '/tmp/tmp_hnzyccl']
[2025-09-08T14:25:05.031+0530] {standard_task_runner.py:91} INFO - Job 45: Subtask run_synth_stream
[2025-09-08T14:25:05.284+0530] {task_command.py:426} INFO - Running <TaskInstance: synth_stream_5min.run_synth_stream scheduled__2025-09-08T08:50:00+00:00 [running]> on host softsuave-ASUS-EXPERTCENTER-D700ME-D500ME
[2025-09-08T14:25:05.800+0530] {taskinstance.py:2648} INFO - Exporting env vars: AIRFLOW_CTX_DAG_OWNER='airflow' AIRFLOW_CTX_DAG_ID='synth_stream_5min' AIRFLOW_CTX_TASK_ID='run_synth_stream' AIRFLOW_CTX_EXECUTION_DATE='2025-09-08T08:50:00+00:00' AIRFLOW_CTX_TRY_NUMBER='1' AIRFLOW_CTX_DAG_RUN_ID='scheduled__2025-09-08T08:50:00+00:00'
[2025-09-08T14:25:05.802+0530] {taskinstance.py:430} INFO - ::endgroup::
[2025-09-08T14:25:05.803+0530] {subprocess.py:63} INFO - Tmp dir root location: /tmp
[2025-09-08T14:25:05.803+0530] {subprocess.py:75} INFO - Running command: ['/usr/bin/bash', '-c', 'bash /media/softsuave/DATA-HDD/DataEngineering/Apache_Airflow/scripts/synth/run_synth_stream.sh | cat']
[2025-09-08T14:25:05.813+0530] {subprocess.py:86} INFO - Output:
[2025-09-08T14:25:05.850+0530] {subprocess.py:93} INFO - [2025-09-08 14:25:05] üöÄ Starting Synthetic E-commerce Data Stream...
[2025-09-08T14:25:05.850+0530] {subprocess.py:93} INFO - ----------------------------------------------
[2025-09-08T14:25:05.850+0530] {subprocess.py:93} INFO -  Database   : ecom_db
[2025-09-08T14:25:05.850+0530] {subprocess.py:93} INFO -  User       : sa
[2025-09-08T14:25:05.850+0530] {subprocess.py:93} INFO -  Server     : localhost:1433
[2025-09-08T14:25:05.850+0530] {subprocess.py:93} INFO -  Interval   : 5 min
[2025-09-08T14:25:05.850+0530] {subprocess.py:93} INFO -  Orders     : 50
[2025-09-08T14:25:05.850+0530] {subprocess.py:93} INFO -  Clicks     : 100
[2025-09-08T14:25:05.851+0530] {subprocess.py:93} INFO -  Webhook    : http://localhost:5000/webhook
[2025-09-08T14:25:05.851+0530] {subprocess.py:93} INFO - ----------------------------------------------
[2025-09-08T14:25:05.851+0530] {subprocess.py:93} INFO - 
[2025-09-08T14:25:05.872+0530] {subprocess.py:93} INFO - [2025-09-08 14:25:05] üîß Activating virtual environment...
[2025-09-08T14:25:05.874+0530] {subprocess.py:93} INFO - [2025-09-08 14:25:05] üîç Checking database connection...
[2025-09-08T14:25:05.900+0530] {subprocess.py:93} INFO - ‚úÖ Database connection successful
[2025-09-08T14:25:05.905+0530] {subprocess.py:93} INFO - [2025-09-08 14:25:05] üîÑ Starting synthetic data stream...
[2025-09-08T14:25:05.905+0530] {subprocess.py:93} INFO - Press Ctrl+C to stop
[2025-09-08T14:25:05.905+0530] {subprocess.py:93} INFO - 
[2025-09-08T14:25:06.078+0530] {subprocess.py:93} INFO - 2025-09-08 14:25:06,078 INFO: Tables ensured/created (if needed).
[2025-09-08T14:25:06.090+0530] {subprocess.py:93} INFO - 2025-09-08 14:25:06,090 INFO: Customers: 1000 already present; skipping seeding.
[2025-09-08T14:25:06.091+0530] {subprocess.py:93} INFO - 2025-09-08 14:25:06,091 INFO: Products: 500 already present; skipping seeding.
[2025-09-08T14:25:06.091+0530] {subprocess.py:93} INFO - 2025-09-08 14:25:06,091 INFO: Running one-shot generation: orders=5000, sessions=3000
[2025-09-08T14:25:06.097+0530] {subprocess.py:93} INFO - /media/softsuave/DATA-HDD/DataEngineering/Apache_Airflow/src/synth_ecom_mssql_stream.py:397: RemovedIn20Warning: Deprecated API features detected! These feature(s) are not compatible with SQLAlchemy 2.0. To prevent incompatible upgrades prior to updating applications, ensure requirements files are pinned to "sqlalchemy<2.0". Set environment variable SQLALCHEMY_WARN_20=1 to show all deprecation warnings.  Set environment variable SQLALCHEMY_SILENCE_UBER_WARNING=1 to silence this message. (Background on SQLAlchemy 2.0 at: https://sqlalche.me/e/b8d9)
[2025-09-08T14:25:06.097+0530] {subprocess.py:93} INFO -   customers = [dict(r) for r in conn.execute(select(self.tables["customers"])).fetchall()]
[2025-09-08T14:25:06.104+0530] {subprocess.py:93} INFO - 2025-09-08 14:25:06,104 INFO: Generating 5000 orders (batch_size=200, force_order_date_now=False)...
[2025-09-08T14:25:06.673+0530] {subprocess.py:93} INFO - 2025-09-08 14:25:06,672 INFO: Flushed batch: orders=200 items=320
[2025-09-08T14:25:06.678+0530] {subprocess.py:93} INFO - 2025-09-08 14:25:06,677 WARNING: Failed to send webhook notification: HTTPConnectionPool(host='localhost', port=5000): Max retries exceeded with url: /webhook (Caused by NewConnectionError('<urllib3.connection.HTTPConnection object at 0x7f06802aa1d0>: Failed to establish a new connection: [Errno 111] Connection refused'))
[2025-09-08T14:25:07.345+0530] {subprocess.py:93} INFO - 2025-09-08 14:25:07,344 INFO: Flushed batch: orders=200 items=351
[2025-09-08T14:25:07.347+0530] {subprocess.py:93} INFO - 2025-09-08 14:25:07,347 WARNING: Failed to send webhook notification: HTTPConnectionPool(host='localhost', port=5000): Max retries exceeded with url: /webhook (Caused by NewConnectionError('<urllib3.connection.HTTPConnection object at 0x7f0680187910>: Failed to establish a new connection: [Errno 111] Connection refused'))
[2025-09-08T14:25:07.570+0530] {subprocess.py:93} INFO - 2025-09-08 14:25:07,570 INFO: Flushed batch: orders=200 items=338
[2025-09-08T14:25:07.573+0530] {subprocess.py:93} INFO - 2025-09-08 14:25:07,573 WARNING: Failed to send webhook notification: HTTPConnectionPool(host='localhost', port=5000): Max retries exceeded with url: /webhook (Caused by NewConnectionError('<urllib3.connection.HTTPConnection object at 0x7f06801ee620>: Failed to establish a new connection: [Errno 111] Connection refused'))
[2025-09-08T14:25:07.813+0530] {subprocess.py:93} INFO - 2025-09-08 14:25:07,813 INFO: Flushed batch: orders=200 items=366
[2025-09-08T14:25:07.816+0530] {subprocess.py:93} INFO - 2025-09-08 14:25:07,815 WARNING: Failed to send webhook notification: HTTPConnectionPool(host='localhost', port=5000): Max retries exceeded with url: /webhook (Caused by NewConnectionError('<urllib3.connection.HTTPConnection object at 0x7f06801ee110>: Failed to establish a new connection: [Errno 111] Connection refused'))
[2025-09-08T14:25:08.038+0530] {subprocess.py:93} INFO - 2025-09-08 14:25:08,038 INFO: Flushed batch: orders=200 items=346
[2025-09-08T14:25:08.041+0530] {subprocess.py:93} INFO - 2025-09-08 14:25:08,041 WARNING: Failed to send webhook notification: HTTPConnectionPool(host='localhost', port=5000): Max retries exceeded with url: /webhook (Caused by NewConnectionError('<urllib3.connection.HTTPConnection object at 0x7f06800099f0>: Failed to establish a new connection: [Errno 111] Connection refused'))
[2025-09-08T14:25:08.589+0530] {subprocess.py:93} INFO - 2025-09-08 14:25:08,589 INFO: Flushed batch: orders=200 items=352
[2025-09-08T14:25:08.592+0530] {subprocess.py:93} INFO - 2025-09-08 14:25:08,592 WARNING: Failed to send webhook notification: HTTPConnectionPool(host='localhost', port=5000): Max retries exceeded with url: /webhook (Caused by NewConnectionError('<urllib3.connection.HTTPConnection object at 0x7f06800280a0>: Failed to establish a new connection: [Errno 111] Connection refused'))
[2025-09-08T14:25:08.798+0530] {subprocess.py:93} INFO - 2025-09-08 14:25:08,798 INFO: Flushed batch: orders=200 items=367
[2025-09-08T14:25:08.801+0530] {subprocess.py:93} INFO - 2025-09-08 14:25:08,800 WARNING: Failed to send webhook notification: HTTPConnectionPool(host='localhost', port=5000): Max retries exceeded with url: /webhook (Caused by NewConnectionError('<urllib3.connection.HTTPConnection object at 0x7f06800289d0>: Failed to establish a new connection: [Errno 111] Connection refused'))
[2025-09-08T14:25:09.341+0530] {subprocess.py:93} INFO - 2025-09-08 14:25:09,341 INFO: Flushed batch: orders=200 items=350
[2025-09-08T14:25:09.344+0530] {subprocess.py:93} INFO - 2025-09-08 14:25:09,343 WARNING: Failed to send webhook notification: HTTPConnectionPool(host='localhost', port=5000): Max retries exceeded with url: /webhook (Caused by NewConnectionError('<urllib3.connection.HTTPConnection object at 0x7f068000a3b0>: Failed to establish a new connection: [Errno 111] Connection refused'))
[2025-09-08T14:25:09.718+0530] {subprocess.py:93} INFO - 2025-09-08 14:25:09,718 INFO: Flushed batch: orders=200 items=338
[2025-09-08T14:25:09.721+0530] {subprocess.py:93} INFO - 2025-09-08 14:25:09,720 WARNING: Failed to send webhook notification: HTTPConnectionPool(host='localhost', port=5000): Max retries exceeded with url: /webhook (Caused by NewConnectionError('<urllib3.connection.HTTPConnection object at 0x7f068002ab30>: Failed to establish a new connection: [Errno 111] Connection refused'))
[2025-09-08T14:25:10.264+0530] {subprocess.py:93} INFO - 2025-09-08 14:25:10,264 INFO: Flushed batch: orders=200 items=332
[2025-09-08T14:25:10.267+0530] {subprocess.py:93} INFO - 2025-09-08 14:25:10,267 WARNING: Failed to send webhook notification: HTTPConnectionPool(host='localhost', port=5000): Max retries exceeded with url: /webhook (Caused by NewConnectionError('<urllib3.connection.HTTPConnection object at 0x7f06800391e0>: Failed to establish a new connection: [Errno 111] Connection refused'))
[2025-09-08T14:25:10.512+0530] {subprocess.py:93} INFO - 2025-09-08 14:25:10,511 INFO: Flushed batch: orders=200 items=316
[2025-09-08T14:25:10.515+0530] {subprocess.py:93} INFO - 2025-09-08 14:25:10,515 WARNING: Failed to send webhook notification: HTTPConnectionPool(host='localhost', port=5000): Max retries exceeded with url: /webhook (Caused by NewConnectionError('<urllib3.connection.HTTPConnection object at 0x7f0680019000>: Failed to establish a new connection: [Errno 111] Connection refused'))
[2025-09-08T14:25:10.798+0530] {subprocess.py:93} INFO - 2025-09-08 14:25:10,798 INFO: Flushed batch: orders=200 items=341
[2025-09-08T14:25:10.800+0530] {subprocess.py:93} INFO - 2025-09-08 14:25:10,800 WARNING: Failed to send webhook notification: HTTPConnectionPool(host='localhost', port=5000): Max retries exceeded with url: /webhook (Caused by NewConnectionError('<urllib3.connection.HTTPConnection object at 0x7f06800086a0>: Failed to establish a new connection: [Errno 111] Connection refused'))
[2025-09-08T14:25:11.321+0530] {subprocess.py:93} INFO - 2025-09-08 14:25:11,320 INFO: Flushed batch: orders=200 items=334
[2025-09-08T14:25:11.324+0530] {subprocess.py:93} INFO - 2025-09-08 14:25:11,324 WARNING: Failed to send webhook notification: HTTPConnectionPool(host='localhost', port=5000): Max retries exceeded with url: /webhook (Caused by NewConnectionError('<urllib3.connection.HTTPConnection object at 0x7f0680038280>: Failed to establish a new connection: [Errno 111] Connection refused'))
[2025-09-08T14:25:11.597+0530] {subprocess.py:93} INFO - 2025-09-08 14:25:11,596 INFO: Flushed batch: orders=200 items=365
[2025-09-08T14:25:11.599+0530] {subprocess.py:93} INFO - 2025-09-08 14:25:11,599 WARNING: Failed to send webhook notification: HTTPConnectionPool(host='localhost', port=5000): Max retries exceeded with url: /webhook (Caused by NewConnectionError('<urllib3.connection.HTTPConnection object at 0x7f06801f8c40>: Failed to establish a new connection: [Errno 111] Connection refused'))
[2025-09-08T14:25:11.997+0530] {subprocess.py:93} INFO - 2025-09-08 14:25:11,996 INFO: Flushed batch: orders=200 items=328
[2025-09-08T14:25:12.000+0530] {subprocess.py:93} INFO - 2025-09-08 14:25:12,000 WARNING: Failed to send webhook notification: HTTPConnectionPool(host='localhost', port=5000): Max retries exceeded with url: /webhook (Caused by NewConnectionError('<urllib3.connection.HTTPConnection object at 0x7f06800353f0>: Failed to establish a new connection: [Errno 111] Connection refused'))
[2025-09-08T14:25:12.414+0530] {subprocess.py:93} INFO - 2025-09-08 14:25:12,414 INFO: Flushed batch: orders=200 items=322
[2025-09-08T14:25:12.417+0530] {subprocess.py:93} INFO - 2025-09-08 14:25:12,417 WARNING: Failed to send webhook notification: HTTPConnectionPool(host='localhost', port=5000): Max retries exceeded with url: /webhook (Caused by NewConnectionError('<urllib3.connection.HTTPConnection object at 0x7f0680038610>: Failed to establish a new connection: [Errno 111] Connection refused'))
[2025-09-08T14:25:12.640+0530] {subprocess.py:93} INFO - 2025-09-08 14:25:12,640 INFO: Flushed batch: orders=200 items=360
[2025-09-08T14:25:12.643+0530] {subprocess.py:93} INFO - 2025-09-08 14:25:12,643 WARNING: Failed to send webhook notification: HTTPConnectionPool(host='localhost', port=5000): Max retries exceeded with url: /webhook (Caused by NewConnectionError('<urllib3.connection.HTTPConnection object at 0x7f0680039330>: Failed to establish a new connection: [Errno 111] Connection refused'))
[2025-09-08T14:25:13.016+0530] {subprocess.py:93} INFO - 2025-09-08 14:25:13,016 INFO: Flushed batch: orders=200 items=349
[2025-09-08T14:25:13.019+0530] {subprocess.py:93} INFO - 2025-09-08 14:25:13,018 WARNING: Failed to send webhook notification: HTTPConnectionPool(host='localhost', port=5000): Max retries exceeded with url: /webhook (Caused by NewConnectionError('<urllib3.connection.HTTPConnection object at 0x7f06801f82e0>: Failed to establish a new connection: [Errno 111] Connection refused'))
[2025-09-08T14:25:13.267+0530] {subprocess.py:93} INFO - 2025-09-08 14:25:13,266 INFO: Flushed batch: orders=200 items=372
[2025-09-08T14:25:13.271+0530] {subprocess.py:93} INFO - 2025-09-08 14:25:13,270 WARNING: Failed to send webhook notification: HTTPConnectionPool(host='localhost', port=5000): Max retries exceeded with url: /webhook (Caused by NewConnectionError('<urllib3.connection.HTTPConnection object at 0x7f0680018850>: Failed to establish a new connection: [Errno 111] Connection refused'))
[2025-09-08T14:25:13.860+0530] {subprocess.py:93} INFO - 2025-09-08 14:25:13,860 INFO: Flushed batch: orders=200 items=357
[2025-09-08T14:25:13.863+0530] {subprocess.py:93} INFO - 2025-09-08 14:25:13,863 WARNING: Failed to send webhook notification: HTTPConnectionPool(host='localhost', port=5000): Max retries exceeded with url: /webhook (Caused by NewConnectionError('<urllib3.connection.HTTPConnection object at 0x7f0680068c10>: Failed to establish a new connection: [Errno 111] Connection refused'))
[2025-09-08T14:25:14.350+0530] {subprocess.py:93} INFO - 2025-09-08 14:25:14,349 INFO: Flushed batch: orders=200 items=350
[2025-09-08T14:25:14.352+0530] {subprocess.py:93} INFO - 2025-09-08 14:25:14,352 WARNING: Failed to send webhook notification: HTTPConnectionPool(host='localhost', port=5000): Max retries exceeded with url: /webhook (Caused by NewConnectionError('<urllib3.connection.HTTPConnection object at 0x7f068006a7a0>: Failed to establish a new connection: [Errno 111] Connection refused'))
[2025-09-08T14:25:14.553+0530] {subprocess.py:93} INFO - 2025-09-08 14:25:14,553 INFO: Flushed batch: orders=200 items=368
[2025-09-08T14:25:14.556+0530] {subprocess.py:93} INFO - 2025-09-08 14:25:14,556 WARNING: Failed to send webhook notification: HTTPConnectionPool(host='localhost', port=5000): Max retries exceeded with url: /webhook (Caused by NewConnectionError('<urllib3.connection.HTTPConnection object at 0x7f0680035ea0>: Failed to establish a new connection: [Errno 111] Connection refused'))
[2025-09-08T14:25:14.754+0530] {subprocess.py:93} INFO - 2025-09-08 14:25:14,754 INFO: Flushed batch: orders=200 items=356
[2025-09-08T14:25:14.757+0530] {subprocess.py:93} INFO - 2025-09-08 14:25:14,756 WARNING: Failed to send webhook notification: HTTPConnectionPool(host='localhost', port=5000): Max retries exceeded with url: /webhook (Caused by NewConnectionError('<urllib3.connection.HTTPConnection object at 0x7f068003b7f0>: Failed to establish a new connection: [Errno 111] Connection refused'))
[2025-09-08T14:25:15.230+0530] {subprocess.py:93} INFO - 2025-09-08 14:25:15,229 INFO: Flushed batch: orders=200 items=347
[2025-09-08T14:25:15.232+0530] {subprocess.py:93} INFO - 2025-09-08 14:25:15,232 WARNING: Failed to send webhook notification: HTTPConnectionPool(host='localhost', port=5000): Max retries exceeded with url: /webhook (Caused by NewConnectionError('<urllib3.connection.HTTPConnection object at 0x7f06801ed5d0>: Failed to establish a new connection: [Errno 111] Connection refused'))
[2025-09-08T14:25:15.447+0530] {subprocess.py:93} INFO - 2025-09-08 14:25:15,447 INFO: Flushed batch: orders=200 items=377
[2025-09-08T14:25:15.450+0530] {subprocess.py:93} INFO - 2025-09-08 14:25:15,450 WARNING: Failed to send webhook notification: HTTPConnectionPool(host='localhost', port=5000): Max retries exceeded with url: /webhook (Caused by NewConnectionError('<urllib3.connection.HTTPConnection object at 0x7f06801ed1e0>: Failed to establish a new connection: [Errno 111] Connection refused'))
[2025-09-08T14:25:15.451+0530] {subprocess.py:93} INFO - 2025-09-08 14:25:15,450 INFO: Generated 5000 orders
[2025-09-08T14:26:04.585+0530] {subprocess.py:93} INFO - 2025-09-08 14:26:04,585 INFO: Inserted 48057 clickstream events.
[2025-09-08T14:26:04.586+0530] {subprocess.py:93} INFO - 2025-09-08 14:26:04,586 WARNING: Failed to send webhook notification: HTTPConnectionPool(host='localhost', port=5000): Max retries exceeded with url: /webhook (Caused by NewConnectionError('<urllib3.connection.HTTPConnection object at 0x7f067eec76a0>: Failed to establish a new connection: [Errno 111] Connection refused'))
[2025-09-08T14:26:07.393+0530] {subprocess.py:93} INFO - 2025-09-08 14:26:07,392 INFO: Validation done: orphans orders=0 items=0 inventory=0 mismatches=0
[2025-09-08T14:26:07.404+0530] {subprocess.py:93} INFO - 2025-09-08 14:26:07,403 INFO: Integrity report: {'orphan_orders': 0, 'orphan_order_items': 0, 'inventory_orphans': 0, 'order_amount_mismatches': []}
[2025-09-08T14:26:07.434+0530] {subprocess.py:93} INFO - [2025-09-08 14:26:07] ‚úÖ Synthetic data streaming completed successfully!
[2025-09-08T14:26:07.434+0530] {subprocess.py:97} INFO - Command exited with return code 0
[2025-09-08T14:26:07.434+0530] {taskinstance.py:441} INFO - ::group::Post task execution logs
[2025-09-08T14:26:07.697+0530] {taskinstance.py:1206} INFO - Marking task as SUCCESS. dag_id=synth_stream_5min, task_id=run_synth_stream, run_id=scheduled__2025-09-08T08:50:00+00:00, execution_date=20250908T085000, start_date=20250908T085504, end_date=20250908T085607
[2025-09-08T14:26:08.012+0530] {local_task_job_runner.py:243} INFO - Task exited with return code 0
[2025-09-08T14:26:08.021+0530] {taskinstance.py:3503} INFO - 0 downstream tasks scheduled from follow-on schedule check
[2025-09-08T14:26:08.021+0530] {local_task_job_runner.py:222} INFO - ::endgroup::
