[2025-09-08T14:40:59.427+0530] {local_task_job_runner.py:120} INFO - ::group::Pre task execution logs
[2025-09-08T14:40:59.979+0530] {taskinstance.py:2076} INFO - Dependencies all met for dep_context=non-requeueable deps ti=<TaskInstance: synth_stream_5min.run_synth_stream scheduled__2025-09-08T08:55:00+00:00 [queued]>
[2025-09-08T14:40:59.982+0530] {taskinstance.py:2076} INFO - Dependencies all met for dep_context=requeueable deps ti=<TaskInstance: synth_stream_5min.run_synth_stream scheduled__2025-09-08T08:55:00+00:00 [queued]>
[2025-09-08T14:40:59.982+0530] {taskinstance.py:2306} INFO - Starting attempt 1 of 2
[2025-09-08T14:41:00.196+0530] {taskinstance.py:2330} INFO - Executing <Task(BashOperator): run_synth_stream> on 2025-09-08 08:55:00+00:00
[2025-09-08T14:41:00.202+0530] {standard_task_runner.py:64} INFO - Started process 733405 to run task
[2025-09-08T14:41:00.204+0530] {standard_task_runner.py:90} INFO - Running: ['airflow', 'tasks', 'run', 'synth_stream_5min', 'run_synth_stream', 'scheduled__2025-09-08T08:55:00+00:00', '--job-id', '47', '--raw', '--subdir', 'DAGS_FOLDER/ecom_schedules.py', '--cfg-path', '/tmp/tmp1_94_dvm']
[2025-09-08T14:41:00.206+0530] {standard_task_runner.py:91} INFO - Job 47: Subtask run_synth_stream
[2025-09-08T14:41:00.465+0530] {task_command.py:426} INFO - Running <TaskInstance: synth_stream_5min.run_synth_stream scheduled__2025-09-08T08:55:00+00:00 [running]> on host softsuave-ASUS-EXPERTCENTER-D700ME-D500ME
[2025-09-08T14:41:00.900+0530] {taskinstance.py:2648} INFO - Exporting env vars: AIRFLOW_CTX_DAG_OWNER='airflow' AIRFLOW_CTX_DAG_ID='synth_stream_5min' AIRFLOW_CTX_TASK_ID='run_synth_stream' AIRFLOW_CTX_EXECUTION_DATE='2025-09-08T08:55:00+00:00' AIRFLOW_CTX_TRY_NUMBER='1' AIRFLOW_CTX_DAG_RUN_ID='scheduled__2025-09-08T08:55:00+00:00'
[2025-09-08T14:41:00.901+0530] {taskinstance.py:430} INFO - ::endgroup::
[2025-09-08T14:41:00.901+0530] {subprocess.py:63} INFO - Tmp dir root location: /tmp
[2025-09-08T14:41:00.902+0530] {subprocess.py:75} INFO - Running command: ['/usr/bin/bash', '-c', 'bash /media/softsuave/DATA-HDD/DataEngineering/Apache_Airflow/scripts/synth/run_synth_stream.sh | cat']
[2025-09-08T14:41:00.907+0530] {subprocess.py:86} INFO - Output:
[2025-09-08T14:41:01.050+0530] {subprocess.py:93} INFO - [2025-09-08 14:41:01] üöÄ Starting Synthetic E-commerce Data Stream...
[2025-09-08T14:41:01.050+0530] {subprocess.py:93} INFO - ----------------------------------------------
[2025-09-08T14:41:01.050+0530] {subprocess.py:93} INFO -  Database   : ecom_db
[2025-09-08T14:41:01.050+0530] {subprocess.py:93} INFO -  User       : sa
[2025-09-08T14:41:01.050+0530] {subprocess.py:93} INFO -  Server     : localhost:1433
[2025-09-08T14:41:01.051+0530] {subprocess.py:93} INFO -  Interval   : 5 min
[2025-09-08T14:41:01.051+0530] {subprocess.py:93} INFO -  Orders     : 50
[2025-09-08T14:41:01.051+0530] {subprocess.py:93} INFO -  Clicks     : 100
[2025-09-08T14:41:01.051+0530] {subprocess.py:93} INFO -  Webhook    : http://localhost:5000/webhook
[2025-09-08T14:41:01.051+0530] {subprocess.py:93} INFO - ----------------------------------------------
[2025-09-08T14:41:01.051+0530] {subprocess.py:93} INFO - 
[2025-09-08T14:41:01.416+0530] {subprocess.py:93} INFO - [2025-09-08 14:41:01] üîß Activating virtual environment...
[2025-09-08T14:41:01.511+0530] {subprocess.py:93} INFO - [2025-09-08 14:41:01] üîç Checking database connection...
[2025-09-08T14:41:02.588+0530] {subprocess.py:93} INFO - ‚úÖ Database connection successful
[2025-09-08T14:41:02.627+0530] {subprocess.py:93} INFO - [2025-09-08 14:41:02] üîÑ Starting synthetic data stream...
[2025-09-08T14:41:02.627+0530] {subprocess.py:93} INFO - Press Ctrl+C to stop
[2025-09-08T14:41:02.628+0530] {subprocess.py:93} INFO - 
[2025-09-08T14:41:04.671+0530] {subprocess.py:93} INFO - 2025-09-08 14:41:04,671 INFO: Tables ensured/created (if needed).
[2025-09-08T14:41:05.304+0530] {subprocess.py:93} INFO - 2025-09-08 14:41:05,303 INFO: Customers: 1000 already present; skipping seeding.
[2025-09-08T14:41:05.308+0530] {subprocess.py:93} INFO - 2025-09-08 14:41:05,307 INFO: Products: 500 already present; skipping seeding.
[2025-09-08T14:41:05.308+0530] {subprocess.py:93} INFO - 2025-09-08 14:41:05,308 INFO: Running one-shot generation: orders=5000, sessions=3000
[2025-09-08T14:41:05.330+0530] {subprocess.py:93} INFO - /media/softsuave/DATA-HDD/DataEngineering/Apache_Airflow/src/synth_ecom_mssql_stream.py:397: RemovedIn20Warning: Deprecated API features detected! These feature(s) are not compatible with SQLAlchemy 2.0. To prevent incompatible upgrades prior to updating applications, ensure requirements files are pinned to "sqlalchemy<2.0". Set environment variable SQLALCHEMY_WARN_20=1 to show all deprecation warnings.  Set environment variable SQLALCHEMY_SILENCE_UBER_WARNING=1 to silence this message. (Background on SQLAlchemy 2.0 at: https://sqlalche.me/e/b8d9)
[2025-09-08T14:41:05.330+0530] {subprocess.py:93} INFO -   customers = [dict(r) for r in conn.execute(select(self.tables["customers"])).fetchall()]
[2025-09-08T14:41:05.338+0530] {subprocess.py:93} INFO - 2025-09-08 14:41:05,337 INFO: Generating 5000 orders (batch_size=200, force_order_date_now=False)...
[2025-09-08T14:41:05.977+0530] {subprocess.py:93} INFO - 2025-09-08 14:41:05,977 INFO: Flushed batch: orders=200 items=339
[2025-09-08T14:41:05.982+0530] {subprocess.py:93} INFO - 2025-09-08 14:41:05,982 WARNING: Failed to send webhook notification: HTTPConnectionPool(host='localhost', port=5000): Max retries exceeded with url: /webhook (Caused by NewConnectionError('<urllib3.connection.HTTPConnection object at 0x72b8e6794f10>: Failed to establish a new connection: [Errno 111] Connection refused'))
[2025-09-08T14:41:06.294+0530] {subprocess.py:93} INFO - 2025-09-08 14:41:06,294 INFO: Flushed batch: orders=200 items=365
[2025-09-08T14:41:06.297+0530] {subprocess.py:93} INFO - 2025-09-08 14:41:06,297 WARNING: Failed to send webhook notification: HTTPConnectionPool(host='localhost', port=5000): Max retries exceeded with url: /webhook (Caused by NewConnectionError('<urllib3.connection.HTTPConnection object at 0x72b8e66d3130>: Failed to establish a new connection: [Errno 111] Connection refused'))
[2025-09-08T14:41:06.570+0530] {subprocess.py:93} INFO - 2025-09-08 14:41:06,569 INFO: Flushed batch: orders=200 items=362
[2025-09-08T14:41:06.572+0530] {subprocess.py:93} INFO - 2025-09-08 14:41:06,572 WARNING: Failed to send webhook notification: HTTPConnectionPool(host='localhost', port=5000): Max retries exceeded with url: /webhook (Caused by NewConnectionError('<urllib3.connection.HTTPConnection object at 0x72b8e66bf0a0>: Failed to establish a new connection: [Errno 111] Connection refused'))
[2025-09-08T14:41:06.945+0530] {subprocess.py:93} INFO - 2025-09-08 14:41:06,945 INFO: Flushed batch: orders=200 items=353
[2025-09-08T14:41:06.948+0530] {subprocess.py:93} INFO - 2025-09-08 14:41:06,948 WARNING: Failed to send webhook notification: HTTPConnectionPool(host='localhost', port=5000): Max retries exceeded with url: /webhook (Caused by NewConnectionError('<urllib3.connection.HTTPConnection object at 0x72b8e66fce20>: Failed to establish a new connection: [Errno 111] Connection refused'))
[2025-09-08T14:41:07.371+0530] {subprocess.py:93} INFO - 2025-09-08 14:41:07,371 INFO: Flushed batch: orders=200 items=376
[2025-09-08T14:41:07.374+0530] {subprocess.py:93} INFO - 2025-09-08 14:41:07,373 WARNING: Failed to send webhook notification: HTTPConnectionPool(host='localhost', port=5000): Max retries exceeded with url: /webhook (Caused by NewConnectionError('<urllib3.connection.HTTPConnection object at 0x72b8e6511690>: Failed to establish a new connection: [Errno 111] Connection refused'))
[2025-09-08T14:41:07.788+0530] {subprocess.py:93} INFO - 2025-09-08 14:41:07,788 INFO: Flushed batch: orders=200 items=347
[2025-09-08T14:41:07.791+0530] {subprocess.py:93} INFO - 2025-09-08 14:41:07,791 WARNING: Failed to send webhook notification: HTTPConnectionPool(host='localhost', port=5000): Max retries exceeded with url: /webhook (Caused by NewConnectionError('<urllib3.connection.HTTPConnection object at 0x72b8e6734040>: Failed to establish a new connection: [Errno 111] Connection refused'))
[2025-09-08T14:41:08.014+0530] {subprocess.py:93} INFO - 2025-09-08 14:41:08,013 INFO: Flushed batch: orders=200 items=354
[2025-09-08T14:41:08.016+0530] {subprocess.py:93} INFO - 2025-09-08 14:41:08,016 WARNING: Failed to send webhook notification: HTTPConnectionPool(host='localhost', port=5000): Max retries exceeded with url: /webhook (Caused by NewConnectionError('<urllib3.connection.HTTPConnection object at 0x72b8e6737fa0>: Failed to establish a new connection: [Errno 111] Connection refused'))
[2025-09-08T14:41:08.916+0530] {subprocess.py:93} INFO - 2025-09-08 14:41:08,915 INFO: Flushed batch: orders=200 items=364
[2025-09-08T14:41:08.919+0530] {subprocess.py:93} INFO - 2025-09-08 14:41:08,918 WARNING: Failed to send webhook notification: HTTPConnectionPool(host='localhost', port=5000): Max retries exceeded with url: /webhook (Caused by NewConnectionError('<urllib3.connection.HTTPConnection object at 0x72b8e65118a0>: Failed to establish a new connection: [Errno 111] Connection refused'))
[2025-09-08T14:41:09.133+0530] {subprocess.py:93} INFO - 2025-09-08 14:41:09,132 INFO: Flushed batch: orders=200 items=360
[2025-09-08T14:41:09.135+0530] {subprocess.py:93} INFO - 2025-09-08 14:41:09,135 WARNING: Failed to send webhook notification: HTTPConnectionPool(host='localhost', port=5000): Max retries exceeded with url: /webhook (Caused by NewConnectionError('<urllib3.connection.HTTPConnection object at 0x72b8e6735930>: Failed to establish a new connection: [Errno 111] Connection refused'))
[2025-09-08T14:41:09.350+0530] {subprocess.py:93} INFO - 2025-09-08 14:41:09,350 INFO: Flushed batch: orders=200 items=349
[2025-09-08T14:41:09.353+0530] {subprocess.py:93} INFO - 2025-09-08 14:41:09,353 WARNING: Failed to send webhook notification: HTTPConnectionPool(host='localhost', port=5000): Max retries exceeded with url: /webhook (Caused by NewConnectionError('<urllib3.connection.HTTPConnection object at 0x72b8e66fdae0>: Failed to establish a new connection: [Errno 111] Connection refused'))
[2025-09-08T14:41:09.876+0530] {subprocess.py:93} INFO - 2025-09-08 14:41:09,875 INFO: Flushed batch: orders=200 items=333
[2025-09-08T14:41:09.878+0530] {subprocess.py:93} INFO - 2025-09-08 14:41:09,878 WARNING: Failed to send webhook notification: HTTPConnectionPool(host='localhost', port=5000): Max retries exceeded with url: /webhook (Caused by NewConnectionError('<urllib3.connection.HTTPConnection object at 0x72b8e67374c0>: Failed to establish a new connection: [Errno 111] Connection refused'))
[2025-09-08T14:41:10.076+0530] {subprocess.py:93} INFO - 2025-09-08 14:41:10,076 INFO: Flushed batch: orders=200 items=325
[2025-09-08T14:41:10.079+0530] {subprocess.py:93} INFO - 2025-09-08 14:41:10,079 WARNING: Failed to send webhook notification: HTTPConnectionPool(host='localhost', port=5000): Max retries exceeded with url: /webhook (Caused by NewConnectionError('<urllib3.connection.HTTPConnection object at 0x72b8e6d4caf0>: Failed to establish a new connection: [Errno 111] Connection refused'))
[2025-09-08T14:41:10.360+0530] {subprocess.py:93} INFO - 2025-09-08 14:41:10,360 INFO: Flushed batch: orders=200 items=380
[2025-09-08T14:41:10.363+0530] {subprocess.py:93} INFO - 2025-09-08 14:41:10,363 WARNING: Failed to send webhook notification: HTTPConnectionPool(host='localhost', port=5000): Max retries exceeded with url: /webhook (Caused by NewConnectionError('<urllib3.connection.HTTPConnection object at 0x72b8e67375b0>: Failed to establish a new connection: [Errno 111] Connection refused'))
[2025-09-08T14:41:11.045+0530] {subprocess.py:93} INFO - 2025-09-08 14:41:11,045 INFO: Flushed batch: orders=200 items=380
[2025-09-08T14:41:11.048+0530] {subprocess.py:93} INFO - 2025-09-08 14:41:11,048 WARNING: Failed to send webhook notification: HTTPConnectionPool(host='localhost', port=5000): Max retries exceeded with url: /webhook (Caused by NewConnectionError('<urllib3.connection.HTTPConnection object at 0x72b8e6526ce0>: Failed to establish a new connection: [Errno 111] Connection refused'))
[2025-09-08T14:41:11.503+0530] {subprocess.py:93} INFO - 2025-09-08 14:41:11,502 INFO: Flushed batch: orders=200 items=349
[2025-09-08T14:41:11.506+0530] {subprocess.py:93} INFO - 2025-09-08 14:41:11,505 WARNING: Failed to send webhook notification: HTTPConnectionPool(host='localhost', port=5000): Max retries exceeded with url: /webhook (Caused by NewConnectionError('<urllib3.connection.HTTPConnection object at 0x72b8e6737cd0>: Failed to establish a new connection: [Errno 111] Connection refused'))
[2025-09-08T14:41:11.845+0530] {subprocess.py:93} INFO - 2025-09-08 14:41:11,845 INFO: Flushed batch: orders=200 items=379
[2025-09-08T14:41:11.848+0530] {subprocess.py:93} INFO - 2025-09-08 14:41:11,848 WARNING: Failed to send webhook notification: HTTPConnectionPool(host='localhost', port=5000): Max retries exceeded with url: /webhook (Caused by NewConnectionError('<urllib3.connection.HTTPConnection object at 0x72b8e65111b0>: Failed to establish a new connection: [Errno 111] Connection refused'))
[2025-09-08T14:41:12.271+0530] {subprocess.py:93} INFO - 2025-09-08 14:41:12,270 INFO: Flushed batch: orders=200 items=369
[2025-09-08T14:41:12.273+0530] {subprocess.py:93} INFO - 2025-09-08 14:41:12,273 WARNING: Failed to send webhook notification: HTTPConnectionPool(host='localhost', port=5000): Max retries exceeded with url: /webhook (Caused by NewConnectionError('<urllib3.connection.HTTPConnection object at 0x72b8e66ee290>: Failed to establish a new connection: [Errno 111] Connection refused'))
[2025-09-08T14:41:12.488+0530] {subprocess.py:93} INFO - 2025-09-08 14:41:12,488 INFO: Flushed batch: orders=200 items=357
[2025-09-08T14:41:12.490+0530] {subprocess.py:93} INFO - 2025-09-08 14:41:12,490 WARNING: Failed to send webhook notification: HTTPConnectionPool(host='localhost', port=5000): Max retries exceeded with url: /webhook (Caused by NewConnectionError('<urllib3.connection.HTTPConnection object at 0x72b8e6541930>: Failed to establish a new connection: [Errno 111] Connection refused'))
[2025-09-08T14:41:12.688+0530] {subprocess.py:93} INFO - 2025-09-08 14:41:12,688 INFO: Flushed batch: orders=200 items=347
[2025-09-08T14:41:12.691+0530] {subprocess.py:93} INFO - 2025-09-08 14:41:12,690 WARNING: Failed to send webhook notification: HTTPConnectionPool(host='localhost', port=5000): Max retries exceeded with url: /webhook (Caused by NewConnectionError('<urllib3.connection.HTTPConnection object at 0x72b8e6510df0>: Failed to establish a new connection: [Errno 111] Connection refused'))
[2025-09-08T14:41:13.314+0530] {subprocess.py:93} INFO - 2025-09-08 14:41:13,314 INFO: Flushed batch: orders=200 items=360
[2025-09-08T14:41:13.317+0530] {subprocess.py:93} INFO - 2025-09-08 14:41:13,317 WARNING: Failed to send webhook notification: HTTPConnectionPool(host='localhost', port=5000): Max retries exceeded with url: /webhook (Caused by NewConnectionError('<urllib3.connection.HTTPConnection object at 0x72b8e6542c50>: Failed to establish a new connection: [Errno 111] Connection refused'))
[2025-09-08T14:41:13.515+0530] {subprocess.py:93} INFO - 2025-09-08 14:41:13,514 INFO: Flushed batch: orders=200 items=325
[2025-09-08T14:41:13.517+0530] {subprocess.py:93} INFO - 2025-09-08 14:41:13,517 WARNING: Failed to send webhook notification: HTTPConnectionPool(host='localhost', port=5000): Max retries exceeded with url: /webhook (Caused by NewConnectionError('<urllib3.connection.HTTPConnection object at 0x72b8e6511690>: Failed to establish a new connection: [Errno 111] Connection refused'))
[2025-09-08T14:41:14.184+0530] {subprocess.py:93} INFO - 2025-09-08 14:41:14,184 INFO: Flushed batch: orders=200 items=358
[2025-09-08T14:41:14.187+0530] {subprocess.py:93} INFO - 2025-09-08 14:41:14,187 WARNING: Failed to send webhook notification: HTTPConnectionPool(host='localhost', port=5000): Max retries exceeded with url: /webhook (Caused by NewConnectionError('<urllib3.connection.HTTPConnection object at 0x72b8e6736200>: Failed to establish a new connection: [Errno 111] Connection refused'))
[2025-09-08T14:41:14.375+0530] {subprocess.py:93} INFO - 2025-09-08 14:41:14,375 INFO: Flushed batch: orders=200 items=357
[2025-09-08T14:41:14.379+0530] {subprocess.py:93} INFO - 2025-09-08 14:41:14,378 WARNING: Failed to send webhook notification: HTTPConnectionPool(host='localhost', port=5000): Max retries exceeded with url: /webhook (Caused by NewConnectionError('<urllib3.connection.HTTPConnection object at 0x72b8e6525a50>: Failed to establish a new connection: [Errno 111] Connection refused'))
[2025-09-08T14:41:14.624+0530] {subprocess.py:93} INFO - 2025-09-08 14:41:14,624 INFO: Flushed batch: orders=200 items=325
[2025-09-08T14:41:14.627+0530] {subprocess.py:93} INFO - 2025-09-08 14:41:14,627 WARNING: Failed to send webhook notification: HTTPConnectionPool(host='localhost', port=5000): Max retries exceeded with url: /webhook (Caused by NewConnectionError('<urllib3.connection.HTTPConnection object at 0x72b8e6796e30>: Failed to establish a new connection: [Errno 111] Connection refused'))
[2025-09-08T14:41:14.827+0530] {subprocess.py:93} INFO - 2025-09-08 14:41:14,827 INFO: Flushed batch: orders=200 items=360
[2025-09-08T14:41:14.830+0530] {subprocess.py:93} INFO - 2025-09-08 14:41:14,829 WARNING: Failed to send webhook notification: HTTPConnectionPool(host='localhost', port=5000): Max retries exceeded with url: /webhook (Caused by NewConnectionError('<urllib3.connection.HTTPConnection object at 0x72b8e6513fa0>: Failed to establish a new connection: [Errno 111] Connection refused'))
[2025-09-08T14:41:14.830+0530] {subprocess.py:93} INFO - 2025-09-08 14:41:14,830 INFO: Generated 5000 orders
[2025-09-08T14:42:14.190+0530] {subprocess.py:93} INFO - 2025-09-08 14:42:14,190 INFO: Inserted 48053 clickstream events.
[2025-09-08T14:42:14.191+0530] {subprocess.py:93} INFO - 2025-09-08 14:42:14,191 WARNING: Failed to send webhook notification: HTTPConnectionPool(host='localhost', port=5000): Max retries exceeded with url: /webhook (Caused by NewConnectionError('<urllib3.connection.HTTPConnection object at 0x72b8e6d13340>: Failed to establish a new connection: [Errno 111] Connection refused'))
[2025-09-08T14:42:16.310+0530] {subprocess.py:93} INFO - 2025-09-08 14:42:16,310 INFO: Validation done: orphans orders=0 items=0 inventory=0 mismatches=0
[2025-09-08T14:42:16.322+0530] {subprocess.py:93} INFO - 2025-09-08 14:42:16,322 INFO: Integrity report: {'orphan_orders': 0, 'orphan_order_items': 0, 'inventory_orphans': 0, 'order_amount_mismatches': []}
[2025-09-08T14:42:16.351+0530] {subprocess.py:93} INFO - [2025-09-08 14:42:16] ‚úÖ Synthetic data streaming completed successfully!
[2025-09-08T14:42:16.352+0530] {subprocess.py:97} INFO - Command exited with return code 0
[2025-09-08T14:42:16.352+0530] {taskinstance.py:441} INFO - ::group::Post task execution logs
[2025-09-08T14:42:16.600+0530] {taskinstance.py:1206} INFO - Marking task as SUCCESS. dag_id=synth_stream_5min, task_id=run_synth_stream, run_id=scheduled__2025-09-08T08:55:00+00:00, execution_date=20250908T085500, start_date=20250908T091059, end_date=20250908T091216
[2025-09-08T14:42:16.970+0530] {local_task_job_runner.py:243} INFO - Task exited with return code 0
[2025-09-08T14:42:16.979+0530] {taskinstance.py:3503} INFO - 0 downstream tasks scheduled from follow-on schedule check
[2025-09-08T14:42:16.979+0530] {local_task_job_runner.py:222} INFO - ::endgroup::
