[2025-09-08T14:55:20.268+0530] {local_task_job_runner.py:120} INFO - ::group::Pre task execution logs
[2025-09-08T14:55:21.288+0530] {taskinstance.py:2076} INFO - Dependencies all met for dep_context=non-requeueable deps ti=<TaskInstance: synth_stream_5min.run_synth_stream scheduled__2025-09-08T09:15:00+00:00 [queued]>
[2025-09-08T14:55:21.291+0530] {taskinstance.py:2076} INFO - Dependencies all met for dep_context=requeueable deps ti=<TaskInstance: synth_stream_5min.run_synth_stream scheduled__2025-09-08T09:15:00+00:00 [queued]>
[2025-09-08T14:55:21.291+0530] {taskinstance.py:2306} INFO - Starting attempt 1 of 2
[2025-09-08T14:55:21.571+0530] {taskinstance.py:2330} INFO - Executing <Task(BashOperator): run_synth_stream> on 2025-09-08 09:15:00+00:00
[2025-09-08T14:55:21.579+0530] {standard_task_runner.py:64} INFO - Started process 737342 to run task
[2025-09-08T14:55:21.585+0530] {standard_task_runner.py:90} INFO - Running: ['airflow', 'tasks', 'run', 'synth_stream_5min', 'run_synth_stream', 'scheduled__2025-09-08T09:15:00+00:00', '--job-id', '52', '--raw', '--subdir', 'DAGS_FOLDER/ecom_schedules.py', '--cfg-path', '/tmp/tmp8e9b_b2x']
[2025-09-08T14:55:21.588+0530] {standard_task_runner.py:91} INFO - Job 52: Subtask run_synth_stream
[2025-09-08T14:55:21.985+0530] {task_command.py:426} INFO - Running <TaskInstance: synth_stream_5min.run_synth_stream scheduled__2025-09-08T09:15:00+00:00 [running]> on host softsuave-ASUS-EXPERTCENTER-D700ME-D500ME
[2025-09-08T14:55:22.587+0530] {taskinstance.py:2648} INFO - Exporting env vars: AIRFLOW_CTX_DAG_OWNER='airflow' AIRFLOW_CTX_DAG_ID='synth_stream_5min' AIRFLOW_CTX_TASK_ID='run_synth_stream' AIRFLOW_CTX_EXECUTION_DATE='2025-09-08T09:15:00+00:00' AIRFLOW_CTX_TRY_NUMBER='1' AIRFLOW_CTX_DAG_RUN_ID='scheduled__2025-09-08T09:15:00+00:00'
[2025-09-08T14:55:22.590+0530] {taskinstance.py:430} INFO - ::endgroup::
[2025-09-08T14:55:22.591+0530] {subprocess.py:63} INFO - Tmp dir root location: /tmp
[2025-09-08T14:55:22.592+0530] {subprocess.py:75} INFO - Running command: ['/usr/bin/bash', '-c', 'bash /media/softsuave/DATA-HDD/DataEngineering/Apache_Airflow/scripts/synth/run_synth_stream.sh | cat']
[2025-09-08T14:55:22.604+0530] {subprocess.py:86} INFO - Output:
[2025-09-08T14:55:22.689+0530] {subprocess.py:93} INFO - [2025-09-08 14:55:22] üöÄ Starting Synthetic E-commerce Data Stream...
[2025-09-08T14:55:22.690+0530] {subprocess.py:93} INFO - ----------------------------------------------
[2025-09-08T14:55:22.690+0530] {subprocess.py:93} INFO -  Database   : ecom_db
[2025-09-08T14:55:22.690+0530] {subprocess.py:93} INFO -  User       : sa
[2025-09-08T14:55:22.690+0530] {subprocess.py:93} INFO -  Server     : localhost:1433
[2025-09-08T14:55:22.690+0530] {subprocess.py:93} INFO -  Interval   : 5 min
[2025-09-08T14:55:22.690+0530] {subprocess.py:93} INFO -  Orders     : 50
[2025-09-08T14:55:22.690+0530] {subprocess.py:93} INFO -  Clicks     : 100
[2025-09-08T14:55:22.690+0530] {subprocess.py:93} INFO -  Webhook    : http://localhost:5000/webhook
[2025-09-08T14:55:22.690+0530] {subprocess.py:93} INFO - ----------------------------------------------
[2025-09-08T14:55:22.690+0530] {subprocess.py:93} INFO - 
[2025-09-08T14:55:23.094+0530] {subprocess.py:93} INFO - [2025-09-08 14:55:23] üîß Activating virtual environment...
[2025-09-08T14:55:23.193+0530] {subprocess.py:93} INFO - [2025-09-08 14:55:23] üîç Checking database connection...
[2025-09-08T14:55:25.639+0530] {subprocess.py:93} INFO - ‚úÖ Database connection successful
[2025-09-08T14:55:25.656+0530] {subprocess.py:93} INFO - [2025-09-08 14:55:25] üîÑ Starting synthetic data stream...
[2025-09-08T14:55:25.657+0530] {subprocess.py:93} INFO - Press Ctrl+C to stop
[2025-09-08T14:55:25.658+0530] {subprocess.py:93} INFO - 
[2025-09-08T14:55:30.211+0530] {subprocess.py:93} INFO - 2025-09-08 14:55:30,211 INFO: Tables ensured/created (if needed).
[2025-09-08T14:55:31.558+0530] {subprocess.py:93} INFO - 2025-09-08 14:55:31,557 INFO: Customers: 1000 already present; skipping seeding.
[2025-09-08T14:55:31.645+0530] {subprocess.py:93} INFO - 2025-09-08 14:55:31,645 INFO: Products: 500 already present; skipping seeding.
[2025-09-08T14:55:31.646+0530] {subprocess.py:93} INFO - 2025-09-08 14:55:31,646 INFO: Running one-shot generation: orders=5000, sessions=3000
[2025-09-08T14:55:31.666+0530] {subprocess.py:93} INFO - /media/softsuave/DATA-HDD/DataEngineering/Apache_Airflow/src/synth_ecom_mssql_stream.py:397: RemovedIn20Warning: Deprecated API features detected! These feature(s) are not compatible with SQLAlchemy 2.0. To prevent incompatible upgrades prior to updating applications, ensure requirements files are pinned to "sqlalchemy<2.0". Set environment variable SQLALCHEMY_WARN_20=1 to show all deprecation warnings.  Set environment variable SQLALCHEMY_SILENCE_UBER_WARNING=1 to silence this message. (Background on SQLAlchemy 2.0 at: https://sqlalche.me/e/b8d9)
[2025-09-08T14:55:31.667+0530] {subprocess.py:93} INFO -   customers = [dict(r) for r in conn.execute(select(self.tables["customers"])).fetchall()]
[2025-09-08T14:55:31.674+0530] {subprocess.py:93} INFO - 2025-09-08 14:55:31,674 INFO: Generating 5000 orders (batch_size=200, force_order_date_now=False)...
[2025-09-08T14:55:33.761+0530] {subprocess.py:93} INFO - 2025-09-08 14:55:33,760 INFO: Flushed batch: orders=200 items=311
[2025-09-08T14:55:33.766+0530] {subprocess.py:93} INFO - 2025-09-08 14:55:33,766 WARNING: Failed to send webhook notification: HTTPConnectionPool(host='localhost', port=5000): Max retries exceeded with url: /webhook (Caused by NewConnectionError('<urllib3.connection.HTTPConnection object at 0x7d4fd9786bf0>: Failed to establish a new connection: [Errno 111] Connection refused'))
[2025-09-08T14:55:34.531+0530] {subprocess.py:93} INFO - 2025-09-08 14:55:34,530 INFO: Flushed batch: orders=200 items=352
[2025-09-08T14:55:34.534+0530] {subprocess.py:93} INFO - 2025-09-08 14:55:34,533 WARNING: Failed to send webhook notification: HTTPConnectionPool(host='localhost', port=5000): Max retries exceeded with url: /webhook (Caused by NewConnectionError('<urllib3.connection.HTTPConnection object at 0x7d4fd96a5c30>: Failed to establish a new connection: [Errno 111] Connection refused'))
[2025-09-08T14:55:35.249+0530] {subprocess.py:93} INFO - 2025-09-08 14:55:35,249 INFO: Flushed batch: orders=200 items=334
[2025-09-08T14:55:35.252+0530] {subprocess.py:93} INFO - 2025-09-08 14:55:35,252 WARNING: Failed to send webhook notification: HTTPConnectionPool(host='localhost', port=5000): Max retries exceeded with url: /webhook (Caused by NewConnectionError('<urllib3.connection.HTTPConnection object at 0x7d4fd96a7fa0>: Failed to establish a new connection: [Errno 111] Connection refused'))
[2025-09-08T14:55:36.087+0530] {subprocess.py:93} INFO - 2025-09-08 14:55:36,086 INFO: Flushed batch: orders=200 items=376
[2025-09-08T14:55:36.090+0530] {subprocess.py:93} INFO - 2025-09-08 14:55:36,089 WARNING: Failed to send webhook notification: HTTPConnectionPool(host='localhost', port=5000): Max retries exceeded with url: /webhook (Caused by NewConnectionError('<urllib3.connection.HTTPConnection object at 0x7d4fd95f8d00>: Failed to establish a new connection: [Errno 111] Connection refused'))
[2025-09-08T14:55:36.334+0530] {subprocess.py:93} INFO - 2025-09-08 14:55:36,334 INFO: Flushed batch: orders=200 items=372
[2025-09-08T14:55:36.337+0530] {subprocess.py:93} INFO - 2025-09-08 14:55:36,337 WARNING: Failed to send webhook notification: HTTPConnectionPool(host='localhost', port=5000): Max retries exceeded with url: /webhook (Caused by NewConnectionError('<urllib3.connection.HTTPConnection object at 0x7d4fd9412410>: Failed to establish a new connection: [Errno 111] Connection refused'))
[2025-09-08T14:55:37.037+0530] {subprocess.py:93} INFO - 2025-09-08 14:55:37,037 INFO: Flushed batch: orders=200 items=338
[2025-09-08T14:55:37.039+0530] {subprocess.py:93} INFO - 2025-09-08 14:55:37,039 WARNING: Failed to send webhook notification: HTTPConnectionPool(host='localhost', port=5000): Max retries exceeded with url: /webhook (Caused by NewConnectionError('<urllib3.connection.HTTPConnection object at 0x7d4fd9410310>: Failed to establish a new connection: [Errno 111] Connection refused'))
[2025-09-08T14:55:37.710+0530] {subprocess.py:93} INFO - 2025-09-08 14:55:37,710 INFO: Flushed batch: orders=200 items=344
[2025-09-08T14:55:37.713+0530] {subprocess.py:93} INFO - 2025-09-08 14:55:37,713 WARNING: Failed to send webhook notification: HTTPConnectionPool(host='localhost', port=5000): Max retries exceeded with url: /webhook (Caused by NewConnectionError('<urllib3.connection.HTTPConnection object at 0x7d4fd95e8790>: Failed to establish a new connection: [Errno 111] Connection refused'))
[2025-09-08T14:55:38.037+0530] {subprocess.py:93} INFO - 2025-09-08 14:55:38,036 INFO: Flushed batch: orders=200 items=347
[2025-09-08T14:55:38.042+0530] {subprocess.py:93} INFO - 2025-09-08 14:55:38,041 WARNING: Failed to send webhook notification: HTTPConnectionPool(host='localhost', port=5000): Max retries exceeded with url: /webhook (Caused by NewConnectionError('<urllib3.connection.HTTPConnection object at 0x7d4fd941dc90>: Failed to establish a new connection: [Errno 111] Connection refused'))
[2025-09-08T14:55:38.787+0530] {subprocess.py:93} INFO - 2025-09-08 14:55:38,787 INFO: Flushed batch: orders=200 items=352
[2025-09-08T14:55:38.790+0530] {subprocess.py:93} INFO - 2025-09-08 14:55:38,790 WARNING: Failed to send webhook notification: HTTPConnectionPool(host='localhost', port=5000): Max retries exceeded with url: /webhook (Caused by NewConnectionError('<urllib3.connection.HTTPConnection object at 0x7d4fd941ea70>: Failed to establish a new connection: [Errno 111] Connection refused'))
[2025-09-08T14:55:39.249+0530] {subprocess.py:93} INFO - 2025-09-08 14:55:39,249 INFO: Flushed batch: orders=200 items=358
[2025-09-08T14:55:39.252+0530] {subprocess.py:93} INFO - 2025-09-08 14:55:39,252 WARNING: Failed to send webhook notification: HTTPConnectionPool(host='localhost', port=5000): Max retries exceeded with url: /webhook (Caused by NewConnectionError('<urllib3.connection.HTTPConnection object at 0x7d4fd95d2f50>: Failed to establish a new connection: [Errno 111] Connection refused'))
[2025-09-08T14:55:39.781+0530] {subprocess.py:93} INFO - 2025-09-08 14:55:39,780 INFO: Flushed batch: orders=200 items=331
[2025-09-08T14:55:39.783+0530] {subprocess.py:93} INFO - 2025-09-08 14:55:39,783 WARNING: Failed to send webhook notification: HTTPConnectionPool(host='localhost', port=5000): Max retries exceeded with url: /webhook (Caused by NewConnectionError('<urllib3.connection.HTTPConnection object at 0x7d4fd9436ce0>: Failed to establish a new connection: [Errno 111] Connection refused'))
[2025-09-08T14:55:40.131+0530] {subprocess.py:93} INFO - 2025-09-08 14:55:40,131 INFO: Flushed batch: orders=200 items=355
[2025-09-08T14:55:40.134+0530] {subprocess.py:93} INFO - 2025-09-08 14:55:40,134 WARNING: Failed to send webhook notification: HTTPConnectionPool(host='localhost', port=5000): Max retries exceeded with url: /webhook (Caused by NewConnectionError('<urllib3.connection.HTTPConnection object at 0x7d4fd9574100>: Failed to establish a new connection: [Errno 111] Connection refused'))
[2025-09-08T14:55:40.829+0530] {subprocess.py:93} INFO - 2025-09-08 14:55:40,829 INFO: Flushed batch: orders=200 items=359
[2025-09-08T14:55:40.832+0530] {subprocess.py:93} INFO - 2025-09-08 14:55:40,832 WARNING: Failed to send webhook notification: HTTPConnectionPool(host='localhost', port=5000): Max retries exceeded with url: /webhook (Caused by NewConnectionError('<urllib3.connection.HTTPConnection object at 0x7d4fd9576830>: Failed to establish a new connection: [Errno 111] Connection refused'))
[2025-09-08T14:55:41.093+0530] {subprocess.py:93} INFO - 2025-09-08 14:55:41,092 INFO: Flushed batch: orders=200 items=369
[2025-09-08T14:55:41.095+0530] {subprocess.py:93} INFO - 2025-09-08 14:55:41,095 WARNING: Failed to send webhook notification: HTTPConnectionPool(host='localhost', port=5000): Max retries exceeded with url: /webhook (Caused by NewConnectionError('<urllib3.connection.HTTPConnection object at 0x7d4fd95742b0>: Failed to establish a new connection: [Errno 111] Connection refused'))
[2025-09-08T14:55:41.435+0530] {subprocess.py:93} INFO - 2025-09-08 14:55:41,434 INFO: Flushed batch: orders=200 items=343
[2025-09-08T14:55:41.437+0530] {subprocess.py:93} INFO - 2025-09-08 14:55:41,437 WARNING: Failed to send webhook notification: HTTPConnectionPool(host='localhost', port=5000): Max retries exceeded with url: /webhook (Caused by NewConnectionError('<urllib3.connection.HTTPConnection object at 0x7d4fd95745e0>: Failed to establish a new connection: [Errno 111] Connection refused'))
[2025-09-08T14:55:41.860+0530] {subprocess.py:93} INFO - 2025-09-08 14:55:41,860 INFO: Flushed batch: orders=200 items=354
[2025-09-08T14:55:41.863+0530] {subprocess.py:93} INFO - 2025-09-08 14:55:41,863 WARNING: Failed to send webhook notification: HTTPConnectionPool(host='localhost', port=5000): Max retries exceeded with url: /webhook (Caused by NewConnectionError('<urllib3.connection.HTTPConnection object at 0x7d4fd9434220>: Failed to establish a new connection: [Errno 111] Connection refused'))
[2025-09-08T14:55:42.361+0530] {subprocess.py:93} INFO - 2025-09-08 14:55:42,361 INFO: Flushed batch: orders=200 items=340
[2025-09-08T14:55:42.364+0530] {subprocess.py:93} INFO - 2025-09-08 14:55:42,364 WARNING: Failed to send webhook notification: HTTPConnectionPool(host='localhost', port=5000): Max retries exceeded with url: /webhook (Caused by NewConnectionError('<urllib3.connection.HTTPConnection object at 0x7d4fd944d930>: Failed to establish a new connection: [Errno 111] Connection refused'))
[2025-09-08T14:55:42.827+0530] {subprocess.py:93} INFO - 2025-09-08 14:55:42,827 INFO: Flushed batch: orders=200 items=354
[2025-09-08T14:55:42.828+0530] {subprocess.py:93} INFO - 2025-09-08 14:55:42,828 WARNING: Failed to send webhook notification: HTTPConnectionPool(host='localhost', port=5000): Max retries exceeded with url: /webhook (Caused by NewConnectionError('<urllib3.connection.HTTPConnection object at 0x7d4fd94695a0>: Failed to establish a new connection: [Errno 111] Connection refused'))
[2025-09-08T14:55:43.370+0530] {subprocess.py:93} INFO - 2025-09-08 14:55:43,369 INFO: Flushed batch: orders=200 items=365
[2025-09-08T14:55:43.373+0530] {subprocess.py:93} INFO - 2025-09-08 14:55:43,372 WARNING: Failed to send webhook notification: HTTPConnectionPool(host='localhost', port=5000): Max retries exceeded with url: /webhook (Caused by NewConnectionError('<urllib3.connection.HTTPConnection object at 0x7d4fd9437a30>: Failed to establish a new connection: [Errno 111] Connection refused'))
[2025-09-08T14:55:43.837+0530] {subprocess.py:93} INFO - 2025-09-08 14:55:43,837 INFO: Flushed batch: orders=200 items=335
[2025-09-08T14:55:43.839+0530] {subprocess.py:93} INFO - 2025-09-08 14:55:43,839 WARNING: Failed to send webhook notification: HTTPConnectionPool(host='localhost', port=5000): Max retries exceeded with url: /webhook (Caused by NewConnectionError('<urllib3.connection.HTTPConnection object at 0x7d4fd9469810>: Failed to establish a new connection: [Errno 111] Connection refused'))
[2025-09-08T14:55:44.346+0530] {subprocess.py:93} INFO - 2025-09-08 14:55:44,346 INFO: Flushed batch: orders=200 items=333
[2025-09-08T14:55:44.349+0530] {subprocess.py:93} INFO - 2025-09-08 14:55:44,349 WARNING: Failed to send webhook notification: HTTPConnectionPool(host='localhost', port=5000): Max retries exceeded with url: /webhook (Caused by NewConnectionError('<urllib3.connection.HTTPConnection object at 0x7d4fd95fa2c0>: Failed to establish a new connection: [Errno 111] Connection refused'))
[2025-09-08T14:55:44.647+0530] {subprocess.py:93} INFO - 2025-09-08 14:55:44,647 INFO: Flushed batch: orders=200 items=327
[2025-09-08T14:55:44.650+0530] {subprocess.py:93} INFO - 2025-09-08 14:55:44,650 WARNING: Failed to send webhook notification: HTTPConnectionPool(host='localhost', port=5000): Max retries exceeded with url: /webhook (Caused by NewConnectionError('<urllib3.connection.HTTPConnection object at 0x7d4fd941c850>: Failed to establish a new connection: [Errno 111] Connection refused'))
[2025-09-08T14:55:45.331+0530] {subprocess.py:93} INFO - 2025-09-08 14:55:45,331 INFO: Flushed batch: orders=200 items=337
[2025-09-08T14:55:45.334+0530] {subprocess.py:93} INFO - 2025-09-08 14:55:45,334 WARNING: Failed to send webhook notification: HTTPConnectionPool(host='localhost', port=5000): Max retries exceeded with url: /webhook (Caused by NewConnectionError('<urllib3.connection.HTTPConnection object at 0x7d4fd94811b0>: Failed to establish a new connection: [Errno 111] Connection refused'))
[2025-09-08T14:55:45.540+0530] {subprocess.py:93} INFO - 2025-09-08 14:55:45,540 INFO: Flushed batch: orders=200 items=357
[2025-09-08T14:55:45.542+0530] {subprocess.py:93} INFO - 2025-09-08 14:55:45,542 WARNING: Failed to send webhook notification: HTTPConnectionPool(host='localhost', port=5000): Max retries exceeded with url: /webhook (Caused by NewConnectionError('<urllib3.connection.HTTPConnection object at 0x7d4fd96a6c50>: Failed to establish a new connection: [Errno 111] Connection refused'))
[2025-09-08T14:55:45.973+0530] {subprocess.py:93} INFO - 2025-09-08 14:55:45,973 INFO: Flushed batch: orders=200 items=342
[2025-09-08T14:55:45.975+0530] {subprocess.py:93} INFO - 2025-09-08 14:55:45,975 WARNING: Failed to send webhook notification: HTTPConnectionPool(host='localhost', port=5000): Max retries exceeded with url: /webhook (Caused by NewConnectionError('<urllib3.connection.HTTPConnection object at 0x7d4fd95ea290>: Failed to establish a new connection: [Errno 111] Connection refused'))
[2025-09-08T14:55:45.975+0530] {subprocess.py:93} INFO - 2025-09-08 14:55:45,975 INFO: Generated 5000 orders
[2025-09-08T14:57:21.172+0530] {subprocess.py:93} INFO - 2025-09-08 14:57:21,172 INFO: Inserted 48137 clickstream events.
[2025-09-08T14:57:21.173+0530] {subprocess.py:93} INFO - 2025-09-08 14:57:21,173 WARNING: Failed to send webhook notification: HTTPConnectionPool(host='localhost', port=5000): Max retries exceeded with url: /webhook (Caused by NewConnectionError('<urllib3.connection.HTTPConnection object at 0x7d4fd814c0d0>: Failed to establish a new connection: [Errno 111] Connection refused'))
[2025-09-08T14:57:25.198+0530] {subprocess.py:93} INFO - 2025-09-08 14:57:25,198 INFO: Validation done: orphans orders=0 items=0 inventory=0 mismatches=0
[2025-09-08T14:57:25.216+0530] {subprocess.py:93} INFO - 2025-09-08 14:57:25,216 INFO: Integrity report: {'orphan_orders': 0, 'orphan_order_items': 0, 'inventory_orphans': 0, 'order_amount_mismatches': []}
[2025-09-08T14:57:25.250+0530] {subprocess.py:93} INFO - [2025-09-08 14:57:25] ‚úÖ Synthetic data streaming completed successfully!
[2025-09-08T14:57:25.250+0530] {subprocess.py:97} INFO - Command exited with return code 0
[2025-09-08T14:57:25.251+0530] {taskinstance.py:441} INFO - ::group::Post task execution logs
[2025-09-08T14:57:25.503+0530] {taskinstance.py:1206} INFO - Marking task as SUCCESS. dag_id=synth_stream_5min, task_id=run_synth_stream, run_id=scheduled__2025-09-08T09:15:00+00:00, execution_date=20250908T091500, start_date=20250908T092521, end_date=20250908T092725
[2025-09-08T14:57:25.710+0530] {local_task_job_runner.py:243} INFO - Task exited with return code 0
[2025-09-08T14:57:25.727+0530] {taskinstance.py:3503} INFO - 0 downstream tasks scheduled from follow-on schedule check
[2025-09-08T14:57:25.727+0530] {local_task_job_runner.py:222} INFO - ::endgroup::
