[2025-09-08T13:42:17.075+0530] {local_task_job_runner.py:120} INFO - ::group::Pre task execution logs
[2025-09-08T13:42:17.315+0530] {taskinstance.py:2076} INFO - Dependencies all met for dep_context=non-requeueable deps ti=<TaskInstance: synth_stream_5min.run_synth_stream scheduled__2025-09-08T08:05:00+00:00 [queued]>
[2025-09-08T13:42:17.326+0530] {taskinstance.py:2076} INFO - Dependencies all met for dep_context=requeueable deps ti=<TaskInstance: synth_stream_5min.run_synth_stream scheduled__2025-09-08T08:05:00+00:00 [queued]>
[2025-09-08T13:42:17.327+0530] {taskinstance.py:2306} INFO - Starting attempt 1 of 2
[2025-09-08T13:42:17.389+0530] {taskinstance.py:2330} INFO - Executing <Task(BashOperator): run_synth_stream> on 2025-09-08 08:05:00+00:00
[2025-09-08T13:42:17.393+0530] {standard_task_runner.py:64} INFO - Started process 720054 to run task
[2025-09-08T13:42:17.395+0530] {standard_task_runner.py:90} INFO - Running: ['airflow', 'tasks', 'run', 'synth_stream_5min', 'run_synth_stream', 'scheduled__2025-09-08T08:05:00+00:00', '--job-id', '32', '--raw', '--subdir', 'DAGS_FOLDER/ecom_schedules.py', '--cfg-path', '/tmp/tmp_wygaf6l']
[2025-09-08T13:42:17.396+0530] {standard_task_runner.py:91} INFO - Job 32: Subtask run_synth_stream
[2025-09-08T13:42:17.467+0530] {task_command.py:426} INFO - Running <TaskInstance: synth_stream_5min.run_synth_stream scheduled__2025-09-08T08:05:00+00:00 [running]> on host softsuave-ASUS-EXPERTCENTER-D700ME-D500ME
[2025-09-08T13:42:17.721+0530] {taskinstance.py:2648} INFO - Exporting env vars: AIRFLOW_CTX_DAG_OWNER='airflow' AIRFLOW_CTX_DAG_ID='synth_stream_5min' AIRFLOW_CTX_TASK_ID='run_synth_stream' AIRFLOW_CTX_EXECUTION_DATE='2025-09-08T08:05:00+00:00' AIRFLOW_CTX_TRY_NUMBER='1' AIRFLOW_CTX_DAG_RUN_ID='scheduled__2025-09-08T08:05:00+00:00'
[2025-09-08T13:42:17.723+0530] {taskinstance.py:430} INFO - ::endgroup::
[2025-09-08T13:42:17.747+0530] {subprocess.py:63} INFO - Tmp dir root location: /tmp
[2025-09-08T13:42:17.748+0530] {subprocess.py:75} INFO - Running command: ['/usr/bin/bash', '-c', 'bash /media/softsuave/DATA-HDD/DataEngineering/Apache_Airflow/scripts/synth/run_synth_stream.sh | cat']
[2025-09-08T13:42:17.765+0530] {subprocess.py:86} INFO - Output:
[2025-09-08T13:42:17.856+0530] {subprocess.py:93} INFO - [2025-09-08 13:42:17] üöÄ Starting Synthetic E-commerce Data Stream...
[2025-09-08T13:42:17.856+0530] {subprocess.py:93} INFO - ----------------------------------------------
[2025-09-08T13:42:17.856+0530] {subprocess.py:93} INFO -  Database   : ecom_db
[2025-09-08T13:42:17.856+0530] {subprocess.py:93} INFO -  User       : sa
[2025-09-08T13:42:17.857+0530] {subprocess.py:93} INFO -  Server     : localhost:1433
[2025-09-08T13:42:17.857+0530] {subprocess.py:93} INFO -  Interval   : 5 min
[2025-09-08T13:42:17.857+0530] {subprocess.py:93} INFO -  Orders     : 50
[2025-09-08T13:42:17.857+0530] {subprocess.py:93} INFO -  Clicks     : 100
[2025-09-08T13:42:17.857+0530] {subprocess.py:93} INFO -  Webhook    : http://localhost:5000/webhook
[2025-09-08T13:42:17.857+0530] {subprocess.py:93} INFO - ----------------------------------------------
[2025-09-08T13:42:17.857+0530] {subprocess.py:93} INFO - 
[2025-09-08T13:42:17.952+0530] {subprocess.py:93} INFO - [2025-09-08 13:42:17] üîß Activating virtual environment...
[2025-09-08T13:42:18.005+0530] {subprocess.py:93} INFO - [2025-09-08 13:42:18] üîç Checking database connection...
[2025-09-08T13:42:18.342+0530] {subprocess.py:93} INFO - ‚úÖ Database connection successful
[2025-09-08T13:42:18.373+0530] {subprocess.py:93} INFO - [2025-09-08 13:42:18] üîÑ Starting synthetic data stream...
[2025-09-08T13:42:18.374+0530] {subprocess.py:93} INFO - Press Ctrl+C to stop
[2025-09-08T13:42:18.374+0530] {subprocess.py:93} INFO - 
[2025-09-08T13:42:18.790+0530] {subprocess.py:93} INFO - 2025-09-08 13:42:18,790 INFO: Tables ensured/created (if needed).
[2025-09-08T13:42:18.834+0530] {subprocess.py:93} INFO - 2025-09-08 13:42:18,834 INFO: Customers: 1000 already present; skipping seeding.
[2025-09-08T13:42:18.835+0530] {subprocess.py:93} INFO - 2025-09-08 13:42:18,835 INFO: Products: 500 already present; skipping seeding.
[2025-09-08T13:42:18.836+0530] {subprocess.py:93} INFO - 2025-09-08 13:42:18,835 INFO: Running one-shot generation: orders=5000, sessions=3000
[2025-09-08T13:42:18.843+0530] {subprocess.py:93} INFO - /media/softsuave/DATA-HDD/DataEngineering/Apache_Airflow/src/synth_ecom_mssql_stream.py:397: RemovedIn20Warning: Deprecated API features detected! These feature(s) are not compatible with SQLAlchemy 2.0. To prevent incompatible upgrades prior to updating applications, ensure requirements files are pinned to "sqlalchemy<2.0". Set environment variable SQLALCHEMY_WARN_20=1 to show all deprecation warnings.  Set environment variable SQLALCHEMY_SILENCE_UBER_WARNING=1 to silence this message. (Background on SQLAlchemy 2.0 at: https://sqlalche.me/e/b8d9)
[2025-09-08T13:42:18.844+0530] {subprocess.py:93} INFO -   customers = [dict(r) for r in conn.execute(select(self.tables["customers"])).fetchall()]
[2025-09-08T13:42:18.854+0530] {subprocess.py:93} INFO - 2025-09-08 13:42:18,854 INFO: Generating 5000 orders (batch_size=200, force_order_date_now=False)...
[2025-09-08T13:42:19.409+0530] {subprocess.py:93} INFO - 2025-09-08 13:42:19,409 INFO: Flushed batch: orders=200 items=331
[2025-09-08T13:42:19.411+0530] {subprocess.py:93} INFO - 2025-09-08 13:42:19,411 WARNING: Failed to send webhook notification: HTTPConnectionPool(host='localhost', port=5000): Max retries exceeded with url: /webhook (Caused by NewConnectionError('<urllib3.connection.HTTPConnection object at 0x7396a8127280>: Failed to establish a new connection: [Errno 111] Connection refused'))
[2025-09-08T13:42:19.576+0530] {subprocess.py:93} INFO - 2025-09-08 13:42:19,576 INFO: Flushed batch: orders=200 items=353
[2025-09-08T13:42:19.579+0530] {subprocess.py:93} INFO - 2025-09-08 13:42:19,578 WARNING: Failed to send webhook notification: HTTPConnectionPool(host='localhost', port=5000): Max retries exceeded with url: /webhook (Caused by NewConnectionError('<urllib3.connection.HTTPConnection object at 0x7396a81246a0>: Failed to establish a new connection: [Errno 111] Connection refused'))
[2025-09-08T13:42:19.761+0530] {subprocess.py:93} INFO - 2025-09-08 13:42:19,760 INFO: Flushed batch: orders=200 items=351
[2025-09-08T13:42:19.762+0530] {subprocess.py:93} INFO - 2025-09-08 13:42:19,761 WARNING: Failed to send webhook notification: HTTPConnectionPool(host='localhost', port=5000): Max retries exceeded with url: /webhook (Caused by NewConnectionError('<urllib3.connection.HTTPConnection object at 0x7396a80d0af0>: Failed to establish a new connection: [Errno 111] Connection refused'))
[2025-09-08T13:42:20.111+0530] {subprocess.py:93} INFO - 2025-09-08 13:42:20,110 INFO: Flushed batch: orders=200 items=365
[2025-09-08T13:42:20.113+0530] {subprocess.py:93} INFO - 2025-09-08 13:42:20,113 WARNING: Failed to send webhook notification: HTTPConnectionPool(host='localhost', port=5000): Max retries exceeded with url: /webhook (Caused by NewConnectionError('<urllib3.connection.HTTPConnection object at 0x7396a7f106a0>: Failed to establish a new connection: [Errno 111] Connection refused'))
[2025-09-08T13:42:20.345+0530] {subprocess.py:93} INFO - 2025-09-08 13:42:20,345 INFO: Flushed batch: orders=200 items=358
[2025-09-08T13:42:20.348+0530] {subprocess.py:93} INFO - 2025-09-08 13:42:20,348 WARNING: Failed to send webhook notification: HTTPConnectionPool(host='localhost', port=5000): Max retries exceeded with url: /webhook (Caused by NewConnectionError('<urllib3.connection.HTTPConnection object at 0x7396a7f127a0>: Failed to establish a new connection: [Errno 111] Connection refused'))
[2025-09-08T13:42:20.553+0530] {subprocess.py:93} INFO - 2025-09-08 13:42:20,552 INFO: Flushed batch: orders=200 items=366
[2025-09-08T13:42:20.555+0530] {subprocess.py:93} INFO - 2025-09-08 13:42:20,555 WARNING: Failed to send webhook notification: HTTPConnectionPool(host='localhost', port=5000): Max retries exceeded with url: /webhook (Caused by NewConnectionError('<urllib3.connection.HTTPConnection object at 0x7396a7f27c40>: Failed to establish a new connection: [Errno 111] Connection refused'))
[2025-09-08T13:42:20.728+0530] {subprocess.py:93} INFO - 2025-09-08 13:42:20,728 INFO: Flushed batch: orders=200 items=350
[2025-09-08T13:42:20.731+0530] {subprocess.py:93} INFO - 2025-09-08 13:42:20,731 WARNING: Failed to send webhook notification: HTTPConnectionPool(host='localhost', port=5000): Max retries exceeded with url: /webhook (Caused by NewConnectionError('<urllib3.connection.HTTPConnection object at 0x7396a808c8b0>: Failed to establish a new connection: [Errno 111] Connection refused'))
[2025-09-08T13:42:21.012+0530] {subprocess.py:93} INFO - 2025-09-08 13:42:21,012 INFO: Flushed batch: orders=200 items=373
[2025-09-08T13:42:21.015+0530] {subprocess.py:93} INFO - 2025-09-08 13:42:21,014 WARNING: Failed to send webhook notification: HTTPConnectionPool(host='localhost', port=5000): Max retries exceeded with url: /webhook (Caused by NewConnectionError('<urllib3.connection.HTTPConnection object at 0x7396a7f252d0>: Failed to establish a new connection: [Errno 111] Connection refused'))
[2025-09-08T13:42:21.187+0530] {subprocess.py:93} INFO - 2025-09-08 13:42:21,187 INFO: Flushed batch: orders=200 items=340
[2025-09-08T13:42:21.190+0530] {subprocess.py:93} INFO - 2025-09-08 13:42:21,189 WARNING: Failed to send webhook notification: HTTPConnectionPool(host='localhost', port=5000): Max retries exceeded with url: /webhook (Caused by NewConnectionError('<urllib3.connection.HTTPConnection object at 0x7396a7f25b40>: Failed to establish a new connection: [Errno 111] Connection refused'))
[2025-09-08T13:42:21.379+0530] {subprocess.py:93} INFO - 2025-09-08 13:42:21,378 INFO: Flushed batch: orders=200 items=352
[2025-09-08T13:42:21.381+0530] {subprocess.py:93} INFO - 2025-09-08 13:42:21,381 WARNING: Failed to send webhook notification: HTTPConnectionPool(host='localhost', port=5000): Max retries exceeded with url: /webhook (Caused by NewConnectionError('<urllib3.connection.HTTPConnection object at 0x7396a814fe20>: Failed to establish a new connection: [Errno 111] Connection refused'))
[2025-09-08T13:42:21.646+0530] {subprocess.py:93} INFO - 2025-09-08 13:42:21,645 INFO: Flushed batch: orders=200 items=341
[2025-09-08T13:42:21.649+0530] {subprocess.py:93} INFO - 2025-09-08 13:42:21,649 WARNING: Failed to send webhook notification: HTTPConnectionPool(host='localhost', port=5000): Max retries exceeded with url: /webhook (Caused by NewConnectionError('<urllib3.connection.HTTPConnection object at 0x7396a814ca00>: Failed to establish a new connection: [Errno 111] Connection refused'))
[2025-09-08T13:42:21.872+0530] {subprocess.py:93} INFO - 2025-09-08 13:42:21,871 INFO: Flushed batch: orders=200 items=346
[2025-09-08T13:42:21.874+0530] {subprocess.py:93} INFO - 2025-09-08 13:42:21,874 WARNING: Failed to send webhook notification: HTTPConnectionPool(host='localhost', port=5000): Max retries exceeded with url: /webhook (Caused by NewConnectionError('<urllib3.connection.HTTPConnection object at 0x7396a7f352a0>: Failed to establish a new connection: [Errno 111] Connection refused'))
[2025-09-08T13:42:22.071+0530] {subprocess.py:93} INFO - 2025-09-08 13:42:22,071 INFO: Flushed batch: orders=200 items=352
[2025-09-08T13:42:22.074+0530] {subprocess.py:93} INFO - 2025-09-08 13:42:22,074 WARNING: Failed to send webhook notification: HTTPConnectionPool(host='localhost', port=5000): Max retries exceeded with url: /webhook (Caused by NewConnectionError('<urllib3.connection.HTTPConnection object at 0x7396a808e4a0>: Failed to establish a new connection: [Errno 111] Connection refused'))
[2025-09-08T13:42:22.254+0530] {subprocess.py:93} INFO - 2025-09-08 13:42:22,254 INFO: Flushed batch: orders=200 items=377
[2025-09-08T13:42:22.256+0530] {subprocess.py:93} INFO - 2025-09-08 13:42:22,255 WARNING: Failed to send webhook notification: HTTPConnectionPool(host='localhost', port=5000): Max retries exceeded with url: /webhook (Caused by NewConnectionError('<urllib3.connection.HTTPConnection object at 0x7396a7f1c190>: Failed to establish a new connection: [Errno 111] Connection refused'))
[2025-09-08T13:42:22.421+0530] {subprocess.py:93} INFO - 2025-09-08 13:42:22,421 INFO: Flushed batch: orders=200 items=327
[2025-09-08T13:42:22.425+0530] {subprocess.py:93} INFO - 2025-09-08 13:42:22,424 WARNING: Failed to send webhook notification: HTTPConnectionPool(host='localhost', port=5000): Max retries exceeded with url: /webhook (Caused by NewConnectionError('<urllib3.connection.HTTPConnection object at 0x7396a7f34190>: Failed to establish a new connection: [Errno 111] Connection refused'))
[2025-09-08T13:42:22.731+0530] {subprocess.py:93} INFO - 2025-09-08 13:42:22,730 INFO: Flushed batch: orders=200 items=321
[2025-09-08T13:42:22.734+0530] {subprocess.py:93} INFO - 2025-09-08 13:42:22,733 WARNING: Failed to send webhook notification: HTTPConnectionPool(host='localhost', port=5000): Max retries exceeded with url: /webhook (Caused by NewConnectionError('<urllib3.connection.HTTPConnection object at 0x7396a80d29b0>: Failed to establish a new connection: [Errno 111] Connection refused'))
[2025-09-08T13:42:22.897+0530] {subprocess.py:93} INFO - 2025-09-08 13:42:22,897 INFO: Flushed batch: orders=200 items=345
[2025-09-08T13:42:22.899+0530] {subprocess.py:93} INFO - 2025-09-08 13:42:22,899 WARNING: Failed to send webhook notification: HTTPConnectionPool(host='localhost', port=5000): Max retries exceeded with url: /webhook (Caused by NewConnectionError('<urllib3.connection.HTTPConnection object at 0x7396a814cfa0>: Failed to establish a new connection: [Errno 111] Connection refused'))
[2025-09-08T13:42:23.080+0530] {subprocess.py:93} INFO - 2025-09-08 13:42:23,080 INFO: Flushed batch: orders=200 items=331
[2025-09-08T13:42:23.082+0530] {subprocess.py:93} INFO - 2025-09-08 13:42:23,082 WARNING: Failed to send webhook notification: HTTPConnectionPool(host='localhost', port=5000): Max retries exceeded with url: /webhook (Caused by NewConnectionError('<urllib3.connection.HTTPConnection object at 0x7396a7f02530>: Failed to establish a new connection: [Errno 111] Connection refused'))
[2025-09-08T13:42:23.272+0530] {subprocess.py:93} INFO - 2025-09-08 13:42:23,272 INFO: Flushed batch: orders=200 items=315
[2025-09-08T13:42:23.275+0530] {subprocess.py:93} INFO - 2025-09-08 13:42:23,275 WARNING: Failed to send webhook notification: HTTPConnectionPool(host='localhost', port=5000): Max retries exceeded with url: /webhook (Caused by NewConnectionError('<urllib3.connection.HTTPConnection object at 0x7396a7f10b50>: Failed to establish a new connection: [Errno 111] Connection refused'))
[2025-09-08T13:42:23.447+0530] {subprocess.py:93} INFO - 2025-09-08 13:42:23,447 INFO: Flushed batch: orders=200 items=324
[2025-09-08T13:42:23.450+0530] {subprocess.py:93} INFO - 2025-09-08 13:42:23,449 WARNING: Failed to send webhook notification: HTTPConnectionPool(host='localhost', port=5000): Max retries exceeded with url: /webhook (Caused by NewConnectionError('<urllib3.connection.HTTPConnection object at 0x7396a7f1d7b0>: Failed to establish a new connection: [Errno 111] Connection refused'))
[2025-09-08T13:42:23.623+0530] {subprocess.py:93} INFO - 2025-09-08 13:42:23,622 INFO: Flushed batch: orders=200 items=353
[2025-09-08T13:42:23.625+0530] {subprocess.py:93} INFO - 2025-09-08 13:42:23,625 WARNING: Failed to send webhook notification: HTTPConnectionPool(host='localhost', port=5000): Max retries exceeded with url: /webhook (Caused by NewConnectionError('<urllib3.connection.HTTPConnection object at 0x7396a7f36860>: Failed to establish a new connection: [Errno 111] Connection refused'))
[2025-09-08T13:42:23.814+0530] {subprocess.py:93} INFO - 2025-09-08 13:42:23,814 INFO: Flushed batch: orders=200 items=370
[2025-09-08T13:42:23.817+0530] {subprocess.py:93} INFO - 2025-09-08 13:42:23,817 WARNING: Failed to send webhook notification: HTTPConnectionPool(host='localhost', port=5000): Max retries exceeded with url: /webhook (Caused by NewConnectionError('<urllib3.connection.HTTPConnection object at 0x7396a7f24dc0>: Failed to establish a new connection: [Errno 111] Connection refused'))
[2025-09-08T13:42:24.206+0530] {subprocess.py:93} INFO - 2025-09-08 13:42:24,206 INFO: Flushed batch: orders=200 items=377
[2025-09-08T13:42:24.209+0530] {subprocess.py:93} INFO - 2025-09-08 13:42:24,209 WARNING: Failed to send webhook notification: HTTPConnectionPool(host='localhost', port=5000): Max retries exceeded with url: /webhook (Caused by NewConnectionError('<urllib3.connection.HTTPConnection object at 0x7396a814c340>: Failed to establish a new connection: [Errno 111] Connection refused'))
[2025-09-08T13:42:24.424+0530] {subprocess.py:93} INFO - 2025-09-08 13:42:24,424 INFO: Flushed batch: orders=200 items=353
[2025-09-08T13:42:24.427+0530] {subprocess.py:93} INFO - 2025-09-08 13:42:24,427 WARNING: Failed to send webhook notification: HTTPConnectionPool(host='localhost', port=5000): Max retries exceeded with url: /webhook (Caused by NewConnectionError('<urllib3.connection.HTTPConnection object at 0x7396a87a82b0>: Failed to establish a new connection: [Errno 111] Connection refused'))
[2025-09-08T13:42:24.608+0530] {subprocess.py:93} INFO - 2025-09-08 13:42:24,608 INFO: Flushed batch: orders=200 items=349
[2025-09-08T13:42:24.611+0530] {subprocess.py:93} INFO - 2025-09-08 13:42:24,611 WARNING: Failed to send webhook notification: HTTPConnectionPool(host='localhost', port=5000): Max retries exceeded with url: /webhook (Caused by NewConnectionError('<urllib3.connection.HTTPConnection object at 0x7396a87c9990>: Failed to establish a new connection: [Errno 111] Connection refused'))
[2025-09-08T13:42:24.612+0530] {subprocess.py:93} INFO - 2025-09-08 13:42:24,611 INFO: Generated 5000 orders
[2025-09-08T13:42:55.580+0530] {subprocess.py:93} INFO - 2025-09-08 13:42:55,580 INFO: Inserted 48075 clickstream events.
[2025-09-08T13:42:55.581+0530] {subprocess.py:93} INFO - 2025-09-08 13:42:55,581 WARNING: Failed to send webhook notification: HTTPConnectionPool(host='localhost', port=5000): Max retries exceeded with url: /webhook (Caused by NewConnectionError('<urllib3.connection.HTTPConnection object at 0x7396a6de3850>: Failed to establish a new connection: [Errno 111] Connection refused'))
[2025-09-08T13:42:56.709+0530] {subprocess.py:93} INFO - 2025-09-08 13:42:56,709 INFO: Validation done: orphans orders=0 items=0 inventory=0 mismatches=0
[2025-09-08T13:42:56.714+0530] {subprocess.py:93} INFO - 2025-09-08 13:42:56,714 INFO: Integrity report: {'orphan_orders': 0, 'orphan_order_items': 0, 'inventory_orphans': 0, 'order_amount_mismatches': []}
[2025-09-08T13:42:56.745+0530] {subprocess.py:93} INFO - [2025-09-08 13:42:56] ‚úÖ Synthetic data streaming completed successfully!
[2025-09-08T13:42:56.745+0530] {subprocess.py:97} INFO - Command exited with return code 0
[2025-09-08T13:42:56.746+0530] {taskinstance.py:441} INFO - ::group::Post task execution logs
[2025-09-08T13:42:56.988+0530] {taskinstance.py:1206} INFO - Marking task as SUCCESS. dag_id=synth_stream_5min, task_id=run_synth_stream, run_id=scheduled__2025-09-08T08:05:00+00:00, execution_date=20250908T080500, start_date=20250908T081217, end_date=20250908T081256
[2025-09-08T13:42:57.225+0530] {local_task_job_runner.py:243} INFO - Task exited with return code 0
[2025-09-08T13:42:57.235+0530] {taskinstance.py:3503} INFO - 0 downstream tasks scheduled from follow-on schedule check
[2025-09-08T13:42:57.235+0530] {local_task_job_runner.py:222} INFO - ::endgroup::
