[2025-09-08T14:05:40.040+0530] {local_task_job_runner.py:120} INFO - ::group::Pre task execution logs
[2025-09-08T14:05:40.052+0530] {taskinstance.py:2076} INFO - Dependencies all met for dep_context=non-requeueable deps ti=<TaskInstance: synth_stream_5min.run_synth_stream scheduled__2025-09-08T08:30:00+00:00 [queued]>
[2025-09-08T14:05:40.054+0530] {taskinstance.py:2076} INFO - Dependencies all met for dep_context=requeueable deps ti=<TaskInstance: synth_stream_5min.run_synth_stream scheduled__2025-09-08T08:30:00+00:00 [queued]>
[2025-09-08T14:05:40.055+0530] {taskinstance.py:2306} INFO - Starting attempt 1 of 2
[2025-09-08T14:05:40.280+0530] {taskinstance.py:2330} INFO - Executing <Task(BashOperator): run_synth_stream> on 2025-09-08 08:30:00+00:00
[2025-09-08T14:05:40.287+0530] {standard_task_runner.py:64} INFO - Started process 725760 to run task
[2025-09-08T14:05:40.290+0530] {standard_task_runner.py:90} INFO - Running: ['airflow', 'tasks', 'run', 'synth_stream_5min', 'run_synth_stream', 'scheduled__2025-09-08T08:30:00+00:00', '--job-id', '39', '--raw', '--subdir', 'DAGS_FOLDER/ecom_schedules.py', '--cfg-path', '/tmp/tmpny62oeaz']
[2025-09-08T14:05:40.293+0530] {standard_task_runner.py:91} INFO - Job 39: Subtask run_synth_stream
[2025-09-08T14:05:40.639+0530] {task_command.py:426} INFO - Running <TaskInstance: synth_stream_5min.run_synth_stream scheduled__2025-09-08T08:30:00+00:00 [running]> on host softsuave-ASUS-EXPERTCENTER-D700ME-D500ME
[2025-09-08T14:05:41.094+0530] {taskinstance.py:2648} INFO - Exporting env vars: AIRFLOW_CTX_DAG_OWNER='airflow' AIRFLOW_CTX_DAG_ID='synth_stream_5min' AIRFLOW_CTX_TASK_ID='run_synth_stream' AIRFLOW_CTX_EXECUTION_DATE='2025-09-08T08:30:00+00:00' AIRFLOW_CTX_TRY_NUMBER='1' AIRFLOW_CTX_DAG_RUN_ID='scheduled__2025-09-08T08:30:00+00:00'
[2025-09-08T14:05:41.095+0530] {taskinstance.py:430} INFO - ::endgroup::
[2025-09-08T14:05:41.095+0530] {subprocess.py:63} INFO - Tmp dir root location: /tmp
[2025-09-08T14:05:41.096+0530] {subprocess.py:75} INFO - Running command: ['/usr/bin/bash', '-c', 'bash /media/softsuave/DATA-HDD/DataEngineering/Apache_Airflow/scripts/synth/run_synth_stream.sh | cat']
[2025-09-08T14:05:41.103+0530] {subprocess.py:86} INFO - Output:
[2025-09-08T14:05:41.142+0530] {subprocess.py:93} INFO - [2025-09-08 14:05:41] üöÄ Starting Synthetic E-commerce Data Stream...
[2025-09-08T14:05:41.142+0530] {subprocess.py:93} INFO - ----------------------------------------------
[2025-09-08T14:05:41.142+0530] {subprocess.py:93} INFO -  Database   : ecom_db
[2025-09-08T14:05:41.142+0530] {subprocess.py:93} INFO -  User       : sa
[2025-09-08T14:05:41.142+0530] {subprocess.py:93} INFO -  Server     : localhost:1433
[2025-09-08T14:05:41.142+0530] {subprocess.py:93} INFO -  Interval   : 5 min
[2025-09-08T14:05:41.142+0530] {subprocess.py:93} INFO -  Orders     : 50
[2025-09-08T14:05:41.142+0530] {subprocess.py:93} INFO -  Clicks     : 100
[2025-09-08T14:05:41.142+0530] {subprocess.py:93} INFO -  Webhook    : http://localhost:5000/webhook
[2025-09-08T14:05:41.142+0530] {subprocess.py:93} INFO - ----------------------------------------------
[2025-09-08T14:05:41.142+0530] {subprocess.py:93} INFO - 
[2025-09-08T14:05:41.163+0530] {subprocess.py:93} INFO - [2025-09-08 14:05:41] üîß Activating virtual environment...
[2025-09-08T14:05:41.165+0530] {subprocess.py:93} INFO - [2025-09-08 14:05:41] üîç Checking database connection...
[2025-09-08T14:05:41.191+0530] {subprocess.py:93} INFO - ‚úÖ Database connection successful
[2025-09-08T14:05:41.197+0530] {subprocess.py:93} INFO - [2025-09-08 14:05:41] üîÑ Starting synthetic data stream...
[2025-09-08T14:05:41.197+0530] {subprocess.py:93} INFO - Press Ctrl+C to stop
[2025-09-08T14:05:41.197+0530] {subprocess.py:93} INFO - 
[2025-09-08T14:05:41.382+0530] {subprocess.py:93} INFO - 2025-09-08 14:05:41,382 INFO: Tables ensured/created (if needed).
[2025-09-08T14:05:41.396+0530] {subprocess.py:93} INFO - 2025-09-08 14:05:41,396 INFO: Customers: 1000 already present; skipping seeding.
[2025-09-08T14:05:41.397+0530] {subprocess.py:93} INFO - 2025-09-08 14:05:41,397 INFO: Products: 500 already present; skipping seeding.
[2025-09-08T14:05:41.397+0530] {subprocess.py:93} INFO - 2025-09-08 14:05:41,397 INFO: Running one-shot generation: orders=5000, sessions=3000
[2025-09-08T14:05:41.403+0530] {subprocess.py:93} INFO - /media/softsuave/DATA-HDD/DataEngineering/Apache_Airflow/src/synth_ecom_mssql_stream.py:397: RemovedIn20Warning: Deprecated API features detected! These feature(s) are not compatible with SQLAlchemy 2.0. To prevent incompatible upgrades prior to updating applications, ensure requirements files are pinned to "sqlalchemy<2.0". Set environment variable SQLALCHEMY_WARN_20=1 to show all deprecation warnings.  Set environment variable SQLALCHEMY_SILENCE_UBER_WARNING=1 to silence this message. (Background on SQLAlchemy 2.0 at: https://sqlalche.me/e/b8d9)
[2025-09-08T14:05:41.404+0530] {subprocess.py:93} INFO -   customers = [dict(r) for r in conn.execute(select(self.tables["customers"])).fetchall()]
[2025-09-08T14:05:41.411+0530] {subprocess.py:93} INFO - 2025-09-08 14:05:41,411 INFO: Generating 5000 orders (batch_size=200, force_order_date_now=False)...
[2025-09-08T14:05:41.853+0530] {subprocess.py:93} INFO - 2025-09-08 14:05:41,852 INFO: Flushed batch: orders=200 items=369
[2025-09-08T14:05:41.858+0530] {subprocess.py:93} INFO - 2025-09-08 14:05:41,858 WARNING: Failed to send webhook notification: HTTPConnectionPool(host='localhost', port=5000): Max retries exceeded with url: /webhook (Caused by NewConnectionError('<urllib3.connection.HTTPConnection object at 0x725674192620>: Failed to establish a new connection: [Errno 111] Connection refused'))
[2025-09-08T14:05:42.853+0530] {subprocess.py:93} INFO - 2025-09-08 14:05:42,852 INFO: Flushed batch: orders=200 items=360
[2025-09-08T14:05:42.856+0530] {subprocess.py:93} INFO - 2025-09-08 14:05:42,855 WARNING: Failed to send webhook notification: HTTPConnectionPool(host='localhost', port=5000): Max retries exceeded with url: /webhook (Caused by NewConnectionError('<urllib3.connection.HTTPConnection object at 0x725674192290>: Failed to establish a new connection: [Errno 111] Connection refused'))
[2025-09-08T14:05:43.453+0530] {subprocess.py:93} INFO - 2025-09-08 14:05:43,453 INFO: Flushed batch: orders=200 items=327
[2025-09-08T14:05:43.456+0530] {subprocess.py:93} INFO - 2025-09-08 14:05:43,456 WARNING: Failed to send webhook notification: HTTPConnectionPool(host='localhost', port=5000): Max retries exceeded with url: /webhook (Caused by NewConnectionError('<urllib3.connection.HTTPConnection object at 0x7256741da530>: Failed to establish a new connection: [Errno 111] Connection refused'))
[2025-09-08T14:05:43.903+0530] {subprocess.py:93} INFO - 2025-09-08 14:05:43,903 INFO: Flushed batch: orders=200 items=341
[2025-09-08T14:05:43.904+0530] {subprocess.py:93} INFO - 2025-09-08 14:05:43,903 WARNING: Failed to send webhook notification: HTTPConnectionPool(host='localhost', port=5000): Max retries exceeded with url: /webhook (Caused by NewConnectionError('<urllib3.connection.HTTPConnection object at 0x7256741f34f0>: Failed to establish a new connection: [Errno 111] Connection refused'))
[2025-09-08T14:05:44.086+0530] {subprocess.py:93} INFO - 2025-09-08 14:05:44,086 INFO: Flushed batch: orders=200 items=345
[2025-09-08T14:05:44.087+0530] {subprocess.py:93} INFO - 2025-09-08 14:05:44,087 WARNING: Failed to send webhook notification: HTTPConnectionPool(host='localhost', port=5000): Max retries exceeded with url: /webhook (Caused by NewConnectionError('<urllib3.connection.HTTPConnection object at 0x725674017af0>: Failed to establish a new connection: [Errno 111] Connection refused'))
[2025-09-08T14:05:44.423+0530] {subprocess.py:93} INFO - 2025-09-08 14:05:44,422 INFO: Flushed batch: orders=200 items=375
[2025-09-08T14:05:44.423+0530] {subprocess.py:93} INFO - 2025-09-08 14:05:44,423 WARNING: Failed to send webhook notification: HTTPConnectionPool(host='localhost', port=5000): Max retries exceeded with url: /webhook (Caused by NewConnectionError('<urllib3.connection.HTTPConnection object at 0x72567402f130>: Failed to establish a new connection: [Errno 111] Connection refused'))
[2025-09-08T14:05:44.858+0530] {subprocess.py:93} INFO - 2025-09-08 14:05:44,857 INFO: Flushed batch: orders=200 items=332
[2025-09-08T14:05:44.860+0530] {subprocess.py:93} INFO - 2025-09-08 14:05:44,860 WARNING: Failed to send webhook notification: HTTPConnectionPool(host='localhost', port=5000): Max retries exceeded with url: /webhook (Caused by NewConnectionError('<urllib3.connection.HTTPConnection object at 0x72567402f6a0>: Failed to establish a new connection: [Errno 111] Connection refused'))
[2025-09-08T14:05:45.100+0530] {subprocess.py:93} INFO - 2025-09-08 14:05:45,099 INFO: Flushed batch: orders=200 items=347
[2025-09-08T14:05:45.102+0530] {subprocess.py:93} INFO - 2025-09-08 14:05:45,102 WARNING: Failed to send webhook notification: HTTPConnectionPool(host='localhost', port=5000): Max retries exceeded with url: /webhook (Caused by NewConnectionError('<urllib3.connection.HTTPConnection object at 0x725674016350>: Failed to establish a new connection: [Errno 111] Connection refused'))
[2025-09-08T14:05:45.300+0530] {subprocess.py:93} INFO - 2025-09-08 14:05:45,300 INFO: Flushed batch: orders=200 items=350
[2025-09-08T14:05:45.303+0530] {subprocess.py:93} INFO - 2025-09-08 14:05:45,303 WARNING: Failed to send webhook notification: HTTPConnectionPool(host='localhost', port=5000): Max retries exceeded with url: /webhook (Caused by NewConnectionError('<urllib3.connection.HTTPConnection object at 0x725674016350>: Failed to establish a new connection: [Errno 111] Connection refused'))
[2025-09-08T14:05:45.643+0530] {subprocess.py:93} INFO - 2025-09-08 14:05:45,643 INFO: Flushed batch: orders=200 items=385
[2025-09-08T14:05:45.646+0530] {subprocess.py:93} INFO - 2025-09-08 14:05:45,645 WARNING: Failed to send webhook notification: HTTPConnectionPool(host='localhost', port=5000): Max retries exceeded with url: /webhook (Caused by NewConnectionError('<urllib3.connection.HTTPConnection object at 0x7256742a50f0>: Failed to establish a new connection: [Errno 111] Connection refused'))
[2025-09-08T14:05:46.059+0530] {subprocess.py:93} INFO - 2025-09-08 14:05:46,059 INFO: Flushed batch: orders=200 items=348
[2025-09-08T14:05:46.060+0530] {subprocess.py:93} INFO - 2025-09-08 14:05:46,060 WARNING: Failed to send webhook notification: HTTPConnectionPool(host='localhost', port=5000): Max retries exceeded with url: /webhook (Caused by NewConnectionError('<urllib3.connection.HTTPConnection object at 0x7256740151b0>: Failed to establish a new connection: [Errno 111] Connection refused'))
[2025-09-08T14:05:46.293+0530] {subprocess.py:93} INFO - 2025-09-08 14:05:46,293 INFO: Flushed batch: orders=200 items=349
[2025-09-08T14:05:46.296+0530] {subprocess.py:93} INFO - 2025-09-08 14:05:46,296 WARNING: Failed to send webhook notification: HTTPConnectionPool(host='localhost', port=5000): Max retries exceeded with url: /webhook (Caused by NewConnectionError('<urllib3.connection.HTTPConnection object at 0x725674035180>: Failed to establish a new connection: [Errno 111] Connection refused'))
[2025-09-08T14:05:46.559+0530] {subprocess.py:93} INFO - 2025-09-08 14:05:46,558 INFO: Flushed batch: orders=200 items=367
[2025-09-08T14:05:46.561+0530] {subprocess.py:93} INFO - 2025-09-08 14:05:46,561 WARNING: Failed to send webhook notification: HTTPConnectionPool(host='localhost', port=5000): Max retries exceeded with url: /webhook (Caused by NewConnectionError('<urllib3.connection.HTTPConnection object at 0x72567404eda0>: Failed to establish a new connection: [Errno 111] Connection refused'))
[2025-09-08T14:05:46.944+0530] {subprocess.py:93} INFO - 2025-09-08 14:05:46,944 INFO: Flushed batch: orders=200 items=341
[2025-09-08T14:05:46.947+0530] {subprocess.py:93} INFO - 2025-09-08 14:05:46,947 WARNING: Failed to send webhook notification: HTTPConnectionPool(host='localhost', port=5000): Max retries exceeded with url: /webhook (Caused by NewConnectionError('<urllib3.connection.HTTPConnection object at 0x72567402df00>: Failed to establish a new connection: [Errno 111] Connection refused'))
[2025-09-08T14:05:47.247+0530] {subprocess.py:93} INFO - 2025-09-08 14:05:47,247 INFO: Flushed batch: orders=200 items=323
[2025-09-08T14:05:47.250+0530] {subprocess.py:93} INFO - 2025-09-08 14:05:47,250 WARNING: Failed to send webhook notification: HTTPConnectionPool(host='localhost', port=5000): Max retries exceeded with url: /webhook (Caused by NewConnectionError('<urllib3.connection.HTTPConnection object at 0x7256741bac50>: Failed to establish a new connection: [Errno 111] Connection refused'))
[2025-09-08T14:05:47.687+0530] {subprocess.py:93} INFO - 2025-09-08 14:05:47,687 INFO: Flushed batch: orders=200 items=325
[2025-09-08T14:05:47.690+0530] {subprocess.py:93} INFO - 2025-09-08 14:05:47,690 WARNING: Failed to send webhook notification: HTTPConnectionPool(host='localhost', port=5000): Max retries exceeded with url: /webhook (Caused by NewConnectionError('<urllib3.connection.HTTPConnection object at 0x7256743591b0>: Failed to establish a new connection: [Errno 111] Connection refused'))
[2025-09-08T14:05:47.910+0530] {subprocess.py:93} INFO - 2025-09-08 14:05:47,910 INFO: Flushed batch: orders=200 items=329
[2025-09-08T14:05:47.913+0530] {subprocess.py:93} INFO - 2025-09-08 14:05:47,913 WARNING: Failed to send webhook notification: HTTPConnectionPool(host='localhost', port=5000): Max retries exceeded with url: /webhook (Caused by NewConnectionError('<urllib3.connection.HTTPConnection object at 0x72567404e5f0>: Failed to establish a new connection: [Errno 111] Connection refused'))
[2025-09-08T14:05:48.464+0530] {subprocess.py:93} INFO - 2025-09-08 14:05:48,464 INFO: Flushed batch: orders=200 items=334
[2025-09-08T14:05:48.467+0530] {subprocess.py:93} INFO - 2025-09-08 14:05:48,467 WARNING: Failed to send webhook notification: HTTPConnectionPool(host='localhost', port=5000): Max retries exceeded with url: /webhook (Caused by NewConnectionError('<urllib3.connection.HTTPConnection object at 0x72567406a500>: Failed to establish a new connection: [Errno 111] Connection refused'))
[2025-09-08T14:05:48.740+0530] {subprocess.py:93} INFO - 2025-09-08 14:05:48,740 INFO: Flushed batch: orders=200 items=371
[2025-09-08T14:05:48.743+0530] {subprocess.py:93} INFO - 2025-09-08 14:05:48,742 WARNING: Failed to send webhook notification: HTTPConnectionPool(host='localhost', port=5000): Max retries exceeded with url: /webhook (Caused by NewConnectionError('<urllib3.connection.HTTPConnection object at 0x725674037460>: Failed to establish a new connection: [Errno 111] Connection refused'))
[2025-09-08T14:05:49.319+0530] {subprocess.py:93} INFO - 2025-09-08 14:05:49,318 INFO: Flushed batch: orders=200 items=338
[2025-09-08T14:05:49.322+0530] {subprocess.py:93} INFO - 2025-09-08 14:05:49,321 WARNING: Failed to send webhook notification: HTTPConnectionPool(host='localhost', port=5000): Max retries exceeded with url: /webhook (Caused by NewConnectionError('<urllib3.connection.HTTPConnection object at 0x72567402e9e0>: Failed to establish a new connection: [Errno 111] Connection refused'))
[2025-09-08T14:05:49.543+0530] {subprocess.py:93} INFO - 2025-09-08 14:05:49,543 INFO: Flushed batch: orders=200 items=377
[2025-09-08T14:05:49.546+0530] {subprocess.py:93} INFO - 2025-09-08 14:05:49,546 WARNING: Failed to send webhook notification: HTTPConnectionPool(host='localhost', port=5000): Max retries exceeded with url: /webhook (Caused by NewConnectionError('<urllib3.connection.HTTPConnection object at 0x72567404fd30>: Failed to establish a new connection: [Errno 111] Connection refused'))
[2025-09-08T14:05:49.784+0530] {subprocess.py:93} INFO - 2025-09-08 14:05:49,784 INFO: Flushed batch: orders=200 items=335
[2025-09-08T14:05:49.785+0530] {subprocess.py:93} INFO - 2025-09-08 14:05:49,785 WARNING: Failed to send webhook notification: HTTPConnectionPool(host='localhost', port=5000): Max retries exceeded with url: /webhook (Caused by NewConnectionError('<urllib3.connection.HTTPConnection object at 0x72567404d3c0>: Failed to establish a new connection: [Errno 111] Connection refused'))
[2025-09-08T14:05:50.286+0530] {subprocess.py:93} INFO - 2025-09-08 14:05:50,285 INFO: Flushed batch: orders=200 items=343
[2025-09-08T14:05:50.288+0530] {subprocess.py:93} INFO - 2025-09-08 14:05:50,288 WARNING: Failed to send webhook notification: HTTPConnectionPool(host='localhost', port=5000): Max retries exceeded with url: /webhook (Caused by NewConnectionError('<urllib3.connection.HTTPConnection object at 0x725674083a30>: Failed to establish a new connection: [Errno 111] Connection refused'))
[2025-09-08T14:05:50.536+0530] {subprocess.py:93} INFO - 2025-09-08 14:05:50,536 INFO: Flushed batch: orders=200 items=344
[2025-09-08T14:05:50.539+0530] {subprocess.py:93} INFO - 2025-09-08 14:05:50,539 WARNING: Failed to send webhook notification: HTTPConnectionPool(host='localhost', port=5000): Max retries exceeded with url: /webhook (Caused by NewConnectionError('<urllib3.connection.HTTPConnection object at 0x725674016bc0>: Failed to establish a new connection: [Errno 111] Connection refused'))
[2025-09-08T14:05:50.829+0530] {subprocess.py:93} INFO - 2025-09-08 14:05:50,829 INFO: Flushed batch: orders=200 items=342
[2025-09-08T14:05:50.832+0530] {subprocess.py:93} INFO - 2025-09-08 14:05:50,831 WARNING: Failed to send webhook notification: HTTPConnectionPool(host='localhost', port=5000): Max retries exceeded with url: /webhook (Caused by NewConnectionError('<urllib3.connection.HTTPConnection object at 0x725674016bf0>: Failed to establish a new connection: [Errno 111] Connection refused'))
[2025-09-08T14:05:50.832+0530] {subprocess.py:93} INFO - 2025-09-08 14:05:50,832 INFO: Generated 5000 orders
[2025-09-08T14:06:35.824+0530] {subprocess.py:93} INFO - 2025-09-08 14:06:35,824 INFO: Inserted 48219 clickstream events.
[2025-09-08T14:06:35.825+0530] {subprocess.py:93} INFO - 2025-09-08 14:06:35,825 WARNING: Failed to send webhook notification: HTTPConnectionPool(host='localhost', port=5000): Max retries exceeded with url: /webhook (Caused by NewConnectionError('<urllib3.connection.HTTPConnection object at 0x725672eed030>: Failed to establish a new connection: [Errno 111] Connection refused'))
[2025-09-08T14:06:38.062+0530] {subprocess.py:93} INFO - 2025-09-08 14:06:38,062 INFO: Validation done: orphans orders=0 items=0 inventory=0 mismatches=0
[2025-09-08T14:06:38.071+0530] {subprocess.py:93} INFO - 2025-09-08 14:06:38,071 INFO: Integrity report: {'orphan_orders': 0, 'orphan_order_items': 0, 'inventory_orphans': 0, 'order_amount_mismatches': []}
[2025-09-08T14:06:38.101+0530] {subprocess.py:93} INFO - [2025-09-08 14:06:38] ‚úÖ Synthetic data streaming completed successfully!
[2025-09-08T14:06:38.102+0530] {subprocess.py:97} INFO - Command exited with return code 0
[2025-09-08T14:06:38.102+0530] {taskinstance.py:441} INFO - ::group::Post task execution logs
[2025-09-08T14:06:38.309+0530] {taskinstance.py:1206} INFO - Marking task as SUCCESS. dag_id=synth_stream_5min, task_id=run_synth_stream, run_id=scheduled__2025-09-08T08:30:00+00:00, execution_date=20250908T083000, start_date=20250908T083540, end_date=20250908T083638
[2025-09-08T14:06:38.593+0530] {local_task_job_runner.py:243} INFO - Task exited with return code 0
[2025-09-08T14:06:38.615+0530] {taskinstance.py:3503} INFO - 0 downstream tasks scheduled from follow-on schedule check
[2025-09-08T14:06:38.616+0530] {local_task_job_runner.py:222} INFO - ::endgroup::
