[2025-09-08T13:15:02.724+0530] {local_task_job_runner.py:120} INFO - ::group::Pre task execution logs
[2025-09-08T13:15:02.736+0530] {taskinstance.py:2076} INFO - Dependencies all met for dep_context=non-requeueable deps ti=<TaskInstance: synth_stream_5min.run_synth_stream scheduled__2025-09-08T07:40:00+00:00 [queued]>
[2025-09-08T13:15:02.739+0530] {taskinstance.py:2076} INFO - Dependencies all met for dep_context=requeueable deps ti=<TaskInstance: synth_stream_5min.run_synth_stream scheduled__2025-09-08T07:40:00+00:00 [queued]>
[2025-09-08T13:15:02.739+0530] {taskinstance.py:2306} INFO - Starting attempt 1 of 2
[2025-09-08T13:15:02.829+0530] {taskinstance.py:2330} INFO - Executing <Task(BashOperator): run_synth_stream> on 2025-09-08 07:40:00+00:00
[2025-09-08T13:15:02.838+0530] {standard_task_runner.py:64} INFO - Started process 711456 to run task
[2025-09-08T13:15:02.844+0530] {standard_task_runner.py:90} INFO - Running: ['airflow', 'tasks', 'run', 'synth_stream_5min', 'run_synth_stream', 'scheduled__2025-09-08T07:40:00+00:00', '--job-id', '23', '--raw', '--subdir', 'DAGS_FOLDER/ecom_schedules.py', '--cfg-path', '/tmp/tmpk1hqvf6p']
[2025-09-08T13:15:02.848+0530] {standard_task_runner.py:91} INFO - Job 23: Subtask run_synth_stream
[2025-09-08T13:15:02.937+0530] {task_command.py:426} INFO - Running <TaskInstance: synth_stream_5min.run_synth_stream scheduled__2025-09-08T07:40:00+00:00 [running]> on host softsuave-ASUS-EXPERTCENTER-D700ME-D500ME
[2025-09-08T13:15:03.092+0530] {taskinstance.py:2648} INFO - Exporting env vars: AIRFLOW_CTX_DAG_OWNER='airflow' AIRFLOW_CTX_DAG_ID='synth_stream_5min' AIRFLOW_CTX_TASK_ID='run_synth_stream' AIRFLOW_CTX_EXECUTION_DATE='2025-09-08T07:40:00+00:00' AIRFLOW_CTX_TRY_NUMBER='1' AIRFLOW_CTX_DAG_RUN_ID='scheduled__2025-09-08T07:40:00+00:00'
[2025-09-08T13:15:03.093+0530] {taskinstance.py:430} INFO - ::endgroup::
[2025-09-08T13:15:03.094+0530] {subprocess.py:63} INFO - Tmp dir root location: /tmp
[2025-09-08T13:15:03.094+0530] {subprocess.py:75} INFO - Running command: ['/usr/bin/bash', '-c', 'bash /media/softsuave/DATA-HDD/DataEngineering/Apache_Airflow/scripts/synth/run_synth_stream.sh | cat']
[2025-09-08T13:15:03.103+0530] {subprocess.py:86} INFO - Output:
[2025-09-08T13:15:03.144+0530] {subprocess.py:93} INFO - [2025-09-08 13:15:03] üöÄ Starting Synthetic E-commerce Data Stream...
[2025-09-08T13:15:03.144+0530] {subprocess.py:93} INFO - ----------------------------------------------
[2025-09-08T13:15:03.144+0530] {subprocess.py:93} INFO -  Database   : ecom_db
[2025-09-08T13:15:03.144+0530] {subprocess.py:93} INFO -  User       : sa
[2025-09-08T13:15:03.144+0530] {subprocess.py:93} INFO -  Server     : localhost:1433
[2025-09-08T13:15:03.144+0530] {subprocess.py:93} INFO -  Interval   : 5 min
[2025-09-08T13:15:03.145+0530] {subprocess.py:93} INFO -  Orders     : 50
[2025-09-08T13:15:03.145+0530] {subprocess.py:93} INFO -  Clicks     : 100
[2025-09-08T13:15:03.145+0530] {subprocess.py:93} INFO -  Webhook    : http://localhost:5000/webhook
[2025-09-08T13:15:03.145+0530] {subprocess.py:93} INFO - ----------------------------------------------
[2025-09-08T13:15:03.145+0530] {subprocess.py:93} INFO - 
[2025-09-08T13:15:03.165+0530] {subprocess.py:93} INFO - [2025-09-08 13:15:03] üîß Activating virtual environment...
[2025-09-08T13:15:03.167+0530] {subprocess.py:93} INFO - [2025-09-08 13:15:03] üîç Checking database connection...
[2025-09-08T13:15:03.196+0530] {subprocess.py:93} INFO - ‚úÖ Database connection successful
[2025-09-08T13:15:03.201+0530] {subprocess.py:93} INFO - [2025-09-08 13:15:03] üîÑ Starting synthetic data stream...
[2025-09-08T13:15:03.201+0530] {subprocess.py:93} INFO - Press Ctrl+C to stop
[2025-09-08T13:15:03.201+0530] {subprocess.py:93} INFO - 
[2025-09-08T13:15:03.383+0530] {subprocess.py:93} INFO - 2025-09-08 13:15:03,383 INFO: Tables ensured/created (if needed).
[2025-09-08T13:15:03.396+0530] {subprocess.py:93} INFO - 2025-09-08 13:15:03,396 INFO: Customers: 1000 already present; skipping seeding.
[2025-09-08T13:15:03.397+0530] {subprocess.py:93} INFO - 2025-09-08 13:15:03,397 INFO: Products: 500 already present; skipping seeding.
[2025-09-08T13:15:03.397+0530] {subprocess.py:93} INFO - 2025-09-08 13:15:03,397 INFO: Running one-shot generation: orders=5000, sessions=3000
[2025-09-08T13:15:03.403+0530] {subprocess.py:93} INFO - /media/softsuave/DATA-HDD/DataEngineering/Apache_Airflow/src/synth_ecom_mssql_stream.py:397: RemovedIn20Warning: Deprecated API features detected! These feature(s) are not compatible with SQLAlchemy 2.0. To prevent incompatible upgrades prior to updating applications, ensure requirements files are pinned to "sqlalchemy<2.0". Set environment variable SQLALCHEMY_WARN_20=1 to show all deprecation warnings.  Set environment variable SQLALCHEMY_SILENCE_UBER_WARNING=1 to silence this message. (Background on SQLAlchemy 2.0 at: https://sqlalche.me/e/b8d9)
[2025-09-08T13:15:03.403+0530] {subprocess.py:93} INFO -   customers = [dict(r) for r in conn.execute(select(self.tables["customers"])).fetchall()]
[2025-09-08T13:15:03.412+0530] {subprocess.py:93} INFO - 2025-09-08 13:15:03,412 INFO: Generating 5000 orders (batch_size=200, force_order_date_now=False)...
[2025-09-08T13:15:03.934+0530] {subprocess.py:93} INFO - 2025-09-08 13:15:03,933 INFO: Flushed batch: orders=200 items=375
[2025-09-08T13:15:03.940+0530] {subprocess.py:93} INFO - 2025-09-08 13:15:03,940 WARNING: Failed to send webhook notification: HTTPConnectionPool(host='localhost', port=5000): Max retries exceeded with url: /webhook (Caused by NewConnectionError('<urllib3.connection.HTTPConnection object at 0x7e0347359330>: Failed to establish a new connection: [Errno 111] Connection refused'))
[2025-09-08T13:15:04.166+0530] {subprocess.py:93} INFO - 2025-09-08 13:15:04,166 INFO: Flushed batch: orders=200 items=326
[2025-09-08T13:15:04.167+0530] {subprocess.py:93} INFO - 2025-09-08 13:15:04,167 WARNING: Failed to send webhook notification: HTTPConnectionPool(host='localhost', port=5000): Max retries exceeded with url: /webhook (Caused by NewConnectionError('<urllib3.connection.HTTPConnection object at 0x7e0346caff10>: Failed to establish a new connection: [Errno 111] Connection refused'))
[2025-09-08T13:15:04.350+0530] {subprocess.py:93} INFO - 2025-09-08 13:15:04,350 INFO: Flushed batch: orders=200 items=344
[2025-09-08T13:15:04.351+0530] {subprocess.py:93} INFO - 2025-09-08 13:15:04,351 WARNING: Failed to send webhook notification: HTTPConnectionPool(host='localhost', port=5000): Max retries exceeded with url: /webhook (Caused by NewConnectionError('<urllib3.connection.HTTPConnection object at 0x7e0346cc25f0>: Failed to establish a new connection: [Errno 111] Connection refused'))
[2025-09-08T13:15:04.542+0530] {subprocess.py:93} INFO - 2025-09-08 13:15:04,542 INFO: Flushed batch: orders=200 items=361
[2025-09-08T13:15:04.543+0530] {subprocess.py:93} INFO - 2025-09-08 13:15:04,543 WARNING: Failed to send webhook notification: HTTPConnectionPool(host='localhost', port=5000): Max retries exceeded with url: /webhook (Caused by NewConnectionError('<urllib3.connection.HTTPConnection object at 0x7e0346ce16c0>: Failed to establish a new connection: [Errno 111] Connection refused'))
[2025-09-08T13:15:04.784+0530] {subprocess.py:93} INFO - 2025-09-08 13:15:04,784 INFO: Flushed batch: orders=200 items=345
[2025-09-08T13:15:04.785+0530] {subprocess.py:93} INFO - 2025-09-08 13:15:04,785 WARNING: Failed to send webhook notification: HTTPConnectionPool(host='localhost', port=5000): Max retries exceeded with url: /webhook (Caused by NewConnectionError('<urllib3.connection.HTTPConnection object at 0x7e0346cc07f0>: Failed to establish a new connection: [Errno 111] Connection refused'))
[2025-09-08T13:15:04.968+0530] {subprocess.py:93} INFO - 2025-09-08 13:15:04,968 INFO: Flushed batch: orders=200 items=355
[2025-09-08T13:15:04.968+0530] {subprocess.py:93} INFO - 2025-09-08 13:15:04,968 WARNING: Failed to send webhook notification: HTTPConnectionPool(host='localhost', port=5000): Max retries exceeded with url: /webhook (Caused by NewConnectionError('<urllib3.connection.HTTPConnection object at 0x7e0346b02a40>: Failed to establish a new connection: [Errno 111] Connection refused'))
[2025-09-08T13:15:05.151+0530] {subprocess.py:93} INFO - 2025-09-08 13:15:05,151 INFO: Flushed batch: orders=200 items=346
[2025-09-08T13:15:05.153+0530] {subprocess.py:93} INFO - 2025-09-08 13:15:05,153 WARNING: Failed to send webhook notification: HTTPConnectionPool(host='localhost', port=5000): Max retries exceeded with url: /webhook (Caused by NewConnectionError('<urllib3.connection.HTTPConnection object at 0x7e0346cc0970>: Failed to establish a new connection: [Errno 111] Connection refused'))
[2025-09-08T13:15:05.369+0530] {subprocess.py:93} INFO - 2025-09-08 13:15:05,369 INFO: Flushed batch: orders=200 items=384
[2025-09-08T13:15:05.370+0530] {subprocess.py:93} INFO - 2025-09-08 13:15:05,370 WARNING: Failed to send webhook notification: HTTPConnectionPool(host='localhost', port=5000): Max retries exceeded with url: /webhook (Caused by NewConnectionError('<urllib3.connection.HTTPConnection object at 0x7e0346cf1330>: Failed to establish a new connection: [Errno 111] Connection refused'))
[2025-09-08T13:15:05.561+0530] {subprocess.py:93} INFO - 2025-09-08 13:15:05,561 INFO: Flushed batch: orders=200 items=327
[2025-09-08T13:15:05.562+0530] {subprocess.py:93} INFO - 2025-09-08 13:15:05,562 WARNING: Failed to send webhook notification: HTTPConnectionPool(host='localhost', port=5000): Max retries exceeded with url: /webhook (Caused by NewConnectionError('<urllib3.connection.HTTPConnection object at 0x7e0346b00700>: Failed to establish a new connection: [Errno 111] Connection refused'))
[2025-09-08T13:15:05.736+0530] {subprocess.py:93} INFO - 2025-09-08 13:15:05,736 INFO: Flushed batch: orders=200 items=315
[2025-09-08T13:15:05.737+0530] {subprocess.py:93} INFO - 2025-09-08 13:15:05,737 WARNING: Failed to send webhook notification: HTTPConnectionPool(host='localhost', port=5000): Max retries exceeded with url: /webhook (Caused by NewConnectionError('<urllib3.connection.HTTPConnection object at 0x7e0346b08d90>: Failed to establish a new connection: [Errno 111] Connection refused'))
[2025-09-08T13:15:05.904+0530] {subprocess.py:93} INFO - 2025-09-08 13:15:05,903 INFO: Flushed batch: orders=200 items=356
[2025-09-08T13:15:05.904+0530] {subprocess.py:93} INFO - 2025-09-08 13:15:05,904 WARNING: Failed to send webhook notification: HTTPConnectionPool(host='localhost', port=5000): Max retries exceeded with url: /webhook (Caused by NewConnectionError('<urllib3.connection.HTTPConnection object at 0x7e0346b0beb0>: Failed to establish a new connection: [Errno 111] Connection refused'))
[2025-09-08T13:15:06.087+0530] {subprocess.py:93} INFO - 2025-09-08 13:15:06,087 INFO: Flushed batch: orders=200 items=349
[2025-09-08T13:15:06.088+0530] {subprocess.py:93} INFO - 2025-09-08 13:15:06,088 WARNING: Failed to send webhook notification: HTTPConnectionPool(host='localhost', port=5000): Max retries exceeded with url: /webhook (Caused by NewConnectionError('<urllib3.connection.HTTPConnection object at 0x7e0346b0bf40>: Failed to establish a new connection: [Errno 111] Connection refused'))
[2025-09-08T13:15:06.272+0530] {subprocess.py:93} INFO - 2025-09-08 13:15:06,271 INFO: Flushed batch: orders=200 items=352
[2025-09-08T13:15:06.274+0530] {subprocess.py:93} INFO - 2025-09-08 13:15:06,274 WARNING: Failed to send webhook notification: HTTPConnectionPool(host='localhost', port=5000): Max retries exceeded with url: /webhook (Caused by NewConnectionError('<urllib3.connection.HTTPConnection object at 0x7e0346b08100>: Failed to establish a new connection: [Errno 111] Connection refused'))
[2025-09-08T13:15:06.447+0530] {subprocess.py:93} INFO - 2025-09-08 13:15:06,447 INFO: Flushed batch: orders=200 items=358
[2025-09-08T13:15:06.449+0530] {subprocess.py:93} INFO - 2025-09-08 13:15:06,449 WARNING: Failed to send webhook notification: HTTPConnectionPool(host='localhost', port=5000): Max retries exceeded with url: /webhook (Caused by NewConnectionError('<urllib3.connection.HTTPConnection object at 0x7e0346cf1f30>: Failed to establish a new connection: [Errno 111] Connection refused'))
[2025-09-08T13:15:06.656+0530] {subprocess.py:93} INFO - 2025-09-08 13:15:06,655 INFO: Flushed batch: orders=200 items=334
[2025-09-08T13:15:06.659+0530] {subprocess.py:93} INFO - 2025-09-08 13:15:06,659 WARNING: Failed to send webhook notification: HTTPConnectionPool(host='localhost', port=5000): Max retries exceeded with url: /webhook (Caused by NewConnectionError('<urllib3.connection.HTTPConnection object at 0x7e0346b09b10>: Failed to establish a new connection: [Errno 111] Connection refused'))
[2025-09-08T13:15:06.864+0530] {subprocess.py:93} INFO - 2025-09-08 13:15:06,864 INFO: Flushed batch: orders=200 items=355
[2025-09-08T13:15:06.867+0530] {subprocess.py:93} INFO - 2025-09-08 13:15:06,867 WARNING: Failed to send webhook notification: HTTPConnectionPool(host='localhost', port=5000): Max retries exceeded with url: /webhook (Caused by NewConnectionError('<urllib3.connection.HTTPConnection object at 0x7e0346ccd750>: Failed to establish a new connection: [Errno 111] Connection refused'))
[2025-09-08T13:15:07.089+0530] {subprocess.py:93} INFO - 2025-09-08 13:15:07,089 INFO: Flushed batch: orders=200 items=355
[2025-09-08T13:15:07.093+0530] {subprocess.py:93} INFO - 2025-09-08 13:15:07,092 WARNING: Failed to send webhook notification: HTTPConnectionPool(host='localhost', port=5000): Max retries exceeded with url: /webhook (Caused by NewConnectionError('<urllib3.connection.HTTPConnection object at 0x7e0346b13700>: Failed to establish a new connection: [Errno 111] Connection refused'))
[2025-09-08T13:15:07.347+0530] {subprocess.py:93} INFO - 2025-09-08 13:15:07,347 INFO: Flushed batch: orders=200 items=341
[2025-09-08T13:15:07.348+0530] {subprocess.py:93} INFO - 2025-09-08 13:15:07,348 WARNING: Failed to send webhook notification: HTTPConnectionPool(host='localhost', port=5000): Max retries exceeded with url: /webhook (Caused by NewConnectionError('<urllib3.connection.HTTPConnection object at 0x7e0346b007f0>: Failed to establish a new connection: [Errno 111] Connection refused'))
[2025-09-08T13:15:07.514+0530] {subprocess.py:93} INFO - 2025-09-08 13:15:07,514 INFO: Flushed batch: orders=200 items=342
[2025-09-08T13:15:07.515+0530] {subprocess.py:93} INFO - 2025-09-08 13:15:07,515 WARNING: Failed to send webhook notification: HTTPConnectionPool(host='localhost', port=5000): Max retries exceeded with url: /webhook (Caused by NewConnectionError('<urllib3.connection.HTTPConnection object at 0x7e0346b0ba60>: Failed to establish a new connection: [Errno 111] Connection refused'))
[2025-09-08T13:15:07.700+0530] {subprocess.py:93} INFO - 2025-09-08 13:15:07,700 INFO: Flushed batch: orders=200 items=349
[2025-09-08T13:15:07.703+0530] {subprocess.py:93} INFO - 2025-09-08 13:15:07,703 WARNING: Failed to send webhook notification: HTTPConnectionPool(host='localhost', port=5000): Max retries exceeded with url: /webhook (Caused by NewConnectionError('<urllib3.connection.HTTPConnection object at 0x7e0346b015d0>: Failed to establish a new connection: [Errno 111] Connection refused'))
[2025-09-08T13:15:07.919+0530] {subprocess.py:93} INFO - 2025-09-08 13:15:07,918 INFO: Flushed batch: orders=200 items=358
[2025-09-08T13:15:07.922+0530] {subprocess.py:93} INFO - 2025-09-08 13:15:07,921 WARNING: Failed to send webhook notification: HTTPConnectionPool(host='localhost', port=5000): Max retries exceeded with url: /webhook (Caused by NewConnectionError('<urllib3.connection.HTTPConnection object at 0x7e0346b3da80>: Failed to establish a new connection: [Errno 111] Connection refused'))
[2025-09-08T13:15:08.118+0530] {subprocess.py:93} INFO - 2025-09-08 13:15:08,117 INFO: Flushed batch: orders=200 items=316
[2025-09-08T13:15:08.120+0530] {subprocess.py:93} INFO - 2025-09-08 13:15:08,120 WARNING: Failed to send webhook notification: HTTPConnectionPool(host='localhost', port=5000): Max retries exceeded with url: /webhook (Caused by NewConnectionError('<urllib3.connection.HTTPConnection object at 0x7e0346b121d0>: Failed to establish a new connection: [Errno 111] Connection refused'))
[2025-09-08T13:15:08.301+0530] {subprocess.py:93} INFO - 2025-09-08 13:15:08,300 INFO: Flushed batch: orders=200 items=362
[2025-09-08T13:15:08.303+0530] {subprocess.py:93} INFO - 2025-09-08 13:15:08,303 WARNING: Failed to send webhook notification: HTTPConnectionPool(host='localhost', port=5000): Max retries exceeded with url: /webhook (Caused by NewConnectionError('<urllib3.connection.HTTPConnection object at 0x7e0346ce1b40>: Failed to establish a new connection: [Errno 111] Connection refused'))
[2025-09-08T13:15:08.476+0530] {subprocess.py:93} INFO - 2025-09-08 13:15:08,475 INFO: Flushed batch: orders=200 items=331
[2025-09-08T13:15:08.478+0530] {subprocess.py:93} INFO - 2025-09-08 13:15:08,477 WARNING: Failed to send webhook notification: HTTPConnectionPool(host='localhost', port=5000): Max retries exceeded with url: /webhook (Caused by NewConnectionError('<urllib3.connection.HTTPConnection object at 0x7e0346cc0f10>: Failed to establish a new connection: [Errno 111] Connection refused'))
[2025-09-08T13:15:08.651+0530] {subprocess.py:93} INFO - 2025-09-08 13:15:08,651 INFO: Flushed batch: orders=200 items=344
[2025-09-08T13:15:08.654+0530] {subprocess.py:93} INFO - 2025-09-08 13:15:08,654 WARNING: Failed to send webhook notification: HTTPConnectionPool(host='localhost', port=5000): Max retries exceeded with url: /webhook (Caused by NewConnectionError('<urllib3.connection.HTTPConnection object at 0x7e0346d7ac50>: Failed to establish a new connection: [Errno 111] Connection refused'))
[2025-09-08T13:15:08.654+0530] {subprocess.py:93} INFO - 2025-09-08 13:15:08,654 INFO: Generated 5000 orders
[2025-09-08T13:15:30.872+0530] {subprocess.py:93} INFO - 2025-09-08 13:15:30,872 INFO: Inserted 47942 clickstream events.
[2025-09-08T13:15:30.874+0530] {subprocess.py:93} INFO - 2025-09-08 13:15:30,873 WARNING: Failed to send webhook notification: HTTPConnectionPool(host='localhost', port=5000): Max retries exceeded with url: /webhook (Caused by NewConnectionError('<urllib3.connection.HTTPConnection object at 0x7e03477f53c0>: Failed to establish a new connection: [Errno 111] Connection refused'))
[2025-09-08T13:15:31.215+0530] {subprocess.py:93} INFO - 2025-09-08 13:15:31,214 INFO: Validation done: orphans orders=0 items=0 inventory=0 mismatches=0
[2025-09-08T13:15:31.216+0530] {subprocess.py:93} INFO - 2025-09-08 13:15:31,215 INFO: Integrity report: {'orphan_orders': 0, 'orphan_order_items': 0, 'inventory_orphans': 0, 'order_amount_mismatches': []}
[2025-09-08T13:15:31.247+0530] {subprocess.py:93} INFO - [2025-09-08 13:15:31] ‚úÖ Synthetic data streaming completed successfully!
[2025-09-08T13:15:31.247+0530] {subprocess.py:97} INFO - Command exited with return code 0
[2025-09-08T13:15:31.247+0530] {taskinstance.py:441} INFO - ::group::Post task execution logs
[2025-09-08T13:15:31.654+0530] {taskinstance.py:1206} INFO - Marking task as SUCCESS. dag_id=synth_stream_5min, task_id=run_synth_stream, run_id=scheduled__2025-09-08T07:40:00+00:00, execution_date=20250908T074000, start_date=20250908T074502, end_date=20250908T074531
[2025-09-08T13:15:31.926+0530] {local_task_job_runner.py:243} INFO - Task exited with return code 0
[2025-09-08T13:15:31.940+0530] {taskinstance.py:3503} INFO - 0 downstream tasks scheduled from follow-on schedule check
[2025-09-08T13:15:31.940+0530] {local_task_job_runner.py:222} INFO - ::endgroup::
