[2025-09-08T14:46:01.907+0530] {local_task_job_runner.py:120} INFO - ::group::Pre task execution logs
[2025-09-08T14:46:02.272+0530] {taskinstance.py:2076} INFO - Dependencies all met for dep_context=non-requeueable deps ti=<TaskInstance: synth_stream_5min.run_synth_stream scheduled__2025-09-08T09:05:00+00:00 [queued]>
[2025-09-08T14:46:02.276+0530] {taskinstance.py:2076} INFO - Dependencies all met for dep_context=requeueable deps ti=<TaskInstance: synth_stream_5min.run_synth_stream scheduled__2025-09-08T09:05:00+00:00 [queued]>
[2025-09-08T14:46:02.276+0530] {taskinstance.py:2306} INFO - Starting attempt 1 of 2
[2025-09-08T14:46:02.464+0530] {taskinstance.py:2330} INFO - Executing <Task(BashOperator): run_synth_stream> on 2025-09-08 09:05:00+00:00
[2025-09-08T14:46:02.472+0530] {standard_task_runner.py:64} INFO - Started process 734969 to run task
[2025-09-08T14:46:02.479+0530] {standard_task_runner.py:90} INFO - Running: ['airflow', 'tasks', 'run', 'synth_stream_5min', 'run_synth_stream', 'scheduled__2025-09-08T09:05:00+00:00', '--job-id', '49', '--raw', '--subdir', 'DAGS_FOLDER/ecom_schedules.py', '--cfg-path', '/tmp/tmppeuntux4']
[2025-09-08T14:46:02.482+0530] {standard_task_runner.py:91} INFO - Job 49: Subtask run_synth_stream
[2025-09-08T14:46:02.712+0530] {task_command.py:426} INFO - Running <TaskInstance: synth_stream_5min.run_synth_stream scheduled__2025-09-08T09:05:00+00:00 [running]> on host softsuave-ASUS-EXPERTCENTER-D700ME-D500ME
[2025-09-08T14:46:03.313+0530] {taskinstance.py:2648} INFO - Exporting env vars: AIRFLOW_CTX_DAG_OWNER='airflow' AIRFLOW_CTX_DAG_ID='synth_stream_5min' AIRFLOW_CTX_TASK_ID='run_synth_stream' AIRFLOW_CTX_EXECUTION_DATE='2025-09-08T09:05:00+00:00' AIRFLOW_CTX_TRY_NUMBER='1' AIRFLOW_CTX_DAG_RUN_ID='scheduled__2025-09-08T09:05:00+00:00'
[2025-09-08T14:46:03.315+0530] {taskinstance.py:430} INFO - ::endgroup::
[2025-09-08T14:46:03.316+0530] {subprocess.py:63} INFO - Tmp dir root location: /tmp
[2025-09-08T14:46:03.316+0530] {subprocess.py:75} INFO - Running command: ['/usr/bin/bash', '-c', 'bash /media/softsuave/DATA-HDD/DataEngineering/Apache_Airflow/scripts/synth/run_synth_stream.sh | cat']
[2025-09-08T14:46:03.326+0530] {subprocess.py:86} INFO - Output:
[2025-09-08T14:46:03.355+0530] {subprocess.py:93} INFO - [2025-09-08 14:46:03] üöÄ Starting Synthetic E-commerce Data Stream...
[2025-09-08T14:46:03.355+0530] {subprocess.py:93} INFO - ----------------------------------------------
[2025-09-08T14:46:03.356+0530] {subprocess.py:93} INFO -  Database   : ecom_db
[2025-09-08T14:46:03.356+0530] {subprocess.py:93} INFO -  User       : sa
[2025-09-08T14:46:03.356+0530] {subprocess.py:93} INFO -  Server     : localhost:1433
[2025-09-08T14:46:03.356+0530] {subprocess.py:93} INFO -  Interval   : 5 min
[2025-09-08T14:46:03.356+0530] {subprocess.py:93} INFO -  Orders     : 50
[2025-09-08T14:46:03.356+0530] {subprocess.py:93} INFO -  Clicks     : 100
[2025-09-08T14:46:03.356+0530] {subprocess.py:93} INFO -  Webhook    : http://localhost:5000/webhook
[2025-09-08T14:46:03.356+0530] {subprocess.py:93} INFO - ----------------------------------------------
[2025-09-08T14:46:03.356+0530] {subprocess.py:93} INFO - 
[2025-09-08T14:46:03.402+0530] {subprocess.py:93} INFO - [2025-09-08 14:46:03] üîß Activating virtual environment...
[2025-09-08T14:46:03.475+0530] {subprocess.py:93} INFO - [2025-09-08 14:46:03] üîç Checking database connection...
[2025-09-08T14:46:04.089+0530] {subprocess.py:93} INFO - ‚úÖ Database connection successful
[2025-09-08T14:46:04.105+0530] {subprocess.py:93} INFO - [2025-09-08 14:46:04] üîÑ Starting synthetic data stream...
[2025-09-08T14:46:04.105+0530] {subprocess.py:93} INFO - Press Ctrl+C to stop
[2025-09-08T14:46:04.106+0530] {subprocess.py:93} INFO - 
[2025-09-08T14:46:05.610+0530] {subprocess.py:93} INFO - 2025-09-08 14:46:05,610 INFO: Tables ensured/created (if needed).
[2025-09-08T14:46:05.940+0530] {subprocess.py:93} INFO - 2025-09-08 14:46:05,939 INFO: Customers: 1000 already present; skipping seeding.
[2025-09-08T14:46:05.945+0530] {subprocess.py:93} INFO - 2025-09-08 14:46:05,944 INFO: Products: 500 already present; skipping seeding.
[2025-09-08T14:46:05.945+0530] {subprocess.py:93} INFO - 2025-09-08 14:46:05,945 INFO: Running one-shot generation: orders=5000, sessions=3000
[2025-09-08T14:46:05.966+0530] {subprocess.py:93} INFO - /media/softsuave/DATA-HDD/DataEngineering/Apache_Airflow/src/synth_ecom_mssql_stream.py:397: RemovedIn20Warning: Deprecated API features detected! These feature(s) are not compatible with SQLAlchemy 2.0. To prevent incompatible upgrades prior to updating applications, ensure requirements files are pinned to "sqlalchemy<2.0". Set environment variable SQLALCHEMY_WARN_20=1 to show all deprecation warnings.  Set environment variable SQLALCHEMY_SILENCE_UBER_WARNING=1 to silence this message. (Background on SQLAlchemy 2.0 at: https://sqlalche.me/e/b8d9)
[2025-09-08T14:46:05.966+0530] {subprocess.py:93} INFO -   customers = [dict(r) for r in conn.execute(select(self.tables["customers"])).fetchall()]
[2025-09-08T14:46:05.973+0530] {subprocess.py:93} INFO - 2025-09-08 14:46:05,973 INFO: Generating 5000 orders (batch_size=200, force_order_date_now=False)...
[2025-09-08T14:46:06.181+0530] {subprocess.py:93} INFO - 2025-09-08 14:46:06,181 INFO: Flushed batch: orders=200 items=364
[2025-09-08T14:46:06.186+0530] {subprocess.py:93} INFO - 2025-09-08 14:46:06,185 WARNING: Failed to send webhook notification: HTTPConnectionPool(host='localhost', port=5000): Max retries exceeded with url: /webhook (Caused by NewConnectionError('<urllib3.connection.HTTPConnection object at 0x7afddbeb17e0>: Failed to establish a new connection: [Errno 111] Connection refused'))
[2025-09-08T14:46:06.435+0530] {subprocess.py:93} INFO - 2025-09-08 14:46:06,435 INFO: Flushed batch: orders=200 items=374
[2025-09-08T14:46:06.438+0530] {subprocess.py:93} INFO - 2025-09-08 14:46:06,438 WARNING: Failed to send webhook notification: HTTPConnectionPool(host='localhost', port=5000): Max retries exceeded with url: /webhook (Caused by NewConnectionError('<urllib3.connection.HTTPConnection object at 0x7afddbd8f8b0>: Failed to establish a new connection: [Errno 111] Connection refused'))
[2025-09-08T14:46:06.663+0530] {subprocess.py:93} INFO - 2025-09-08 14:46:06,663 INFO: Flushed batch: orders=200 items=351
[2025-09-08T14:46:06.666+0530] {subprocess.py:93} INFO - 2025-09-08 14:46:06,666 WARNING: Failed to send webhook notification: HTTPConnectionPool(host='localhost', port=5000): Max retries exceeded with url: /webhook (Caused by NewConnectionError('<urllib3.connection.HTTPConnection object at 0x7afddbdc7460>: Failed to establish a new connection: [Errno 111] Connection refused'))
[2025-09-08T14:46:06.875+0530] {subprocess.py:93} INFO - 2025-09-08 14:46:06,875 INFO: Flushed batch: orders=200 items=372
[2025-09-08T14:46:06.877+0530] {subprocess.py:93} INFO - 2025-09-08 14:46:06,877 WARNING: Failed to send webhook notification: HTTPConnectionPool(host='localhost', port=5000): Max retries exceeded with url: /webhook (Caused by NewConnectionError('<urllib3.connection.HTTPConnection object at 0x7afddbc08eb0>: Failed to establish a new connection: [Errno 111] Connection refused'))
[2025-09-08T14:46:07.212+0530] {subprocess.py:93} INFO - 2025-09-08 14:46:07,212 INFO: Flushed batch: orders=200 items=352
[2025-09-08T14:46:07.213+0530] {subprocess.py:93} INFO - 2025-09-08 14:46:07,213 WARNING: Failed to send webhook notification: HTTPConnectionPool(host='localhost', port=5000): Max retries exceeded with url: /webhook (Caused by NewConnectionError('<urllib3.connection.HTTPConnection object at 0x7afddbdf8940>: Failed to establish a new connection: [Errno 111] Connection refused'))
[2025-09-08T14:46:07.800+0530] {subprocess.py:93} INFO - 2025-09-08 14:46:07,800 INFO: Flushed batch: orders=200 items=351
[2025-09-08T14:46:07.801+0530] {subprocess.py:93} INFO - 2025-09-08 14:46:07,801 WARNING: Failed to send webhook notification: HTTPConnectionPool(host='localhost', port=5000): Max retries exceeded with url: /webhook (Caused by NewConnectionError('<urllib3.connection.HTTPConnection object at 0x7afddbc2f0d0>: Failed to establish a new connection: [Errno 111] Connection refused'))
[2025-09-08T14:46:08.042+0530] {subprocess.py:93} INFO - 2025-09-08 14:46:08,042 INFO: Flushed batch: orders=200 items=358
[2025-09-08T14:46:08.043+0530] {subprocess.py:93} INFO - 2025-09-08 14:46:08,043 WARNING: Failed to send webhook notification: HTTPConnectionPool(host='localhost', port=5000): Max retries exceeded with url: /webhook (Caused by NewConnectionError('<urllib3.connection.HTTPConnection object at 0x7afddbc2d570>: Failed to establish a new connection: [Errno 111] Connection refused'))
[2025-09-08T14:46:08.746+0530] {subprocess.py:93} INFO - 2025-09-08 14:46:08,745 INFO: Flushed batch: orders=200 items=383
[2025-09-08T14:46:08.748+0530] {subprocess.py:93} INFO - 2025-09-08 14:46:08,748 WARNING: Failed to send webhook notification: HTTPConnectionPool(host='localhost', port=5000): Max retries exceeded with url: /webhook (Caused by NewConnectionError('<urllib3.connection.HTTPConnection object at 0x7afddbc2d7b0>: Failed to establish a new connection: [Errno 111] Connection refused'))
[2025-09-08T14:46:09.030+0530] {subprocess.py:93} INFO - 2025-09-08 14:46:09,030 INFO: Flushed batch: orders=200 items=369
[2025-09-08T14:46:09.033+0530] {subprocess.py:93} INFO - 2025-09-08 14:46:09,032 WARNING: Failed to send webhook notification: HTTPConnectionPool(host='localhost', port=5000): Max retries exceeded with url: /webhook (Caused by NewConnectionError('<urllib3.connection.HTTPConnection object at 0x7afddbd20370>: Failed to establish a new connection: [Errno 111] Connection refused'))
[2025-09-08T14:46:09.622+0530] {subprocess.py:93} INFO - 2025-09-08 14:46:09,622 INFO: Flushed batch: orders=200 items=361
[2025-09-08T14:46:09.625+0530] {subprocess.py:93} INFO - 2025-09-08 14:46:09,625 WARNING: Failed to send webhook notification: HTTPConnectionPool(host='localhost', port=5000): Max retries exceeded with url: /webhook (Caused by NewConnectionError('<urllib3.connection.HTTPConnection object at 0x7afddbc2d0c0>: Failed to establish a new connection: [Errno 111] Connection refused'))
[2025-09-08T14:46:09.822+0530] {subprocess.py:93} INFO - 2025-09-08 14:46:09,822 INFO: Flushed batch: orders=200 items=338
[2025-09-08T14:46:09.825+0530] {subprocess.py:93} INFO - 2025-09-08 14:46:09,825 WARNING: Failed to send webhook notification: HTTPConnectionPool(host='localhost', port=5000): Max retries exceeded with url: /webhook (Caused by NewConnectionError('<urllib3.connection.HTTPConnection object at 0x7afddbdd84f0>: Failed to establish a new connection: [Errno 111] Connection refused'))
[2025-09-08T14:46:10.022+0530] {subprocess.py:93} INFO - 2025-09-08 14:46:10,022 INFO: Flushed batch: orders=200 items=337
[2025-09-08T14:46:10.025+0530] {subprocess.py:93} INFO - 2025-09-08 14:46:10,025 WARNING: Failed to send webhook notification: HTTPConnectionPool(host='localhost', port=5000): Max retries exceeded with url: /webhook (Caused by NewConnectionError('<urllib3.connection.HTTPConnection object at 0x7afddbc2dd20>: Failed to establish a new connection: [Errno 111] Connection refused'))
[2025-09-08T14:46:10.448+0530] {subprocess.py:93} INFO - 2025-09-08 14:46:10,448 INFO: Flushed batch: orders=200 items=326
[2025-09-08T14:46:10.451+0530] {subprocess.py:93} INFO - 2025-09-08 14:46:10,451 WARNING: Failed to send webhook notification: HTTPConnectionPool(host='localhost', port=5000): Max retries exceeded with url: /webhook (Caused by NewConnectionError('<urllib3.connection.HTTPConnection object at 0x7afddbc15d80>: Failed to establish a new connection: [Errno 111] Connection refused'))
[2025-09-08T14:46:10.702+0530] {subprocess.py:93} INFO - 2025-09-08 14:46:10,702 INFO: Flushed batch: orders=200 items=360
[2025-09-08T14:46:10.705+0530] {subprocess.py:93} INFO - 2025-09-08 14:46:10,705 WARNING: Failed to send webhook notification: HTTPConnectionPool(host='localhost', port=5000): Max retries exceeded with url: /webhook (Caused by NewConnectionError('<urllib3.connection.HTTPConnection object at 0x7afddbd21a20>: Failed to establish a new connection: [Errno 111] Connection refused'))
[2025-09-08T14:46:11.374+0530] {subprocess.py:93} INFO - 2025-09-08 14:46:11,374 INFO: Flushed batch: orders=200 items=351
[2025-09-08T14:46:11.377+0530] {subprocess.py:93} INFO - 2025-09-08 14:46:11,377 WARNING: Failed to send webhook notification: HTTPConnectionPool(host='localhost', port=5000): Max retries exceeded with url: /webhook (Caused by NewConnectionError('<urllib3.connection.HTTPConnection object at 0x7afddbc4acb0>: Failed to establish a new connection: [Errno 111] Connection refused'))
[2025-09-08T14:46:11.591+0530] {subprocess.py:93} INFO - 2025-09-08 14:46:11,591 INFO: Flushed batch: orders=200 items=358
[2025-09-08T14:46:11.592+0530] {subprocess.py:93} INFO - 2025-09-08 14:46:11,591 WARNING: Failed to send webhook notification: HTTPConnectionPool(host='localhost', port=5000): Max retries exceeded with url: /webhook (Caused by NewConnectionError('<urllib3.connection.HTTPConnection object at 0x7afddbc2fb20>: Failed to establish a new connection: [Errno 111] Connection refused'))
[2025-09-08T14:46:12.084+0530] {subprocess.py:93} INFO - 2025-09-08 14:46:12,084 INFO: Flushed batch: orders=200 items=332
[2025-09-08T14:46:12.087+0530] {subprocess.py:93} INFO - 2025-09-08 14:46:12,087 WARNING: Failed to send webhook notification: HTTPConnectionPool(host='localhost', port=5000): Max retries exceeded with url: /webhook (Caused by NewConnectionError('<urllib3.connection.HTTPConnection object at 0x7afddbd23850>: Failed to establish a new connection: [Errno 111] Connection refused'))
[2025-09-08T14:46:12.552+0530] {subprocess.py:93} INFO - 2025-09-08 14:46:12,552 INFO: Flushed batch: orders=200 items=370
[2025-09-08T14:46:12.555+0530] {subprocess.py:93} INFO - 2025-09-08 14:46:12,554 WARNING: Failed to send webhook notification: HTTPConnectionPool(host='localhost', port=5000): Max retries exceeded with url: /webhook (Caused by NewConnectionError('<urllib3.connection.HTTPConnection object at 0x7afddbd22bf0>: Failed to establish a new connection: [Errno 111] Connection refused'))
[2025-09-08T14:46:12.744+0530] {subprocess.py:93} INFO - 2025-09-08 14:46:12,743 INFO: Flushed batch: orders=200 items=338
[2025-09-08T14:46:12.746+0530] {subprocess.py:93} INFO - 2025-09-08 14:46:12,746 WARNING: Failed to send webhook notification: HTTPConnectionPool(host='localhost', port=5000): Max retries exceeded with url: /webhook (Caused by NewConnectionError('<urllib3.connection.HTTPConnection object at 0x7afddbd20b20>: Failed to establish a new connection: [Errno 111] Connection refused'))
[2025-09-08T14:46:13.474+0530] {subprocess.py:93} INFO - 2025-09-08 14:46:13,473 INFO: Flushed batch: orders=200 items=352
[2025-09-08T14:46:13.475+0530] {subprocess.py:93} INFO - 2025-09-08 14:46:13,475 WARNING: Failed to send webhook notification: HTTPConnectionPool(host='localhost', port=5000): Max retries exceeded with url: /webhook (Caused by NewConnectionError('<urllib3.connection.HTTPConnection object at 0x7afddbc60340>: Failed to establish a new connection: [Errno 111] Connection refused'))
[2025-09-08T14:46:13.863+0530] {subprocess.py:93} INFO - 2025-09-08 14:46:13,863 INFO: Flushed batch: orders=200 items=340
[2025-09-08T14:46:13.867+0530] {subprocess.py:93} INFO - 2025-09-08 14:46:13,867 WARNING: Failed to send webhook notification: HTTPConnectionPool(host='localhost', port=5000): Max retries exceeded with url: /webhook (Caused by NewConnectionError('<urllib3.connection.HTTPConnection object at 0x7afddbc4b640>: Failed to establish a new connection: [Errno 111] Connection refused'))
[2025-09-08T14:46:14.106+0530] {subprocess.py:93} INFO - 2025-09-08 14:46:14,106 INFO: Flushed batch: orders=200 items=348
[2025-09-08T14:46:14.109+0530] {subprocess.py:93} INFO - 2025-09-08 14:46:14,109 WARNING: Failed to send webhook notification: HTTPConnectionPool(host='localhost', port=5000): Max retries exceeded with url: /webhook (Caused by NewConnectionError('<urllib3.connection.HTTPConnection object at 0x7afddbc16ec0>: Failed to establish a new connection: [Errno 111] Connection refused'))
[2025-09-08T14:46:14.931+0530] {subprocess.py:93} INFO - 2025-09-08 14:46:14,931 INFO: Flushed batch: orders=200 items=360
[2025-09-08T14:46:14.934+0530] {subprocess.py:93} INFO - 2025-09-08 14:46:14,934 WARNING: Failed to send webhook notification: HTTPConnectionPool(host='localhost', port=5000): Max retries exceeded with url: /webhook (Caused by NewConnectionError('<urllib3.connection.HTTPConnection object at 0x7afddbc2ebc0>: Failed to establish a new connection: [Errno 111] Connection refused'))
[2025-09-08T14:46:15.141+0530] {subprocess.py:93} INFO - 2025-09-08 14:46:15,141 INFO: Flushed batch: orders=200 items=338
[2025-09-08T14:46:15.144+0530] {subprocess.py:93} INFO - 2025-09-08 14:46:15,143 WARNING: Failed to send webhook notification: HTTPConnectionPool(host='localhost', port=5000): Max retries exceeded with url: /webhook (Caused by NewConnectionError('<urllib3.connection.HTTPConnection object at 0x7afddbe9de70>: Failed to establish a new connection: [Errno 111] Connection refused'))
[2025-09-08T14:46:15.608+0530] {subprocess.py:93} INFO - 2025-09-08 14:46:15,607 INFO: Flushed batch: orders=200 items=335
[2025-09-08T14:46:15.610+0530] {subprocess.py:93} INFO - 2025-09-08 14:46:15,610 WARNING: Failed to send webhook notification: HTTPConnectionPool(host='localhost', port=5000): Max retries exceeded with url: /webhook (Caused by NewConnectionError('<urllib3.connection.HTTPConnection object at 0x7afddbd8ea40>: Failed to establish a new connection: [Errno 111] Connection refused'))
[2025-09-08T14:46:15.611+0530] {subprocess.py:93} INFO - 2025-09-08 14:46:15,611 INFO: Generated 5000 orders
[2025-09-08T14:46:56.821+0530] {subprocess.py:93} INFO - 2025-09-08 14:46:56,821 INFO: Inserted 48004 clickstream events.
[2025-09-08T14:46:56.822+0530] {subprocess.py:93} INFO - 2025-09-08 14:46:56,822 WARNING: Failed to send webhook notification: HTTPConnectionPool(host='localhost', port=5000): Max retries exceeded with url: /webhook (Caused by NewConnectionError('<urllib3.connection.HTTPConnection object at 0x7afddc5f18d0>: Failed to establish a new connection: [Errno 111] Connection refused'))
[2025-09-08T14:47:01.886+0530] {subprocess.py:93} INFO - 2025-09-08 14:47:01,885 INFO: Validation done: orphans orders=0 items=0 inventory=0 mismatches=0
[2025-09-08T14:47:01.898+0530] {subprocess.py:93} INFO - 2025-09-08 14:47:01,898 INFO: Integrity report: {'orphan_orders': 0, 'orphan_order_items': 0, 'inventory_orphans': 0, 'order_amount_mismatches': []}
[2025-09-08T14:47:01.929+0530] {subprocess.py:93} INFO - [2025-09-08 14:47:01] ‚úÖ Synthetic data streaming completed successfully!
[2025-09-08T14:47:01.930+0530] {subprocess.py:97} INFO - Command exited with return code 0
[2025-09-08T14:47:01.930+0530] {taskinstance.py:441} INFO - ::group::Post task execution logs
[2025-09-08T14:47:02.431+0530] {taskinstance.py:1206} INFO - Marking task as SUCCESS. dag_id=synth_stream_5min, task_id=run_synth_stream, run_id=scheduled__2025-09-08T09:05:00+00:00, execution_date=20250908T090500, start_date=20250908T091602, end_date=20250908T091702
[2025-09-08T14:47:02.773+0530] {local_task_job_runner.py:243} INFO - Task exited with return code 0
[2025-09-08T14:47:02.782+0530] {taskinstance.py:3503} INFO - 0 downstream tasks scheduled from follow-on schedule check
[2025-09-08T14:47:02.782+0530] {local_task_job_runner.py:222} INFO - ::endgroup::
