[2025-09-08T13:31:00.971+0530] {local_task_job_runner.py:120} INFO - ::group::Pre task execution logs
[2025-09-08T13:31:00.985+0530] {taskinstance.py:2076} INFO - Dependencies all met for dep_context=non-requeueable deps ti=<TaskInstance: synth_stream_5min.run_synth_stream scheduled__2025-09-08T07:55:00+00:00 [queued]>
[2025-09-08T13:31:00.988+0530] {taskinstance.py:2076} INFO - Dependencies all met for dep_context=requeueable deps ti=<TaskInstance: synth_stream_5min.run_synth_stream scheduled__2025-09-08T07:55:00+00:00 [queued]>
[2025-09-08T13:31:00.988+0530] {taskinstance.py:2306} INFO - Starting attempt 1 of 2
[2025-09-08T13:31:01.061+0530] {taskinstance.py:2330} INFO - Executing <Task(BashOperator): run_synth_stream> on 2025-09-08 07:55:00+00:00
[2025-09-08T13:31:01.069+0530] {standard_task_runner.py:64} INFO - Started process 716816 to run task
[2025-09-08T13:31:01.075+0530] {standard_task_runner.py:90} INFO - Running: ['airflow', 'tasks', 'run', 'synth_stream_5min', 'run_synth_stream', 'scheduled__2025-09-08T07:55:00+00:00', '--job-id', '29', '--raw', '--subdir', 'DAGS_FOLDER/ecom_schedules.py', '--cfg-path', '/tmp/tmpuza1p6tl']
[2025-09-08T13:31:01.078+0530] {standard_task_runner.py:91} INFO - Job 29: Subtask run_synth_stream
[2025-09-08T13:31:01.163+0530] {task_command.py:426} INFO - Running <TaskInstance: synth_stream_5min.run_synth_stream scheduled__2025-09-08T07:55:00+00:00 [running]> on host softsuave-ASUS-EXPERTCENTER-D700ME-D500ME
[2025-09-08T13:31:01.322+0530] {taskinstance.py:2648} INFO - Exporting env vars: AIRFLOW_CTX_DAG_OWNER='airflow' AIRFLOW_CTX_DAG_ID='synth_stream_5min' AIRFLOW_CTX_TASK_ID='run_synth_stream' AIRFLOW_CTX_EXECUTION_DATE='2025-09-08T07:55:00+00:00' AIRFLOW_CTX_TRY_NUMBER='1' AIRFLOW_CTX_DAG_RUN_ID='scheduled__2025-09-08T07:55:00+00:00'
[2025-09-08T13:31:01.323+0530] {taskinstance.py:430} INFO - ::endgroup::
[2025-09-08T13:31:01.324+0530] {subprocess.py:63} INFO - Tmp dir root location: /tmp
[2025-09-08T13:31:01.324+0530] {subprocess.py:75} INFO - Running command: ['/usr/bin/bash', '-c', 'bash /media/softsuave/DATA-HDD/DataEngineering/Apache_Airflow/scripts/synth/run_synth_stream.sh | cat']
[2025-09-08T13:31:01.331+0530] {subprocess.py:86} INFO - Output:
[2025-09-08T13:31:01.370+0530] {subprocess.py:93} INFO - [2025-09-08 13:31:01] üöÄ Starting Synthetic E-commerce Data Stream...
[2025-09-08T13:31:01.370+0530] {subprocess.py:93} INFO - ----------------------------------------------
[2025-09-08T13:31:01.370+0530] {subprocess.py:93} INFO -  Database   : ecom_db
[2025-09-08T13:31:01.370+0530] {subprocess.py:93} INFO -  User       : sa
[2025-09-08T13:31:01.370+0530] {subprocess.py:93} INFO -  Server     : localhost:1433
[2025-09-08T13:31:01.370+0530] {subprocess.py:93} INFO -  Interval   : 5 min
[2025-09-08T13:31:01.371+0530] {subprocess.py:93} INFO -  Orders     : 50
[2025-09-08T13:31:01.371+0530] {subprocess.py:93} INFO -  Clicks     : 100
[2025-09-08T13:31:01.371+0530] {subprocess.py:93} INFO -  Webhook    : http://localhost:5000/webhook
[2025-09-08T13:31:01.371+0530] {subprocess.py:93} INFO - ----------------------------------------------
[2025-09-08T13:31:01.371+0530] {subprocess.py:93} INFO - 
[2025-09-08T13:31:01.591+0530] {subprocess.py:93} INFO - [2025-09-08 13:31:01] üîß Activating virtual environment...
[2025-09-08T13:31:01.650+0530] {subprocess.py:93} INFO - [2025-09-08 13:31:01] üîç Checking database connection...
[2025-09-08T13:31:01.869+0530] {subprocess.py:93} INFO - ‚úÖ Database connection successful
[2025-09-08T13:31:01.877+0530] {subprocess.py:93} INFO - [2025-09-08 13:31:01] üîÑ Starting synthetic data stream...
[2025-09-08T13:31:01.877+0530] {subprocess.py:93} INFO - Press Ctrl+C to stop
[2025-09-08T13:31:01.877+0530] {subprocess.py:93} INFO - 
[2025-09-08T13:31:02.212+0530] {subprocess.py:93} INFO - 2025-09-08 13:31:02,212 INFO: Tables ensured/created (if needed).
[2025-09-08T13:31:02.237+0530] {subprocess.py:93} INFO - 2025-09-08 13:31:02,237 INFO: Customers: 1000 already present; skipping seeding.
[2025-09-08T13:31:02.238+0530] {subprocess.py:93} INFO - 2025-09-08 13:31:02,238 INFO: Products: 500 already present; skipping seeding.
[2025-09-08T13:31:02.238+0530] {subprocess.py:93} INFO - 2025-09-08 13:31:02,238 INFO: Running one-shot generation: orders=5000, sessions=3000
[2025-09-08T13:31:02.244+0530] {subprocess.py:93} INFO - /media/softsuave/DATA-HDD/DataEngineering/Apache_Airflow/src/synth_ecom_mssql_stream.py:397: RemovedIn20Warning: Deprecated API features detected! These feature(s) are not compatible with SQLAlchemy 2.0. To prevent incompatible upgrades prior to updating applications, ensure requirements files are pinned to "sqlalchemy<2.0". Set environment variable SQLALCHEMY_WARN_20=1 to show all deprecation warnings.  Set environment variable SQLALCHEMY_SILENCE_UBER_WARNING=1 to silence this message. (Background on SQLAlchemy 2.0 at: https://sqlalche.me/e/b8d9)
[2025-09-08T13:31:02.244+0530] {subprocess.py:93} INFO -   customers = [dict(r) for r in conn.execute(select(self.tables["customers"])).fetchall()]
[2025-09-08T13:31:02.251+0530] {subprocess.py:93} INFO - 2025-09-08 13:31:02,251 INFO: Generating 5000 orders (batch_size=200, force_order_date_now=False)...
[2025-09-08T13:31:02.662+0530] {subprocess.py:93} INFO - 2025-09-08 13:31:02,661 INFO: Flushed batch: orders=200 items=318
[2025-09-08T13:31:02.667+0530] {subprocess.py:93} INFO - 2025-09-08 13:31:02,667 WARNING: Failed to send webhook notification: HTTPConnectionPool(host='localhost', port=5000): Max retries exceeded with url: /webhook (Caused by NewConnectionError('<urllib3.connection.HTTPConnection object at 0x70564dc7c310>: Failed to establish a new connection: [Errno 111] Connection refused'))
[2025-09-08T13:31:02.853+0530] {subprocess.py:93} INFO - 2025-09-08 13:31:02,853 INFO: Flushed batch: orders=200 items=376
[2025-09-08T13:31:02.856+0530] {subprocess.py:93} INFO - 2025-09-08 13:31:02,856 WARNING: Failed to send webhook notification: HTTPConnectionPool(host='localhost', port=5000): Max retries exceeded with url: /webhook (Caused by NewConnectionError('<urllib3.connection.HTTPConnection object at 0x70564db5f010>: Failed to establish a new connection: [Errno 111] Connection refused'))
[2025-09-08T13:31:03.045+0530] {subprocess.py:93} INFO - 2025-09-08 13:31:03,044 INFO: Flushed batch: orders=200 items=345
[2025-09-08T13:31:03.047+0530] {subprocess.py:93} INFO - 2025-09-08 13:31:03,047 WARNING: Failed to send webhook notification: HTTPConnectionPool(host='localhost', port=5000): Max retries exceeded with url: /webhook (Caused by NewConnectionError('<urllib3.connection.HTTPConnection object at 0x70564db86110>: Failed to establish a new connection: [Errno 111] Connection refused'))
[2025-09-08T13:31:03.412+0530] {subprocess.py:93} INFO - 2025-09-08 13:31:03,412 INFO: Flushed batch: orders=200 items=365
[2025-09-08T13:31:03.413+0530] {subprocess.py:93} INFO - 2025-09-08 13:31:03,413 WARNING: Failed to send webhook notification: HTTPConnectionPool(host='localhost', port=5000): Max retries exceeded with url: /webhook (Caused by NewConnectionError('<urllib3.connection.HTTPConnection object at 0x70564dbb2da0>: Failed to establish a new connection: [Errno 111] Connection refused'))
[2025-09-08T13:31:03.646+0530] {subprocess.py:93} INFO - 2025-09-08 13:31:03,645 INFO: Flushed batch: orders=200 items=341
[2025-09-08T13:31:03.648+0530] {subprocess.py:93} INFO - 2025-09-08 13:31:03,648 WARNING: Failed to send webhook notification: HTTPConnectionPool(host='localhost', port=5000): Max retries exceeded with url: /webhook (Caused by NewConnectionError('<urllib3.connection.HTTPConnection object at 0x70564dbe3f40>: Failed to establish a new connection: [Errno 111] Connection refused'))
[2025-09-08T13:31:03.837+0530] {subprocess.py:93} INFO - 2025-09-08 13:31:03,837 INFO: Flushed batch: orders=200 items=338
[2025-09-08T13:31:03.840+0530] {subprocess.py:93} INFO - 2025-09-08 13:31:03,839 WARNING: Failed to send webhook notification: HTTPConnectionPool(host='localhost', port=5000): Max retries exceeded with url: /webhook (Caused by NewConnectionError('<urllib3.connection.HTTPConnection object at 0x70564db4c250>: Failed to establish a new connection: [Errno 111] Connection refused'))
[2025-09-08T13:31:04.104+0530] {subprocess.py:93} INFO - 2025-09-08 13:31:04,104 INFO: Flushed batch: orders=200 items=351
[2025-09-08T13:31:04.106+0530] {subprocess.py:93} INFO - 2025-09-08 13:31:04,106 WARNING: Failed to send webhook notification: HTTPConnectionPool(host='localhost', port=5000): Max retries exceeded with url: /webhook (Caused by NewConnectionError('<urllib3.connection.HTTPConnection object at 0x70564dbe17e0>: Failed to establish a new connection: [Errno 111] Connection refused'))
[2025-09-08T13:31:04.304+0530] {subprocess.py:93} INFO - 2025-09-08 13:31:04,304 INFO: Flushed batch: orders=200 items=379
[2025-09-08T13:31:04.307+0530] {subprocess.py:93} INFO - 2025-09-08 13:31:04,307 WARNING: Failed to send webhook notification: HTTPConnectionPool(host='localhost', port=5000): Max retries exceeded with url: /webhook (Caused by NewConnectionError('<urllib3.connection.HTTPConnection object at 0x70564db4ee30>: Failed to establish a new connection: [Errno 111] Connection refused'))
[2025-09-08T13:31:04.514+0530] {subprocess.py:93} INFO - 2025-09-08 13:31:04,514 INFO: Flushed batch: orders=200 items=355
[2025-09-08T13:31:04.517+0530] {subprocess.py:93} INFO - 2025-09-08 13:31:04,517 WARNING: Failed to send webhook notification: HTTPConnectionPool(host='localhost', port=5000): Max retries exceeded with url: /webhook (Caused by NewConnectionError('<urllib3.connection.HTTPConnection object at 0x70564db5d5d0>: Failed to establish a new connection: [Errno 111] Connection refused'))
[2025-09-08T13:31:04.697+0530] {subprocess.py:93} INFO - 2025-09-08 13:31:04,697 INFO: Flushed batch: orders=200 items=346
[2025-09-08T13:31:04.700+0530] {subprocess.py:93} INFO - 2025-09-08 13:31:04,700 WARNING: Failed to send webhook notification: HTTPConnectionPool(host='localhost', port=5000): Max retries exceeded with url: /webhook (Caused by NewConnectionError('<urllib3.connection.HTTPConnection object at 0x70564db5c130>: Failed to establish a new connection: [Errno 111] Connection refused'))
[2025-09-08T13:31:04.864+0530] {subprocess.py:93} INFO - 2025-09-08 13:31:04,864 INFO: Flushed batch: orders=200 items=346
[2025-09-08T13:31:04.866+0530] {subprocess.py:93} INFO - 2025-09-08 13:31:04,866 WARNING: Failed to send webhook notification: HTTPConnectionPool(host='localhost', port=5000): Max retries exceeded with url: /webhook (Caused by NewConnectionError('<urllib3.connection.HTTPConnection object at 0x70564dbe3d30>: Failed to establish a new connection: [Errno 111] Connection refused'))
[2025-09-08T13:31:05.040+0530] {subprocess.py:93} INFO - 2025-09-08 13:31:05,039 INFO: Flushed batch: orders=200 items=337
[2025-09-08T13:31:05.042+0530] {subprocess.py:93} INFO - 2025-09-08 13:31:05,042 WARNING: Failed to send webhook notification: HTTPConnectionPool(host='localhost', port=5000): Max retries exceeded with url: /webhook (Caused by NewConnectionError('<urllib3.connection.HTTPConnection object at 0x70564dbf3fd0>: Failed to establish a new connection: [Errno 111] Connection refused'))
[2025-09-08T13:31:05.232+0530] {subprocess.py:93} INFO - 2025-09-08 13:31:05,232 INFO: Flushed batch: orders=200 items=319
[2025-09-08T13:31:05.235+0530] {subprocess.py:93} INFO - 2025-09-08 13:31:05,234 WARNING: Failed to send webhook notification: HTTPConnectionPool(host='localhost', port=5000): Max retries exceeded with url: /webhook (Caused by NewConnectionError('<urllib3.connection.HTTPConnection object at 0x70564da0c550>: Failed to establish a new connection: [Errno 111] Connection refused'))
[2025-09-08T13:31:05.448+0530] {subprocess.py:93} INFO - 2025-09-08 13:31:05,448 INFO: Flushed batch: orders=200 items=304
[2025-09-08T13:31:05.450+0530] {subprocess.py:93} INFO - 2025-09-08 13:31:05,450 WARNING: Failed to send webhook notification: HTTPConnectionPool(host='localhost', port=5000): Max retries exceeded with url: /webhook (Caused by NewConnectionError('<urllib3.connection.HTTPConnection object at 0x70564da0f010>: Failed to establish a new connection: [Errno 111] Connection refused'))
[2025-09-08T13:31:06.040+0530] {subprocess.py:93} INFO - 2025-09-08 13:31:06,040 INFO: Flushed batch: orders=200 items=351
[2025-09-08T13:31:06.043+0530] {subprocess.py:93} INFO - 2025-09-08 13:31:06,043 WARNING: Failed to send webhook notification: HTTPConnectionPool(host='localhost', port=5000): Max retries exceeded with url: /webhook (Caused by NewConnectionError('<urllib3.connection.HTTPConnection object at 0x70564db4f220>: Failed to establish a new connection: [Errno 111] Connection refused'))
[2025-09-08T13:31:06.259+0530] {subprocess.py:93} INFO - 2025-09-08 13:31:06,258 INFO: Flushed batch: orders=200 items=334
[2025-09-08T13:31:06.262+0530] {subprocess.py:93} INFO - 2025-09-08 13:31:06,262 WARNING: Failed to send webhook notification: HTTPConnectionPool(host='localhost', port=5000): Max retries exceeded with url: /webhook (Caused by NewConnectionError('<urllib3.connection.HTTPConnection object at 0x70564dbe1ba0>: Failed to establish a new connection: [Errno 111] Connection refused'))
[2025-09-08T13:31:06.467+0530] {subprocess.py:93} INFO - 2025-09-08 13:31:06,467 INFO: Flushed batch: orders=200 items=342
[2025-09-08T13:31:06.470+0530] {subprocess.py:93} INFO - 2025-09-08 13:31:06,470 WARNING: Failed to send webhook notification: HTTPConnectionPool(host='localhost', port=5000): Max retries exceeded with url: /webhook (Caused by NewConnectionError('<urllib3.connection.HTTPConnection object at 0x70564dbe0280>: Failed to establish a new connection: [Errno 111] Connection refused'))
[2025-09-08T13:31:06.752+0530] {subprocess.py:93} INFO - 2025-09-08 13:31:06,751 INFO: Flushed batch: orders=200 items=339
[2025-09-08T13:31:06.754+0530] {subprocess.py:93} INFO - 2025-09-08 13:31:06,754 WARNING: Failed to send webhook notification: HTTPConnectionPool(host='localhost', port=5000): Max retries exceeded with url: /webhook (Caused by NewConnectionError('<urllib3.connection.HTTPConnection object at 0x70564db4d0c0>: Failed to establish a new connection: [Errno 111] Connection refused'))
[2025-09-08T13:31:06.942+0530] {subprocess.py:93} INFO - 2025-09-08 13:31:06,942 INFO: Flushed batch: orders=200 items=349
[2025-09-08T13:31:06.945+0530] {subprocess.py:93} INFO - 2025-09-08 13:31:06,945 WARNING: Failed to send webhook notification: HTTPConnectionPool(host='localhost', port=5000): Max retries exceeded with url: /webhook (Caused by NewConnectionError('<urllib3.connection.HTTPConnection object at 0x70564db4e9b0>: Failed to establish a new connection: [Errno 111] Connection refused'))
[2025-09-08T13:31:07.167+0530] {subprocess.py:93} INFO - 2025-09-08 13:31:07,167 INFO: Flushed batch: orders=200 items=386
[2025-09-08T13:31:07.169+0530] {subprocess.py:93} INFO - 2025-09-08 13:31:07,169 WARNING: Failed to send webhook notification: HTTPConnectionPool(host='localhost', port=5000): Max retries exceeded with url: /webhook (Caused by NewConnectionError('<urllib3.connection.HTTPConnection object at 0x70564da0d2d0>: Failed to establish a new connection: [Errno 111] Connection refused'))
[2025-09-08T13:31:07.335+0530] {subprocess.py:93} INFO - 2025-09-08 13:31:07,335 INFO: Flushed batch: orders=200 items=359
[2025-09-08T13:31:07.338+0530] {subprocess.py:93} INFO - 2025-09-08 13:31:07,338 WARNING: Failed to send webhook notification: HTTPConnectionPool(host='localhost', port=5000): Max retries exceeded with url: /webhook (Caused by NewConnectionError('<urllib3.connection.HTTPConnection object at 0x70564da05540>: Failed to establish a new connection: [Errno 111] Connection refused'))
[2025-09-08T13:31:07.543+0530] {subprocess.py:93} INFO - 2025-09-08 13:31:07,543 INFO: Flushed batch: orders=200 items=379
[2025-09-08T13:31:07.547+0530] {subprocess.py:93} INFO - 2025-09-08 13:31:07,546 WARNING: Failed to send webhook notification: HTTPConnectionPool(host='localhost', port=5000): Max retries exceeded with url: /webhook (Caused by NewConnectionError('<urllib3.connection.HTTPConnection object at 0x70564da26260>: Failed to establish a new connection: [Errno 111] Connection refused'))
[2025-09-08T13:31:07.743+0530] {subprocess.py:93} INFO - 2025-09-08 13:31:07,743 INFO: Flushed batch: orders=200 items=381
[2025-09-08T13:31:07.746+0530] {subprocess.py:93} INFO - 2025-09-08 13:31:07,745 WARNING: Failed to send webhook notification: HTTPConnectionPool(host='localhost', port=5000): Max retries exceeded with url: /webhook (Caused by NewConnectionError('<urllib3.connection.HTTPConnection object at 0x70564db4d930>: Failed to establish a new connection: [Errno 111] Connection refused'))
[2025-09-08T13:31:07.960+0530] {subprocess.py:93} INFO - 2025-09-08 13:31:07,960 INFO: Flushed batch: orders=200 items=361
[2025-09-08T13:31:07.963+0530] {subprocess.py:93} INFO - 2025-09-08 13:31:07,962 WARNING: Failed to send webhook notification: HTTPConnectionPool(host='localhost', port=5000): Max retries exceeded with url: /webhook (Caused by NewConnectionError('<urllib3.connection.HTTPConnection object at 0x70564dd34e50>: Failed to establish a new connection: [Errno 111] Connection refused'))
[2025-09-08T13:31:08.160+0530] {subprocess.py:93} INFO - 2025-09-08 13:31:08,160 INFO: Flushed batch: orders=200 items=328
[2025-09-08T13:31:08.162+0530] {subprocess.py:93} INFO - 2025-09-08 13:31:08,162 WARNING: Failed to send webhook notification: HTTPConnectionPool(host='localhost', port=5000): Max retries exceeded with url: /webhook (Caused by NewConnectionError('<urllib3.connection.HTTPConnection object at 0x70564dc7c6d0>: Failed to establish a new connection: [Errno 111] Connection refused'))
[2025-09-08T13:31:08.162+0530] {subprocess.py:93} INFO - 2025-09-08 13:31:08,162 INFO: Generated 5000 orders
[2025-09-08T13:31:32.214+0530] {subprocess.py:93} INFO - 2025-09-08 13:31:32,214 INFO: Inserted 48057 clickstream events.
[2025-09-08T13:31:32.215+0530] {subprocess.py:93} INFO - 2025-09-08 13:31:32,215 WARNING: Failed to send webhook notification: HTTPConnectionPool(host='localhost', port=5000): Max retries exceeded with url: /webhook (Caused by NewConnectionError('<urllib3.connection.HTTPConnection object at 0x70564c8b6da0>: Failed to establish a new connection: [Errno 111] Connection refused'))
[2025-09-08T13:31:32.771+0530] {subprocess.py:93} INFO - 2025-09-08 13:31:32,771 INFO: Validation done: orphans orders=0 items=0 inventory=0 mismatches=0
[2025-09-08T13:31:32.774+0530] {subprocess.py:93} INFO - 2025-09-08 13:31:32,774 INFO: Integrity report: {'orphan_orders': 0, 'orphan_order_items': 0, 'inventory_orphans': 0, 'order_amount_mismatches': []}
[2025-09-08T13:31:32.805+0530] {subprocess.py:93} INFO - [2025-09-08 13:31:32] ‚úÖ Synthetic data streaming completed successfully!
[2025-09-08T13:31:32.805+0530] {subprocess.py:97} INFO - Command exited with return code 0
[2025-09-08T13:31:32.805+0530] {taskinstance.py:441} INFO - ::group::Post task execution logs
[2025-09-08T13:31:33.027+0530] {taskinstance.py:1206} INFO - Marking task as SUCCESS. dag_id=synth_stream_5min, task_id=run_synth_stream, run_id=scheduled__2025-09-08T07:55:00+00:00, execution_date=20250908T075500, start_date=20250908T080100, end_date=20250908T080133
[2025-09-08T13:31:33.453+0530] {local_task_job_runner.py:243} INFO - Task exited with return code 0
[2025-09-08T13:31:33.464+0530] {taskinstance.py:3503} INFO - 0 downstream tasks scheduled from follow-on schedule check
[2025-09-08T13:31:33.465+0530] {local_task_job_runner.py:222} INFO - ::endgroup::
