[2025-09-08T13:55:04.008+0530] {local_task_job_runner.py:120} INFO - ::group::Pre task execution logs
[2025-09-08T13:55:04.020+0530] {taskinstance.py:2076} INFO - Dependencies all met for dep_context=non-requeueable deps ti=<TaskInstance: synth_stream_5min.run_synth_stream scheduled__2025-09-08T08:20:00+00:00 [queued]>
[2025-09-08T13:55:04.023+0530] {taskinstance.py:2076} INFO - Dependencies all met for dep_context=requeueable deps ti=<TaskInstance: synth_stream_5min.run_synth_stream scheduled__2025-09-08T08:20:00+00:00 [queued]>
[2025-09-08T13:55:04.023+0530] {taskinstance.py:2306} INFO - Starting attempt 1 of 2
[2025-09-08T13:55:04.244+0530] {taskinstance.py:2330} INFO - Executing <Task(BashOperator): run_synth_stream> on 2025-09-08 08:20:00+00:00
[2025-09-08T13:55:04.250+0530] {standard_task_runner.py:64} INFO - Started process 723381 to run task
[2025-09-08T13:55:04.252+0530] {standard_task_runner.py:90} INFO - Running: ['airflow', 'tasks', 'run', 'synth_stream_5min', 'run_synth_stream', 'scheduled__2025-09-08T08:20:00+00:00', '--job-id', '36', '--raw', '--subdir', 'DAGS_FOLDER/ecom_schedules.py', '--cfg-path', '/tmp/tmpq035elme']
[2025-09-08T13:55:04.255+0530] {standard_task_runner.py:91} INFO - Job 36: Subtask run_synth_stream
[2025-09-08T13:55:04.508+0530] {task_command.py:426} INFO - Running <TaskInstance: synth_stream_5min.run_synth_stream scheduled__2025-09-08T08:20:00+00:00 [running]> on host softsuave-ASUS-EXPERTCENTER-D700ME-D500ME
[2025-09-08T13:55:05.066+0530] {taskinstance.py:2648} INFO - Exporting env vars: AIRFLOW_CTX_DAG_OWNER='airflow' AIRFLOW_CTX_DAG_ID='synth_stream_5min' AIRFLOW_CTX_TASK_ID='run_synth_stream' AIRFLOW_CTX_EXECUTION_DATE='2025-09-08T08:20:00+00:00' AIRFLOW_CTX_TRY_NUMBER='1' AIRFLOW_CTX_DAG_RUN_ID='scheduled__2025-09-08T08:20:00+00:00'
[2025-09-08T13:55:05.068+0530] {taskinstance.py:430} INFO - ::endgroup::
[2025-09-08T13:55:05.069+0530] {subprocess.py:63} INFO - Tmp dir root location: /tmp
[2025-09-08T13:55:05.069+0530] {subprocess.py:75} INFO - Running command: ['/usr/bin/bash', '-c', 'bash /media/softsuave/DATA-HDD/DataEngineering/Apache_Airflow/scripts/synth/run_synth_stream.sh | cat']
[2025-09-08T13:55:05.076+0530] {subprocess.py:86} INFO - Output:
[2025-09-08T13:55:05.107+0530] {subprocess.py:93} INFO - [2025-09-08 13:55:05] üöÄ Starting Synthetic E-commerce Data Stream...
[2025-09-08T13:55:05.107+0530] {subprocess.py:93} INFO - ----------------------------------------------
[2025-09-08T13:55:05.107+0530] {subprocess.py:93} INFO -  Database   : ecom_db
[2025-09-08T13:55:05.107+0530] {subprocess.py:93} INFO -  User       : sa
[2025-09-08T13:55:05.107+0530] {subprocess.py:93} INFO -  Server     : localhost:1433
[2025-09-08T13:55:05.107+0530] {subprocess.py:93} INFO -  Interval   : 5 min
[2025-09-08T13:55:05.107+0530] {subprocess.py:93} INFO -  Orders     : 50
[2025-09-08T13:55:05.107+0530] {subprocess.py:93} INFO -  Clicks     : 100
[2025-09-08T13:55:05.108+0530] {subprocess.py:93} INFO -  Webhook    : http://localhost:5000/webhook
[2025-09-08T13:55:05.108+0530] {subprocess.py:93} INFO - ----------------------------------------------
[2025-09-08T13:55:05.108+0530] {subprocess.py:93} INFO - 
[2025-09-08T13:55:05.126+0530] {subprocess.py:93} INFO - [2025-09-08 13:55:05] üîß Activating virtual environment...
[2025-09-08T13:55:05.128+0530] {subprocess.py:93} INFO - [2025-09-08 13:55:05] üîç Checking database connection...
[2025-09-08T13:55:05.174+0530] {subprocess.py:93} INFO - ‚úÖ Database connection successful
[2025-09-08T13:55:05.186+0530] {subprocess.py:93} INFO - [2025-09-08 13:55:05] üîÑ Starting synthetic data stream...
[2025-09-08T13:55:05.187+0530] {subprocess.py:93} INFO - Press Ctrl+C to stop
[2025-09-08T13:55:05.187+0530] {subprocess.py:93} INFO - 
[2025-09-08T13:55:05.390+0530] {subprocess.py:93} INFO - 2025-09-08 13:55:05,390 INFO: Tables ensured/created (if needed).
[2025-09-08T13:55:05.403+0530] {subprocess.py:93} INFO - 2025-09-08 13:55:05,403 INFO: Customers: 1000 already present; skipping seeding.
[2025-09-08T13:55:05.404+0530] {subprocess.py:93} INFO - 2025-09-08 13:55:05,404 INFO: Products: 500 already present; skipping seeding.
[2025-09-08T13:55:05.404+0530] {subprocess.py:93} INFO - 2025-09-08 13:55:05,404 INFO: Running one-shot generation: orders=5000, sessions=3000
[2025-09-08T13:55:05.411+0530] {subprocess.py:93} INFO - /media/softsuave/DATA-HDD/DataEngineering/Apache_Airflow/src/synth_ecom_mssql_stream.py:397: RemovedIn20Warning: Deprecated API features detected! These feature(s) are not compatible with SQLAlchemy 2.0. To prevent incompatible upgrades prior to updating applications, ensure requirements files are pinned to "sqlalchemy<2.0". Set environment variable SQLALCHEMY_WARN_20=1 to show all deprecation warnings.  Set environment variable SQLALCHEMY_SILENCE_UBER_WARNING=1 to silence this message. (Background on SQLAlchemy 2.0 at: https://sqlalche.me/e/b8d9)
[2025-09-08T13:55:05.411+0530] {subprocess.py:93} INFO -   customers = [dict(r) for r in conn.execute(select(self.tables["customers"])).fetchall()]
[2025-09-08T13:55:05.418+0530] {subprocess.py:93} INFO - 2025-09-08 13:55:05,418 INFO: Generating 5000 orders (batch_size=200, force_order_date_now=False)...
[2025-09-08T13:55:06.269+0530] {subprocess.py:93} INFO - 2025-09-08 13:55:06,269 INFO: Flushed batch: orders=200 items=341
[2025-09-08T13:55:06.274+0530] {subprocess.py:93} INFO - 2025-09-08 13:55:06,274 WARNING: Failed to send webhook notification: HTTPConnectionPool(host='localhost', port=5000): Max retries exceeded with url: /webhook (Caused by NewConnectionError('<urllib3.connection.HTTPConnection object at 0x78ab7cda94e0>: Failed to establish a new connection: [Errno 111] Connection refused'))
[2025-09-08T13:55:06.832+0530] {subprocess.py:93} INFO - 2025-09-08 13:55:06,831 INFO: Flushed batch: orders=200 items=334
[2025-09-08T13:55:06.834+0530] {subprocess.py:93} INFO - 2025-09-08 13:55:06,834 WARNING: Failed to send webhook notification: HTTPConnectionPool(host='localhost', port=5000): Max retries exceeded with url: /webhook (Caused by NewConnectionError('<urllib3.connection.HTTPConnection object at 0x78ab7cc7f310>: Failed to establish a new connection: [Errno 111] Connection refused'))
[2025-09-08T13:55:07.153+0530] {subprocess.py:93} INFO - 2025-09-08 13:55:07,153 INFO: Flushed batch: orders=200 items=349
[2025-09-08T13:55:07.156+0530] {subprocess.py:93} INFO - 2025-09-08 13:55:07,155 WARNING: Failed to send webhook notification: HTTPConnectionPool(host='localhost', port=5000): Max retries exceeded with url: /webhook (Caused by NewConnectionError('<urllib3.connection.HTTPConnection object at 0x78ab7ccc4f10>: Failed to establish a new connection: [Errno 111] Connection refused'))
[2025-09-08T13:55:07.679+0530] {subprocess.py:93} INFO - 2025-09-08 13:55:07,679 INFO: Flushed batch: orders=200 items=359
[2025-09-08T13:55:07.682+0530] {subprocess.py:93} INFO - 2025-09-08 13:55:07,681 WARNING: Failed to send webhook notification: HTTPConnectionPool(host='localhost', port=5000): Max retries exceeded with url: /webhook (Caused by NewConnectionError('<urllib3.connection.HTTPConnection object at 0x78ab7cce9510>: Failed to establish a new connection: [Errno 111] Connection refused'))
[2025-09-08T13:55:07.913+0530] {subprocess.py:93} INFO - 2025-09-08 13:55:07,912 INFO: Flushed batch: orders=200 items=332
[2025-09-08T13:55:07.915+0530] {subprocess.py:93} INFO - 2025-09-08 13:55:07,915 WARNING: Failed to send webhook notification: HTTPConnectionPool(host='localhost', port=5000): Max retries exceeded with url: /webhook (Caused by NewConnectionError('<urllib3.connection.HTTPConnection object at 0x78ab7cceb7f0>: Failed to establish a new connection: [Errno 111] Connection refused'))
[2025-09-08T13:55:08.148+0530] {subprocess.py:93} INFO - 2025-09-08 13:55:08,148 INFO: Flushed batch: orders=200 items=373
[2025-09-08T13:55:08.149+0530] {subprocess.py:93} INFO - 2025-09-08 13:55:08,149 WARNING: Failed to send webhook notification: HTTPConnectionPool(host='localhost', port=5000): Max retries exceeded with url: /webhook (Caused by NewConnectionError('<urllib3.connection.HTTPConnection object at 0x78ab7ccfe500>: Failed to establish a new connection: [Errno 111] Connection refused'))
[2025-09-08T13:55:08.339+0530] {subprocess.py:93} INFO - 2025-09-08 13:55:08,339 INFO: Flushed batch: orders=200 items=355
[2025-09-08T13:55:08.342+0530] {subprocess.py:93} INFO - 2025-09-08 13:55:08,342 WARNING: Failed to send webhook notification: HTTPConnectionPool(host='localhost', port=5000): Max retries exceeded with url: /webhook (Caused by NewConnectionError('<urllib3.connection.HTTPConnection object at 0x78ab7cb18f70>: Failed to establish a new connection: [Errno 111] Connection refused'))
[2025-09-08T13:55:08.663+0530] {subprocess.py:93} INFO - 2025-09-08 13:55:08,662 INFO: Flushed batch: orders=200 items=312
[2025-09-08T13:55:08.665+0530] {subprocess.py:93} INFO - 2025-09-08 13:55:08,665 WARNING: Failed to send webhook notification: HTTPConnectionPool(host='localhost', port=5000): Max retries exceeded with url: /webhook (Caused by NewConnectionError('<urllib3.connection.HTTPConnection object at 0x78ab7cb184c0>: Failed to establish a new connection: [Errno 111] Connection refused'))
[2025-09-08T13:55:09.148+0530] {subprocess.py:93} INFO - 2025-09-08 13:55:09,148 INFO: Flushed batch: orders=200 items=342
[2025-09-08T13:55:09.151+0530] {subprocess.py:93} INFO - 2025-09-08 13:55:09,151 WARNING: Failed to send webhook notification: HTTPConnectionPool(host='localhost', port=5000): Max retries exceeded with url: /webhook (Caused by NewConnectionError('<urllib3.connection.HTTPConnection object at 0x78ab7cb18a00>: Failed to establish a new connection: [Errno 111] Connection refused'))
[2025-09-08T13:55:09.450+0530] {subprocess.py:93} INFO - 2025-09-08 13:55:09,450 INFO: Flushed batch: orders=200 items=327
[2025-09-08T13:55:09.453+0530] {subprocess.py:93} INFO - 2025-09-08 13:55:09,453 WARNING: Failed to send webhook notification: HTTPConnectionPool(host='localhost', port=5000): Max retries exceeded with url: /webhook (Caused by NewConnectionError('<urllib3.connection.HTTPConnection object at 0x78ab7cceb220>: Failed to establish a new connection: [Errno 111] Connection refused'))
[2025-09-08T13:55:09.666+0530] {subprocess.py:93} INFO - 2025-09-08 13:55:09,666 INFO: Flushed batch: orders=200 items=326
[2025-09-08T13:55:09.667+0530] {subprocess.py:93} INFO - 2025-09-08 13:55:09,667 WARNING: Failed to send webhook notification: HTTPConnectionPool(host='localhost', port=5000): Max retries exceeded with url: /webhook (Caused by NewConnectionError('<urllib3.connection.HTTPConnection object at 0x78ab7cce83d0>: Failed to establish a new connection: [Errno 111] Connection refused'))
[2025-09-08T13:55:09.859+0530] {subprocess.py:93} INFO - 2025-09-08 13:55:09,859 INFO: Flushed batch: orders=200 items=347
[2025-09-08T13:55:09.862+0530] {subprocess.py:93} INFO - 2025-09-08 13:55:09,862 WARNING: Failed to send webhook notification: HTTPConnectionPool(host='localhost', port=5000): Max retries exceeded with url: /webhook (Caused by NewConnectionError('<urllib3.connection.HTTPConnection object at 0x78ab7cc2db40>: Failed to establish a new connection: [Errno 111] Connection refused'))
[2025-09-08T13:55:10.043+0530] {subprocess.py:93} INFO - 2025-09-08 13:55:10,043 INFO: Flushed batch: orders=200 items=320
[2025-09-08T13:55:10.047+0530] {subprocess.py:93} INFO - 2025-09-08 13:55:10,046 WARNING: Failed to send webhook notification: HTTPConnectionPool(host='localhost', port=5000): Max retries exceeded with url: /webhook (Caused by NewConnectionError('<urllib3.connection.HTTPConnection object at 0x78ab7ccffc70>: Failed to establish a new connection: [Errno 111] Connection refused'))
[2025-09-08T13:55:10.319+0530] {subprocess.py:93} INFO - 2025-09-08 13:55:10,318 INFO: Flushed batch: orders=200 items=355
[2025-09-08T13:55:10.321+0530] {subprocess.py:93} INFO - 2025-09-08 13:55:10,321 WARNING: Failed to send webhook notification: HTTPConnectionPool(host='localhost', port=5000): Max retries exceeded with url: /webhook (Caused by NewConnectionError('<urllib3.connection.HTTPConnection object at 0x78ab7cc2da80>: Failed to establish a new connection: [Errno 111] Connection refused'))
[2025-09-08T13:55:10.594+0530] {subprocess.py:93} INFO - 2025-09-08 13:55:10,594 INFO: Flushed batch: orders=200 items=368
[2025-09-08T13:55:10.597+0530] {subprocess.py:93} INFO - 2025-09-08 13:55:10,596 WARNING: Failed to send webhook notification: HTTPConnectionPool(host='localhost', port=5000): Max retries exceeded with url: /webhook (Caused by NewConnectionError('<urllib3.connection.HTTPConnection object at 0x78ab7cb3d8a0>: Failed to establish a new connection: [Errno 111] Connection refused'))
[2025-09-08T13:55:10.803+0530] {subprocess.py:93} INFO - 2025-09-08 13:55:10,803 INFO: Flushed batch: orders=200 items=389
[2025-09-08T13:55:10.806+0530] {subprocess.py:93} INFO - 2025-09-08 13:55:10,806 WARNING: Failed to send webhook notification: HTTPConnectionPool(host='localhost', port=5000): Max retries exceeded with url: /webhook (Caused by NewConnectionError('<urllib3.connection.HTTPConnection object at 0x78ab7cd34460>: Failed to establish a new connection: [Errno 111] Connection refused'))
[2025-09-08T13:55:11.112+0530] {subprocess.py:93} INFO - 2025-09-08 13:55:11,112 INFO: Flushed batch: orders=200 items=363
[2025-09-08T13:55:11.115+0530] {subprocess.py:93} INFO - 2025-09-08 13:55:11,115 WARNING: Failed to send webhook notification: HTTPConnectionPool(host='localhost', port=5000): Max retries exceeded with url: /webhook (Caused by NewConnectionError('<urllib3.connection.HTTPConnection object at 0x78ab7ccfc5b0>: Failed to establish a new connection: [Errno 111] Connection refused'))
[2025-09-08T13:55:11.397+0530] {subprocess.py:93} INFO - 2025-09-08 13:55:11,396 INFO: Flushed batch: orders=200 items=342
[2025-09-08T13:55:11.400+0530] {subprocess.py:93} INFO - 2025-09-08 13:55:11,400 WARNING: Failed to send webhook notification: HTTPConnectionPool(host='localhost', port=5000): Max retries exceeded with url: /webhook (Caused by NewConnectionError('<urllib3.connection.HTTPConnection object at 0x78ab7cb3ddb0>: Failed to establish a new connection: [Errno 111] Connection refused'))
[2025-09-08T13:55:11.614+0530] {subprocess.py:93} INFO - 2025-09-08 13:55:11,613 INFO: Flushed batch: orders=200 items=354
[2025-09-08T13:55:11.617+0530] {subprocess.py:93} INFO - 2025-09-08 13:55:11,617 WARNING: Failed to send webhook notification: HTTPConnectionPool(host='localhost', port=5000): Max retries exceeded with url: /webhook (Caused by NewConnectionError('<urllib3.connection.HTTPConnection object at 0x78ab7cd34a00>: Failed to establish a new connection: [Errno 111] Connection refused'))
[2025-09-08T13:55:11.873+0530] {subprocess.py:93} INFO - 2025-09-08 13:55:11,872 INFO: Flushed batch: orders=200 items=339
[2025-09-08T13:55:11.875+0530] {subprocess.py:93} INFO - 2025-09-08 13:55:11,875 WARNING: Failed to send webhook notification: HTTPConnectionPool(host='localhost', port=5000): Max retries exceeded with url: /webhook (Caused by NewConnectionError('<urllib3.connection.HTTPConnection object at 0x78ab7cb3d060>: Failed to establish a new connection: [Errno 111] Connection refused'))
[2025-09-08T13:55:12.073+0530] {subprocess.py:93} INFO - 2025-09-08 13:55:12,072 INFO: Flushed batch: orders=200 items=350
[2025-09-08T13:55:12.076+0530] {subprocess.py:93} INFO - 2025-09-08 13:55:12,075 WARNING: Failed to send webhook notification: HTTPConnectionPool(host='localhost', port=5000): Max retries exceeded with url: /webhook (Caused by NewConnectionError('<urllib3.connection.HTTPConnection object at 0x78ab7cb578b0>: Failed to establish a new connection: [Errno 111] Connection refused'))
[2025-09-08T13:55:12.383+0530] {subprocess.py:93} INFO - 2025-09-08 13:55:12,383 INFO: Flushed batch: orders=200 items=327
[2025-09-08T13:55:12.386+0530] {subprocess.py:93} INFO - 2025-09-08 13:55:12,386 WARNING: Failed to send webhook notification: HTTPConnectionPool(host='localhost', port=5000): Max retries exceeded with url: /webhook (Caused by NewConnectionError('<urllib3.connection.HTTPConnection object at 0x78ab7cb1ae00>: Failed to establish a new connection: [Errno 111] Connection refused'))
[2025-09-08T13:55:12.592+0530] {subprocess.py:93} INFO - 2025-09-08 13:55:12,592 INFO: Flushed batch: orders=200 items=363
[2025-09-08T13:55:12.595+0530] {subprocess.py:93} INFO - 2025-09-08 13:55:12,594 WARNING: Failed to send webhook notification: HTTPConnectionPool(host='localhost', port=5000): Max retries exceeded with url: /webhook (Caused by NewConnectionError('<urllib3.connection.HTTPConnection object at 0x78ab7cb3e980>: Failed to establish a new connection: [Errno 111] Connection refused'))
[2025-09-08T13:55:12.826+0530] {subprocess.py:93} INFO - 2025-09-08 13:55:12,825 INFO: Flushed batch: orders=200 items=344
[2025-09-08T13:55:12.828+0530] {subprocess.py:93} INFO - 2025-09-08 13:55:12,828 WARNING: Failed to send webhook notification: HTTPConnectionPool(host='localhost', port=5000): Max retries exceeded with url: /webhook (Caused by NewConnectionError('<urllib3.connection.HTTPConnection object at 0x78ab7cd37b80>: Failed to establish a new connection: [Errno 111] Connection refused'))
[2025-09-08T13:55:13.194+0530] {subprocess.py:93} INFO - 2025-09-08 13:55:13,193 INFO: Flushed batch: orders=200 items=351
[2025-09-08T13:55:13.196+0530] {subprocess.py:93} INFO - 2025-09-08 13:55:13,196 WARNING: Failed to send webhook notification: HTTPConnectionPool(host='localhost', port=5000): Max retries exceeded with url: /webhook (Caused by NewConnectionError('<urllib3.connection.HTTPConnection object at 0x78ab7cc2e530>: Failed to establish a new connection: [Errno 111] Connection refused'))
[2025-09-08T13:55:13.197+0530] {subprocess.py:93} INFO - 2025-09-08 13:55:13,197 INFO: Generated 5000 orders
[2025-09-08T13:55:43.854+0530] {subprocess.py:93} INFO - 2025-09-08 13:55:43,854 INFO: Inserted 47761 clickstream events.
[2025-09-08T13:55:43.855+0530] {subprocess.py:93} INFO - 2025-09-08 13:55:43,855 WARNING: Failed to send webhook notification: HTTPConnectionPool(host='localhost', port=5000): Max retries exceeded with url: /webhook (Caused by NewConnectionError('<urllib3.connection.HTTPConnection object at 0x78ab7d7eaf50>: Failed to establish a new connection: [Errno 111] Connection refused'))
[2025-09-08T13:55:46.238+0530] {subprocess.py:93} INFO - 2025-09-08 13:55:46,238 INFO: Validation done: orphans orders=0 items=0 inventory=0 mismatches=0
[2025-09-08T13:55:46.246+0530] {subprocess.py:93} INFO - 2025-09-08 13:55:46,246 INFO: Integrity report: {'orphan_orders': 0, 'orphan_order_items': 0, 'inventory_orphans': 0, 'order_amount_mismatches': []}
[2025-09-08T13:55:46.276+0530] {subprocess.py:93} INFO - [2025-09-08 13:55:46] ‚úÖ Synthetic data streaming completed successfully!
[2025-09-08T13:55:46.276+0530] {subprocess.py:97} INFO - Command exited with return code 0
[2025-09-08T13:55:46.277+0530] {taskinstance.py:441} INFO - ::group::Post task execution logs
[2025-09-08T13:55:47.498+0530] {taskinstance.py:1206} INFO - Marking task as SUCCESS. dag_id=synth_stream_5min, task_id=run_synth_stream, run_id=scheduled__2025-09-08T08:20:00+00:00, execution_date=20250908T082000, start_date=20250908T082504, end_date=20250908T082547
[2025-09-08T13:55:48.069+0530] {local_task_job_runner.py:243} INFO - Task exited with return code 0
[2025-09-08T13:55:48.073+0530] {taskinstance.py:3503} INFO - 0 downstream tasks scheduled from follow-on schedule check
[2025-09-08T13:55:48.074+0530] {local_task_job_runner.py:222} INFO - ::endgroup::
