[2025-09-08T14:47:08.990+0530] {local_task_job_runner.py:120} INFO - ::group::Pre task execution logs
[2025-09-08T14:47:09.002+0530] {taskinstance.py:2076} INFO - Dependencies all met for dep_context=non-requeueable deps ti=<TaskInstance: synth_stream_5min.run_synth_stream scheduled__2025-09-08T09:10:00+00:00 [queued]>
[2025-09-08T14:47:09.004+0530] {taskinstance.py:2076} INFO - Dependencies all met for dep_context=requeueable deps ti=<TaskInstance: synth_stream_5min.run_synth_stream scheduled__2025-09-08T09:10:00+00:00 [queued]>
[2025-09-08T14:47:09.005+0530] {taskinstance.py:2306} INFO - Starting attempt 1 of 2
[2025-09-08T14:47:09.210+0530] {taskinstance.py:2330} INFO - Executing <Task(BashOperator): run_synth_stream> on 2025-09-08 09:10:00+00:00
[2025-09-08T14:47:09.219+0530] {standard_task_runner.py:64} INFO - Started process 735098 to run task
[2025-09-08T14:47:09.224+0530] {standard_task_runner.py:90} INFO - Running: ['airflow', 'tasks', 'run', 'synth_stream_5min', 'run_synth_stream', 'scheduled__2025-09-08T09:10:00+00:00', '--job-id', '50', '--raw', '--subdir', 'DAGS_FOLDER/ecom_schedules.py', '--cfg-path', '/tmp/tmprhbk9dwq']
[2025-09-08T14:47:09.226+0530] {standard_task_runner.py:91} INFO - Job 50: Subtask run_synth_stream
[2025-09-08T14:47:09.457+0530] {task_command.py:426} INFO - Running <TaskInstance: synth_stream_5min.run_synth_stream scheduled__2025-09-08T09:10:00+00:00 [running]> on host softsuave-ASUS-EXPERTCENTER-D700ME-D500ME
[2025-09-08T14:47:09.965+0530] {taskinstance.py:2648} INFO - Exporting env vars: AIRFLOW_CTX_DAG_OWNER='airflow' AIRFLOW_CTX_DAG_ID='synth_stream_5min' AIRFLOW_CTX_TASK_ID='run_synth_stream' AIRFLOW_CTX_EXECUTION_DATE='2025-09-08T09:10:00+00:00' AIRFLOW_CTX_TRY_NUMBER='1' AIRFLOW_CTX_DAG_RUN_ID='scheduled__2025-09-08T09:10:00+00:00'
[2025-09-08T14:47:09.966+0530] {taskinstance.py:430} INFO - ::endgroup::
[2025-09-08T14:47:09.966+0530] {subprocess.py:63} INFO - Tmp dir root location: /tmp
[2025-09-08T14:47:09.966+0530] {subprocess.py:75} INFO - Running command: ['/usr/bin/bash', '-c', 'bash /media/softsuave/DATA-HDD/DataEngineering/Apache_Airflow/scripts/synth/run_synth_stream.sh | cat']
[2025-09-08T14:47:09.973+0530] {subprocess.py:86} INFO - Output:
[2025-09-08T14:47:10.011+0530] {subprocess.py:93} INFO - [2025-09-08 14:47:10] üöÄ Starting Synthetic E-commerce Data Stream...
[2025-09-08T14:47:10.011+0530] {subprocess.py:93} INFO - ----------------------------------------------
[2025-09-08T14:47:10.011+0530] {subprocess.py:93} INFO -  Database   : ecom_db
[2025-09-08T14:47:10.012+0530] {subprocess.py:93} INFO -  User       : sa
[2025-09-08T14:47:10.012+0530] {subprocess.py:93} INFO -  Server     : localhost:1433
[2025-09-08T14:47:10.012+0530] {subprocess.py:93} INFO -  Interval   : 5 min
[2025-09-08T14:47:10.012+0530] {subprocess.py:93} INFO -  Orders     : 50
[2025-09-08T14:47:10.012+0530] {subprocess.py:93} INFO -  Clicks     : 100
[2025-09-08T14:47:10.012+0530] {subprocess.py:93} INFO -  Webhook    : http://localhost:5000/webhook
[2025-09-08T14:47:10.012+0530] {subprocess.py:93} INFO - ----------------------------------------------
[2025-09-08T14:47:10.012+0530] {subprocess.py:93} INFO - 
[2025-09-08T14:47:10.036+0530] {subprocess.py:93} INFO - [2025-09-08 14:47:10] üîß Activating virtual environment...
[2025-09-08T14:47:10.038+0530] {subprocess.py:93} INFO - [2025-09-08 14:47:10] üîç Checking database connection...
[2025-09-08T14:47:10.065+0530] {subprocess.py:93} INFO - ‚úÖ Database connection successful
[2025-09-08T14:47:10.069+0530] {subprocess.py:93} INFO - [2025-09-08 14:47:10] üîÑ Starting synthetic data stream...
[2025-09-08T14:47:10.069+0530] {subprocess.py:93} INFO - Press Ctrl+C to stop
[2025-09-08T14:47:10.069+0530] {subprocess.py:93} INFO - 
[2025-09-08T14:47:10.249+0530] {subprocess.py:93} INFO - 2025-09-08 14:47:10,249 INFO: Tables ensured/created (if needed).
[2025-09-08T14:47:10.262+0530] {subprocess.py:93} INFO - 2025-09-08 14:47:10,262 INFO: Customers: 1000 already present; skipping seeding.
[2025-09-08T14:47:10.263+0530] {subprocess.py:93} INFO - 2025-09-08 14:47:10,263 INFO: Products: 500 already present; skipping seeding.
[2025-09-08T14:47:10.263+0530] {subprocess.py:93} INFO - 2025-09-08 14:47:10,263 INFO: Running one-shot generation: orders=5000, sessions=3000
[2025-09-08T14:47:10.269+0530] {subprocess.py:93} INFO - /media/softsuave/DATA-HDD/DataEngineering/Apache_Airflow/src/synth_ecom_mssql_stream.py:397: RemovedIn20Warning: Deprecated API features detected! These feature(s) are not compatible with SQLAlchemy 2.0. To prevent incompatible upgrades prior to updating applications, ensure requirements files are pinned to "sqlalchemy<2.0". Set environment variable SQLALCHEMY_WARN_20=1 to show all deprecation warnings.  Set environment variable SQLALCHEMY_SILENCE_UBER_WARNING=1 to silence this message. (Background on SQLAlchemy 2.0 at: https://sqlalche.me/e/b8d9)
[2025-09-08T14:47:10.269+0530] {subprocess.py:93} INFO -   customers = [dict(r) for r in conn.execute(select(self.tables["customers"])).fetchall()]
[2025-09-08T14:47:10.276+0530] {subprocess.py:93} INFO - 2025-09-08 14:47:10,276 INFO: Generating 5000 orders (batch_size=200, force_order_date_now=False)...
[2025-09-08T14:47:10.842+0530] {subprocess.py:93} INFO - 2025-09-08 14:47:10,842 INFO: Flushed batch: orders=200 items=324
[2025-09-08T14:47:10.848+0530] {subprocess.py:93} INFO - 2025-09-08 14:47:10,847 WARNING: Failed to send webhook notification: HTTPConnectionPool(host='localhost', port=5000): Max retries exceeded with url: /webhook (Caused by NewConnectionError('<urllib3.connection.HTTPConnection object at 0x772a083afdc0>: Failed to establish a new connection: [Errno 111] Connection refused'))
[2025-09-08T14:47:11.628+0530] {subprocess.py:93} INFO - 2025-09-08 14:47:11,628 INFO: Flushed batch: orders=200 items=343
[2025-09-08T14:47:11.632+0530] {subprocess.py:93} INFO - 2025-09-08 14:47:11,631 WARNING: Failed to send webhook notification: HTTPConnectionPool(host='localhost', port=5000): Max retries exceeded with url: /webhook (Caused by NewConnectionError('<urllib3.connection.HTTPConnection object at 0x772a08327ee0>: Failed to establish a new connection: [Errno 111] Connection refused'))
[2025-09-08T14:47:12.285+0530] {subprocess.py:93} INFO - 2025-09-08 14:47:12,284 INFO: Flushed batch: orders=200 items=374
[2025-09-08T14:47:12.288+0530] {subprocess.py:93} INFO - 2025-09-08 14:47:12,288 WARNING: Failed to send webhook notification: HTTPConnectionPool(host='localhost', port=5000): Max retries exceeded with url: /webhook (Caused by NewConnectionError('<urllib3.connection.HTTPConnection object at 0x772a08293250>: Failed to establish a new connection: [Errno 111] Connection refused'))
[2025-09-08T14:47:12.702+0530] {subprocess.py:93} INFO - 2025-09-08 14:47:12,702 INFO: Flushed batch: orders=200 items=340
[2025-09-08T14:47:12.705+0530] {subprocess.py:93} INFO - 2025-09-08 14:47:12,705 WARNING: Failed to send webhook notification: HTTPConnectionPool(host='localhost', port=5000): Max retries exceeded with url: /webhook (Caused by NewConnectionError('<urllib3.connection.HTTPConnection object at 0x772a08244280>: Failed to establish a new connection: [Errno 111] Connection refused'))
[2025-09-08T14:47:13.410+0530] {subprocess.py:93} INFO - 2025-09-08 14:47:13,410 INFO: Flushed batch: orders=200 items=339
[2025-09-08T14:47:13.413+0530] {subprocess.py:93} INFO - 2025-09-08 14:47:13,413 WARNING: Failed to send webhook notification: HTTPConnectionPool(host='localhost', port=5000): Max retries exceeded with url: /webhook (Caused by NewConnectionError('<urllib3.connection.HTTPConnection object at 0x772a0810eda0>: Failed to establish a new connection: [Errno 111] Connection refused'))
[2025-09-08T14:47:13.937+0530] {subprocess.py:93} INFO - 2025-09-08 14:47:13,937 INFO: Flushed batch: orders=200 items=366
[2025-09-08T14:47:13.940+0530] {subprocess.py:93} INFO - 2025-09-08 14:47:13,939 WARNING: Failed to send webhook notification: HTTPConnectionPool(host='localhost', port=5000): Max retries exceeded with url: /webhook (Caused by NewConnectionError('<urllib3.connection.HTTPConnection object at 0x772a08119540>: Failed to establish a new connection: [Errno 111] Connection refused'))
[2025-09-08T14:47:14.341+0530] {subprocess.py:93} INFO - 2025-09-08 14:47:14,340 INFO: Flushed batch: orders=200 items=347
[2025-09-08T14:47:14.345+0530] {subprocess.py:93} INFO - 2025-09-08 14:47:14,344 WARNING: Failed to send webhook notification: HTTPConnectionPool(host='localhost', port=5000): Max retries exceeded with url: /webhook (Caused by NewConnectionError('<urllib3.connection.HTTPConnection object at 0x772a08135150>: Failed to establish a new connection: [Errno 111] Connection refused'))
[2025-09-08T14:47:14.939+0530] {subprocess.py:93} INFO - 2025-09-08 14:47:14,939 INFO: Flushed batch: orders=200 items=338
[2025-09-08T14:47:14.942+0530] {subprocess.py:93} INFO - 2025-09-08 14:47:14,942 WARNING: Failed to send webhook notification: HTTPConnectionPool(host='localhost', port=5000): Max retries exceeded with url: /webhook (Caused by NewConnectionError('<urllib3.connection.HTTPConnection object at 0x772a081354e0>: Failed to establish a new connection: [Errno 111] Connection refused'))
[2025-09-08T14:47:15.698+0530] {subprocess.py:93} INFO - 2025-09-08 14:47:15,698 INFO: Flushed batch: orders=200 items=345
[2025-09-08T14:47:15.702+0530] {subprocess.py:93} INFO - 2025-09-08 14:47:15,701 WARNING: Failed to send webhook notification: HTTPConnectionPool(host='localhost', port=5000): Max retries exceeded with url: /webhook (Caused by NewConnectionError('<urllib3.connection.HTTPConnection object at 0x772a08136c20>: Failed to establish a new connection: [Errno 111] Connection refused'))
[2025-09-08T14:47:16.255+0530] {subprocess.py:93} INFO - 2025-09-08 14:47:16,255 INFO: Flushed batch: orders=200 items=329
[2025-09-08T14:47:16.258+0530] {subprocess.py:93} INFO - 2025-09-08 14:47:16,258 WARNING: Failed to send webhook notification: HTTPConnectionPool(host='localhost', port=5000): Max retries exceeded with url: /webhook (Caused by NewConnectionError('<urllib3.connection.HTTPConnection object at 0x772a081373a0>: Failed to establish a new connection: [Errno 111] Connection refused'))
[2025-09-08T14:47:16.694+0530] {subprocess.py:93} INFO - 2025-09-08 14:47:16,694 INFO: Flushed batch: orders=200 items=368
[2025-09-08T14:47:16.698+0530] {subprocess.py:93} INFO - 2025-09-08 14:47:16,698 WARNING: Failed to send webhook notification: HTTPConnectionPool(host='localhost', port=5000): Max retries exceeded with url: /webhook (Caused by NewConnectionError('<urllib3.connection.HTTPConnection object at 0x772a081511e0>: Failed to establish a new connection: [Errno 111] Connection refused'))
[2025-09-08T14:47:17.109+0530] {subprocess.py:93} INFO - 2025-09-08 14:47:17,108 INFO: Flushed batch: orders=200 items=370
[2025-09-08T14:47:17.112+0530] {subprocess.py:93} INFO - 2025-09-08 14:47:17,112 WARNING: Failed to send webhook notification: HTTPConnectionPool(host='localhost', port=5000): Max retries exceeded with url: /webhook (Caused by NewConnectionError('<urllib3.connection.HTTPConnection object at 0x772a082fb790>: Failed to establish a new connection: [Errno 111] Connection refused'))
[2025-09-08T14:47:17.659+0530] {subprocess.py:93} INFO - 2025-09-08 14:47:17,659 INFO: Flushed batch: orders=200 items=353
[2025-09-08T14:47:17.662+0530] {subprocess.py:93} INFO - 2025-09-08 14:47:17,662 WARNING: Failed to send webhook notification: HTTPConnectionPool(host='localhost', port=5000): Max retries exceeded with url: /webhook (Caused by NewConnectionError('<urllib3.connection.HTTPConnection object at 0x772a082fb640>: Failed to establish a new connection: [Errno 111] Connection refused'))
[2025-09-08T14:47:18.273+0530] {subprocess.py:93} INFO - 2025-09-08 14:47:18,273 INFO: Flushed batch: orders=200 items=354
[2025-09-08T14:47:18.277+0530] {subprocess.py:93} INFO - 2025-09-08 14:47:18,277 WARNING: Failed to send webhook notification: HTTPConnectionPool(host='localhost', port=5000): Max retries exceeded with url: /webhook (Caused by NewConnectionError('<urllib3.connection.HTTPConnection object at 0x772a08153910>: Failed to establish a new connection: [Errno 111] Connection refused'))
[2025-09-08T14:47:18.527+0530] {subprocess.py:93} INFO - 2025-09-08 14:47:18,527 INFO: Flushed batch: orders=200 items=355
[2025-09-08T14:47:18.531+0530] {subprocess.py:93} INFO - 2025-09-08 14:47:18,530 WARNING: Failed to send webhook notification: HTTPConnectionPool(host='localhost', port=5000): Max retries exceeded with url: /webhook (Caused by NewConnectionError('<urllib3.connection.HTTPConnection object at 0x772a0813d030>: Failed to establish a new connection: [Errno 111] Connection refused'))
[2025-09-08T14:47:19.228+0530] {subprocess.py:93} INFO - 2025-09-08 14:47:19,228 INFO: Flushed batch: orders=200 items=351
[2025-09-08T14:47:19.231+0530] {subprocess.py:93} INFO - 2025-09-08 14:47:19,230 WARNING: Failed to send webhook notification: HTTPConnectionPool(host='localhost', port=5000): Max retries exceeded with url: /webhook (Caused by NewConnectionError('<urllib3.connection.HTTPConnection object at 0x772a08137c70>: Failed to establish a new connection: [Errno 111] Connection refused'))
[2025-09-08T14:47:19.738+0530] {subprocess.py:93} INFO - 2025-09-08 14:47:19,738 INFO: Flushed batch: orders=200 items=349
[2025-09-08T14:47:19.741+0530] {subprocess.py:93} INFO - 2025-09-08 14:47:19,741 WARNING: Failed to send webhook notification: HTTPConnectionPool(host='localhost', port=5000): Max retries exceeded with url: /webhook (Caused by NewConnectionError('<urllib3.connection.HTTPConnection object at 0x772a0811b310>: Failed to establish a new connection: [Errno 111] Connection refused'))
[2025-09-08T14:47:19.981+0530] {subprocess.py:93} INFO - 2025-09-08 14:47:19,981 INFO: Flushed batch: orders=200 items=328
[2025-09-08T14:47:19.982+0530] {subprocess.py:93} INFO - 2025-09-08 14:47:19,982 WARNING: Failed to send webhook notification: HTTPConnectionPool(host='localhost', port=5000): Max retries exceeded with url: /webhook (Caused by NewConnectionError('<urllib3.connection.HTTPConnection object at 0x772a08135480>: Failed to establish a new connection: [Errno 111] Connection refused'))
[2025-09-08T14:47:20.734+0530] {subprocess.py:93} INFO - 2025-09-08 14:47:20,733 INFO: Flushed batch: orders=200 items=349
[2025-09-08T14:47:20.736+0530] {subprocess.py:93} INFO - 2025-09-08 14:47:20,736 WARNING: Failed to send webhook notification: HTTPConnectionPool(host='localhost', port=5000): Max retries exceeded with url: /webhook (Caused by NewConnectionError('<urllib3.connection.HTTPConnection object at 0x772a08119f60>: Failed to establish a new connection: [Errno 111] Connection refused'))
[2025-09-08T14:47:21.098+0530] {subprocess.py:93} INFO - 2025-09-08 14:47:21,098 INFO: Flushed batch: orders=200 items=358
[2025-09-08T14:47:21.101+0530] {subprocess.py:93} INFO - 2025-09-08 14:47:21,101 WARNING: Failed to send webhook notification: HTTPConnectionPool(host='localhost', port=5000): Max retries exceeded with url: /webhook (Caused by NewConnectionError('<urllib3.connection.HTTPConnection object at 0x772a08966710>: Failed to establish a new connection: [Errno 111] Connection refused'))
[2025-09-08T14:47:21.390+0530] {subprocess.py:93} INFO - 2025-09-08 14:47:21,390 INFO: Flushed batch: orders=200 items=341
[2025-09-08T14:47:21.393+0530] {subprocess.py:93} INFO - 2025-09-08 14:47:21,392 WARNING: Failed to send webhook notification: HTTPConnectionPool(host='localhost', port=5000): Max retries exceeded with url: /webhook (Caused by NewConnectionError('<urllib3.connection.HTTPConnection object at 0x772a08173c40>: Failed to establish a new connection: [Errno 111] Connection refused'))
[2025-09-08T14:47:22.150+0530] {subprocess.py:93} INFO - 2025-09-08 14:47:22,149 INFO: Flushed batch: orders=200 items=352
[2025-09-08T14:47:22.153+0530] {subprocess.py:93} INFO - 2025-09-08 14:47:22,153 WARNING: Failed to send webhook notification: HTTPConnectionPool(host='localhost', port=5000): Max retries exceeded with url: /webhook (Caused by NewConnectionError('<urllib3.connection.HTTPConnection object at 0x772a08153a90>: Failed to establish a new connection: [Errno 111] Connection refused'))
[2025-09-08T14:47:22.350+0530] {subprocess.py:93} INFO - 2025-09-08 14:47:22,350 INFO: Flushed batch: orders=200 items=362
[2025-09-08T14:47:22.354+0530] {subprocess.py:93} INFO - 2025-09-08 14:47:22,353 WARNING: Failed to send webhook notification: HTTPConnectionPool(host='localhost', port=5000): Max retries exceeded with url: /webhook (Caused by NewConnectionError('<urllib3.connection.HTTPConnection object at 0x772a0813f9a0>: Failed to establish a new connection: [Errno 111] Connection refused'))
[2025-09-08T14:47:22.684+0530] {subprocess.py:93} INFO - 2025-09-08 14:47:22,683 INFO: Flushed batch: orders=200 items=365
[2025-09-08T14:47:22.688+0530] {subprocess.py:93} INFO - 2025-09-08 14:47:22,688 WARNING: Failed to send webhook notification: HTTPConnectionPool(host='localhost', port=5000): Max retries exceeded with url: /webhook (Caused by NewConnectionError('<urllib3.connection.HTTPConnection object at 0x772a08172d10>: Failed to establish a new connection: [Errno 111] Connection refused'))
[2025-09-08T14:47:23.201+0530] {subprocess.py:93} INFO - 2025-09-08 14:47:23,200 INFO: Flushed batch: orders=200 items=342
[2025-09-08T14:47:23.204+0530] {subprocess.py:93} INFO - 2025-09-08 14:47:23,204 WARNING: Failed to send webhook notification: HTTPConnectionPool(host='localhost', port=5000): Max retries exceeded with url: /webhook (Caused by NewConnectionError('<urllib3.connection.HTTPConnection object at 0x772a081344c0>: Failed to establish a new connection: [Errno 111] Connection refused'))
[2025-09-08T14:47:23.204+0530] {subprocess.py:93} INFO - 2025-09-08 14:47:23,204 INFO: Generated 5000 orders
[2025-09-08T14:48:04.553+0530] {subprocess.py:93} INFO - 2025-09-08 14:48:04,552 INFO: Inserted 48056 clickstream events.
[2025-09-08T14:48:04.553+0530] {subprocess.py:93} INFO - 2025-09-08 14:48:04,553 WARNING: Failed to send webhook notification: HTTPConnectionPool(host='localhost', port=5000): Max retries exceeded with url: /webhook (Caused by NewConnectionError('<urllib3.connection.HTTPConnection object at 0x772a06fe39a0>: Failed to establish a new connection: [Errno 111] Connection refused'))
[2025-09-08T14:48:06.463+0530] {subprocess.py:93} INFO - 2025-09-08 14:48:06,463 INFO: Validation done: orphans orders=0 items=0 inventory=0 mismatches=0
[2025-09-08T14:48:06.477+0530] {subprocess.py:93} INFO - 2025-09-08 14:48:06,476 INFO: Integrity report: {'orphan_orders': 0, 'orphan_order_items': 0, 'inventory_orphans': 0, 'order_amount_mismatches': []}
[2025-09-08T14:48:06.507+0530] {subprocess.py:93} INFO - [2025-09-08 14:48:06] ‚úÖ Synthetic data streaming completed successfully!
[2025-09-08T14:48:06.508+0530] {subprocess.py:97} INFO - Command exited with return code 0
[2025-09-08T14:48:06.508+0530] {taskinstance.py:441} INFO - ::group::Post task execution logs
[2025-09-08T14:48:07.404+0530] {taskinstance.py:1206} INFO - Marking task as SUCCESS. dag_id=synth_stream_5min, task_id=run_synth_stream, run_id=scheduled__2025-09-08T09:10:00+00:00, execution_date=20250908T091000, start_date=20250908T091709, end_date=20250908T091807
[2025-09-08T14:48:08.692+0530] {local_task_job_runner.py:243} INFO - Task exited with return code 0
[2025-09-08T14:48:08.696+0530] {taskinstance.py:3503} INFO - 0 downstream tasks scheduled from follow-on schedule check
[2025-09-08T14:48:08.697+0530] {local_task_job_runner.py:222} INFO - ::endgroup::
