[2025-09-08T13:10:51.302+0530] {local_task_job_runner.py:120} INFO - ::group::Pre task execution logs
[2025-09-08T13:10:51.315+0530] {taskinstance.py:2076} INFO - Dependencies all met for dep_context=non-requeueable deps ti=<TaskInstance: synth_stream_5min.run_synth_stream scheduled__2025-09-08T07:35:00+00:00 [queued]>
[2025-09-08T13:10:51.318+0530] {taskinstance.py:2076} INFO - Dependencies all met for dep_context=requeueable deps ti=<TaskInstance: synth_stream_5min.run_synth_stream scheduled__2025-09-08T07:35:00+00:00 [queued]>
[2025-09-08T13:10:51.318+0530] {taskinstance.py:2306} INFO - Starting attempt 1 of 2
[2025-09-08T13:10:51.370+0530] {taskinstance.py:2330} INFO - Executing <Task(BashOperator): run_synth_stream> on 2025-09-08 07:35:00+00:00
[2025-09-08T13:10:51.378+0530] {standard_task_runner.py:64} INFO - Started process 710451 to run task
[2025-09-08T13:10:51.385+0530] {standard_task_runner.py:90} INFO - Running: ['airflow', 'tasks', 'run', 'synth_stream_5min', 'run_synth_stream', 'scheduled__2025-09-08T07:35:00+00:00', '--job-id', '22', '--raw', '--subdir', 'DAGS_FOLDER/ecom_schedules.py', '--cfg-path', '/tmp/tmpf6dyris4']
[2025-09-08T13:10:51.389+0530] {standard_task_runner.py:91} INFO - Job 22: Subtask run_synth_stream
[2025-09-08T13:10:51.470+0530] {task_command.py:426} INFO - Running <TaskInstance: synth_stream_5min.run_synth_stream scheduled__2025-09-08T07:35:00+00:00 [running]> on host softsuave-ASUS-EXPERTCENTER-D700ME-D500ME
[2025-09-08T13:10:51.609+0530] {taskinstance.py:2648} INFO - Exporting env vars: AIRFLOW_CTX_DAG_OWNER='airflow' AIRFLOW_CTX_DAG_ID='synth_stream_5min' AIRFLOW_CTX_TASK_ID='run_synth_stream' AIRFLOW_CTX_EXECUTION_DATE='2025-09-08T07:35:00+00:00' AIRFLOW_CTX_TRY_NUMBER='1' AIRFLOW_CTX_DAG_RUN_ID='scheduled__2025-09-08T07:35:00+00:00'
[2025-09-08T13:10:51.611+0530] {taskinstance.py:430} INFO - ::endgroup::
[2025-09-08T13:10:51.612+0530] {subprocess.py:63} INFO - Tmp dir root location: /tmp
[2025-09-08T13:10:51.613+0530] {subprocess.py:75} INFO - Running command: ['/usr/bin/bash', '-c', 'bash /media/softsuave/DATA-HDD/DataEngineering/Apache_Airflow/scripts/synth/run_synth_stream.sh | cat']
[2025-09-08T13:10:51.627+0530] {subprocess.py:86} INFO - Output:
[2025-09-08T13:10:51.669+0530] {subprocess.py:93} INFO - [2025-09-08 13:10:51] üöÄ Starting Synthetic E-commerce Data Stream...
[2025-09-08T13:10:51.670+0530] {subprocess.py:93} INFO - ----------------------------------------------
[2025-09-08T13:10:51.670+0530] {subprocess.py:93} INFO -  Database   : ecom_db
[2025-09-08T13:10:51.670+0530] {subprocess.py:93} INFO -  User       : sa
[2025-09-08T13:10:51.670+0530] {subprocess.py:93} INFO -  Server     : localhost:1433
[2025-09-08T13:10:51.670+0530] {subprocess.py:93} INFO -  Interval   : 5 min
[2025-09-08T13:10:51.670+0530] {subprocess.py:93} INFO -  Orders     : 50
[2025-09-08T13:10:51.670+0530] {subprocess.py:93} INFO -  Clicks     : 100
[2025-09-08T13:10:51.670+0530] {subprocess.py:93} INFO -  Webhook    : http://localhost:5000/webhook
[2025-09-08T13:10:51.670+0530] {subprocess.py:93} INFO - ----------------------------------------------
[2025-09-08T13:10:51.670+0530] {subprocess.py:93} INFO - 
[2025-09-08T13:10:51.691+0530] {subprocess.py:93} INFO - [2025-09-08 13:10:51] üîß Activating virtual environment...
[2025-09-08T13:10:51.693+0530] {subprocess.py:93} INFO - [2025-09-08 13:10:51] üîç Checking database connection...
[2025-09-08T13:10:52.224+0530] {subprocess.py:93} INFO - ‚úÖ Database connection successful
[2025-09-08T13:10:52.240+0530] {subprocess.py:93} INFO - [2025-09-08 13:10:52] üîÑ Starting synthetic data stream...
[2025-09-08T13:10:52.240+0530] {subprocess.py:93} INFO - Press Ctrl+C to stop
[2025-09-08T13:10:52.241+0530] {subprocess.py:93} INFO - 
[2025-09-08T13:10:52.680+0530] {subprocess.py:93} INFO - 2025-09-08 13:10:52,680 INFO: Tables ensured/created (if needed).
[2025-09-08T13:10:52.756+0530] {subprocess.py:93} INFO - 2025-09-08 13:10:52,756 INFO: Seeding 1000 customers (existing 0).
[2025-09-08T13:10:55.479+0530] {subprocess.py:93} INFO - 2025-09-08 13:10:55,479 INFO: Inserted 1000 new customers (skipped 0 duplicate emails).
[2025-09-08T13:10:55.481+0530] {subprocess.py:93} INFO - 2025-09-08 13:10:55,481 WARNING: Failed to send webhook notification: HTTPConnectionPool(host='localhost', port=5000): Max retries exceeded with url: /webhook (Caused by NewConnectionError('<urllib3.connection.HTTPConnection object at 0x7bdcfc392920>: Failed to establish a new connection: [Errno 111] Connection refused'))
[2025-09-08T13:10:55.512+0530] {subprocess.py:93} INFO - 2025-09-08 13:10:55,512 INFO: Seeding 500 products (existing 0).
[2025-09-08T13:10:56.009+0530] {subprocess.py:93} INFO - 2025-09-08 13:10:56,009 INFO: Inserted 500 new products (skipped 0 duplicate skus).
[2025-09-08T13:10:56.010+0530] {subprocess.py:93} INFO - 2025-09-08 13:10:56,009 WARNING: Failed to send webhook notification: HTTPConnectionPool(host='localhost', port=5000): Max retries exceeded with url: /webhook (Caused by NewConnectionError('<urllib3.connection.HTTPConnection object at 0x7bdcfc7fa3e0>: Failed to establish a new connection: [Errno 111] Connection refused'))
[2025-09-08T13:10:56.108+0530] {subprocess.py:93} INFO - 2025-09-08 13:10:56,108 INFO: Initialized inventory for 500 products.
[2025-09-08T13:10:56.226+0530] {subprocess.py:93} INFO - 2025-09-08 13:10:56,226 INFO: Running one-shot generation: orders=5000, sessions=3000
[2025-09-08T13:10:56.249+0530] {subprocess.py:93} INFO - /media/softsuave/DATA-HDD/DataEngineering/Apache_Airflow/src/synth_ecom_mssql_stream.py:397: RemovedIn20Warning: Deprecated API features detected! These feature(s) are not compatible with SQLAlchemy 2.0. To prevent incompatible upgrades prior to updating applications, ensure requirements files are pinned to "sqlalchemy<2.0". Set environment variable SQLALCHEMY_WARN_20=1 to show all deprecation warnings.  Set environment variable SQLALCHEMY_SILENCE_UBER_WARNING=1 to silence this message. (Background on SQLAlchemy 2.0 at: https://sqlalche.me/e/b8d9)
[2025-09-08T13:10:56.249+0530] {subprocess.py:93} INFO -   customers = [dict(r) for r in conn.execute(select(self.tables["customers"])).fetchall()]
[2025-09-08T13:10:56.257+0530] {subprocess.py:93} INFO - 2025-09-08 13:10:56,257 INFO: Generating 5000 orders (batch_size=200, force_order_date_now=False)...
[2025-09-08T13:10:56.936+0530] {subprocess.py:93} INFO - 2025-09-08 13:10:56,935 INFO: Flushed batch: orders=200 items=342
[2025-09-08T13:10:56.938+0530] {subprocess.py:93} INFO - 2025-09-08 13:10:56,938 WARNING: Failed to send webhook notification: HTTPConnectionPool(host='localhost', port=5000): Max retries exceeded with url: /webhook (Caused by NewConnectionError('<urllib3.connection.HTTPConnection object at 0x7bdcfbcecee0>: Failed to establish a new connection: [Errno 111] Connection refused'))
[2025-09-08T13:10:57.311+0530] {subprocess.py:93} INFO - 2025-09-08 13:10:57,311 INFO: Flushed batch: orders=200 items=360
[2025-09-08T13:10:57.313+0530] {subprocess.py:93} INFO - 2025-09-08 13:10:57,312 WARNING: Failed to send webhook notification: HTTPConnectionPool(host='localhost', port=5000): Max retries exceeded with url: /webhook (Caused by NewConnectionError('<urllib3.connection.HTTPConnection object at 0x7bdcfbb14700>: Failed to establish a new connection: [Errno 111] Connection refused'))
[2025-09-08T13:10:57.645+0530] {subprocess.py:93} INFO - 2025-09-08 13:10:57,645 INFO: Flushed batch: orders=200 items=364
[2025-09-08T13:10:57.648+0530] {subprocess.py:93} INFO - 2025-09-08 13:10:57,647 WARNING: Failed to send webhook notification: HTTPConnectionPool(host='localhost', port=5000): Max retries exceeded with url: /webhook (Caused by NewConnectionError('<urllib3.connection.HTTPConnection object at 0x7bdcfbb50fa0>: Failed to establish a new connection: [Errno 111] Connection refused'))
[2025-09-08T13:10:58.214+0530] {subprocess.py:93} INFO - 2025-09-08 13:10:58,213 INFO: Flushed batch: orders=200 items=353
[2025-09-08T13:10:58.217+0530] {subprocess.py:93} INFO - 2025-09-08 13:10:58,217 WARNING: Failed to send webhook notification: HTTPConnectionPool(host='localhost', port=5000): Max retries exceeded with url: /webhook (Caused by NewConnectionError('<urllib3.connection.HTTPConnection object at 0x7bdcfbc55cc0>: Failed to establish a new connection: [Errno 111] Connection refused'))
[2025-09-08T13:10:58.439+0530] {subprocess.py:93} INFO - 2025-09-08 13:10:58,438 INFO: Flushed batch: orders=200 items=335
[2025-09-08T13:10:58.441+0530] {subprocess.py:93} INFO - 2025-09-08 13:10:58,441 WARNING: Failed to send webhook notification: HTTPConnectionPool(host='localhost', port=5000): Max retries exceeded with url: /webhook (Caused by NewConnectionError('<urllib3.connection.HTTPConnection object at 0x7bdcfbc73d00>: Failed to establish a new connection: [Errno 111] Connection refused'))
[2025-09-08T13:10:58.715+0530] {subprocess.py:93} INFO - 2025-09-08 13:10:58,714 INFO: Flushed batch: orders=200 items=355
[2025-09-08T13:10:58.717+0530] {subprocess.py:93} INFO - 2025-09-08 13:10:58,717 WARNING: Failed to send webhook notification: HTTPConnectionPool(host='localhost', port=5000): Max retries exceeded with url: /webhook (Caused by NewConnectionError('<urllib3.connection.HTTPConnection object at 0x7bdcfbb6f4c0>: Failed to establish a new connection: [Errno 111] Connection refused'))
[2025-09-08T13:10:58.932+0530] {subprocess.py:93} INFO - 2025-09-08 13:10:58,931 INFO: Flushed batch: orders=200 items=324
[2025-09-08T13:10:58.935+0530] {subprocess.py:93} INFO - 2025-09-08 13:10:58,935 WARNING: Failed to send webhook notification: HTTPConnectionPool(host='localhost', port=5000): Max retries exceeded with url: /webhook (Caused by NewConnectionError('<urllib3.connection.HTTPConnection object at 0x7bdcfbceeb00>: Failed to establish a new connection: [Errno 111] Connection refused'))
[2025-09-08T13:10:59.284+0530] {subprocess.py:93} INFO - 2025-09-08 13:10:59,284 INFO: Flushed batch: orders=200 items=348
[2025-09-08T13:10:59.286+0530] {subprocess.py:93} INFO - 2025-09-08 13:10:59,286 WARNING: Failed to send webhook notification: HTTPConnectionPool(host='localhost', port=5000): Max retries exceeded with url: /webhook (Caused by NewConnectionError('<urllib3.connection.HTTPConnection object at 0x7bdcfbb6df00>: Failed to establish a new connection: [Errno 111] Connection refused'))
[2025-09-08T13:10:59.535+0530] {subprocess.py:93} INFO - 2025-09-08 13:10:59,534 INFO: Flushed batch: orders=200 items=343
[2025-09-08T13:10:59.538+0530] {subprocess.py:93} INFO - 2025-09-08 13:10:59,538 WARNING: Failed to send webhook notification: HTTPConnectionPool(host='localhost', port=5000): Max retries exceeded with url: /webhook (Caused by NewConnectionError('<urllib3.connection.HTTPConnection object at 0x7bdcfbc70f70>: Failed to establish a new connection: [Errno 111] Connection refused'))
[2025-09-08T13:10:59.818+0530] {subprocess.py:93} INFO - 2025-09-08 13:10:59,818 INFO: Flushed batch: orders=200 items=360
[2025-09-08T13:10:59.819+0530] {subprocess.py:93} INFO - 2025-09-08 13:10:59,819 WARNING: Failed to send webhook notification: HTTPConnectionPool(host='localhost', port=5000): Max retries exceeded with url: /webhook (Caused by NewConnectionError('<urllib3.connection.HTTPConnection object at 0x7bdcfbc57a90>: Failed to establish a new connection: [Errno 111] Connection refused'))
[2025-09-08T13:11:00.019+0530] {subprocess.py:93} INFO - 2025-09-08 13:11:00,019 INFO: Flushed batch: orders=200 items=349
[2025-09-08T13:11:00.020+0530] {subprocess.py:93} INFO - 2025-09-08 13:11:00,020 WARNING: Failed to send webhook notification: HTTPConnectionPool(host='localhost', port=5000): Max retries exceeded with url: /webhook (Caused by NewConnectionError('<urllib3.connection.HTTPConnection object at 0x7bdcfbc57f40>: Failed to establish a new connection: [Errno 111] Connection refused'))
[2025-09-08T13:11:00.261+0530] {subprocess.py:93} INFO - 2025-09-08 13:11:00,261 INFO: Flushed batch: orders=200 items=356
[2025-09-08T13:11:00.262+0530] {subprocess.py:93} INFO - 2025-09-08 13:11:00,262 WARNING: Failed to send webhook notification: HTTPConnectionPool(host='localhost', port=5000): Max retries exceeded with url: /webhook (Caused by NewConnectionError('<urllib3.connection.HTTPConnection object at 0x7bdcfbb8fe50>: Failed to establish a new connection: [Errno 111] Connection refused'))
[2025-09-08T13:11:00.595+0530] {subprocess.py:93} INFO - 2025-09-08 13:11:00,595 INFO: Flushed batch: orders=200 items=359
[2025-09-08T13:11:00.596+0530] {subprocess.py:93} INFO - 2025-09-08 13:11:00,596 WARNING: Failed to send webhook notification: HTTPConnectionPool(host='localhost', port=5000): Max retries exceeded with url: /webhook (Caused by NewConnectionError('<urllib3.connection.HTTPConnection object at 0x7bdcfbb803d0>: Failed to establish a new connection: [Errno 111] Connection refused'))
[2025-09-08T13:11:00.804+0530] {subprocess.py:93} INFO - 2025-09-08 13:11:00,804 INFO: Flushed batch: orders=200 items=344
[2025-09-08T13:11:00.805+0530] {subprocess.py:93} INFO - 2025-09-08 13:11:00,805 WARNING: Failed to send webhook notification: HTTPConnectionPool(host='localhost', port=5000): Max retries exceeded with url: /webhook (Caused by NewConnectionError('<urllib3.connection.HTTPConnection object at 0x7bdcfbb8e980>: Failed to establish a new connection: [Errno 111] Connection refused'))
[2025-09-08T13:11:01.119+0530] {subprocess.py:93} INFO - 2025-09-08 13:11:01,119 INFO: Flushed batch: orders=200 items=320
[2025-09-08T13:11:01.120+0530] {subprocess.py:93} INFO - 2025-09-08 13:11:01,119 WARNING: Failed to send webhook notification: HTTPConnectionPool(host='localhost', port=5000): Max retries exceeded with url: /webhook (Caused by NewConnectionError('<urllib3.connection.HTTPConnection object at 0x7bdcfbb52b30>: Failed to establish a new connection: [Errno 111] Connection refused'))
[2025-09-08T13:11:01.305+0530] {subprocess.py:93} INFO - 2025-09-08 13:11:01,304 INFO: Flushed batch: orders=200 items=332
[2025-09-08T13:11:01.305+0530] {subprocess.py:93} INFO - 2025-09-08 13:11:01,305 WARNING: Failed to send webhook notification: HTTPConnectionPool(host='localhost', port=5000): Max retries exceeded with url: /webhook (Caused by NewConnectionError('<urllib3.connection.HTTPConnection object at 0x7bdcfbb15cf0>: Failed to establish a new connection: [Errno 111] Connection refused'))
[2025-09-08T13:11:01.505+0530] {subprocess.py:93} INFO - 2025-09-08 13:11:01,505 INFO: Flushed batch: orders=200 items=378
[2025-09-08T13:11:01.506+0530] {subprocess.py:93} INFO - 2025-09-08 13:11:01,506 WARNING: Failed to send webhook notification: HTTPConnectionPool(host='localhost', port=5000): Max retries exceeded with url: /webhook (Caused by NewConnectionError('<urllib3.connection.HTTPConnection object at 0x7bdcfbbad420>: Failed to establish a new connection: [Errno 111] Connection refused'))
[2025-09-08T13:11:01.757+0530] {subprocess.py:93} INFO - 2025-09-08 13:11:01,757 INFO: Flushed batch: orders=200 items=327
[2025-09-08T13:11:01.760+0530] {subprocess.py:93} INFO - 2025-09-08 13:11:01,760 WARNING: Failed to send webhook notification: HTTPConnectionPool(host='localhost', port=5000): Max retries exceeded with url: /webhook (Caused by NewConnectionError('<urllib3.connection.HTTPConnection object at 0x7bdcfbb6ec50>: Failed to establish a new connection: [Errno 111] Connection refused'))
[2025-09-08T13:11:02.124+0530] {subprocess.py:93} INFO - 2025-09-08 13:11:02,123 INFO: Flushed batch: orders=200 items=327
[2025-09-08T13:11:02.127+0530] {subprocess.py:93} INFO - 2025-09-08 13:11:02,126 WARNING: Failed to send webhook notification: HTTPConnectionPool(host='localhost', port=5000): Max retries exceeded with url: /webhook (Caused by NewConnectionError('<urllib3.connection.HTTPConnection object at 0x7bdcfbb43310>: Failed to establish a new connection: [Errno 111] Connection refused'))
[2025-09-08T13:11:02.600+0530] {subprocess.py:93} INFO - 2025-09-08 13:11:02,600 INFO: Flushed batch: orders=200 items=342
[2025-09-08T13:11:02.603+0530] {subprocess.py:93} INFO - 2025-09-08 13:11:02,603 WARNING: Failed to send webhook notification: HTTPConnectionPool(host='localhost', port=5000): Max retries exceeded with url: /webhook (Caused by NewConnectionError('<urllib3.connection.HTTPConnection object at 0x7bdcfbceff40>: Failed to establish a new connection: [Errno 111] Connection refused'))
[2025-09-08T13:11:02.960+0530] {subprocess.py:93} INFO - 2025-09-08 13:11:02,960 INFO: Flushed batch: orders=200 items=351
[2025-09-08T13:11:02.963+0530] {subprocess.py:93} INFO - 2025-09-08 13:11:02,963 WARNING: Failed to send webhook notification: HTTPConnectionPool(host='localhost', port=5000): Max retries exceeded with url: /webhook (Caused by NewConnectionError('<urllib3.connection.HTTPConnection object at 0x7bdcfbb17fa0>: Failed to establish a new connection: [Errno 111] Connection refused'))
[2025-09-08T13:11:05.064+0530] {subprocess.py:93} INFO - 2025-09-08 13:11:05,063 INFO: Flushed batch: orders=200 items=359
[2025-09-08T13:11:05.066+0530] {subprocess.py:93} INFO - 2025-09-08 13:11:05,066 WARNING: Failed to send webhook notification: HTTPConnectionPool(host='localhost', port=5000): Max retries exceeded with url: /webhook (Caused by NewConnectionError('<urllib3.connection.HTTPConnection object at 0x7bdcfbd5f2e0>: Failed to establish a new connection: [Errno 111] Connection refused'))
[2025-09-08T13:11:05.448+0530] {subprocess.py:93} INFO - 2025-09-08 13:11:05,448 INFO: Flushed batch: orders=200 items=322
[2025-09-08T13:11:05.451+0530] {subprocess.py:93} INFO - 2025-09-08 13:11:05,451 WARNING: Failed to send webhook notification: HTTPConnectionPool(host='localhost', port=5000): Max retries exceeded with url: /webhook (Caused by NewConnectionError('<urllib3.connection.HTTPConnection object at 0x7bdcfbcd0820>: Failed to establish a new connection: [Errno 111] Connection refused'))
[2025-09-08T13:11:05.743+0530] {subprocess.py:93} INFO - 2025-09-08 13:11:05,742 INFO: Flushed batch: orders=200 items=336
[2025-09-08T13:11:05.746+0530] {subprocess.py:93} INFO - 2025-09-08 13:11:05,745 WARNING: Failed to send webhook notification: HTTPConnectionPool(host='localhost', port=5000): Max retries exceeded with url: /webhook (Caused by NewConnectionError('<urllib3.connection.HTTPConnection object at 0x7bdcfbb81090>: Failed to establish a new connection: [Errno 111] Connection refused'))
[2025-09-08T13:11:06.008+0530] {subprocess.py:93} INFO - 2025-09-08 13:11:06,008 INFO: Flushed batch: orders=200 items=353
[2025-09-08T13:11:06.009+0530] {subprocess.py:93} INFO - 2025-09-08 13:11:06,009 WARNING: Failed to send webhook notification: HTTPConnectionPool(host='localhost', port=5000): Max retries exceeded with url: /webhook (Caused by NewConnectionError('<urllib3.connection.HTTPConnection object at 0x7bdcfbb82f50>: Failed to establish a new connection: [Errno 111] Connection refused'))
[2025-09-08T13:11:06.010+0530] {subprocess.py:93} INFO - 2025-09-08 13:11:06,010 INFO: Generated 5000 orders
[2025-09-08T13:11:33.621+0530] {subprocess.py:93} INFO - 2025-09-08 13:11:33,621 INFO: Inserted 47857 clickstream events.
[2025-09-08T13:11:33.622+0530] {subprocess.py:93} INFO - 2025-09-08 13:11:33,622 WARNING: Failed to send webhook notification: HTTPConnectionPool(host='localhost', port=5000): Max retries exceeded with url: /webhook (Caused by NewConnectionError('<urllib3.connection.HTTPConnection object at 0x7bdcfbb82ec0>: Failed to establish a new connection: [Errno 111] Connection refused'))
[2025-09-08T13:11:33.935+0530] {subprocess.py:93} INFO - 2025-09-08 13:11:33,935 INFO: Validation done: orphans orders=0 items=0 inventory=0 mismatches=0
[2025-09-08T13:11:33.936+0530] {subprocess.py:93} INFO - 2025-09-08 13:11:33,936 INFO: Integrity report: {'orphan_orders': 0, 'orphan_order_items': 0, 'inventory_orphans': 0, 'order_amount_mismatches': []}
[2025-09-08T13:11:33.965+0530] {subprocess.py:93} INFO - [2025-09-08 13:11:33] ‚úÖ Synthetic data streaming completed successfully!
[2025-09-08T13:11:33.965+0530] {subprocess.py:97} INFO - Command exited with return code 0
[2025-09-08T13:11:33.965+0530] {taskinstance.py:441} INFO - ::group::Post task execution logs
[2025-09-08T13:11:34.043+0530] {taskinstance.py:1206} INFO - Marking task as SUCCESS. dag_id=synth_stream_5min, task_id=run_synth_stream, run_id=scheduled__2025-09-08T07:35:00+00:00, execution_date=20250908T073500, start_date=20250908T074051, end_date=20250908T074134
[2025-09-08T13:11:34.151+0530] {local_task_job_runner.py:243} INFO - Task exited with return code 0
[2025-09-08T13:11:34.161+0530] {taskinstance.py:3503} INFO - 0 downstream tasks scheduled from follow-on schedule check
[2025-09-08T13:11:34.161+0530] {local_task_job_runner.py:222} INFO - ::endgroup::
