[2025-09-08T14:15:02.709+0530] {local_task_job_runner.py:120} INFO - ::group::Pre task execution logs
[2025-09-08T14:15:02.721+0530] {taskinstance.py:2076} INFO - Dependencies all met for dep_context=non-requeueable deps ti=<TaskInstance: synth_stream_5min.run_synth_stream scheduled__2025-09-08T08:40:00+00:00 [queued]>
[2025-09-08T14:15:02.724+0530] {taskinstance.py:2076} INFO - Dependencies all met for dep_context=requeueable deps ti=<TaskInstance: synth_stream_5min.run_synth_stream scheduled__2025-09-08T08:40:00+00:00 [queued]>
[2025-09-08T14:15:02.724+0530] {taskinstance.py:2306} INFO - Starting attempt 1 of 2
[2025-09-08T14:15:02.790+0530] {taskinstance.py:2330} INFO - Executing <Task(BashOperator): run_synth_stream> on 2025-09-08 08:40:00+00:00
[2025-09-08T14:15:02.798+0530] {standard_task_runner.py:64} INFO - Started process 727989 to run task
[2025-09-08T14:15:02.803+0530] {standard_task_runner.py:90} INFO - Running: ['airflow', 'tasks', 'run', 'synth_stream_5min', 'run_synth_stream', 'scheduled__2025-09-08T08:40:00+00:00', '--job-id', '42', '--raw', '--subdir', 'DAGS_FOLDER/ecom_schedules.py', '--cfg-path', '/tmp/tmplphqv8k3']
[2025-09-08T14:15:02.805+0530] {standard_task_runner.py:91} INFO - Job 42: Subtask run_synth_stream
[2025-09-08T14:15:02.890+0530] {task_command.py:426} INFO - Running <TaskInstance: synth_stream_5min.run_synth_stream scheduled__2025-09-08T08:40:00+00:00 [running]> on host softsuave-ASUS-EXPERTCENTER-D700ME-D500ME
[2025-09-08T14:15:03.068+0530] {taskinstance.py:2648} INFO - Exporting env vars: AIRFLOW_CTX_DAG_OWNER='airflow' AIRFLOW_CTX_DAG_ID='synth_stream_5min' AIRFLOW_CTX_TASK_ID='run_synth_stream' AIRFLOW_CTX_EXECUTION_DATE='2025-09-08T08:40:00+00:00' AIRFLOW_CTX_TRY_NUMBER='1' AIRFLOW_CTX_DAG_RUN_ID='scheduled__2025-09-08T08:40:00+00:00'
[2025-09-08T14:15:03.070+0530] {taskinstance.py:430} INFO - ::endgroup::
[2025-09-08T14:15:03.070+0530] {subprocess.py:63} INFO - Tmp dir root location: /tmp
[2025-09-08T14:15:03.071+0530] {subprocess.py:75} INFO - Running command: ['/usr/bin/bash', '-c', 'bash /media/softsuave/DATA-HDD/DataEngineering/Apache_Airflow/scripts/synth/run_synth_stream.sh | cat']
[2025-09-08T14:15:03.080+0530] {subprocess.py:86} INFO - Output:
[2025-09-08T14:15:03.115+0530] {subprocess.py:93} INFO - [2025-09-08 14:15:03] üöÄ Starting Synthetic E-commerce Data Stream...
[2025-09-08T14:15:03.115+0530] {subprocess.py:93} INFO - ----------------------------------------------
[2025-09-08T14:15:03.115+0530] {subprocess.py:93} INFO -  Database   : ecom_db
[2025-09-08T14:15:03.115+0530] {subprocess.py:93} INFO -  User       : sa
[2025-09-08T14:15:03.115+0530] {subprocess.py:93} INFO -  Server     : localhost:1433
[2025-09-08T14:15:03.115+0530] {subprocess.py:93} INFO -  Interval   : 5 min
[2025-09-08T14:15:03.115+0530] {subprocess.py:93} INFO -  Orders     : 50
[2025-09-08T14:15:03.115+0530] {subprocess.py:93} INFO -  Clicks     : 100
[2025-09-08T14:15:03.115+0530] {subprocess.py:93} INFO -  Webhook    : http://localhost:5000/webhook
[2025-09-08T14:15:03.115+0530] {subprocess.py:93} INFO - ----------------------------------------------
[2025-09-08T14:15:03.116+0530] {subprocess.py:93} INFO - 
[2025-09-08T14:15:03.133+0530] {subprocess.py:93} INFO - [2025-09-08 14:15:03] üîß Activating virtual environment...
[2025-09-08T14:15:03.135+0530] {subprocess.py:93} INFO - [2025-09-08 14:15:03] üîç Checking database connection...
[2025-09-08T14:15:03.160+0530] {subprocess.py:93} INFO - ‚úÖ Database connection successful
[2025-09-08T14:15:03.164+0530] {subprocess.py:93} INFO - [2025-09-08 14:15:03] üîÑ Starting synthetic data stream...
[2025-09-08T14:15:03.164+0530] {subprocess.py:93} INFO - Press Ctrl+C to stop
[2025-09-08T14:15:03.165+0530] {subprocess.py:93} INFO - 
[2025-09-08T14:15:03.335+0530] {subprocess.py:93} INFO - 2025-09-08 14:15:03,335 INFO: Tables ensured/created (if needed).
[2025-09-08T14:15:03.348+0530] {subprocess.py:93} INFO - 2025-09-08 14:15:03,348 INFO: Customers: 1000 already present; skipping seeding.
[2025-09-08T14:15:03.349+0530] {subprocess.py:93} INFO - 2025-09-08 14:15:03,349 INFO: Products: 500 already present; skipping seeding.
[2025-09-08T14:15:03.349+0530] {subprocess.py:93} INFO - 2025-09-08 14:15:03,349 INFO: Running one-shot generation: orders=5000, sessions=3000
[2025-09-08T14:15:03.355+0530] {subprocess.py:93} INFO - /media/softsuave/DATA-HDD/DataEngineering/Apache_Airflow/src/synth_ecom_mssql_stream.py:397: RemovedIn20Warning: Deprecated API features detected! These feature(s) are not compatible with SQLAlchemy 2.0. To prevent incompatible upgrades prior to updating applications, ensure requirements files are pinned to "sqlalchemy<2.0". Set environment variable SQLALCHEMY_WARN_20=1 to show all deprecation warnings.  Set environment variable SQLALCHEMY_SILENCE_UBER_WARNING=1 to silence this message. (Background on SQLAlchemy 2.0 at: https://sqlalche.me/e/b8d9)
[2025-09-08T14:15:03.355+0530] {subprocess.py:93} INFO -   customers = [dict(r) for r in conn.execute(select(self.tables["customers"])).fetchall()]
[2025-09-08T14:15:03.362+0530] {subprocess.py:93} INFO - 2025-09-08 14:15:03,362 INFO: Generating 5000 orders (batch_size=200, force_order_date_now=False)...
[2025-09-08T14:15:03.922+0530] {subprocess.py:93} INFO - 2025-09-08 14:15:03,921 INFO: Flushed batch: orders=200 items=338
[2025-09-08T14:15:03.927+0530] {subprocess.py:93} INFO - 2025-09-08 14:15:03,927 WARNING: Failed to send webhook notification: HTTPConnectionPool(host='localhost', port=5000): Max retries exceeded with url: /webhook (Caused by NewConnectionError('<urllib3.connection.HTTPConnection object at 0x709bcf7974c0>: Failed to establish a new connection: [Errno 111] Connection refused'))
[2025-09-08T14:15:04.655+0530] {subprocess.py:93} INFO - 2025-09-08 14:15:04,655 INFO: Flushed batch: orders=200 items=338
[2025-09-08T14:15:04.658+0530] {subprocess.py:93} INFO - 2025-09-08 14:15:04,657 WARNING: Failed to send webhook notification: HTTPConnectionPool(host='localhost', port=5000): Max retries exceeded with url: /webhook (Caused by NewConnectionError('<urllib3.connection.HTTPConnection object at 0x709bcf7970a0>: Failed to establish a new connection: [Errno 111] Connection refused'))
[2025-09-08T14:15:04.847+0530] {subprocess.py:93} INFO - 2025-09-08 14:15:04,846 INFO: Flushed batch: orders=200 items=343
[2025-09-08T14:15:04.849+0530] {subprocess.py:93} INFO - 2025-09-08 14:15:04,849 WARNING: Failed to send webhook notification: HTTPConnectionPool(host='localhost', port=5000): Max retries exceeded with url: /webhook (Caused by NewConnectionError('<urllib3.connection.HTTPConnection object at 0x709bcf6b6440>: Failed to establish a new connection: [Errno 111] Connection refused'))
[2025-09-08T14:15:05.047+0530] {subprocess.py:93} INFO - 2025-09-08 14:15:05,047 INFO: Flushed batch: orders=200 items=337
[2025-09-08T14:15:05.050+0530] {subprocess.py:93} INFO - 2025-09-08 14:15:05,050 WARNING: Failed to send webhook notification: HTTPConnectionPool(host='localhost', port=5000): Max retries exceeded with url: /webhook (Caused by NewConnectionError('<urllib3.connection.HTTPConnection object at 0x709bcf7a42e0>: Failed to establish a new connection: [Errno 111] Connection refused'))
[2025-09-08T14:15:06.025+0530] {subprocess.py:93} INFO - 2025-09-08 14:15:06,025 INFO: Flushed batch: orders=200 items=364
[2025-09-08T14:15:06.028+0530] {subprocess.py:93} INFO - 2025-09-08 14:15:06,028 WARNING: Failed to send webhook notification: HTTPConnectionPool(host='localhost', port=5000): Max retries exceeded with url: /webhook (Caused by NewConnectionError('<urllib3.connection.HTTPConnection object at 0x709bcf6c7a00>: Failed to establish a new connection: [Errno 111] Connection refused'))
[2025-09-08T14:15:06.230+0530] {subprocess.py:93} INFO - 2025-09-08 14:15:06,230 INFO: Flushed batch: orders=200 items=387
[2025-09-08T14:15:06.233+0530] {subprocess.py:93} INFO - 2025-09-08 14:15:06,233 WARNING: Failed to send webhook notification: HTTPConnectionPool(host='localhost', port=5000): Max retries exceeded with url: /webhook (Caused by NewConnectionError('<urllib3.connection.HTTPConnection object at 0x709bcf523940>: Failed to establish a new connection: [Errno 111] Connection refused'))
[2025-09-08T14:15:06.615+0530] {subprocess.py:93} INFO - 2025-09-08 14:15:06,615 INFO: Flushed batch: orders=200 items=367
[2025-09-08T14:15:06.616+0530] {subprocess.py:93} INFO - 2025-09-08 14:15:06,616 WARNING: Failed to send webhook notification: HTTPConnectionPool(host='localhost', port=5000): Max retries exceeded with url: /webhook (Caused by NewConnectionError('<urllib3.connection.HTTPConnection object at 0x709bcf50e170>: Failed to establish a new connection: [Errno 111] Connection refused'))
[2025-09-08T14:15:06.884+0530] {subprocess.py:93} INFO - 2025-09-08 14:15:06,884 INFO: Flushed batch: orders=200 items=322
[2025-09-08T14:15:06.887+0530] {subprocess.py:93} INFO - 2025-09-08 14:15:06,887 WARNING: Failed to send webhook notification: HTTPConnectionPool(host='localhost', port=5000): Max retries exceeded with url: /webhook (Caused by NewConnectionError('<urllib3.connection.HTTPConnection object at 0x709bcf5229b0>: Failed to establish a new connection: [Errno 111] Connection refused'))
[2025-09-08T14:15:07.384+0530] {subprocess.py:93} INFO - 2025-09-08 14:15:07,384 INFO: Flushed batch: orders=200 items=341
[2025-09-08T14:15:07.387+0530] {subprocess.py:93} INFO - 2025-09-08 14:15:07,387 WARNING: Failed to send webhook notification: HTTPConnectionPool(host='localhost', port=5000): Max retries exceeded with url: /webhook (Caused by NewConnectionError('<urllib3.connection.HTTPConnection object at 0x709bcf50e290>: Failed to establish a new connection: [Errno 111] Connection refused'))
[2025-09-08T14:15:07.567+0530] {subprocess.py:93} INFO - 2025-09-08 14:15:07,566 INFO: Flushed batch: orders=200 items=359
[2025-09-08T14:15:07.570+0530] {subprocess.py:93} INFO - 2025-09-08 14:15:07,570 WARNING: Failed to send webhook notification: HTTPConnectionPool(host='localhost', port=5000): Max retries exceeded with url: /webhook (Caused by NewConnectionError('<urllib3.connection.HTTPConnection object at 0x709bcf6b4ee0>: Failed to establish a new connection: [Errno 111] Connection refused'))
[2025-09-08T14:15:07.809+0530] {subprocess.py:93} INFO - 2025-09-08 14:15:07,808 INFO: Flushed batch: orders=200 items=343
[2025-09-08T14:15:07.811+0530] {subprocess.py:93} INFO - 2025-09-08 14:15:07,811 WARNING: Failed to send webhook notification: HTTPConnectionPool(host='localhost', port=5000): Max retries exceeded with url: /webhook (Caused by NewConnectionError('<urllib3.connection.HTTPConnection object at 0x709bcf521180>: Failed to establish a new connection: [Errno 111] Connection refused'))
[2025-09-08T14:15:08.410+0530] {subprocess.py:93} INFO - 2025-09-08 14:15:08,409 INFO: Flushed batch: orders=200 items=352
[2025-09-08T14:15:08.413+0530] {subprocess.py:93} INFO - 2025-09-08 14:15:08,412 WARNING: Failed to send webhook notification: HTTPConnectionPool(host='localhost', port=5000): Max retries exceeded with url: /webhook (Caused by NewConnectionError('<urllib3.connection.HTTPConnection object at 0x709bcf50ee00>: Failed to establish a new connection: [Errno 111] Connection refused'))
[2025-09-08T14:15:08.602+0530] {subprocess.py:93} INFO - 2025-09-08 14:15:08,601 INFO: Flushed batch: orders=200 items=353
[2025-09-08T14:15:08.604+0530] {subprocess.py:93} INFO - 2025-09-08 14:15:08,604 WARNING: Failed to send webhook notification: HTTPConnectionPool(host='localhost', port=5000): Max retries exceeded with url: /webhook (Caused by NewConnectionError('<urllib3.connection.HTTPConnection object at 0x709bcf50cf70>: Failed to establish a new connection: [Errno 111] Connection refused'))
[2025-09-08T14:15:09.086+0530] {subprocess.py:93} INFO - 2025-09-08 14:15:09,086 INFO: Flushed batch: orders=200 items=370
[2025-09-08T14:15:09.089+0530] {subprocess.py:93} INFO - 2025-09-08 14:15:09,088 WARNING: Failed to send webhook notification: HTTPConnectionPool(host='localhost', port=5000): Max retries exceeded with url: /webhook (Caused by NewConnectionError('<urllib3.connection.HTTPConnection object at 0x709bcf540a60>: Failed to establish a new connection: [Errno 111] Connection refused'))
[2025-09-08T14:15:09.277+0530] {subprocess.py:93} INFO - 2025-09-08 14:15:09,277 INFO: Flushed batch: orders=200 items=350
[2025-09-08T14:15:09.280+0530] {subprocess.py:93} INFO - 2025-09-08 14:15:09,280 WARNING: Failed to send webhook notification: HTTPConnectionPool(host='localhost', port=5000): Max retries exceeded with url: /webhook (Caused by NewConnectionError('<urllib3.connection.HTTPConnection object at 0x709bcf5203d0>: Failed to establish a new connection: [Errno 111] Connection refused'))
[2025-09-08T14:15:10.045+0530] {subprocess.py:93} INFO - 2025-09-08 14:15:10,045 INFO: Flushed batch: orders=200 items=339
[2025-09-08T14:15:10.048+0530] {subprocess.py:93} INFO - 2025-09-08 14:15:10,048 WARNING: Failed to send webhook notification: HTTPConnectionPool(host='localhost', port=5000): Max retries exceeded with url: /webhook (Caused by NewConnectionError('<urllib3.connection.HTTPConnection object at 0x709bcfd4f5b0>: Failed to establish a new connection: [Errno 111] Connection refused'))
[2025-09-08T14:15:10.244+0530] {subprocess.py:93} INFO - 2025-09-08 14:15:10,244 INFO: Flushed batch: orders=200 items=349
[2025-09-08T14:15:10.246+0530] {subprocess.py:93} INFO - 2025-09-08 14:15:10,246 WARNING: Failed to send webhook notification: HTTPConnectionPool(host='localhost', port=5000): Max retries exceeded with url: /webhook (Caused by NewConnectionError('<urllib3.connection.HTTPConnection object at 0x709bcf7345b0>: Failed to establish a new connection: [Errno 111] Connection refused'))
[2025-09-08T14:15:10.446+0530] {subprocess.py:93} INFO - 2025-09-08 14:15:10,445 INFO: Flushed batch: orders=200 items=319
[2025-09-08T14:15:10.448+0530] {subprocess.py:93} INFO - 2025-09-08 14:15:10,448 WARNING: Failed to send webhook notification: HTTPConnectionPool(host='localhost', port=5000): Max retries exceeded with url: /webhook (Caused by NewConnectionError('<urllib3.connection.HTTPConnection object at 0x709bcf6c5540>: Failed to establish a new connection: [Errno 111] Connection refused'))
[2025-09-08T14:15:10.629+0530] {subprocess.py:93} INFO - 2025-09-08 14:15:10,628 INFO: Flushed batch: orders=200 items=343
[2025-09-08T14:15:10.631+0530] {subprocess.py:93} INFO - 2025-09-08 14:15:10,631 WARNING: Failed to send webhook notification: HTTPConnectionPool(host='localhost', port=5000): Max retries exceeded with url: /webhook (Caused by NewConnectionError('<urllib3.connection.HTTPConnection object at 0x709bcf541cc0>: Failed to establish a new connection: [Errno 111] Connection refused'))
[2025-09-08T14:15:10.954+0530] {subprocess.py:93} INFO - 2025-09-08 14:15:10,954 INFO: Flushed batch: orders=200 items=325
[2025-09-08T14:15:10.957+0530] {subprocess.py:93} INFO - 2025-09-08 14:15:10,957 WARNING: Failed to send webhook notification: HTTPConnectionPool(host='localhost', port=5000): Max retries exceeded with url: /webhook (Caused by NewConnectionError('<urllib3.connection.HTTPConnection object at 0x709bcf522d70>: Failed to establish a new connection: [Errno 111] Connection refused'))
[2025-09-08T14:15:11.447+0530] {subprocess.py:93} INFO - 2025-09-08 14:15:11,446 INFO: Flushed batch: orders=200 items=338
[2025-09-08T14:15:11.449+0530] {subprocess.py:93} INFO - 2025-09-08 14:15:11,449 WARNING: Failed to send webhook notification: HTTPConnectionPool(host='localhost', port=5000): Max retries exceeded with url: /webhook (Caused by NewConnectionError('<urllib3.connection.HTTPConnection object at 0x709bcf7361d0>: Failed to establish a new connection: [Errno 111] Connection refused'))
[2025-09-08T14:15:11.621+0530] {subprocess.py:93} INFO - 2025-09-08 14:15:11,621 INFO: Flushed batch: orders=200 items=331
[2025-09-08T14:15:11.624+0530] {subprocess.py:93} INFO - 2025-09-08 14:15:11,623 WARNING: Failed to send webhook notification: HTTPConnectionPool(host='localhost', port=5000): Max retries exceeded with url: /webhook (Caused by NewConnectionError('<urllib3.connection.HTTPConnection object at 0x709bcf5200a0>: Failed to establish a new connection: [Errno 111] Connection refused'))
[2025-09-08T14:15:11.972+0530] {subprocess.py:93} INFO - 2025-09-08 14:15:11,972 INFO: Flushed batch: orders=200 items=343
[2025-09-08T14:15:11.976+0530] {subprocess.py:93} INFO - 2025-09-08 14:15:11,976 WARNING: Failed to send webhook notification: HTTPConnectionPool(host='localhost', port=5000): Max retries exceeded with url: /webhook (Caused by NewConnectionError('<urllib3.connection.HTTPConnection object at 0x709bcf6c4550>: Failed to establish a new connection: [Errno 111] Connection refused'))
[2025-09-08T14:15:12.180+0530] {subprocess.py:93} INFO - 2025-09-08 14:15:12,180 INFO: Flushed batch: orders=200 items=357
[2025-09-08T14:15:12.183+0530] {subprocess.py:93} INFO - 2025-09-08 14:15:12,183 WARNING: Failed to send webhook notification: HTTPConnectionPool(host='localhost', port=5000): Max retries exceeded with url: /webhook (Caused by NewConnectionError('<urllib3.connection.HTTPConnection object at 0x709bcf522710>: Failed to establish a new connection: [Errno 111] Connection refused'))
[2025-09-08T14:15:12.513+0530] {subprocess.py:93} INFO - 2025-09-08 14:15:12,513 INFO: Flushed batch: orders=200 items=335
[2025-09-08T14:15:12.514+0530] {subprocess.py:93} INFO - 2025-09-08 14:15:12,514 WARNING: Failed to send webhook notification: HTTPConnectionPool(host='localhost', port=5000): Max retries exceeded with url: /webhook (Caused by NewConnectionError('<urllib3.connection.HTTPConnection object at 0x709bcf5232b0>: Failed to establish a new connection: [Errno 111] Connection refused'))
[2025-09-08T14:15:12.514+0530] {subprocess.py:93} INFO - 2025-09-08 14:15:12,514 INFO: Generated 5000 orders
[2025-09-08T14:15:48.508+0530] {subprocess.py:93} INFO - 2025-09-08 14:15:48,508 INFO: Inserted 47862 clickstream events.
[2025-09-08T14:15:48.510+0530] {subprocess.py:93} INFO - 2025-09-08 14:15:48,509 WARNING: Failed to send webhook notification: HTTPConnectionPool(host='localhost', port=5000): Max retries exceeded with url: /webhook (Caused by NewConnectionError('<urllib3.connection.HTTPConnection object at 0x709bce3c4940>: Failed to establish a new connection: [Errno 111] Connection refused'))
[2025-09-08T14:15:51.325+0530] {subprocess.py:93} INFO - 2025-09-08 14:15:51,325 INFO: Validation done: orphans orders=0 items=0 inventory=0 mismatches=0
[2025-09-08T14:15:51.336+0530] {subprocess.py:93} INFO - 2025-09-08 14:15:51,336 INFO: Integrity report: {'orphan_orders': 0, 'orphan_order_items': 0, 'inventory_orphans': 0, 'order_amount_mismatches': []}
[2025-09-08T14:15:51.366+0530] {subprocess.py:93} INFO - [2025-09-08 14:15:51] ‚úÖ Synthetic data streaming completed successfully!
[2025-09-08T14:15:51.366+0530] {subprocess.py:97} INFO - Command exited with return code 0
[2025-09-08T14:15:51.366+0530] {taskinstance.py:441} INFO - ::group::Post task execution logs
[2025-09-08T14:15:51.600+0530] {taskinstance.py:1206} INFO - Marking task as SUCCESS. dag_id=synth_stream_5min, task_id=run_synth_stream, run_id=scheduled__2025-09-08T08:40:00+00:00, execution_date=20250908T084000, start_date=20250908T084502, end_date=20250908T084551
[2025-09-08T14:15:51.859+0530] {local_task_job_runner.py:243} INFO - Task exited with return code 0
[2025-09-08T14:15:51.868+0530] {taskinstance.py:3503} INFO - 0 downstream tasks scheduled from follow-on schedule check
[2025-09-08T14:15:51.869+0530] {local_task_job_runner.py:222} INFO - ::endgroup::
