[2025-09-08T13:45:02.963+0530] {local_task_job_runner.py:120} INFO - ::group::Pre task execution logs
[2025-09-08T13:45:02.975+0530] {taskinstance.py:2076} INFO - Dependencies all met for dep_context=non-requeueable deps ti=<TaskInstance: synth_stream_5min.run_synth_stream scheduled__2025-09-08T08:10:00+00:00 [queued]>
[2025-09-08T13:45:02.978+0530] {taskinstance.py:2076} INFO - Dependencies all met for dep_context=requeueable deps ti=<TaskInstance: synth_stream_5min.run_synth_stream scheduled__2025-09-08T08:10:00+00:00 [queued]>
[2025-09-08T13:45:02.978+0530] {taskinstance.py:2306} INFO - Starting attempt 1 of 2
[2025-09-08T13:45:03.040+0530] {taskinstance.py:2330} INFO - Executing <Task(BashOperator): run_synth_stream> on 2025-09-08 08:10:00+00:00
[2025-09-08T13:45:03.048+0530] {standard_task_runner.py:64} INFO - Started process 720747 to run task
[2025-09-08T13:45:03.055+0530] {standard_task_runner.py:90} INFO - Running: ['airflow', 'tasks', 'run', 'synth_stream_5min', 'run_synth_stream', 'scheduled__2025-09-08T08:10:00+00:00', '--job-id', '33', '--raw', '--subdir', 'DAGS_FOLDER/ecom_schedules.py', '--cfg-path', '/tmp/tmpucrycvpw']
[2025-09-08T13:45:03.058+0530] {standard_task_runner.py:91} INFO - Job 33: Subtask run_synth_stream
[2025-09-08T13:45:03.140+0530] {task_command.py:426} INFO - Running <TaskInstance: synth_stream_5min.run_synth_stream scheduled__2025-09-08T08:10:00+00:00 [running]> on host softsuave-ASUS-EXPERTCENTER-D700ME-D500ME
[2025-09-08T13:45:03.415+0530] {taskinstance.py:2648} INFO - Exporting env vars: AIRFLOW_CTX_DAG_OWNER='airflow' AIRFLOW_CTX_DAG_ID='synth_stream_5min' AIRFLOW_CTX_TASK_ID='run_synth_stream' AIRFLOW_CTX_EXECUTION_DATE='2025-09-08T08:10:00+00:00' AIRFLOW_CTX_TRY_NUMBER='1' AIRFLOW_CTX_DAG_RUN_ID='scheduled__2025-09-08T08:10:00+00:00'
[2025-09-08T13:45:03.416+0530] {taskinstance.py:430} INFO - ::endgroup::
[2025-09-08T13:45:03.416+0530] {subprocess.py:63} INFO - Tmp dir root location: /tmp
[2025-09-08T13:45:03.416+0530] {subprocess.py:75} INFO - Running command: ['/usr/bin/bash', '-c', 'bash /media/softsuave/DATA-HDD/DataEngineering/Apache_Airflow/scripts/synth/run_synth_stream.sh | cat']
[2025-09-08T13:45:03.422+0530] {subprocess.py:86} INFO - Output:
[2025-09-08T13:45:03.466+0530] {subprocess.py:93} INFO - [2025-09-08 13:45:03] üöÄ Starting Synthetic E-commerce Data Stream...
[2025-09-08T13:45:03.466+0530] {subprocess.py:93} INFO - ----------------------------------------------
[2025-09-08T13:45:03.466+0530] {subprocess.py:93} INFO -  Database   : ecom_db
[2025-09-08T13:45:03.466+0530] {subprocess.py:93} INFO -  User       : sa
[2025-09-08T13:45:03.466+0530] {subprocess.py:93} INFO -  Server     : localhost:1433
[2025-09-08T13:45:03.466+0530] {subprocess.py:93} INFO -  Interval   : 5 min
[2025-09-08T13:45:03.467+0530] {subprocess.py:93} INFO -  Orders     : 50
[2025-09-08T13:45:03.467+0530] {subprocess.py:93} INFO -  Clicks     : 100
[2025-09-08T13:45:03.467+0530] {subprocess.py:93} INFO -  Webhook    : http://localhost:5000/webhook
[2025-09-08T13:45:03.467+0530] {subprocess.py:93} INFO - ----------------------------------------------
[2025-09-08T13:45:03.467+0530] {subprocess.py:93} INFO - 
[2025-09-08T13:45:03.488+0530] {subprocess.py:93} INFO - [2025-09-08 13:45:03] üîß Activating virtual environment...
[2025-09-08T13:45:03.490+0530] {subprocess.py:93} INFO - [2025-09-08 13:45:03] üîç Checking database connection...
[2025-09-08T13:45:03.522+0530] {subprocess.py:93} INFO - ‚úÖ Database connection successful
[2025-09-08T13:45:03.527+0530] {subprocess.py:93} INFO - [2025-09-08 13:45:03] üîÑ Starting synthetic data stream...
[2025-09-08T13:45:03.528+0530] {subprocess.py:93} INFO - Press Ctrl+C to stop
[2025-09-08T13:45:03.528+0530] {subprocess.py:93} INFO - 
[2025-09-08T13:45:03.699+0530] {subprocess.py:93} INFO - 2025-09-08 13:45:03,698 INFO: Tables ensured/created (if needed).
[2025-09-08T13:45:03.711+0530] {subprocess.py:93} INFO - 2025-09-08 13:45:03,711 INFO: Customers: 1000 already present; skipping seeding.
[2025-09-08T13:45:03.712+0530] {subprocess.py:93} INFO - 2025-09-08 13:45:03,712 INFO: Products: 500 already present; skipping seeding.
[2025-09-08T13:45:03.712+0530] {subprocess.py:93} INFO - 2025-09-08 13:45:03,712 INFO: Running one-shot generation: orders=5000, sessions=3000
[2025-09-08T13:45:03.718+0530] {subprocess.py:93} INFO - /media/softsuave/DATA-HDD/DataEngineering/Apache_Airflow/src/synth_ecom_mssql_stream.py:397: RemovedIn20Warning: Deprecated API features detected! These feature(s) are not compatible with SQLAlchemy 2.0. To prevent incompatible upgrades prior to updating applications, ensure requirements files are pinned to "sqlalchemy<2.0". Set environment variable SQLALCHEMY_WARN_20=1 to show all deprecation warnings.  Set environment variable SQLALCHEMY_SILENCE_UBER_WARNING=1 to silence this message. (Background on SQLAlchemy 2.0 at: https://sqlalche.me/e/b8d9)
[2025-09-08T13:45:03.718+0530] {subprocess.py:93} INFO -   customers = [dict(r) for r in conn.execute(select(self.tables["customers"])).fetchall()]
[2025-09-08T13:45:03.725+0530] {subprocess.py:93} INFO - 2025-09-08 13:45:03,725 INFO: Generating 5000 orders (batch_size=200, force_order_date_now=False)...
[2025-09-08T13:45:04.187+0530] {subprocess.py:93} INFO - 2025-09-08 13:45:04,187 INFO: Flushed batch: orders=200 items=340
[2025-09-08T13:45:04.193+0530] {subprocess.py:93} INFO - 2025-09-08 13:45:04,192 WARNING: Failed to send webhook notification: HTTPConnectionPool(host='localhost', port=5000): Max retries exceeded with url: /webhook (Caused by NewConnectionError('<urllib3.connection.HTTPConnection object at 0x72cba9783f10>: Failed to establish a new connection: [Errno 111] Connection refused'))
[2025-09-08T13:45:04.429+0530] {subprocess.py:93} INFO - 2025-09-08 13:45:04,428 INFO: Flushed batch: orders=200 items=314
[2025-09-08T13:45:04.431+0530] {subprocess.py:93} INFO - 2025-09-08 13:45:04,431 WARNING: Failed to send webhook notification: HTTPConnectionPool(host='localhost', port=5000): Max retries exceeded with url: /webhook (Caused by NewConnectionError('<urllib3.connection.HTTPConnection object at 0x72cba96af490>: Failed to establish a new connection: [Errno 111] Connection refused'))
[2025-09-08T13:45:04.629+0530] {subprocess.py:93} INFO - 2025-09-08 13:45:04,629 INFO: Flushed batch: orders=200 items=328
[2025-09-08T13:45:04.632+0530] {subprocess.py:93} INFO - 2025-09-08 13:45:04,631 WARNING: Failed to send webhook notification: HTTPConnectionPool(host='localhost', port=5000): Max retries exceeded with url: /webhook (Caused by NewConnectionError('<urllib3.connection.HTTPConnection object at 0x72cba96cc220>: Failed to establish a new connection: [Errno 111] Connection refused'))
[2025-09-08T13:45:04.821+0530] {subprocess.py:93} INFO - 2025-09-08 13:45:04,821 INFO: Flushed batch: orders=200 items=397
[2025-09-08T13:45:04.824+0530] {subprocess.py:93} INFO - 2025-09-08 13:45:04,824 WARNING: Failed to send webhook notification: HTTPConnectionPool(host='localhost', port=5000): Max retries exceeded with url: /webhook (Caused by NewConnectionError('<urllib3.connection.HTTPConnection object at 0x72cba96ce170>: Failed to establish a new connection: [Errno 111] Connection refused'))
[2025-09-08T13:45:05.013+0530] {subprocess.py:93} INFO - 2025-09-08 13:45:05,013 INFO: Flushed batch: orders=200 items=328
[2025-09-08T13:45:05.016+0530] {subprocess.py:93} INFO - 2025-09-08 13:45:05,016 WARNING: Failed to send webhook notification: HTTPConnectionPool(host='localhost', port=5000): Max retries exceeded with url: /webhook (Caused by NewConnectionError('<urllib3.connection.HTTPConnection object at 0x72cba9664970>: Failed to establish a new connection: [Errno 111] Connection refused'))
[2025-09-08T13:45:05.196+0530] {subprocess.py:93} INFO - 2025-09-08 13:45:05,196 INFO: Flushed batch: orders=200 items=369
[2025-09-08T13:45:05.199+0530] {subprocess.py:93} INFO - 2025-09-08 13:45:05,199 WARNING: Failed to send webhook notification: HTTPConnectionPool(host='localhost', port=5000): Max retries exceeded with url: /webhook (Caused by NewConnectionError('<urllib3.connection.HTTPConnection object at 0x72cba96cd9c0>: Failed to establish a new connection: [Errno 111] Connection refused'))
[2025-09-08T13:45:05.371+0530] {subprocess.py:93} INFO - 2025-09-08 13:45:05,370 INFO: Flushed batch: orders=200 items=358
[2025-09-08T13:45:05.372+0530] {subprocess.py:93} INFO - 2025-09-08 13:45:05,372 WARNING: Failed to send webhook notification: HTTPConnectionPool(host='localhost', port=5000): Max retries exceeded with url: /webhook (Caused by NewConnectionError('<urllib3.connection.HTTPConnection object at 0x72cba95051b0>: Failed to establish a new connection: [Errno 111] Connection refused'))
[2025-09-08T13:45:05.538+0530] {subprocess.py:93} INFO - 2025-09-08 13:45:05,538 INFO: Flushed batch: orders=200 items=347
[2025-09-08T13:45:05.540+0530] {subprocess.py:93} INFO - 2025-09-08 13:45:05,540 WARNING: Failed to send webhook notification: HTTPConnectionPool(host='localhost', port=5000): Max retries exceeded with url: /webhook (Caused by NewConnectionError('<urllib3.connection.HTTPConnection object at 0x72cba9507f10>: Failed to establish a new connection: [Errno 111] Connection refused'))
[2025-09-08T13:45:05.821+0530] {subprocess.py:93} INFO - 2025-09-08 13:45:05,821 INFO: Flushed batch: orders=200 items=346
[2025-09-08T13:45:05.822+0530] {subprocess.py:93} INFO - 2025-09-08 13:45:05,822 WARNING: Failed to send webhook notification: HTTPConnectionPool(host='localhost', port=5000): Max retries exceeded with url: /webhook (Caused by NewConnectionError('<urllib3.connection.HTTPConnection object at 0x72cba965ee90>: Failed to establish a new connection: [Errno 111] Connection refused'))
[2025-09-08T13:45:06.047+0530] {subprocess.py:93} INFO - 2025-09-08 13:45:06,046 INFO: Flushed batch: orders=200 items=357
[2025-09-08T13:45:06.050+0530] {subprocess.py:93} INFO - 2025-09-08 13:45:06,050 WARNING: Failed to send webhook notification: HTTPConnectionPool(host='localhost', port=5000): Max retries exceeded with url: /webhook (Caused by NewConnectionError('<urllib3.connection.HTTPConnection object at 0x72cba96cd1e0>: Failed to establish a new connection: [Errno 111] Connection refused'))
[2025-09-08T13:45:06.471+0530] {subprocess.py:93} INFO - 2025-09-08 13:45:06,471 INFO: Flushed batch: orders=200 items=329
[2025-09-08T13:45:06.474+0530] {subprocess.py:93} INFO - 2025-09-08 13:45:06,474 WARNING: Failed to send webhook notification: HTTPConnectionPool(host='localhost', port=5000): Max retries exceeded with url: /webhook (Caused by NewConnectionError('<urllib3.connection.HTTPConnection object at 0x72cba965c190>: Failed to establish a new connection: [Errno 111] Connection refused'))
[2025-09-08T13:45:06.698+0530] {subprocess.py:93} INFO - 2025-09-08 13:45:06,697 INFO: Flushed batch: orders=200 items=331
[2025-09-08T13:45:06.701+0530] {subprocess.py:93} INFO - 2025-09-08 13:45:06,701 WARNING: Failed to send webhook notification: HTTPConnectionPool(host='localhost', port=5000): Max retries exceeded with url: /webhook (Caused by NewConnectionError('<urllib3.connection.HTTPConnection object at 0x72cba96cd180>: Failed to establish a new connection: [Errno 111] Connection refused'))
[2025-09-08T13:45:06.872+0530] {subprocess.py:93} INFO - 2025-09-08 13:45:06,872 INFO: Flushed batch: orders=200 items=337
[2025-09-08T13:45:06.875+0530] {subprocess.py:93} INFO - 2025-09-08 13:45:06,874 WARNING: Failed to send webhook notification: HTTPConnectionPool(host='localhost', port=5000): Max retries exceeded with url: /webhook (Caused by NewConnectionError('<urllib3.connection.HTTPConnection object at 0x72cba95268c0>: Failed to establish a new connection: [Errno 111] Connection refused'))
[2025-09-08T13:45:07.047+0530] {subprocess.py:93} INFO - 2025-09-08 13:45:07,047 INFO: Flushed batch: orders=200 items=349
[2025-09-08T13:45:07.050+0530] {subprocess.py:93} INFO - 2025-09-08 13:45:07,049 WARNING: Failed to send webhook notification: HTTPConnectionPool(host='localhost', port=5000): Max retries exceeded with url: /webhook (Caused by NewConnectionError('<urllib3.connection.HTTPConnection object at 0x72cba9506620>: Failed to establish a new connection: [Errno 111] Connection refused'))
[2025-09-08T13:45:07.223+0530] {subprocess.py:93} INFO - 2025-09-08 13:45:07,223 INFO: Flushed batch: orders=200 items=345
[2025-09-08T13:45:07.226+0530] {subprocess.py:93} INFO - 2025-09-08 13:45:07,225 WARNING: Failed to send webhook notification: HTTPConnectionPool(host='localhost', port=5000): Max retries exceeded with url: /webhook (Caused by NewConnectionError('<urllib3.connection.HTTPConnection object at 0x72cba965e890>: Failed to establish a new connection: [Errno 111] Connection refused'))
[2025-09-08T13:45:07.440+0530] {subprocess.py:93} INFO - 2025-09-08 13:45:07,440 INFO: Flushed batch: orders=200 items=346
[2025-09-08T13:45:07.441+0530] {subprocess.py:93} INFO - 2025-09-08 13:45:07,441 WARNING: Failed to send webhook notification: HTTPConnectionPool(host='localhost', port=5000): Max retries exceeded with url: /webhook (Caused by NewConnectionError('<urllib3.connection.HTTPConnection object at 0x72cba9507f70>: Failed to establish a new connection: [Errno 111] Connection refused'))
[2025-09-08T13:45:07.641+0530] {subprocess.py:93} INFO - 2025-09-08 13:45:07,640 INFO: Flushed batch: orders=200 items=352
[2025-09-08T13:45:07.643+0530] {subprocess.py:93} INFO - 2025-09-08 13:45:07,643 WARNING: Failed to send webhook notification: HTTPConnectionPool(host='localhost', port=5000): Max retries exceeded with url: /webhook (Caused by NewConnectionError('<urllib3.connection.HTTPConnection object at 0x72cba96cdb70>: Failed to establish a new connection: [Errno 111] Connection refused'))
[2025-09-08T13:45:07.841+0530] {subprocess.py:93} INFO - 2025-09-08 13:45:07,841 INFO: Flushed batch: orders=200 items=332
[2025-09-08T13:45:07.844+0530] {subprocess.py:93} INFO - 2025-09-08 13:45:07,843 WARNING: Failed to send webhook notification: HTTPConnectionPool(host='localhost', port=5000): Max retries exceeded with url: /webhook (Caused by NewConnectionError('<urllib3.connection.HTTPConnection object at 0x72cba9726d40>: Failed to establish a new connection: [Errno 111] Connection refused'))
[2025-09-08T13:45:08.025+0530] {subprocess.py:93} INFO - 2025-09-08 13:45:08,025 INFO: Flushed batch: orders=200 items=309
[2025-09-08T13:45:08.028+0530] {subprocess.py:93} INFO - 2025-09-08 13:45:08,028 WARNING: Failed to send webhook notification: HTTPConnectionPool(host='localhost', port=5000): Max retries exceeded with url: /webhook (Caused by NewConnectionError('<urllib3.connection.HTTPConnection object at 0x72cba9546a10>: Failed to establish a new connection: [Errno 111] Connection refused'))
[2025-09-08T13:45:08.508+0530] {subprocess.py:93} INFO - 2025-09-08 13:45:08,507 INFO: Flushed batch: orders=200 items=382
[2025-09-08T13:45:08.510+0530] {subprocess.py:93} INFO - 2025-09-08 13:45:08,509 WARNING: Failed to send webhook notification: HTTPConnectionPool(host='localhost', port=5000): Max retries exceeded with url: /webhook (Caused by NewConnectionError('<urllib3.connection.HTTPConnection object at 0x72cba9547a60>: Failed to establish a new connection: [Errno 111] Connection refused'))
[2025-09-08T13:45:08.717+0530] {subprocess.py:93} INFO - 2025-09-08 13:45:08,716 INFO: Flushed batch: orders=200 items=378
[2025-09-08T13:45:08.718+0530] {subprocess.py:93} INFO - 2025-09-08 13:45:08,718 WARNING: Failed to send webhook notification: HTTPConnectionPool(host='localhost', port=5000): Max retries exceeded with url: /webhook (Caused by NewConnectionError('<urllib3.connection.HTTPConnection object at 0x72cba9544b50>: Failed to establish a new connection: [Errno 111] Connection refused'))
[2025-09-08T13:45:08.908+0530] {subprocess.py:93} INFO - 2025-09-08 13:45:08,908 INFO: Flushed batch: orders=200 items=346
[2025-09-08T13:45:08.911+0530] {subprocess.py:93} INFO - 2025-09-08 13:45:08,911 WARNING: Failed to send webhook notification: HTTPConnectionPool(host='localhost', port=5000): Max retries exceeded with url: /webhook (Caused by NewConnectionError('<urllib3.connection.HTTPConnection object at 0x72cba9504130>: Failed to establish a new connection: [Errno 111] Connection refused'))
[2025-09-08T13:45:09.109+0530] {subprocess.py:93} INFO - 2025-09-08 13:45:09,109 INFO: Flushed batch: orders=200 items=331
[2025-09-08T13:45:09.112+0530] {subprocess.py:93} INFO - 2025-09-08 13:45:09,112 WARNING: Failed to send webhook notification: HTTPConnectionPool(host='localhost', port=5000): Max retries exceeded with url: /webhook (Caused by NewConnectionError('<urllib3.connection.HTTPConnection object at 0x72cba96ce5f0>: Failed to establish a new connection: [Errno 111] Connection refused'))
[2025-09-08T13:45:09.318+0530] {subprocess.py:93} INFO - 2025-09-08 13:45:09,317 INFO: Flushed batch: orders=200 items=351
[2025-09-08T13:45:09.321+0530] {subprocess.py:93} INFO - 2025-09-08 13:45:09,320 WARNING: Failed to send webhook notification: HTTPConnectionPool(host='localhost', port=5000): Max retries exceeded with url: /webhook (Caused by NewConnectionError('<urllib3.connection.HTTPConnection object at 0x72cba965f220>: Failed to establish a new connection: [Errno 111] Connection refused'))
[2025-09-08T13:45:09.736+0530] {subprocess.py:93} INFO - 2025-09-08 13:45:09,735 INFO: Flushed batch: orders=200 items=362
[2025-09-08T13:45:09.738+0530] {subprocess.py:93} INFO - 2025-09-08 13:45:09,738 WARNING: Failed to send webhook notification: HTTPConnectionPool(host='localhost', port=5000): Max retries exceeded with url: /webhook (Caused by NewConnectionError('<urllib3.connection.HTTPConnection object at 0x72cba96c09d0>: Failed to establish a new connection: [Errno 111] Connection refused'))
[2025-09-08T13:45:09.739+0530] {subprocess.py:93} INFO - 2025-09-08 13:45:09,738 INFO: Generated 5000 orders
[2025-09-08T13:45:35.072+0530] {subprocess.py:93} INFO - 2025-09-08 13:45:35,072 INFO: Inserted 47948 clickstream events.
[2025-09-08T13:45:35.074+0530] {subprocess.py:93} INFO - 2025-09-08 13:45:35,073 WARNING: Failed to send webhook notification: HTTPConnectionPool(host='localhost', port=5000): Max retries exceeded with url: /webhook (Caused by NewConnectionError('<urllib3.connection.HTTPConnection object at 0x72cba83abe80>: Failed to establish a new connection: [Errno 111] Connection refused'))
[2025-09-08T13:45:36.950+0530] {subprocess.py:93} INFO - 2025-09-08 13:45:36,950 INFO: Validation done: orphans orders=0 items=0 inventory=0 mismatches=0
[2025-09-08T13:45:36.956+0530] {subprocess.py:93} INFO - 2025-09-08 13:45:36,956 INFO: Integrity report: {'orphan_orders': 0, 'orphan_order_items': 0, 'inventory_orphans': 0, 'order_amount_mismatches': []}
[2025-09-08T13:45:36.993+0530] {subprocess.py:93} INFO - [2025-09-08 13:45:36] ‚úÖ Synthetic data streaming completed successfully!
[2025-09-08T13:45:36.994+0530] {subprocess.py:97} INFO - Command exited with return code 0
[2025-09-08T13:45:36.994+0530] {taskinstance.py:441} INFO - ::group::Post task execution logs
[2025-09-08T13:45:37.151+0530] {taskinstance.py:1206} INFO - Marking task as SUCCESS. dag_id=synth_stream_5min, task_id=run_synth_stream, run_id=scheduled__2025-09-08T08:10:00+00:00, execution_date=20250908T081000, start_date=20250908T081502, end_date=20250908T081537
[2025-09-08T13:45:37.487+0530] {local_task_job_runner.py:243} INFO - Task exited with return code 0
[2025-09-08T13:45:37.495+0530] {taskinstance.py:3503} INFO - 0 downstream tasks scheduled from follow-on schedule check
[2025-09-08T13:45:37.495+0530] {local_task_job_runner.py:222} INFO - ::endgroup::
