[2025-09-08T14:21:44.714+0530] {local_task_job_runner.py:120} INFO - ::group::Pre task execution logs
[2025-09-08T14:21:44.865+0530] {taskinstance.py:2076} INFO - Dependencies all met for dep_context=non-requeueable deps ti=<TaskInstance: synth_stream_5min.run_synth_stream scheduled__2025-09-08T08:45:00+00:00 [queued]>
[2025-09-08T14:21:44.876+0530] {taskinstance.py:2076} INFO - Dependencies all met for dep_context=requeueable deps ti=<TaskInstance: synth_stream_5min.run_synth_stream scheduled__2025-09-08T08:45:00+00:00 [queued]>
[2025-09-08T14:21:44.877+0530] {taskinstance.py:2306} INFO - Starting attempt 1 of 2
[2025-09-08T14:21:45.192+0530] {taskinstance.py:2330} INFO - Executing <Task(BashOperator): run_synth_stream> on 2025-09-08 08:45:00+00:00
[2025-09-08T14:21:45.200+0530] {standard_task_runner.py:64} INFO - Started process 729759 to run task
[2025-09-08T14:21:45.206+0530] {standard_task_runner.py:90} INFO - Running: ['airflow', 'tasks', 'run', 'synth_stream_5min', 'run_synth_stream', 'scheduled__2025-09-08T08:45:00+00:00', '--job-id', '44', '--raw', '--subdir', 'DAGS_FOLDER/ecom_schedules.py', '--cfg-path', '/tmp/tmp_jmax89r']
[2025-09-08T14:21:45.208+0530] {standard_task_runner.py:91} INFO - Job 44: Subtask run_synth_stream
[2025-09-08T14:21:45.461+0530] {task_command.py:426} INFO - Running <TaskInstance: synth_stream_5min.run_synth_stream scheduled__2025-09-08T08:45:00+00:00 [running]> on host softsuave-ASUS-EXPERTCENTER-D700ME-D500ME
[2025-09-08T14:21:46.037+0530] {taskinstance.py:2648} INFO - Exporting env vars: AIRFLOW_CTX_DAG_OWNER='airflow' AIRFLOW_CTX_DAG_ID='synth_stream_5min' AIRFLOW_CTX_TASK_ID='run_synth_stream' AIRFLOW_CTX_EXECUTION_DATE='2025-09-08T08:45:00+00:00' AIRFLOW_CTX_TRY_NUMBER='1' AIRFLOW_CTX_DAG_RUN_ID='scheduled__2025-09-08T08:45:00+00:00'
[2025-09-08T14:21:46.038+0530] {taskinstance.py:430} INFO - ::endgroup::
[2025-09-08T14:21:46.062+0530] {subprocess.py:63} INFO - Tmp dir root location: /tmp
[2025-09-08T14:21:46.063+0530] {subprocess.py:75} INFO - Running command: ['/usr/bin/bash', '-c', 'bash /media/softsuave/DATA-HDD/DataEngineering/Apache_Airflow/scripts/synth/run_synth_stream.sh | cat']
[2025-09-08T14:21:46.078+0530] {subprocess.py:86} INFO - Output:
[2025-09-08T14:21:46.148+0530] {subprocess.py:93} INFO - [2025-09-08 14:21:46] üöÄ Starting Synthetic E-commerce Data Stream...
[2025-09-08T14:21:46.149+0530] {subprocess.py:93} INFO - ----------------------------------------------
[2025-09-08T14:21:46.149+0530] {subprocess.py:93} INFO -  Database   : ecom_db
[2025-09-08T14:21:46.149+0530] {subprocess.py:93} INFO -  User       : sa
[2025-09-08T14:21:46.149+0530] {subprocess.py:93} INFO -  Server     : localhost:1433
[2025-09-08T14:21:46.149+0530] {subprocess.py:93} INFO -  Interval   : 5 min
[2025-09-08T14:21:46.149+0530] {subprocess.py:93} INFO -  Orders     : 50
[2025-09-08T14:21:46.149+0530] {subprocess.py:93} INFO -  Clicks     : 100
[2025-09-08T14:21:46.149+0530] {subprocess.py:93} INFO -  Webhook    : http://localhost:5000/webhook
[2025-09-08T14:21:46.149+0530] {subprocess.py:93} INFO - ----------------------------------------------
[2025-09-08T14:21:46.149+0530] {subprocess.py:93} INFO - 
[2025-09-08T14:21:46.326+0530] {subprocess.py:93} INFO - [2025-09-08 14:21:46] üîß Activating virtual environment...
[2025-09-08T14:21:46.354+0530] {subprocess.py:93} INFO - [2025-09-08 14:21:46] üîç Checking database connection...
[2025-09-08T14:21:47.527+0530] {subprocess.py:93} INFO - ‚úÖ Database connection successful
[2025-09-08T14:21:47.534+0530] {subprocess.py:93} INFO - [2025-09-08 14:21:47] üîÑ Starting synthetic data stream...
[2025-09-08T14:21:47.534+0530] {subprocess.py:93} INFO - Press Ctrl+C to stop
[2025-09-08T14:21:47.534+0530] {subprocess.py:93} INFO - 
[2025-09-08T14:21:48.355+0530] {subprocess.py:93} INFO - 2025-09-08 14:21:48,355 INFO: Tables ensured/created (if needed).
[2025-09-08T14:21:48.379+0530] {subprocess.py:93} INFO - 2025-09-08 14:21:48,379 INFO: Customers: 1000 already present; skipping seeding.
[2025-09-08T14:21:48.380+0530] {subprocess.py:93} INFO - 2025-09-08 14:21:48,380 INFO: Products: 500 already present; skipping seeding.
[2025-09-08T14:21:48.380+0530] {subprocess.py:93} INFO - 2025-09-08 14:21:48,380 INFO: Running one-shot generation: orders=5000, sessions=3000
[2025-09-08T14:21:48.386+0530] {subprocess.py:93} INFO - /media/softsuave/DATA-HDD/DataEngineering/Apache_Airflow/src/synth_ecom_mssql_stream.py:397: RemovedIn20Warning: Deprecated API features detected! These feature(s) are not compatible with SQLAlchemy 2.0. To prevent incompatible upgrades prior to updating applications, ensure requirements files are pinned to "sqlalchemy<2.0". Set environment variable SQLALCHEMY_WARN_20=1 to show all deprecation warnings.  Set environment variable SQLALCHEMY_SILENCE_UBER_WARNING=1 to silence this message. (Background on SQLAlchemy 2.0 at: https://sqlalche.me/e/b8d9)
[2025-09-08T14:21:48.386+0530] {subprocess.py:93} INFO -   customers = [dict(r) for r in conn.execute(select(self.tables["customers"])).fetchall()]
[2025-09-08T14:21:48.393+0530] {subprocess.py:93} INFO - 2025-09-08 14:21:48,393 INFO: Generating 5000 orders (batch_size=200, force_order_date_now=False)...
[2025-09-08T14:21:48.851+0530] {subprocess.py:93} INFO - 2025-09-08 14:21:48,851 INFO: Flushed batch: orders=200 items=341
[2025-09-08T14:21:48.885+0530] {subprocess.py:93} INFO - 2025-09-08 14:21:48,885 WARNING: Failed to send webhook notification: HTTPConnectionPool(host='localhost', port=5000): Max retries exceeded with url: /webhook (Caused by NewConnectionError('<urllib3.connection.HTTPConnection object at 0x7acc35097280>: Failed to establish a new connection: [Errno 111] Connection refused'))
[2025-09-08T14:21:49.194+0530] {subprocess.py:93} INFO - 2025-09-08 14:21:49,194 INFO: Flushed batch: orders=200 items=349
[2025-09-08T14:21:49.197+0530] {subprocess.py:93} INFO - 2025-09-08 14:21:49,197 WARNING: Failed to send webhook notification: HTTPConnectionPool(host='localhost', port=5000): Max retries exceeded with url: /webhook (Caused by NewConnectionError('<urllib3.connection.HTTPConnection object at 0x7acc35085c90>: Failed to establish a new connection: [Errno 111] Connection refused'))
[2025-09-08T14:21:49.678+0530] {subprocess.py:93} INFO - 2025-09-08 14:21:49,678 INFO: Flushed batch: orders=200 items=329
[2025-09-08T14:21:49.681+0530] {subprocess.py:93} INFO - 2025-09-08 14:21:49,681 WARNING: Failed to send webhook notification: HTTPConnectionPool(host='localhost', port=5000): Max retries exceeded with url: /webhook (Caused by NewConnectionError('<urllib3.connection.HTTPConnection object at 0x7acc34faa680>: Failed to establish a new connection: [Errno 111] Connection refused'))
[2025-09-08T14:21:50.021+0530] {subprocess.py:93} INFO - 2025-09-08 14:21:50,020 INFO: Flushed batch: orders=200 items=342
[2025-09-08T14:21:50.022+0530] {subprocess.py:93} INFO - 2025-09-08 14:21:50,022 WARNING: Failed to send webhook notification: HTTPConnectionPool(host='localhost', port=5000): Max retries exceeded with url: /webhook (Caused by NewConnectionError('<urllib3.connection.HTTPConnection object at 0x7acc34fd7910>: Failed to establish a new connection: [Errno 111] Connection refused'))
[2025-09-08T14:21:50.630+0530] {subprocess.py:93} INFO - 2025-09-08 14:21:50,629 INFO: Flushed batch: orders=200 items=326
[2025-09-08T14:21:50.633+0530] {subprocess.py:93} INFO - 2025-09-08 14:21:50,633 WARNING: Failed to send webhook notification: HTTPConnectionPool(host='localhost', port=5000): Max retries exceeded with url: /webhook (Caused by NewConnectionError('<urllib3.connection.HTTPConnection object at 0x7acc34fe7970>: Failed to establish a new connection: [Errno 111] Connection refused'))
[2025-09-08T14:21:51.246+0530] {subprocess.py:93} INFO - 2025-09-08 14:21:51,246 INFO: Flushed batch: orders=200 items=340
[2025-09-08T14:21:51.247+0530] {subprocess.py:93} INFO - 2025-09-08 14:21:51,247 WARNING: Failed to send webhook notification: HTTPConnectionPool(host='localhost', port=5000): Max retries exceeded with url: /webhook (Caused by NewConnectionError('<urllib3.connection.HTTPConnection object at 0x7acc34e02260>: Failed to establish a new connection: [Errno 111] Connection refused'))
[2025-09-08T14:21:51.633+0530] {subprocess.py:93} INFO - 2025-09-08 14:21:51,632 INFO: Flushed batch: orders=200 items=349
[2025-09-08T14:21:51.636+0530] {subprocess.py:93} INFO - 2025-09-08 14:21:51,636 WARNING: Failed to send webhook notification: HTTPConnectionPool(host='localhost', port=5000): Max retries exceeded with url: /webhook (Caused by NewConnectionError('<urllib3.connection.HTTPConnection object at 0x7acc34fe7280>: Failed to establish a new connection: [Errno 111] Connection refused'))
[2025-09-08T14:21:51.865+0530] {subprocess.py:93} INFO - 2025-09-08 14:21:51,864 INFO: Flushed batch: orders=200 items=326
[2025-09-08T14:21:51.867+0530] {subprocess.py:93} INFO - 2025-09-08 14:21:51,867 WARNING: Failed to send webhook notification: HTTPConnectionPool(host='localhost', port=5000): Max retries exceeded with url: /webhook (Caused by NewConnectionError('<urllib3.connection.HTTPConnection object at 0x7acc34ff9030>: Failed to establish a new connection: [Errno 111] Connection refused'))
[2025-09-08T14:21:52.349+0530] {subprocess.py:93} INFO - 2025-09-08 14:21:52,349 INFO: Flushed batch: orders=200 items=318
[2025-09-08T14:21:52.352+0530] {subprocess.py:93} INFO - 2025-09-08 14:21:52,351 WARNING: Failed to send webhook notification: HTTPConnectionPool(host='localhost', port=5000): Max retries exceeded with url: /webhook (Caused by NewConnectionError('<urllib3.connection.HTTPConnection object at 0x7acc34e17220>: Failed to establish a new connection: [Errno 111] Connection refused'))
[2025-09-08T14:21:52.584+0530] {subprocess.py:93} INFO - 2025-09-08 14:21:52,583 INFO: Flushed batch: orders=200 items=338
[2025-09-08T14:21:52.586+0530] {subprocess.py:93} INFO - 2025-09-08 14:21:52,586 WARNING: Failed to send webhook notification: HTTPConnectionPool(host='localhost', port=5000): Max retries exceeded with url: /webhook (Caused by NewConnectionError('<urllib3.connection.HTTPConnection object at 0x7acc34e177c0>: Failed to establish a new connection: [Errno 111] Connection refused'))
[2025-09-08T14:21:52.785+0530] {subprocess.py:93} INFO - 2025-09-08 14:21:52,784 INFO: Flushed batch: orders=200 items=344
[2025-09-08T14:21:52.787+0530] {subprocess.py:93} INFO - 2025-09-08 14:21:52,787 WARNING: Failed to send webhook notification: HTTPConnectionPool(host='localhost', port=5000): Max retries exceeded with url: /webhook (Caused by NewConnectionError('<urllib3.connection.HTTPConnection object at 0x7acc34e03ee0>: Failed to establish a new connection: [Errno 111] Connection refused'))
[2025-09-08T14:21:53.331+0530] {subprocess.py:93} INFO - 2025-09-08 14:21:53,330 INFO: Flushed batch: orders=200 items=346
[2025-09-08T14:21:53.333+0530] {subprocess.py:93} INFO - 2025-09-08 14:21:53,333 WARNING: Failed to send webhook notification: HTTPConnectionPool(host='localhost', port=5000): Max retries exceeded with url: /webhook (Caused by NewConnectionError('<urllib3.connection.HTTPConnection object at 0x7acc34fe6620>: Failed to establish a new connection: [Errno 111] Connection refused'))
[2025-09-08T14:21:53.545+0530] {subprocess.py:93} INFO - 2025-09-08 14:21:53,544 INFO: Flushed batch: orders=200 items=329
[2025-09-08T14:21:53.547+0530] {subprocess.py:93} INFO - 2025-09-08 14:21:53,547 WARNING: Failed to send webhook notification: HTTPConnectionPool(host='localhost', port=5000): Max retries exceeded with url: /webhook (Caused by NewConnectionError('<urllib3.connection.HTTPConnection object at 0x7acc34ff9db0>: Failed to establish a new connection: [Errno 111] Connection refused'))
[2025-09-08T14:21:54.044+0530] {subprocess.py:93} INFO - 2025-09-08 14:21:54,044 INFO: Flushed batch: orders=200 items=332
[2025-09-08T14:21:54.045+0530] {subprocess.py:93} INFO - 2025-09-08 14:21:54,045 WARNING: Failed to send webhook notification: HTTPConnectionPool(host='localhost', port=5000): Max retries exceeded with url: /webhook (Caused by NewConnectionError('<urllib3.connection.HTTPConnection object at 0x7acc34e15630>: Failed to establish a new connection: [Errno 111] Connection refused'))
[2025-09-08T14:21:54.228+0530] {subprocess.py:93} INFO - 2025-09-08 14:21:54,228 INFO: Flushed batch: orders=200 items=339
[2025-09-08T14:21:54.229+0530] {subprocess.py:93} INFO - 2025-09-08 14:21:54,229 WARNING: Failed to send webhook notification: HTTPConnectionPool(host='localhost', port=5000): Max retries exceeded with url: /webhook (Caused by NewConnectionError('<urllib3.connection.HTTPConnection object at 0x7acc34e28c10>: Failed to establish a new connection: [Errno 111] Connection refused'))
[2025-09-08T14:21:54.437+0530] {subprocess.py:93} INFO - 2025-09-08 14:21:54,437 INFO: Flushed batch: orders=200 items=345
[2025-09-08T14:21:54.438+0530] {subprocess.py:93} INFO - 2025-09-08 14:21:54,438 WARNING: Failed to send webhook notification: HTTPConnectionPool(host='localhost', port=5000): Max retries exceeded with url: /webhook (Caused by NewConnectionError('<urllib3.connection.HTTPConnection object at 0x7acc34faa4d0>: Failed to establish a new connection: [Errno 111] Connection refused'))
[2025-09-08T14:21:54.975+0530] {subprocess.py:93} INFO - 2025-09-08 14:21:54,975 INFO: Flushed batch: orders=200 items=353
[2025-09-08T14:21:54.978+0530] {subprocess.py:93} INFO - 2025-09-08 14:21:54,978 WARNING: Failed to send webhook notification: HTTPConnectionPool(host='localhost', port=5000): Max retries exceeded with url: /webhook (Caused by NewConnectionError('<urllib3.connection.HTTPConnection object at 0x7acc34fe57b0>: Failed to establish a new connection: [Errno 111] Connection refused'))
[2025-09-08T14:21:55.231+0530] {subprocess.py:93} INFO - 2025-09-08 14:21:55,231 INFO: Flushed batch: orders=200 items=349
[2025-09-08T14:21:55.234+0530] {subprocess.py:93} INFO - 2025-09-08 14:21:55,233 WARNING: Failed to send webhook notification: HTTPConnectionPool(host='localhost', port=5000): Max retries exceeded with url: /webhook (Caused by NewConnectionError('<urllib3.connection.HTTPConnection object at 0x7acc34e019c0>: Failed to establish a new connection: [Errno 111] Connection refused'))
[2025-09-08T14:21:55.474+0530] {subprocess.py:93} INFO - 2025-09-08 14:21:55,474 INFO: Flushed batch: orders=200 items=333
[2025-09-08T14:21:55.477+0530] {subprocess.py:93} INFO - 2025-09-08 14:21:55,477 WARNING: Failed to send webhook notification: HTTPConnectionPool(host='localhost', port=5000): Max retries exceeded with url: /webhook (Caused by NewConnectionError('<urllib3.connection.HTTPConnection object at 0x7acc34ffa4a0>: Failed to establish a new connection: [Errno 111] Connection refused'))
[2025-09-08T14:21:55.732+0530] {subprocess.py:93} INFO - 2025-09-08 14:21:55,732 INFO: Flushed batch: orders=200 items=351
[2025-09-08T14:21:55.735+0530] {subprocess.py:93} INFO - 2025-09-08 14:21:55,735 WARNING: Failed to send webhook notification: HTTPConnectionPool(host='localhost', port=5000): Max retries exceeded with url: /webhook (Caused by NewConnectionError('<urllib3.connection.HTTPConnection object at 0x7acc34fe7eb0>: Failed to establish a new connection: [Errno 111] Connection refused'))
[2025-09-08T14:21:55.958+0530] {subprocess.py:93} INFO - 2025-09-08 14:21:55,957 INFO: Flushed batch: orders=200 items=335
[2025-09-08T14:21:55.962+0530] {subprocess.py:93} INFO - 2025-09-08 14:21:55,961 WARNING: Failed to send webhook notification: HTTPConnectionPool(host='localhost', port=5000): Max retries exceeded with url: /webhook (Caused by NewConnectionError('<urllib3.connection.HTTPConnection object at 0x7acc34ff8c10>: Failed to establish a new connection: [Errno 111] Connection refused'))
[2025-09-08T14:21:56.250+0530] {subprocess.py:93} INFO - 2025-09-08 14:21:56,250 INFO: Flushed batch: orders=200 items=332
[2025-09-08T14:21:56.255+0530] {subprocess.py:93} INFO - 2025-09-08 14:21:56,254 WARNING: Failed to send webhook notification: HTTPConnectionPool(host='localhost', port=5000): Max retries exceeded with url: /webhook (Caused by NewConnectionError('<urllib3.connection.HTTPConnection object at 0x7acc3513ea70>: Failed to establish a new connection: [Errno 111] Connection refused'))
[2025-09-08T14:21:56.538+0530] {subprocess.py:93} INFO - 2025-09-08 14:21:56,538 INFO: Flushed batch: orders=200 items=326
[2025-09-08T14:21:56.541+0530] {subprocess.py:93} INFO - 2025-09-08 14:21:56,541 WARNING: Failed to send webhook notification: HTTPConnectionPool(host='localhost', port=5000): Max retries exceeded with url: /webhook (Caused by NewConnectionError('<urllib3.connection.HTTPConnection object at 0x7acc34e45480>: Failed to establish a new connection: [Errno 111] Connection refused'))
[2025-09-08T14:21:56.911+0530] {subprocess.py:93} INFO - 2025-09-08 14:21:56,910 INFO: Flushed batch: orders=200 items=351
[2025-09-08T14:21:56.913+0530] {subprocess.py:93} INFO - 2025-09-08 14:21:56,913 WARNING: Failed to send webhook notification: HTTPConnectionPool(host='localhost', port=5000): Max retries exceeded with url: /webhook (Caused by NewConnectionError('<urllib3.connection.HTTPConnection object at 0x7acc34e2a0e0>: Failed to establish a new connection: [Errno 111] Connection refused'))
[2025-09-08T14:21:57.329+0530] {subprocess.py:93} INFO - 2025-09-08 14:21:57,329 INFO: Flushed batch: orders=200 items=353
[2025-09-08T14:21:57.332+0530] {subprocess.py:93} INFO - 2025-09-08 14:21:57,332 WARNING: Failed to send webhook notification: HTTPConnectionPool(host='localhost', port=5000): Max retries exceeded with url: /webhook (Caused by NewConnectionError('<urllib3.connection.HTTPConnection object at 0x7acc34e01f00>: Failed to establish a new connection: [Errno 111] Connection refused'))
[2025-09-08T14:21:57.332+0530] {subprocess.py:93} INFO - 2025-09-08 14:21:57,332 INFO: Generated 5000 orders
[2025-09-08T14:23:10.088+0530] {subprocess.py:93} INFO - 2025-09-08 14:23:10,088 INFO: Inserted 47962 clickstream events.
[2025-09-08T14:23:10.089+0530] {subprocess.py:93} INFO - 2025-09-08 14:23:10,089 WARNING: Failed to send webhook notification: HTTPConnectionPool(host='localhost', port=5000): Max retries exceeded with url: /webhook (Caused by NewConnectionError('<urllib3.connection.HTTPConnection object at 0x7acc351c2f80>: Failed to establish a new connection: [Errno 111] Connection refused'))
[2025-09-08T14:23:11.188+0530] {subprocess.py:93} INFO - 2025-09-08 14:23:11,187 INFO: Validation done: orphans orders=0 items=0 inventory=0 mismatches=0
[2025-09-08T14:23:11.198+0530] {subprocess.py:93} INFO - 2025-09-08 14:23:11,198 INFO: Integrity report: {'orphan_orders': 0, 'orphan_order_items': 0, 'inventory_orphans': 0, 'order_amount_mismatches': []}
[2025-09-08T14:23:11.230+0530] {subprocess.py:93} INFO - [2025-09-08 14:23:11] ‚úÖ Synthetic data streaming completed successfully!
[2025-09-08T14:23:11.230+0530] {subprocess.py:97} INFO - Command exited with return code 0
[2025-09-08T14:23:11.231+0530] {taskinstance.py:441} INFO - ::group::Post task execution logs
[2025-09-08T14:23:11.489+0530] {taskinstance.py:1206} INFO - Marking task as SUCCESS. dag_id=synth_stream_5min, task_id=run_synth_stream, run_id=scheduled__2025-09-08T08:45:00+00:00, execution_date=20250908T084500, start_date=20250908T085144, end_date=20250908T085311
[2025-09-08T14:23:11.831+0530] {local_task_job_runner.py:243} INFO - Task exited with return code 0
[2025-09-08T14:23:11.848+0530] {taskinstance.py:3503} INFO - 0 downstream tasks scheduled from follow-on schedule check
[2025-09-08T14:23:11.849+0530] {local_task_job_runner.py:222} INFO - ::endgroup::
