[2025-09-08T13:25:02.610+0530] {local_task_job_runner.py:120} INFO - ::group::Pre task execution logs
[2025-09-08T13:25:02.622+0530] {taskinstance.py:2076} INFO - Dependencies all met for dep_context=non-requeueable deps ti=<TaskInstance: synth_stream_5min.run_synth_stream scheduled__2025-09-08T07:50:00+00:00 [queued]>
[2025-09-08T13:25:02.625+0530] {taskinstance.py:2076} INFO - Dependencies all met for dep_context=requeueable deps ti=<TaskInstance: synth_stream_5min.run_synth_stream scheduled__2025-09-08T07:50:00+00:00 [queued]>
[2025-09-08T13:25:02.625+0530] {taskinstance.py:2306} INFO - Starting attempt 1 of 2
[2025-09-08T13:25:02.685+0530] {taskinstance.py:2330} INFO - Executing <Task(BashOperator): run_synth_stream> on 2025-09-08 07:50:00+00:00
[2025-09-08T13:25:02.693+0530] {standard_task_runner.py:64} INFO - Started process 714135 to run task
[2025-09-08T13:25:02.699+0530] {standard_task_runner.py:90} INFO - Running: ['airflow', 'tasks', 'run', 'synth_stream_5min', 'run_synth_stream', 'scheduled__2025-09-08T07:50:00+00:00', '--job-id', '26', '--raw', '--subdir', 'DAGS_FOLDER/ecom_schedules.py', '--cfg-path', '/tmp/tmprmrq937y']
[2025-09-08T13:25:02.701+0530] {standard_task_runner.py:91} INFO - Job 26: Subtask run_synth_stream
[2025-09-08T13:25:02.778+0530] {task_command.py:426} INFO - Running <TaskInstance: synth_stream_5min.run_synth_stream scheduled__2025-09-08T07:50:00+00:00 [running]> on host softsuave-ASUS-EXPERTCENTER-D700ME-D500ME
[2025-09-08T13:25:02.923+0530] {taskinstance.py:2648} INFO - Exporting env vars: AIRFLOW_CTX_DAG_OWNER='airflow' AIRFLOW_CTX_DAG_ID='synth_stream_5min' AIRFLOW_CTX_TASK_ID='run_synth_stream' AIRFLOW_CTX_EXECUTION_DATE='2025-09-08T07:50:00+00:00' AIRFLOW_CTX_TRY_NUMBER='1' AIRFLOW_CTX_DAG_RUN_ID='scheduled__2025-09-08T07:50:00+00:00'
[2025-09-08T13:25:02.925+0530] {taskinstance.py:430} INFO - ::endgroup::
[2025-09-08T13:25:02.926+0530] {subprocess.py:63} INFO - Tmp dir root location: /tmp
[2025-09-08T13:25:02.926+0530] {subprocess.py:75} INFO - Running command: ['/usr/bin/bash', '-c', 'bash /media/softsuave/DATA-HDD/DataEngineering/Apache_Airflow/scripts/synth/run_synth_stream.sh | cat']
[2025-09-08T13:25:02.933+0530] {subprocess.py:86} INFO - Output:
[2025-09-08T13:25:02.970+0530] {subprocess.py:93} INFO - [2025-09-08 13:25:02] üöÄ Starting Synthetic E-commerce Data Stream...
[2025-09-08T13:25:02.970+0530] {subprocess.py:93} INFO - ----------------------------------------------
[2025-09-08T13:25:02.971+0530] {subprocess.py:93} INFO -  Database   : ecom_db
[2025-09-08T13:25:02.971+0530] {subprocess.py:93} INFO -  User       : sa
[2025-09-08T13:25:02.971+0530] {subprocess.py:93} INFO -  Server     : localhost:1433
[2025-09-08T13:25:02.971+0530] {subprocess.py:93} INFO -  Interval   : 5 min
[2025-09-08T13:25:02.971+0530] {subprocess.py:93} INFO -  Orders     : 50
[2025-09-08T13:25:02.971+0530] {subprocess.py:93} INFO -  Clicks     : 100
[2025-09-08T13:25:02.971+0530] {subprocess.py:93} INFO -  Webhook    : http://localhost:5000/webhook
[2025-09-08T13:25:02.971+0530] {subprocess.py:93} INFO - ----------------------------------------------
[2025-09-08T13:25:02.971+0530] {subprocess.py:93} INFO - 
[2025-09-08T13:25:02.991+0530] {subprocess.py:93} INFO - [2025-09-08 13:25:02] üîß Activating virtual environment...
[2025-09-08T13:25:02.993+0530] {subprocess.py:93} INFO - [2025-09-08 13:25:02] üîç Checking database connection...
[2025-09-08T13:25:03.024+0530] {subprocess.py:93} INFO - ‚úÖ Database connection successful
[2025-09-08T13:25:03.030+0530] {subprocess.py:93} INFO - [2025-09-08 13:25:03] üîÑ Starting synthetic data stream...
[2025-09-08T13:25:03.030+0530] {subprocess.py:93} INFO - Press Ctrl+C to stop
[2025-09-08T13:25:03.031+0530] {subprocess.py:93} INFO - 
[2025-09-08T13:25:03.204+0530] {subprocess.py:93} INFO - 2025-09-08 13:25:03,204 INFO: Tables ensured/created (if needed).
[2025-09-08T13:25:03.216+0530] {subprocess.py:93} INFO - 2025-09-08 13:25:03,216 INFO: Customers: 1000 already present; skipping seeding.
[2025-09-08T13:25:03.217+0530] {subprocess.py:93} INFO - 2025-09-08 13:25:03,217 INFO: Products: 500 already present; skipping seeding.
[2025-09-08T13:25:03.218+0530] {subprocess.py:93} INFO - 2025-09-08 13:25:03,217 INFO: Running one-shot generation: orders=5000, sessions=3000
[2025-09-08T13:25:03.224+0530] {subprocess.py:93} INFO - /media/softsuave/DATA-HDD/DataEngineering/Apache_Airflow/src/synth_ecom_mssql_stream.py:397: RemovedIn20Warning: Deprecated API features detected! These feature(s) are not compatible with SQLAlchemy 2.0. To prevent incompatible upgrades prior to updating applications, ensure requirements files are pinned to "sqlalchemy<2.0". Set environment variable SQLALCHEMY_WARN_20=1 to show all deprecation warnings.  Set environment variable SQLALCHEMY_SILENCE_UBER_WARNING=1 to silence this message. (Background on SQLAlchemy 2.0 at: https://sqlalche.me/e/b8d9)
[2025-09-08T13:25:03.224+0530] {subprocess.py:93} INFO -   customers = [dict(r) for r in conn.execute(select(self.tables["customers"])).fetchall()]
[2025-09-08T13:25:03.231+0530] {subprocess.py:93} INFO - 2025-09-08 13:25:03,231 INFO: Generating 5000 orders (batch_size=200, force_order_date_now=False)...
[2025-09-08T13:25:03.540+0530] {subprocess.py:93} INFO - 2025-09-08 13:25:03,540 INFO: Flushed batch: orders=200 items=337
[2025-09-08T13:25:03.543+0530] {subprocess.py:93} INFO - 2025-09-08 13:25:03,543 WARNING: Failed to send webhook notification: HTTPConnectionPool(host='localhost', port=5000): Max retries exceeded with url: /webhook (Caused by NewConnectionError('<urllib3.connection.HTTPConnection object at 0x7fd74161aa70>: Failed to establish a new connection: [Errno 111] Connection refused'))
[2025-09-08T13:25:03.750+0530] {subprocess.py:93} INFO - 2025-09-08 13:25:03,749 INFO: Flushed batch: orders=200 items=334
[2025-09-08T13:25:03.753+0530] {subprocess.py:93} INFO - 2025-09-08 13:25:03,752 WARNING: Failed to send webhook notification: HTTPConnectionPool(host='localhost', port=5000): Max retries exceeded with url: /webhook (Caused by NewConnectionError('<urllib3.connection.HTTPConnection object at 0x7fd7415d0b50>: Failed to establish a new connection: [Errno 111] Connection refused'))
[2025-09-08T13:25:03.942+0530] {subprocess.py:93} INFO - 2025-09-08 13:25:03,941 INFO: Flushed batch: orders=200 items=327
[2025-09-08T13:25:03.945+0530] {subprocess.py:93} INFO - 2025-09-08 13:25:03,945 WARNING: Failed to send webhook notification: HTTPConnectionPool(host='localhost', port=5000): Max retries exceeded with url: /webhook (Caused by NewConnectionError('<urllib3.connection.HTTPConnection object at 0x7fd7415bff10>: Failed to establish a new connection: [Errno 111] Connection refused'))
[2025-09-08T13:25:04.234+0530] {subprocess.py:93} INFO - 2025-09-08 13:25:04,233 INFO: Flushed batch: orders=200 items=354
[2025-09-08T13:25:04.236+0530] {subprocess.py:93} INFO - 2025-09-08 13:25:04,236 WARNING: Failed to send webhook notification: HTTPConnectionPool(host='localhost', port=5000): Max retries exceeded with url: /webhook (Caused by NewConnectionError('<urllib3.connection.HTTPConnection object at 0x7fd7415bd1b0>: Failed to establish a new connection: [Errno 111] Connection refused'))
[2025-09-08T13:25:04.426+0530] {subprocess.py:93} INFO - 2025-09-08 13:25:04,425 INFO: Flushed batch: orders=200 items=323
[2025-09-08T13:25:04.428+0530] {subprocess.py:93} INFO - 2025-09-08 13:25:04,428 WARNING: Failed to send webhook notification: HTTPConnectionPool(host='localhost', port=5000): Max retries exceeded with url: /webhook (Caused by NewConnectionError('<urllib3.connection.HTTPConnection object at 0x7fd7414073a0>: Failed to establish a new connection: [Errno 111] Connection refused'))
[2025-09-08T13:25:04.592+0530] {subprocess.py:93} INFO - 2025-09-08 13:25:04,592 INFO: Flushed batch: orders=200 items=358
[2025-09-08T13:25:04.595+0530] {subprocess.py:93} INFO - 2025-09-08 13:25:04,595 WARNING: Failed to send webhook notification: HTTPConnectionPool(host='localhost', port=5000): Max retries exceeded with url: /webhook (Caused by NewConnectionError('<urllib3.connection.HTTPConnection object at 0x7fd7415f3370>: Failed to establish a new connection: [Errno 111] Connection refused'))
[2025-09-08T13:25:04.776+0530] {subprocess.py:93} INFO - 2025-09-08 13:25:04,775 INFO: Flushed batch: orders=200 items=357
[2025-09-08T13:25:04.778+0530] {subprocess.py:93} INFO - 2025-09-08 13:25:04,777 WARNING: Failed to send webhook notification: HTTPConnectionPool(host='localhost', port=5000): Max retries exceeded with url: /webhook (Caused by NewConnectionError('<urllib3.connection.HTTPConnection object at 0x7fd7415be320>: Failed to establish a new connection: [Errno 111] Connection refused'))
[2025-09-08T13:25:04.967+0530] {subprocess.py:93} INFO - 2025-09-08 13:25:04,967 INFO: Flushed batch: orders=200 items=357
[2025-09-08T13:25:04.968+0530] {subprocess.py:93} INFO - 2025-09-08 13:25:04,968 WARNING: Failed to send webhook notification: HTTPConnectionPool(host='localhost', port=5000): Max retries exceeded with url: /webhook (Caused by NewConnectionError('<urllib3.connection.HTTPConnection object at 0x7fd7414063b0>: Failed to establish a new connection: [Errno 111] Connection refused'))
[2025-09-08T13:25:05.160+0530] {subprocess.py:93} INFO - 2025-09-08 13:25:05,160 INFO: Flushed batch: orders=200 items=359
[2025-09-08T13:25:05.163+0530] {subprocess.py:93} INFO - 2025-09-08 13:25:05,162 WARNING: Failed to send webhook notification: HTTPConnectionPool(host='localhost', port=5000): Max retries exceeded with url: /webhook (Caused by NewConnectionError('<urllib3.connection.HTTPConnection object at 0x7fd741538880>: Failed to establish a new connection: [Errno 111] Connection refused'))
[2025-09-08T13:25:05.418+0530] {subprocess.py:93} INFO - 2025-09-08 13:25:05,418 INFO: Flushed batch: orders=200 items=365
[2025-09-08T13:25:05.420+0530] {subprocess.py:93} INFO - 2025-09-08 13:25:05,419 WARNING: Failed to send webhook notification: HTTPConnectionPool(host='localhost', port=5000): Max retries exceeded with url: /webhook (Caused by NewConnectionError('<urllib3.connection.HTTPConnection object at 0x7fd741422230>: Failed to establish a new connection: [Errno 111] Connection refused'))
[2025-09-08T13:25:05.635+0530] {subprocess.py:93} INFO - 2025-09-08 13:25:05,634 INFO: Flushed batch: orders=200 items=336
[2025-09-08T13:25:05.636+0530] {subprocess.py:93} INFO - 2025-09-08 13:25:05,636 WARNING: Failed to send webhook notification: HTTPConnectionPool(host='localhost', port=5000): Max retries exceeded with url: /webhook (Caused by NewConnectionError('<urllib3.connection.HTTPConnection object at 0x7fd741405210>: Failed to establish a new connection: [Errno 111] Connection refused'))
[2025-09-08T13:25:05.818+0530] {subprocess.py:93} INFO - 2025-09-08 13:25:05,818 INFO: Flushed batch: orders=200 items=327
[2025-09-08T13:25:05.819+0530] {subprocess.py:93} INFO - 2025-09-08 13:25:05,819 WARNING: Failed to send webhook notification: HTTPConnectionPool(host='localhost', port=5000): Max retries exceeded with url: /webhook (Caused by NewConnectionError('<urllib3.connection.HTTPConnection object at 0x7fd7414308e0>: Failed to establish a new connection: [Errno 111] Connection refused'))
[2025-09-08T13:25:05.994+0530] {subprocess.py:93} INFO - 2025-09-08 13:25:05,993 INFO: Flushed batch: orders=200 items=365
[2025-09-08T13:25:05.996+0530] {subprocess.py:93} INFO - 2025-09-08 13:25:05,996 WARNING: Failed to send webhook notification: HTTPConnectionPool(host='localhost', port=5000): Max retries exceeded with url: /webhook (Caused by NewConnectionError('<urllib3.connection.HTTPConnection object at 0x7fd7415be320>: Failed to establish a new connection: [Errno 111] Connection refused'))
[2025-09-08T13:25:06.160+0530] {subprocess.py:93} INFO - 2025-09-08 13:25:06,160 INFO: Flushed batch: orders=200 items=349
[2025-09-08T13:25:06.163+0530] {subprocess.py:93} INFO - 2025-09-08 13:25:06,163 WARNING: Failed to send webhook notification: HTTPConnectionPool(host='localhost', port=5000): Max retries exceeded with url: /webhook (Caused by NewConnectionError('<urllib3.connection.HTTPConnection object at 0x7fd741421510>: Failed to establish a new connection: [Errno 111] Connection refused'))
[2025-09-08T13:25:06.386+0530] {subprocess.py:93} INFO - 2025-09-08 13:25:06,386 INFO: Flushed batch: orders=200 items=334
[2025-09-08T13:25:06.388+0530] {subprocess.py:93} INFO - 2025-09-08 13:25:06,388 WARNING: Failed to send webhook notification: HTTPConnectionPool(host='localhost', port=5000): Max retries exceeded with url: /webhook (Caused by NewConnectionError('<urllib3.connection.HTTPConnection object at 0x7fd74144d600>: Failed to establish a new connection: [Errno 111] Connection refused'))
[2025-09-08T13:25:06.620+0530] {subprocess.py:93} INFO - 2025-09-08 13:25:06,620 INFO: Flushed batch: orders=200 items=350
[2025-09-08T13:25:06.624+0530] {subprocess.py:93} INFO - 2025-09-08 13:25:06,624 WARNING: Failed to send webhook notification: HTTPConnectionPool(host='localhost', port=5000): Max retries exceeded with url: /webhook (Caused by NewConnectionError('<urllib3.connection.HTTPConnection object at 0x7fd74144d090>: Failed to establish a new connection: [Errno 111] Connection refused'))
[2025-09-08T13:25:06.862+0530] {subprocess.py:93} INFO - 2025-09-08 13:25:06,862 INFO: Flushed batch: orders=200 items=362
[2025-09-08T13:25:06.866+0530] {subprocess.py:93} INFO - 2025-09-08 13:25:06,866 WARNING: Failed to send webhook notification: HTTPConnectionPool(host='localhost', port=5000): Max retries exceeded with url: /webhook (Caused by NewConnectionError('<urllib3.connection.HTTPConnection object at 0x7fd741421a50>: Failed to establish a new connection: [Errno 111] Connection refused'))
[2025-09-08T13:25:07.037+0530] {subprocess.py:93} INFO - 2025-09-08 13:25:07,036 INFO: Flushed batch: orders=200 items=343
[2025-09-08T13:25:07.038+0530] {subprocess.py:93} INFO - 2025-09-08 13:25:07,038 WARNING: Failed to send webhook notification: HTTPConnectionPool(host='localhost', port=5000): Max retries exceeded with url: /webhook (Caused by NewConnectionError('<urllib3.connection.HTTPConnection object at 0x7fd7414302b0>: Failed to establish a new connection: [Errno 111] Connection refused'))
[2025-09-08T13:25:07.212+0530] {subprocess.py:93} INFO - 2025-09-08 13:25:07,212 INFO: Flushed batch: orders=200 items=371
[2025-09-08T13:25:07.214+0530] {subprocess.py:93} INFO - 2025-09-08 13:25:07,214 WARNING: Failed to send webhook notification: HTTPConnectionPool(host='localhost', port=5000): Max retries exceeded with url: /webhook (Caused by NewConnectionError('<urllib3.connection.HTTPConnection object at 0x7fd7414328c0>: Failed to establish a new connection: [Errno 111] Connection refused'))
[2025-09-08T13:25:07.447+0530] {subprocess.py:93} INFO - 2025-09-08 13:25:07,446 INFO: Flushed batch: orders=200 items=352
[2025-09-08T13:25:07.450+0530] {subprocess.py:93} INFO - 2025-09-08 13:25:07,450 WARNING: Failed to send webhook notification: HTTPConnectionPool(host='localhost', port=5000): Max retries exceeded with url: /webhook (Caused by NewConnectionError('<urllib3.connection.HTTPConnection object at 0x7fd74144f1c0>: Failed to establish a new connection: [Errno 111] Connection refused'))
[2025-09-08T13:25:07.663+0530] {subprocess.py:93} INFO - 2025-09-08 13:25:07,662 INFO: Flushed batch: orders=200 items=369
[2025-09-08T13:25:07.665+0530] {subprocess.py:93} INFO - 2025-09-08 13:25:07,665 WARNING: Failed to send webhook notification: HTTPConnectionPool(host='localhost', port=5000): Max retries exceeded with url: /webhook (Caused by NewConnectionError('<urllib3.connection.HTTPConnection object at 0x7fd7414303d0>: Failed to establish a new connection: [Errno 111] Connection refused'))
[2025-09-08T13:25:07.922+0530] {subprocess.py:93} INFO - 2025-09-08 13:25:07,922 INFO: Flushed batch: orders=200 items=348
[2025-09-08T13:25:07.925+0530] {subprocess.py:93} INFO - 2025-09-08 13:25:07,925 WARNING: Failed to send webhook notification: HTTPConnectionPool(host='localhost', port=5000): Max retries exceeded with url: /webhook (Caused by NewConnectionError('<urllib3.connection.HTTPConnection object at 0x7fd7414667d0>: Failed to establish a new connection: [Errno 111] Connection refused'))
[2025-09-08T13:25:08.213+0530] {subprocess.py:93} INFO - 2025-09-08 13:25:08,213 INFO: Flushed batch: orders=200 items=364
[2025-09-08T13:25:08.216+0530] {subprocess.py:93} INFO - 2025-09-08 13:25:08,216 WARNING: Failed to send webhook notification: HTTPConnectionPool(host='localhost', port=5000): Max retries exceeded with url: /webhook (Caused by NewConnectionError('<urllib3.connection.HTTPConnection object at 0x7fd74147bc10>: Failed to establish a new connection: [Errno 111] Connection refused'))
[2025-09-08T13:25:08.438+0530] {subprocess.py:93} INFO - 2025-09-08 13:25:08,438 INFO: Flushed batch: orders=200 items=365
[2025-09-08T13:25:08.439+0530] {subprocess.py:93} INFO - 2025-09-08 13:25:08,439 WARNING: Failed to send webhook notification: HTTPConnectionPool(host='localhost', port=5000): Max retries exceeded with url: /webhook (Caused by NewConnectionError('<urllib3.connection.HTTPConnection object at 0x7fd7415f3190>: Failed to establish a new connection: [Errno 111] Connection refused'))
[2025-09-08T13:25:08.622+0530] {subprocess.py:93} INFO - 2025-09-08 13:25:08,621 INFO: Flushed batch: orders=200 items=322
[2025-09-08T13:25:08.623+0530] {subprocess.py:93} INFO - 2025-09-08 13:25:08,622 WARNING: Failed to send webhook notification: HTTPConnectionPool(host='localhost', port=5000): Max retries exceeded with url: /webhook (Caused by NewConnectionError('<urllib3.connection.HTTPConnection object at 0x7fd741407640>: Failed to establish a new connection: [Errno 111] Connection refused'))
[2025-09-08T13:25:08.623+0530] {subprocess.py:93} INFO - 2025-09-08 13:25:08,623 INFO: Generated 5000 orders
[2025-09-08T13:25:30.621+0530] {subprocess.py:93} INFO - 2025-09-08 13:25:30,621 INFO: Inserted 48289 clickstream events.
[2025-09-08T13:25:30.622+0530] {subprocess.py:93} INFO - 2025-09-08 13:25:30,622 WARNING: Failed to send webhook notification: HTTPConnectionPool(host='localhost', port=5000): Max retries exceeded with url: /webhook (Caused by NewConnectionError('<urllib3.connection.HTTPConnection object at 0x7fd7402e2560>: Failed to establish a new connection: [Errno 111] Connection refused'))
[2025-09-08T13:25:31.317+0530] {subprocess.py:93} INFO - 2025-09-08 13:25:31,316 INFO: Validation done: orphans orders=0 items=0 inventory=0 mismatches=0
[2025-09-08T13:25:31.319+0530] {subprocess.py:93} INFO - 2025-09-08 13:25:31,319 INFO: Integrity report: {'orphan_orders': 0, 'orphan_order_items': 0, 'inventory_orphans': 0, 'order_amount_mismatches': []}
[2025-09-08T13:25:31.349+0530] {subprocess.py:93} INFO - [2025-09-08 13:25:31] ‚úÖ Synthetic data streaming completed successfully!
[2025-09-08T13:25:31.349+0530] {subprocess.py:97} INFO - Command exited with return code 0
[2025-09-08T13:25:31.349+0530] {taskinstance.py:441} INFO - ::group::Post task execution logs
[2025-09-08T13:25:31.596+0530] {taskinstance.py:1206} INFO - Marking task as SUCCESS. dag_id=synth_stream_5min, task_id=run_synth_stream, run_id=scheduled__2025-09-08T07:50:00+00:00, execution_date=20250908T075000, start_date=20250908T075502, end_date=20250908T075531
[2025-09-08T13:25:31.889+0530] {local_task_job_runner.py:243} INFO - Task exited with return code 0
[2025-09-08T13:25:31.903+0530] {taskinstance.py:3503} INFO - 0 downstream tasks scheduled from follow-on schedule check
[2025-09-08T13:25:31.903+0530] {local_task_job_runner.py:222} INFO - ::endgroup::
