[2025-09-08T14:04:20.900+0530] {local_task_job_runner.py:120} INFO - ::group::Pre task execution logs
[2025-09-08T14:04:21.027+0530] {taskinstance.py:2076} INFO - Dependencies all met for dep_context=non-requeueable deps ti=<TaskInstance: synth_stream_5min.run_synth_stream scheduled__2025-09-08T08:25:00+00:00 [queued]>
[2025-09-08T14:04:21.030+0530] {taskinstance.py:2076} INFO - Dependencies all met for dep_context=requeueable deps ti=<TaskInstance: synth_stream_5min.run_synth_stream scheduled__2025-09-08T08:25:00+00:00 [queued]>
[2025-09-08T14:04:21.030+0530] {taskinstance.py:2306} INFO - Starting attempt 1 of 2
[2025-09-08T14:04:21.126+0530] {taskinstance.py:2330} INFO - Executing <Task(BashOperator): run_synth_stream> on 2025-09-08 08:25:00+00:00
[2025-09-08T14:04:21.134+0530] {standard_task_runner.py:64} INFO - Started process 725590 to run task
[2025-09-08T14:04:21.140+0530] {standard_task_runner.py:90} INFO - Running: ['airflow', 'tasks', 'run', 'synth_stream_5min', 'run_synth_stream', 'scheduled__2025-09-08T08:25:00+00:00', '--job-id', '38', '--raw', '--subdir', 'DAGS_FOLDER/ecom_schedules.py', '--cfg-path', '/tmp/tmpgo7_5p4h']
[2025-09-08T14:04:21.144+0530] {standard_task_runner.py:91} INFO - Job 38: Subtask run_synth_stream
[2025-09-08T14:04:21.232+0530] {task_command.py:426} INFO - Running <TaskInstance: synth_stream_5min.run_synth_stream scheduled__2025-09-08T08:25:00+00:00 [running]> on host softsuave-ASUS-EXPERTCENTER-D700ME-D500ME
[2025-09-08T14:04:21.455+0530] {taskinstance.py:2648} INFO - Exporting env vars: AIRFLOW_CTX_DAG_OWNER='airflow' AIRFLOW_CTX_DAG_ID='synth_stream_5min' AIRFLOW_CTX_TASK_ID='run_synth_stream' AIRFLOW_CTX_EXECUTION_DATE='2025-09-08T08:25:00+00:00' AIRFLOW_CTX_TRY_NUMBER='1' AIRFLOW_CTX_DAG_RUN_ID='scheduled__2025-09-08T08:25:00+00:00'
[2025-09-08T14:04:21.457+0530] {taskinstance.py:430} INFO - ::endgroup::
[2025-09-08T14:04:21.457+0530] {subprocess.py:63} INFO - Tmp dir root location: /tmp
[2025-09-08T14:04:21.458+0530] {subprocess.py:75} INFO - Running command: ['/usr/bin/bash', '-c', 'bash /media/softsuave/DATA-HDD/DataEngineering/Apache_Airflow/scripts/synth/run_synth_stream.sh | cat']
[2025-09-08T14:04:21.466+0530] {subprocess.py:86} INFO - Output:
[2025-09-08T14:04:21.559+0530] {subprocess.py:93} INFO - [2025-09-08 14:04:21] üöÄ Starting Synthetic E-commerce Data Stream...
[2025-09-08T14:04:21.559+0530] {subprocess.py:93} INFO - ----------------------------------------------
[2025-09-08T14:04:21.560+0530] {subprocess.py:93} INFO -  Database   : ecom_db
[2025-09-08T14:04:21.560+0530] {subprocess.py:93} INFO -  User       : sa
[2025-09-08T14:04:21.560+0530] {subprocess.py:93} INFO -  Server     : localhost:1433
[2025-09-08T14:04:21.560+0530] {subprocess.py:93} INFO -  Interval   : 5 min
[2025-09-08T14:04:21.560+0530] {subprocess.py:93} INFO -  Orders     : 50
[2025-09-08T14:04:21.560+0530] {subprocess.py:93} INFO -  Clicks     : 100
[2025-09-08T14:04:21.560+0530] {subprocess.py:93} INFO -  Webhook    : http://localhost:5000/webhook
[2025-09-08T14:04:21.560+0530] {subprocess.py:93} INFO - ----------------------------------------------
[2025-09-08T14:04:21.560+0530] {subprocess.py:93} INFO - 
[2025-09-08T14:04:21.679+0530] {subprocess.py:93} INFO - [2025-09-08 14:04:21] üîß Activating virtual environment...
[2025-09-08T14:04:21.732+0530] {subprocess.py:93} INFO - [2025-09-08 14:04:21] üîç Checking database connection...
[2025-09-08T14:04:22.271+0530] {subprocess.py:93} INFO - ‚úÖ Database connection successful
[2025-09-08T14:04:22.288+0530] {subprocess.py:93} INFO - [2025-09-08 14:04:22] üîÑ Starting synthetic data stream...
[2025-09-08T14:04:22.288+0530] {subprocess.py:93} INFO - Press Ctrl+C to stop
[2025-09-08T14:04:22.289+0530] {subprocess.py:93} INFO - 
[2025-09-08T14:04:22.923+0530] {subprocess.py:93} INFO - 2025-09-08 14:04:22,923 INFO: Tables ensured/created (if needed).
[2025-09-08T14:04:22.986+0530] {subprocess.py:93} INFO - 2025-09-08 14:04:22,986 INFO: Customers: 1000 already present; skipping seeding.
[2025-09-08T14:04:22.989+0530] {subprocess.py:93} INFO - 2025-09-08 14:04:22,988 INFO: Products: 500 already present; skipping seeding.
[2025-09-08T14:04:22.989+0530] {subprocess.py:93} INFO - 2025-09-08 14:04:22,989 INFO: Running one-shot generation: orders=5000, sessions=3000
[2025-09-08T14:04:22.999+0530] {subprocess.py:93} INFO - /media/softsuave/DATA-HDD/DataEngineering/Apache_Airflow/src/synth_ecom_mssql_stream.py:397: RemovedIn20Warning: Deprecated API features detected! These feature(s) are not compatible with SQLAlchemy 2.0. To prevent incompatible upgrades prior to updating applications, ensure requirements files are pinned to "sqlalchemy<2.0". Set environment variable SQLALCHEMY_WARN_20=1 to show all deprecation warnings.  Set environment variable SQLALCHEMY_SILENCE_UBER_WARNING=1 to silence this message. (Background on SQLAlchemy 2.0 at: https://sqlalche.me/e/b8d9)
[2025-09-08T14:04:22.999+0530] {subprocess.py:93} INFO -   customers = [dict(r) for r in conn.execute(select(self.tables["customers"])).fetchall()]
[2025-09-08T14:04:23.006+0530] {subprocess.py:93} INFO - 2025-09-08 14:04:23,006 INFO: Generating 5000 orders (batch_size=200, force_order_date_now=False)...
[2025-09-08T14:04:23.492+0530] {subprocess.py:93} INFO - 2025-09-08 14:04:23,491 INFO: Flushed batch: orders=200 items=333
[2025-09-08T14:04:23.497+0530] {subprocess.py:93} INFO - 2025-09-08 14:04:23,497 WARNING: Failed to send webhook notification: HTTPConnectionPool(host='localhost', port=5000): Max retries exceeded with url: /webhook (Caused by NewConnectionError('<urllib3.connection.HTTPConnection object at 0x7ee613c7fa30>: Failed to establish a new connection: [Errno 111] Connection refused'))
[2025-09-08T14:04:23.701+0530] {subprocess.py:93} INFO - 2025-09-08 14:04:23,700 INFO: Flushed batch: orders=200 items=374
[2025-09-08T14:04:23.703+0530] {subprocess.py:93} INFO - 2025-09-08 14:04:23,703 WARNING: Failed to send webhook notification: HTTPConnectionPool(host='localhost', port=5000): Max retries exceeded with url: /webhook (Caused by NewConnectionError('<urllib3.connection.HTTPConnection object at 0x7ee613b67220>: Failed to establish a new connection: [Errno 111] Connection refused'))
[2025-09-08T14:04:23.917+0530] {subprocess.py:93} INFO - 2025-09-08 14:04:23,917 INFO: Flushed batch: orders=200 items=327
[2025-09-08T14:04:23.920+0530] {subprocess.py:93} INFO - 2025-09-08 14:04:23,920 WARNING: Failed to send webhook notification: HTTPConnectionPool(host='localhost', port=5000): Max retries exceeded with url: /webhook (Caused by NewConnectionError('<urllib3.connection.HTTPConnection object at 0x7ee613ba2da0>: Failed to establish a new connection: [Errno 111] Connection refused'))
[2025-09-08T14:04:24.168+0530] {subprocess.py:93} INFO - 2025-09-08 14:04:24,168 INFO: Flushed batch: orders=200 items=319
[2025-09-08T14:04:24.171+0530] {subprocess.py:93} INFO - 2025-09-08 14:04:24,170 WARNING: Failed to send webhook notification: HTTPConnectionPool(host='localhost', port=5000): Max retries exceeded with url: /webhook (Caused by NewConnectionError('<urllib3.connection.HTTPConnection object at 0x7ee613bb6200>: Failed to establish a new connection: [Errno 111] Connection refused'))
[2025-09-08T14:04:24.377+0530] {subprocess.py:93} INFO - 2025-09-08 14:04:24,377 INFO: Flushed batch: orders=200 items=356
[2025-09-08T14:04:24.380+0530] {subprocess.py:93} INFO - 2025-09-08 14:04:24,379 WARNING: Failed to send webhook notification: HTTPConnectionPool(host='localhost', port=5000): Max retries exceeded with url: /webhook (Caused by NewConnectionError('<urllib3.connection.HTTPConnection object at 0x7ee613bdbc10>: Failed to establish a new connection: [Errno 111] Connection refused'))
[2025-09-08T14:04:24.844+0530] {subprocess.py:93} INFO - 2025-09-08 14:04:24,844 INFO: Flushed batch: orders=200 items=340
[2025-09-08T14:04:24.846+0530] {subprocess.py:93} INFO - 2025-09-08 14:04:24,846 WARNING: Failed to send webhook notification: HTTPConnectionPool(host='localhost', port=5000): Max retries exceeded with url: /webhook (Caused by NewConnectionError('<urllib3.connection.HTTPConnection object at 0x7ee613ba1390>: Failed to establish a new connection: [Errno 111] Connection refused'))
[2025-09-08T14:04:25.053+0530] {subprocess.py:93} INFO - 2025-09-08 14:04:25,053 INFO: Flushed batch: orders=200 items=329
[2025-09-08T14:04:25.056+0530] {subprocess.py:93} INFO - 2025-09-08 14:04:25,056 WARNING: Failed to send webhook notification: HTTPConnectionPool(host='localhost', port=5000): Max retries exceeded with url: /webhook (Caused by NewConnectionError('<urllib3.connection.HTTPConnection object at 0x7ee613bdab30>: Failed to establish a new connection: [Errno 111] Connection refused'))
[2025-09-08T14:04:25.347+0530] {subprocess.py:93} INFO - 2025-09-08 14:04:25,346 INFO: Flushed batch: orders=200 items=331
[2025-09-08T14:04:25.349+0530] {subprocess.py:93} INFO - 2025-09-08 14:04:25,349 WARNING: Failed to send webhook notification: HTTPConnectionPool(host='localhost', port=5000): Max retries exceeded with url: /webhook (Caused by NewConnectionError('<urllib3.connection.HTTPConnection object at 0x7ee613bdb910>: Failed to establish a new connection: [Errno 111] Connection refused'))
[2025-09-08T14:04:25.689+0530] {subprocess.py:93} INFO - 2025-09-08 14:04:25,689 INFO: Flushed batch: orders=200 items=351
[2025-09-08T14:04:25.691+0530] {subprocess.py:93} INFO - 2025-09-08 14:04:25,691 WARNING: Failed to send webhook notification: HTTPConnectionPool(host='localhost', port=5000): Max retries exceeded with url: /webhook (Caused by NewConnectionError('<urllib3.connection.HTTPConnection object at 0x7ee613b56710>: Failed to establish a new connection: [Errno 111] Connection refused'))
[2025-09-08T14:04:25.956+0530] {subprocess.py:93} INFO - 2025-09-08 14:04:25,956 INFO: Flushed batch: orders=200 items=338
[2025-09-08T14:04:25.960+0530] {subprocess.py:93} INFO - 2025-09-08 14:04:25,959 WARNING: Failed to send webhook notification: HTTPConnectionPool(host='localhost', port=5000): Max retries exceeded with url: /webhook (Caused by NewConnectionError('<urllib3.connection.HTTPConnection object at 0x7ee613bf5c00>: Failed to establish a new connection: [Errno 111] Connection refused'))
[2025-09-08T14:04:26.607+0530] {subprocess.py:93} INFO - 2025-09-08 14:04:26,607 INFO: Flushed batch: orders=200 items=353
[2025-09-08T14:04:26.610+0530] {subprocess.py:93} INFO - 2025-09-08 14:04:26,610 WARNING: Failed to send webhook notification: HTTPConnectionPool(host='localhost', port=5000): Max retries exceeded with url: /webhook (Caused by NewConnectionError('<urllib3.connection.HTTPConnection object at 0x7ee613b553c0>: Failed to establish a new connection: [Errno 111] Connection refused'))
[2025-09-08T14:04:26.850+0530] {subprocess.py:93} INFO - 2025-09-08 14:04:26,849 INFO: Flushed batch: orders=200 items=364
[2025-09-08T14:04:26.852+0530] {subprocess.py:93} INFO - 2025-09-08 14:04:26,852 WARNING: Failed to send webhook notification: HTTPConnectionPool(host='localhost', port=5000): Max retries exceeded with url: /webhook (Caused by NewConnectionError('<urllib3.connection.HTTPConnection object at 0x7ee613b54d90>: Failed to establish a new connection: [Errno 111] Connection refused'))
[2025-09-08T14:04:27.092+0530] {subprocess.py:93} INFO - 2025-09-08 14:04:27,091 INFO: Flushed batch: orders=200 items=348
[2025-09-08T14:04:27.094+0530] {subprocess.py:93} INFO - 2025-09-08 14:04:27,094 WARNING: Failed to send webhook notification: HTTPConnectionPool(host='localhost', port=5000): Max retries exceeded with url: /webhook (Caused by NewConnectionError('<urllib3.connection.HTTPConnection object at 0x7ee613bf4c40>: Failed to establish a new connection: [Errno 111] Connection refused'))
[2025-09-08T14:04:27.643+0530] {subprocess.py:93} INFO - 2025-09-08 14:04:27,642 INFO: Flushed batch: orders=200 items=377
[2025-09-08T14:04:27.645+0530] {subprocess.py:93} INFO - 2025-09-08 14:04:27,645 WARNING: Failed to send webhook notification: HTTPConnectionPool(host='localhost', port=5000): Max retries exceeded with url: /webhook (Caused by NewConnectionError('<urllib3.connection.HTTPConnection object at 0x7ee613b57bb0>: Failed to establish a new connection: [Errno 111] Connection refused'))
[2025-09-08T14:04:27.825+0530] {subprocess.py:93} INFO - 2025-09-08 14:04:27,825 INFO: Flushed batch: orders=200 items=320
[2025-09-08T14:04:27.827+0530] {subprocess.py:93} INFO - 2025-09-08 14:04:27,827 WARNING: Failed to send webhook notification: HTTPConnectionPool(host='localhost', port=5000): Max retries exceeded with url: /webhook (Caused by NewConnectionError('<urllib3.connection.HTTPConnection object at 0x7ee613bdb370>: Failed to establish a new connection: [Errno 111] Connection refused'))
[2025-09-08T14:04:28.277+0530] {subprocess.py:93} INFO - 2025-09-08 14:04:28,277 INFO: Flushed batch: orders=200 items=321
[2025-09-08T14:04:28.280+0530] {subprocess.py:93} INFO - 2025-09-08 14:04:28,279 WARNING: Failed to send webhook notification: HTTPConnectionPool(host='localhost', port=5000): Max retries exceeded with url: /webhook (Caused by NewConnectionError('<urllib3.connection.HTTPConnection object at 0x7ee613a27ac0>: Failed to establish a new connection: [Errno 111] Connection refused'))
[2025-09-08T14:04:28.639+0530] {subprocess.py:93} INFO - 2025-09-08 14:04:28,639 INFO: Flushed batch: orders=200 items=353
[2025-09-08T14:04:28.642+0530] {subprocess.py:93} INFO - 2025-09-08 14:04:28,642 WARNING: Failed to send webhook notification: HTTPConnectionPool(host='localhost', port=5000): Max retries exceeded with url: /webhook (Caused by NewConnectionError('<urllib3.connection.HTTPConnection object at 0x7ee613b56260>: Failed to establish a new connection: [Errno 111] Connection refused'))
[2025-09-08T14:04:28.869+0530] {subprocess.py:93} INFO - 2025-09-08 14:04:28,869 INFO: Flushed batch: orders=200 items=367
[2025-09-08T14:04:28.872+0530] {subprocess.py:93} INFO - 2025-09-08 14:04:28,872 WARNING: Failed to send webhook notification: HTTPConnectionPool(host='localhost', port=5000): Max retries exceeded with url: /webhook (Caused by NewConnectionError('<urllib3.connection.HTTPConnection object at 0x7ee613a407f0>: Failed to establish a new connection: [Errno 111] Connection refused'))
[2025-09-08T14:04:29.435+0530] {subprocess.py:93} INFO - 2025-09-08 14:04:29,435 INFO: Flushed batch: orders=200 items=342
[2025-09-08T14:04:29.438+0530] {subprocess.py:93} INFO - 2025-09-08 14:04:29,438 WARNING: Failed to send webhook notification: HTTPConnectionPool(host='localhost', port=5000): Max retries exceeded with url: /webhook (Caused by NewConnectionError('<urllib3.connection.HTTPConnection object at 0x7ee613b55030>: Failed to establish a new connection: [Errno 111] Connection refused'))
[2025-09-08T14:04:29.639+0530] {subprocess.py:93} INFO - 2025-09-08 14:04:29,638 INFO: Flushed batch: orders=200 items=347
[2025-09-08T14:04:29.642+0530] {subprocess.py:93} INFO - 2025-09-08 14:04:29,642 WARNING: Failed to send webhook notification: HTTPConnectionPool(host='localhost', port=5000): Max retries exceeded with url: /webhook (Caused by NewConnectionError('<urllib3.connection.HTTPConnection object at 0x7ee613b56800>: Failed to establish a new connection: [Errno 111] Connection refused'))
[2025-09-08T14:04:29.948+0530] {subprocess.py:93} INFO - 2025-09-08 14:04:29,948 INFO: Flushed batch: orders=200 items=374
[2025-09-08T14:04:29.951+0530] {subprocess.py:93} INFO - 2025-09-08 14:04:29,951 WARNING: Failed to send webhook notification: HTTPConnectionPool(host='localhost', port=5000): Max retries exceeded with url: /webhook (Caused by NewConnectionError('<urllib3.connection.HTTPConnection object at 0x7ee613a27c70>: Failed to establish a new connection: [Errno 111] Connection refused'))
[2025-09-08T14:04:30.183+0530] {subprocess.py:93} INFO - 2025-09-08 14:04:30,183 INFO: Flushed batch: orders=200 items=333
[2025-09-08T14:04:30.187+0530] {subprocess.py:93} INFO - 2025-09-08 14:04:30,187 WARNING: Failed to send webhook notification: HTTPConnectionPool(host='localhost', port=5000): Max retries exceeded with url: /webhook (Caused by NewConnectionError('<urllib3.connection.HTTPConnection object at 0x7ee613b57be0>: Failed to establish a new connection: [Errno 111] Connection refused'))
[2025-09-08T14:04:30.516+0530] {subprocess.py:93} INFO - 2025-09-08 14:04:30,515 INFO: Flushed batch: orders=200 items=358
[2025-09-08T14:04:30.518+0530] {subprocess.py:93} INFO - 2025-09-08 14:04:30,518 WARNING: Failed to send webhook notification: HTTPConnectionPool(host='localhost', port=5000): Max retries exceeded with url: /webhook (Caused by NewConnectionError('<urllib3.connection.HTTPConnection object at 0x7ee613dfd510>: Failed to establish a new connection: [Errno 111] Connection refused'))
[2025-09-08T14:04:30.741+0530] {subprocess.py:93} INFO - 2025-09-08 14:04:30,741 INFO: Flushed batch: orders=200 items=361
[2025-09-08T14:04:30.744+0530] {subprocess.py:93} INFO - 2025-09-08 14:04:30,744 WARNING: Failed to send webhook notification: HTTPConnectionPool(host='localhost', port=5000): Max retries exceeded with url: /webhook (Caused by NewConnectionError('<urllib3.connection.HTTPConnection object at 0x7ee613bd8e20>: Failed to establish a new connection: [Errno 111] Connection refused'))
[2025-09-08T14:04:30.966+0530] {subprocess.py:93} INFO - 2025-09-08 14:04:30,966 INFO: Flushed batch: orders=200 items=348
[2025-09-08T14:04:30.969+0530] {subprocess.py:93} INFO - 2025-09-08 14:04:30,969 WARNING: Failed to send webhook notification: HTTPConnectionPool(host='localhost', port=5000): Max retries exceeded with url: /webhook (Caused by NewConnectionError('<urllib3.connection.HTTPConnection object at 0x7ee613d9b910>: Failed to establish a new connection: [Errno 111] Connection refused'))
[2025-09-08T14:04:30.969+0530] {subprocess.py:93} INFO - 2025-09-08 14:04:30,969 INFO: Generated 5000 orders
[2025-09-08T14:05:30.236+0530] {subprocess.py:93} INFO - 2025-09-08 14:05:30,236 INFO: Inserted 48280 clickstream events.
[2025-09-08T14:05:30.237+0530] {subprocess.py:93} INFO - 2025-09-08 14:05:30,237 WARNING: Failed to send webhook notification: HTTPConnectionPool(host='localhost', port=5000): Max retries exceeded with url: /webhook (Caused by NewConnectionError('<urllib3.connection.HTTPConnection object at 0x7ee6143d21d0>: Failed to establish a new connection: [Errno 111] Connection refused'))
[2025-09-08T14:05:31.648+0530] {subprocess.py:93} INFO - 2025-09-08 14:05:31,648 INFO: Validation done: orphans orders=0 items=0 inventory=0 mismatches=0
[2025-09-08T14:05:31.656+0530] {subprocess.py:93} INFO - 2025-09-08 14:05:31,655 INFO: Integrity report: {'orphan_orders': 0, 'orphan_order_items': 0, 'inventory_orphans': 0, 'order_amount_mismatches': []}
[2025-09-08T14:05:31.686+0530] {subprocess.py:93} INFO - [2025-09-08 14:05:31] ‚úÖ Synthetic data streaming completed successfully!
[2025-09-08T14:05:31.686+0530] {subprocess.py:97} INFO - Command exited with return code 0
[2025-09-08T14:05:31.686+0530] {taskinstance.py:441} INFO - ::group::Post task execution logs
[2025-09-08T14:05:31.928+0530] {taskinstance.py:1206} INFO - Marking task as SUCCESS. dag_id=synth_stream_5min, task_id=run_synth_stream, run_id=scheduled__2025-09-08T08:25:00+00:00, execution_date=20250908T082500, start_date=20250908T083421, end_date=20250908T083531
[2025-09-08T14:05:32.236+0530] {local_task_job_runner.py:243} INFO - Task exited with return code 0
[2025-09-08T14:05:32.246+0530] {taskinstance.py:3503} INFO - 0 downstream tasks scheduled from follow-on schedule check
[2025-09-08T14:05:32.246+0530] {local_task_job_runner.py:222} INFO - ::endgroup::
