[2025-09-08T14:12:48.384+0530] {local_task_job_runner.py:120} INFO - ::group::Pre task execution logs
[2025-09-08T14:12:48.397+0530] {taskinstance.py:2076} INFO - Dependencies all met for dep_context=non-requeueable deps ti=<TaskInstance: synth_stream_5min.run_synth_stream scheduled__2025-09-08T08:35:00+00:00 [queued]>
[2025-09-08T14:12:48.400+0530] {taskinstance.py:2076} INFO - Dependencies all met for dep_context=requeueable deps ti=<TaskInstance: synth_stream_5min.run_synth_stream scheduled__2025-09-08T08:35:00+00:00 [queued]>
[2025-09-08T14:12:48.400+0530] {taskinstance.py:2306} INFO - Starting attempt 1 of 2
[2025-09-08T14:12:49.154+0530] {taskinstance.py:2330} INFO - Executing <Task(BashOperator): run_synth_stream> on 2025-09-08 08:35:00+00:00
[2025-09-08T14:12:49.161+0530] {standard_task_runner.py:64} INFO - Started process 727597 to run task
[2025-09-08T14:12:49.163+0530] {standard_task_runner.py:90} INFO - Running: ['airflow', 'tasks', 'run', 'synth_stream_5min', 'run_synth_stream', 'scheduled__2025-09-08T08:35:00+00:00', '--job-id', '41', '--raw', '--subdir', 'DAGS_FOLDER/ecom_schedules.py', '--cfg-path', '/tmp/tmpbe2xlr0n']
[2025-09-08T14:12:49.165+0530] {standard_task_runner.py:91} INFO - Job 41: Subtask run_synth_stream
[2025-09-08T14:12:49.705+0530] {task_command.py:426} INFO - Running <TaskInstance: synth_stream_5min.run_synth_stream scheduled__2025-09-08T08:35:00+00:00 [running]> on host softsuave-ASUS-EXPERTCENTER-D700ME-D500ME
[2025-09-08T14:12:50.333+0530] {taskinstance.py:2648} INFO - Exporting env vars: AIRFLOW_CTX_DAG_OWNER='airflow' AIRFLOW_CTX_DAG_ID='synth_stream_5min' AIRFLOW_CTX_TASK_ID='run_synth_stream' AIRFLOW_CTX_EXECUTION_DATE='2025-09-08T08:35:00+00:00' AIRFLOW_CTX_TRY_NUMBER='1' AIRFLOW_CTX_DAG_RUN_ID='scheduled__2025-09-08T08:35:00+00:00'
[2025-09-08T14:12:50.334+0530] {taskinstance.py:430} INFO - ::endgroup::
[2025-09-08T14:12:50.334+0530] {subprocess.py:63} INFO - Tmp dir root location: /tmp
[2025-09-08T14:12:50.334+0530] {subprocess.py:75} INFO - Running command: ['/usr/bin/bash', '-c', 'bash /media/softsuave/DATA-HDD/DataEngineering/Apache_Airflow/scripts/synth/run_synth_stream.sh | cat']
[2025-09-08T14:12:50.340+0530] {subprocess.py:86} INFO - Output:
[2025-09-08T14:12:50.409+0530] {subprocess.py:93} INFO - [2025-09-08 14:12:50] üöÄ Starting Synthetic E-commerce Data Stream...
[2025-09-08T14:12:50.410+0530] {subprocess.py:93} INFO - ----------------------------------------------
[2025-09-08T14:12:50.410+0530] {subprocess.py:93} INFO -  Database   : ecom_db
[2025-09-08T14:12:50.410+0530] {subprocess.py:93} INFO -  User       : sa
[2025-09-08T14:12:50.410+0530] {subprocess.py:93} INFO -  Server     : localhost:1433
[2025-09-08T14:12:50.410+0530] {subprocess.py:93} INFO -  Interval   : 5 min
[2025-09-08T14:12:50.410+0530] {subprocess.py:93} INFO -  Orders     : 50
[2025-09-08T14:12:50.410+0530] {subprocess.py:93} INFO -  Clicks     : 100
[2025-09-08T14:12:50.410+0530] {subprocess.py:93} INFO -  Webhook    : http://localhost:5000/webhook
[2025-09-08T14:12:50.410+0530] {subprocess.py:93} INFO - ----------------------------------------------
[2025-09-08T14:12:50.410+0530] {subprocess.py:93} INFO - 
[2025-09-08T14:12:50.502+0530] {subprocess.py:93} INFO - [2025-09-08 14:12:50] üîß Activating virtual environment...
[2025-09-08T14:12:50.624+0530] {subprocess.py:93} INFO - [2025-09-08 14:12:50] üîç Checking database connection...
[2025-09-08T14:12:51.503+0530] {subprocess.py:93} INFO - ‚úÖ Database connection successful
[2025-09-08T14:12:51.514+0530] {subprocess.py:93} INFO - [2025-09-08 14:12:51] üîÑ Starting synthetic data stream...
[2025-09-08T14:12:51.514+0530] {subprocess.py:93} INFO - Press Ctrl+C to stop
[2025-09-08T14:12:51.515+0530] {subprocess.py:93} INFO - 
[2025-09-08T14:12:52.720+0530] {subprocess.py:93} INFO - 2025-09-08 14:12:52,720 INFO: Tables ensured/created (if needed).
[2025-09-08T14:12:53.134+0530] {subprocess.py:93} INFO - 2025-09-08 14:12:53,134 INFO: Customers: 1000 already present; skipping seeding.
[2025-09-08T14:12:53.138+0530] {subprocess.py:93} INFO - 2025-09-08 14:12:53,138 INFO: Products: 500 already present; skipping seeding.
[2025-09-08T14:12:53.139+0530] {subprocess.py:93} INFO - 2025-09-08 14:12:53,138 INFO: Running one-shot generation: orders=5000, sessions=3000
[2025-09-08T14:12:53.154+0530] {subprocess.py:93} INFO - /media/softsuave/DATA-HDD/DataEngineering/Apache_Airflow/src/synth_ecom_mssql_stream.py:397: RemovedIn20Warning: Deprecated API features detected! These feature(s) are not compatible with SQLAlchemy 2.0. To prevent incompatible upgrades prior to updating applications, ensure requirements files are pinned to "sqlalchemy<2.0". Set environment variable SQLALCHEMY_WARN_20=1 to show all deprecation warnings.  Set environment variable SQLALCHEMY_SILENCE_UBER_WARNING=1 to silence this message. (Background on SQLAlchemy 2.0 at: https://sqlalche.me/e/b8d9)
[2025-09-08T14:12:53.154+0530] {subprocess.py:93} INFO -   customers = [dict(r) for r in conn.execute(select(self.tables["customers"])).fetchall()]
[2025-09-08T14:12:53.162+0530] {subprocess.py:93} INFO - 2025-09-08 14:12:53,162 INFO: Generating 5000 orders (batch_size=200, force_order_date_now=False)...
[2025-09-08T14:12:53.706+0530] {subprocess.py:93} INFO - 2025-09-08 14:12:53,706 INFO: Flushed batch: orders=200 items=343
[2025-09-08T14:12:53.711+0530] {subprocess.py:93} INFO - 2025-09-08 14:12:53,711 WARNING: Failed to send webhook notification: HTTPConnectionPool(host='localhost', port=5000): Max retries exceeded with url: /webhook (Caused by NewConnectionError('<urllib3.connection.HTTPConnection object at 0x749d8f5951b0>: Failed to establish a new connection: [Errno 111] Connection refused'))
[2025-09-08T14:12:53.957+0530] {subprocess.py:93} INFO - 2025-09-08 14:12:53,956 INFO: Flushed batch: orders=200 items=337
[2025-09-08T14:12:53.959+0530] {subprocess.py:93} INFO - 2025-09-08 14:12:53,959 WARNING: Failed to send webhook notification: HTTPConnectionPool(host='localhost', port=5000): Max retries exceeded with url: /webhook (Caused by NewConnectionError('<urllib3.connection.HTTPConnection object at 0x749d8f4c9b10>: Failed to establish a new connection: [Errno 111] Connection refused'))
[2025-09-08T14:12:54.682+0530] {subprocess.py:93} INFO - 2025-09-08 14:12:54,682 INFO: Flushed batch: orders=200 items=331
[2025-09-08T14:12:54.685+0530] {subprocess.py:93} INFO - 2025-09-08 14:12:54,684 WARNING: Failed to send webhook notification: HTTPConnectionPool(host='localhost', port=5000): Max retries exceeded with url: /webhook (Caused by NewConnectionError('<urllib3.connection.HTTPConnection object at 0x749d8f4c9240>: Failed to establish a new connection: [Errno 111] Connection refused'))
[2025-09-08T14:12:54.932+0530] {subprocess.py:93} INFO - 2025-09-08 14:12:54,932 INFO: Flushed batch: orders=200 items=335
[2025-09-08T14:12:54.935+0530] {subprocess.py:93} INFO - 2025-09-08 14:12:54,935 WARNING: Failed to send webhook notification: HTTPConnectionPool(host='localhost', port=5000): Max retries exceeded with url: /webhook (Caused by NewConnectionError('<urllib3.connection.HTTPConnection object at 0x749d8f4e68c0>: Failed to establish a new connection: [Errno 111] Connection refused'))
[2025-09-08T14:12:55.336+0530] {subprocess.py:93} INFO - 2025-09-08 14:12:55,336 INFO: Flushed batch: orders=200 items=360
[2025-09-08T14:12:55.339+0530] {subprocess.py:93} INFO - 2025-09-08 14:12:55,339 WARNING: Failed to send webhook notification: HTTPConnectionPool(host='localhost', port=5000): Max retries exceeded with url: /webhook (Caused by NewConnectionError('<urllib3.connection.HTTPConnection object at 0x749d8f4baef0>: Failed to establish a new connection: [Errno 111] Connection refused'))
[2025-09-08T14:12:55.693+0530] {subprocess.py:93} INFO - 2025-09-08 14:12:55,693 INFO: Flushed batch: orders=200 items=351
[2025-09-08T14:12:55.697+0530] {subprocess.py:93} INFO - 2025-09-08 14:12:55,696 WARNING: Failed to send webhook notification: HTTPConnectionPool(host='localhost', port=5000): Max retries exceeded with url: /webhook (Caused by NewConnectionError('<urllib3.connection.HTTPConnection object at 0x749d8f4ca800>: Failed to establish a new connection: [Errno 111] Connection refused'))
[2025-09-08T14:12:56.043+0530] {subprocess.py:93} INFO - 2025-09-08 14:12:56,043 INFO: Flushed batch: orders=200 items=356
[2025-09-08T14:12:56.046+0530] {subprocess.py:93} INFO - 2025-09-08 14:12:56,046 WARNING: Failed to send webhook notification: HTTPConnectionPool(host='localhost', port=5000): Max retries exceeded with url: /webhook (Caused by NewConnectionError('<urllib3.connection.HTTPConnection object at 0x749d8f4f49a0>: Failed to establish a new connection: [Errno 111] Connection refused'))
[2025-09-08T14:12:56.360+0530] {subprocess.py:93} INFO - 2025-09-08 14:12:56,360 INFO: Flushed batch: orders=200 items=322
[2025-09-08T14:12:56.363+0530] {subprocess.py:93} INFO - 2025-09-08 14:12:56,363 WARNING: Failed to send webhook notification: HTTPConnectionPool(host='localhost', port=5000): Max retries exceeded with url: /webhook (Caused by NewConnectionError('<urllib3.connection.HTTPConnection object at 0x749d8f4f7940>: Failed to establish a new connection: [Errno 111] Connection refused'))
[2025-09-08T14:12:56.711+0530] {subprocess.py:93} INFO - 2025-09-08 14:12:56,711 INFO: Flushed batch: orders=200 items=351
[2025-09-08T14:12:56.714+0530] {subprocess.py:93} INFO - 2025-09-08 14:12:56,714 WARNING: Failed to send webhook notification: HTTPConnectionPool(host='localhost', port=5000): Max retries exceeded with url: /webhook (Caused by NewConnectionError('<urllib3.connection.HTTPConnection object at 0x749d8f4f7850>: Failed to establish a new connection: [Errno 111] Connection refused'))
[2025-09-08T14:12:57.312+0530] {subprocess.py:93} INFO - 2025-09-08 14:12:57,312 INFO: Flushed batch: orders=200 items=355
[2025-09-08T14:12:57.315+0530] {subprocess.py:93} INFO - 2025-09-08 14:12:57,315 WARNING: Failed to send webhook notification: HTTPConnectionPool(host='localhost', port=5000): Max retries exceeded with url: /webhook (Caused by NewConnectionError('<urllib3.connection.HTTPConnection object at 0x749d8f323880>: Failed to establish a new connection: [Errno 111] Connection refused'))
[2025-09-08T14:12:57.616+0530] {subprocess.py:93} INFO - 2025-09-08 14:12:57,616 INFO: Flushed batch: orders=200 items=374
[2025-09-08T14:12:57.619+0530] {subprocess.py:93} INFO - 2025-09-08 14:12:57,619 WARNING: Failed to send webhook notification: HTTPConnectionPool(host='localhost', port=5000): Max retries exceeded with url: /webhook (Caused by NewConnectionError('<urllib3.connection.HTTPConnection object at 0x749d8f4e5390>: Failed to establish a new connection: [Errno 111] Connection refused'))
[2025-09-08T14:12:57.805+0530] {subprocess.py:93} INFO - 2025-09-08 14:12:57,805 INFO: Flushed batch: orders=200 items=335
[2025-09-08T14:12:57.808+0530] {subprocess.py:93} INFO - 2025-09-08 14:12:57,808 WARNING: Failed to send webhook notification: HTTPConnectionPool(host='localhost', port=5000): Max retries exceeded with url: /webhook (Caused by NewConnectionError('<urllib3.connection.HTTPConnection object at 0x749d8f4e5c90>: Failed to establish a new connection: [Errno 111] Connection refused'))
[2025-09-08T14:12:58.607+0530] {subprocess.py:93} INFO - 2025-09-08 14:12:58,606 INFO: Flushed batch: orders=200 items=323
[2025-09-08T14:12:58.609+0530] {subprocess.py:93} INFO - 2025-09-08 14:12:58,609 WARNING: Failed to send webhook notification: HTTPConnectionPool(host='localhost', port=5000): Max retries exceeded with url: /webhook (Caused by NewConnectionError('<urllib3.connection.HTTPConnection object at 0x749d8f31b0a0>: Failed to establish a new connection: [Errno 111] Connection refused'))
[2025-09-08T14:12:58.865+0530] {subprocess.py:93} INFO - 2025-09-08 14:12:58,865 INFO: Flushed batch: orders=200 items=371
[2025-09-08T14:12:58.867+0530] {subprocess.py:93} INFO - 2025-09-08 14:12:58,867 WARNING: Failed to send webhook notification: HTTPConnectionPool(host='localhost', port=5000): Max retries exceeded with url: /webhook (Caused by NewConnectionError('<urllib3.connection.HTTPConnection object at 0x749d8f320340>: Failed to establish a new connection: [Errno 111] Connection refused'))
[2025-09-08T14:12:59.108+0530] {subprocess.py:93} INFO - 2025-09-08 14:12:59,108 INFO: Flushed batch: orders=200 items=361
[2025-09-08T14:12:59.113+0530] {subprocess.py:93} INFO - 2025-09-08 14:12:59,113 WARNING: Failed to send webhook notification: HTTPConnectionPool(host='localhost', port=5000): Max retries exceeded with url: /webhook (Caused by NewConnectionError('<urllib3.connection.HTTPConnection object at 0x749d8f4f7880>: Failed to establish a new connection: [Errno 111] Connection refused'))
[2025-09-08T14:12:59.468+0530] {subprocess.py:93} INFO - 2025-09-08 14:12:59,468 INFO: Flushed batch: orders=200 items=343
[2025-09-08T14:12:59.471+0530] {subprocess.py:93} INFO - 2025-09-08 14:12:59,471 WARNING: Failed to send webhook notification: HTTPConnectionPool(host='localhost', port=5000): Max retries exceeded with url: /webhook (Caused by NewConnectionError('<urllib3.connection.HTTPConnection object at 0x749d8f4f46a0>: Failed to establish a new connection: [Errno 111] Connection refused'))
[2025-09-08T14:13:00.037+0530] {subprocess.py:93} INFO - 2025-09-08 14:13:00,037 INFO: Flushed batch: orders=200 items=355
[2025-09-08T14:13:00.040+0530] {subprocess.py:93} INFO - 2025-09-08 14:13:00,040 WARNING: Failed to send webhook notification: HTTPConnectionPool(host='localhost', port=5000): Max retries exceeded with url: /webhook (Caused by NewConnectionError('<urllib3.connection.HTTPConnection object at 0x749d8f31a320>: Failed to establish a new connection: [Errno 111] Connection refused'))
[2025-09-08T14:13:00.328+0530] {subprocess.py:93} INFO - 2025-09-08 14:13:00,328 INFO: Flushed batch: orders=200 items=346
[2025-09-08T14:13:00.331+0530] {subprocess.py:93} INFO - 2025-09-08 14:13:00,331 WARNING: Failed to send webhook notification: HTTPConnectionPool(host='localhost', port=5000): Max retries exceeded with url: /webhook (Caused by NewConnectionError('<urllib3.connection.HTTPConnection object at 0x749d8f35b640>: Failed to establish a new connection: [Errno 111] Connection refused'))
[2025-09-08T14:13:00.611+0530] {subprocess.py:93} INFO - 2025-09-08 14:13:00,611 INFO: Flushed batch: orders=200 items=346
[2025-09-08T14:13:00.615+0530] {subprocess.py:93} INFO - 2025-09-08 14:13:00,615 WARNING: Failed to send webhook notification: HTTPConnectionPool(host='localhost', port=5000): Max retries exceeded with url: /webhook (Caused by NewConnectionError('<urllib3.connection.HTTPConnection object at 0x749d8f4f7700>: Failed to establish a new connection: [Errno 111] Connection refused'))
[2025-09-08T14:13:00.920+0530] {subprocess.py:93} INFO - 2025-09-08 14:13:00,920 INFO: Flushed batch: orders=200 items=327
[2025-09-08T14:13:00.923+0530] {subprocess.py:93} INFO - 2025-09-08 14:13:00,923 WARNING: Failed to send webhook notification: HTTPConnectionPool(host='localhost', port=5000): Max retries exceeded with url: /webhook (Caused by NewConnectionError('<urllib3.connection.HTTPConnection object at 0x749d8f321ba0>: Failed to establish a new connection: [Errno 111] Connection refused'))
[2025-09-08T14:13:01.171+0530] {subprocess.py:93} INFO - 2025-09-08 14:13:01,171 INFO: Flushed batch: orders=200 items=348
[2025-09-08T14:13:01.174+0530] {subprocess.py:93} INFO - 2025-09-08 14:13:01,174 WARNING: Failed to send webhook notification: HTTPConnectionPool(host='localhost', port=5000): Max retries exceeded with url: /webhook (Caused by NewConnectionError('<urllib3.connection.HTTPConnection object at 0x749d8f33faf0>: Failed to establish a new connection: [Errno 111] Connection refused'))
[2025-09-08T14:13:01.682+0530] {subprocess.py:93} INFO - 2025-09-08 14:13:01,682 INFO: Flushed batch: orders=200 items=342
[2025-09-08T14:13:01.686+0530] {subprocess.py:93} INFO - 2025-09-08 14:13:01,685 WARNING: Failed to send webhook notification: HTTPConnectionPool(host='localhost', port=5000): Max retries exceeded with url: /webhook (Caused by NewConnectionError('<urllib3.connection.HTTPConnection object at 0x749d8f35aaa0>: Failed to establish a new connection: [Errno 111] Connection refused'))
[2025-09-08T14:13:01.939+0530] {subprocess.py:93} INFO - 2025-09-08 14:13:01,939 INFO: Flushed batch: orders=200 items=347
[2025-09-08T14:13:01.943+0530] {subprocess.py:93} INFO - 2025-09-08 14:13:01,942 WARNING: Failed to send webhook notification: HTTPConnectionPool(host='localhost', port=5000): Max retries exceeded with url: /webhook (Caused by NewConnectionError('<urllib3.connection.HTTPConnection object at 0x749d8fb4cc10>: Failed to establish a new connection: [Errno 111] Connection refused'))
[2025-09-08T14:13:02.190+0530] {subprocess.py:93} INFO - 2025-09-08 14:13:02,190 INFO: Flushed batch: orders=200 items=336
[2025-09-08T14:13:02.193+0530] {subprocess.py:93} INFO - 2025-09-08 14:13:02,192 WARNING: Failed to send webhook notification: HTTPConnectionPool(host='localhost', port=5000): Max retries exceeded with url: /webhook (Caused by NewConnectionError('<urllib3.connection.HTTPConnection object at 0x749d8f596fe0>: Failed to establish a new connection: [Errno 111] Connection refused'))
[2025-09-08T14:13:02.658+0530] {subprocess.py:93} INFO - 2025-09-08 14:13:02,657 INFO: Flushed batch: orders=200 items=347
[2025-09-08T14:13:02.660+0530] {subprocess.py:93} INFO - 2025-09-08 14:13:02,660 WARNING: Failed to send webhook notification: HTTPConnectionPool(host='localhost', port=5000): Max retries exceeded with url: /webhook (Caused by NewConnectionError('<urllib3.connection.HTTPConnection object at 0x749d8f47e890>: Failed to establish a new connection: [Errno 111] Connection refused'))
[2025-09-08T14:13:02.661+0530] {subprocess.py:93} INFO - 2025-09-08 14:13:02,661 INFO: Generated 5000 orders
[2025-09-08T14:13:44.348+0530] {subprocess.py:93} INFO - 2025-09-08 14:13:44,348 INFO: Inserted 47943 clickstream events.
[2025-09-08T14:13:44.349+0530] {subprocess.py:93} INFO - 2025-09-08 14:13:44,349 WARNING: Failed to send webhook notification: HTTPConnectionPool(host='localhost', port=5000): Max retries exceeded with url: /webhook (Caused by NewConnectionError('<urllib3.connection.HTTPConnection object at 0x749d8fb4ce50>: Failed to establish a new connection: [Errno 111] Connection refused'))
[2025-09-08T14:13:46.090+0530] {subprocess.py:93} INFO - 2025-09-08 14:13:46,090 INFO: Validation done: orphans orders=0 items=0 inventory=0 mismatches=0
[2025-09-08T14:13:46.100+0530] {subprocess.py:93} INFO - 2025-09-08 14:13:46,100 INFO: Integrity report: {'orphan_orders': 0, 'orphan_order_items': 0, 'inventory_orphans': 0, 'order_amount_mismatches': []}
[2025-09-08T14:13:46.130+0530] {subprocess.py:93} INFO - [2025-09-08 14:13:46] ‚úÖ Synthetic data streaming completed successfully!
[2025-09-08T14:13:46.130+0530] {subprocess.py:97} INFO - Command exited with return code 0
[2025-09-08T14:13:46.131+0530] {taskinstance.py:441} INFO - ::group::Post task execution logs
[2025-09-08T14:13:46.387+0530] {taskinstance.py:1206} INFO - Marking task as SUCCESS. dag_id=synth_stream_5min, task_id=run_synth_stream, run_id=scheduled__2025-09-08T08:35:00+00:00, execution_date=20250908T083500, start_date=20250908T084248, end_date=20250908T084346
[2025-09-08T14:13:46.661+0530] {local_task_job_runner.py:243} INFO - Task exited with return code 0
[2025-09-08T14:13:46.678+0530] {taskinstance.py:3503} INFO - 0 downstream tasks scheduled from follow-on schedule check
[2025-09-08T14:13:46.679+0530] {local_task_job_runner.py:222} INFO - ::endgroup::
